Workbook
Name A1048577: #REF!
Name A1048577: #REF!
Name A1048577: #REF!
Name A1048577: #REF!
Name A1048577: #REF!
Name A1048577: #REF!
Name Ф80: #REF!
Name Ф80: #REF!
Name Ф80: #REF!
Name Ф80: #REF!
Name Ф80: #REF!
Name Ф80: #REF!

Sheet Зведена D5
A1: S
C3: ВІДОКРЕМЛЕНИЙ СТРУКТУРНИЙ ПІДРОЗДІЛ «ФАХОВИЙ КОЛЕДЖ НАФТОГАЗОВИХ ТЕХНОЛОГІЙ, ІНЖЕНЕРІЇ ТА ІНФРАСТРУКТУРИ СЕРВІСУ ОДЕСЬКОГО НАЦІОНАЛЬНОГО ТЕХНОЛОГІЧНОГО УНІВЕРСИТЕТУ»
C4: ЗВЕДЕНА ВІДОМІСТЬ
C5: Успішності студентів спеціальності D5 «Маркетинг»
C6: За І семестр 2025-2026 н.р.
C7: Група 26-1 курс І
C8: Б/К | D8: № п/п | E8: Прізвище, ім’я, по батькові | F8: Підсумкові оцінки дисциплін | T8: Середній бал
F9: Біологія Богданенко О.В. | G9: Всесвітня історія Мельничук С.А. | H9: Географія Наговська Т.С. | I9: Зарубіжна література Сербулова Ю.А. | J9: Захист України Лазар В.І. | K9: Іноземна мова Сербулова Ю.А. | L9: Інформатика Бєльдюгіна С.С. | M9: Історія України Левчук Т.Г. | N9: Математика Бондаренко О.С. | O9: Українська література Антропова Л.І. | P9: Українська мова Антропова Л.І. | Q9: Фізика Калюта Н.М. | R9: Фізична культура Возіян О.Г. | S9: Хімія Сахно Н.О.
C10: Б | D10: 1 | E10: Бондаренко Андрій Миколайович | F10: 4 | G10: 5 | H10: 9 | I10: 4 | J10: 5 | K10: 7 | L10: 8 | M10: н/а | N10: 10 | O10: 8 | P10: 7 | Q10: 8 | R10: 9 | S10: 5 | T10: =IF(COUNTIF($F10:S10,"=*")>0,IF($C10="К","-"," - "),IF(COUNTIF($F10:S10,"<4")>0,IF(C10="К","-"," - "),(IFERROR(AVERAGE($F10:S10),"Очікую")))) -> -
C11: Б | D11: 2 | E11: Гриценко Світлана Анатоліївна | F11: 8 | G11: 5 | H11: 7 | I11: 9 | J11: 6 | K11: 9 | L11: 11 | M11: н/а | N11: 8 | O11: 7 | P11: 7 | Q11: 11 | R11: 4 | S11: 5 | T11: =IF(COUNTIF($F11:S11,"=*")>0,IF($C11="К","-"," - "),IF(COUNTIF($F11:S11,"<4")>0,IF(C11="К","-"," - "),(IFERROR(AVERAGE($F11:S11),"Очікую")))) -> -
C12: К | D12: 3 | E12: Карєва Анастасія Сергіївна | F12: 11 | G12: 5 | H12: 4 | I12: н/а | J12: 4 | K12: 10 | L12: 11 | M12: 6 | N12: 8 | O12: 9 | P12: 10 | Q12: 10 | R12: н/а | S12: 9 | T12: =IF(COUNTIF($F12:S12,"=*")>0,IF($C12="К","-"," - "),IF(COUNTIF($F12:S12,"<4")>0,IF(C12="К","-"," - "),(IFERROR(AVERAGE($F12:S12),"Очікую")))) -> -
C13: К | D13: 4 | E13: Ковальчук Наталія Петрівна | F13: 5 | G13: 6 | H13: 6 | I13: 10 | J13: 7 | K13: 9 | L13: 5 | M13: 8 | N13: 10 | O13: 5 | P13: 8 | Q13: 6 | R13: 11 | S13: 11 | T13: =IF(COUNTIF($F13:S13,"=*")>0,IF($C13="К","-"," - "),IF(COUNTIF($F13:S13,"<4")>0,IF(C13="К","-"," - "),(IFERROR(AVERAGE($F13:S13),"Очікую")))) -> 7.6428571
C14: Б | D14: 5 | E14: Кравченко Денис Юрійович | F14: 6 | G14: 7 | H14: 4 | I14: 6 | J14: 7 | K14: н/а | L14: 6 | M14: 11 | N14: 10 | O14: н/а | P14: 5 | Q14: 10 | R14: 10 | S14: 5 | T14: =IF(COUNTIF($F14:S14,"=*")>0,IF($C14="К","-"," - "),IF(COUNTIF($F14:S14,"<4")>0,IF(C14="К","-"," - "),(IFERROR(AVERAGE($F14:S14),"Очікую")))) -> -
C15: К | D15: 6 | E15: Лєрманова Олена Євгенівна | F15: 8 | G15: 4 | H15: 5 | I15: 11 | J15: 6 | K15: 8 | L15: 8 | M15: 10 | N15: 7 | O15: н/а | P15: 5 | Q15: н/а | R15: 11 | S15: н/а | T15: =IF(COUNTIF($F15:S15,"=*")>0,IF($C15="К","-"," - "),IF(COUNTIF($F15:S15,"<4")>0,IF(C15="К","-"," - "),(IFERROR(AVERAGE($F15:S15),"Очікую")))) -> -
C16: Б | D16: 7 | E16: Лисенко Олена Володимирівна | F16: 8 | G16: 8 | H16: н/а | I16: 10 | J16: 8 | K16: 8 | L16: 4 | M16: 8 | N16: 8 | O16: н/а | P16: н/а | Q16: 5 | R16: 10 | S16: 10 | T16: =IF(COUNTIF($F16:S16,"=*")>0,IF($C16="К","-"," - "),IF(COUNTIF($F16:S16,"<4")>0,IF(C16="К","-"," - "),(IFERROR(AVERAGE($F16:S16),"Очікую")))) -> -
C17: К | D17: 8 | E17: Мельниченко Софія Ігорівна | F17: 8 | G17: 7 | H17: 8 | I17: 11 | J17: 9 | K17: 10 | L17: 10 | M17: 9 | N17: 6 | O17: 5 | P17: 7 | Q17: 8 | R17: 10 | S17: 4 | T17: =IF(COUNTIF($F17:S17,"=*")>0,IF($C17="К","-"," - "),IF(COUNTIF($F17:S17,"<4")>0,IF(C17="К","-"," - "),(IFERROR(AVERAGE($F17:S17),"Очікую")))) -> 8
C18: К | D18: 9 | E18: Мороз Віктор Васильович | F18: 9 | G18: 4 | H18: н/а | I18: 9 | J18: 6 | K18: н/а | L18: 11 | M18: 11 | N18: 10 | O18: 8 | P18: 11 | Q18: 9 | R18: 7 | S18: 11 | T18: =IF(COUNTIF($F18:S18,"=*")>0,IF($C18="К","-"," - "),IF(COUNTIF($F18:S18,"<4")>0,IF(C18="К","-"," - "),(IFERROR(AVERAGE($F18:S18),"Очікую")))) -> -
C19: Б | D19: 10 | E19: Поліщук Артем Валерійович | F19: 4 | G19: 7 | H19: 9 | I19: 9 | J19: 6 | K19: 8 | L19: 8 | M19: 10 | N19: 4 | O19: 11 | P19: 7 | Q19: 8 | R19: 10 | S19: 8 | T19: =IF(COUNTIF($F19:S19,"=*")>0,IF($C19="К","-"," - "),IF(COUNTIF($F19:S19,"<4")>0,IF(C19="К","-"," - "),(IFERROR(AVERAGE($F19:S19),"Очікую")))) -> 7.7857143
C20: Б | D20: 11 | E20: Присяжнюк Аміна Михайлівна | F20: 11 | G20: 4 | H20: 10 | I20: 5 | J20: 8 | K20: 11 | L20: 9 | M20: 5 | N20: 8 | O20: 4 | P20: 7 | Q20: 11 | R20: 8 | S20: 5 | T20: =IF(COUNTIF($F20:S20,"=*")>0,IF($C20="К","-"," - "),IF(COUNTIF($F20:S20,"<4")>0,IF(C20="К","-"," - "),(IFERROR(AVERAGE($F20:S20),"Очікую")))) -> 7.5714286
C21: К | D21: 12 | E21: Савельєв Олександр Вячеславович | F21: 8 | G21: 11 | H21: 5 | I21: 8 | J21: 5 | K21: 5 | L21: 8 | M21: 6 | N21: 11 | O21: 9 | P21: 8 | Q21: 8 | R21: 8 | S21: 8 | T21: =IF(COUNTIF($F21:S21,"=*")>0,IF($C21="К","-"," - "),IF(COUNTIF($F21:S21,"<4")>0,IF(C21="К","-"," - "),(IFERROR(AVERAGE($F21:S21),"Очікую")))) -> 7.7142857
C22: К | D22: 13 | E22: Савченко Марія Олегівна | F22: 6 | G22: н/а | H22: 9 | I22: 9 | J22: н/а | K22: 8 | L22: 11 | M22: 5 | N22: 6 | O22: 4 | P22: 11 | Q22: 9 | R22: 6 | S22: 8 | T22: =IF(COUNTIF($F22:S22,"=*")>0,IF($C22="К","-"," - "),IF(COUNTIF($F22:S22,"<4")>0,IF(C22="К","-"," - "),(IFERROR(AVERAGE($F22:S22),"Очікую")))) -> -
C23: Б | D23: 14 | E23: Самойлова Яна Вячеславівна | F23: 8 | G23: 4 | H23: 9 | I23: 7 | J23: 5 | K23: 8 | L23: 5 | M23: 9 | N23: 4 | O23: 8 | P23: 8 | Q23: 6 | R23: 9 | S23: 9 | T23: =IF(COUNTIF($F23:S23,"=*")>0,IF($C23="К","-"," - "),IF(COUNTIF($F23:S23,"<4")>0,IF(C23="К","-"," - "),(IFERROR(AVERAGE($F23:S23),"Очікую")))) -> 7.0714286
C24: Б | D24: 15 | E24: Стегарь Евеліна Сергіївна | F24: 5 | G24: 6 | H24: 6 | I24: н/а | J24: 10 | K24: 9 | L24: 11 | M24: 11 | N24: 11 | O24: 10 | P24: 11 | Q24: 10 | R24: 11 | S24: 8 | T24: =IF(COUNTIF($F24:S24,"=*")>0,IF($C24="К","-"," - "),IF(COUNTIF($F24:S24,"<4")>0,IF(C24="К","-"," - "),(IFERROR(AVERAGE($F24:S24),"Очікую")))) -> -
C25: К | D25: 16 | E25: Ткаченко Ірина Сергіївна | F25: 10 | G25: 10 | H25: 8 | I25: 9 | J25: 9 | K25: 9 | L25: 4 | M25: 9 | N25: 8 | O25: 10 | P25: 8 | Q25: 11 | R25: 8 | S25: 8 | T25: =IF(COUNTIF($F25:S25,"=*")>0,IF($C25="К","-"," - "),IF(COUNTIF($F25:S25,"<4")>0,IF(C25="К","-"," - "),(IFERROR(AVERAGE($F25:S25),"Очікую")))) -> 8.6428571
C26: Б | D26: 17 | E26: Цвєтков Андрій Геннадійович | F26: 7 | G26: н/а | H26: 4 | I26: 7 | J26: 8 | K26: 5 | L26: 10 | M26: 4 | N26: 8 | O26: 8 | P26: 6 | Q26: 4 | R26: 7 | S26: 10 | T26: =IF(COUNTIF($F26:S26,"=*")>0,IF($C26="К","-"," - "),IF(COUNTIF($F26:S26,"<4")>0,IF(C26="К","-"," - "),(IFERROR(AVERAGE($F26:S26),"Очікую")))) -> -
C27: Б | D27: 18 | E27: Шевченко Олександр Іванович | F27: 9 | G27: 7 | H27: 11 | I27: н/а | J27: 10 | K27: 8 | L27: 8 | M27: 5 | N27: 7 | O27: 7 | P27: 4 | Q27: 8 | R27: 4 | S27: 8 | T27: =IF(COUNTIF($F27:S27,"=*")>0,IF($C27="К","-"," - "),IF(COUNTIF($F27:S27,"<4")>0,IF(C27="К","-"," - "),(IFERROR(AVERAGE($F27:S27),"Очікую")))) -> -
E28: Середній бал успішності з дисципліни | F28: =IF(SUM(F$10:F27)=0,IF(COUNTA(F$10:F27)=0,"Очікую",0),SUM(F$10:F27)/$D27) -> 7.5 | G28: =IF(SUM(G$10:G27)=0,IF(COUNTA(G$10:G27)=0,"Очікую",0),SUM(G$10:G27)/$D27) -> 5.5555556 | H28: =IF(SUM(H$10:H27)=0,IF(COUNTA(H$10:H27)=0,"Очікую",0),SUM(H$10:H27)/$D27) -> 6.3333333 | I28: =IF(SUM(I$10:I27)=0,IF(COUNTA(I$10:I27)=0,"Очікую",0),SUM(I$10:I27)/$D27) -> 6.8888889 | J28: =IF(SUM(J$10:J27)=0,IF(COUNTA(J$10:J27)=0,"Очікую",0),SUM(J$10:J27)/$D27) -> 6.6111111 | K28: =IF(SUM(K$10:K27)=0,IF(COUNTA(K$10:K27)=0,"Очікую",0),SUM(K$10:K27)/$D27) -> 7.3333333 | L28: =IF(SUM(L$10:L27)=0,IF(COUNTA(L$10:L27)=0,"Очікую",0),SUM(L$10:L27)/$D27) -> 8.2222222 | M28: =IF(SUM(M$10:M27)=0,IF(COUNTA(M$10:M27)=0,"Очікую",0),SUM(M$10:M27)/$D27) -> 7.0555556 | ... S28: =IF(SUM(S$10:S27)=0,IF(COUNTA(S$10:S27)=0,"Очікую",0),SUM(S$10:S27)/$D27) -> 7.3333333 | T28: =IFERROR(AVERAGE($F28:S28),"Очікую") -> 7.1547619
E29: Абсолютна успішність | F29: =IF(SUM(F$10:F27)=0,IF(COUNTA(F$10:F27)=0,"Очікую",0),IF(COUNTIF(F$10:F27,">=4")=0,0,COUNTIF(F$10:F27,">=4")/$D27*100)) -> 100 | G29: =IF(SUM(G$10:G27)=0,IF(COUNTA(G$10:G27)=0,"Очікую",0),IF(COUNTIF(G$10:G27,">=4")=0,0,COUNTIF(G$10:G27,">=4")/$D27*100)) -> 88.888889 | H29: =IF(SUM(H$10:H27)=0,IF(COUNTA(H$10:H27)=0,"Очікую",0),IF(COUNTIF(H$10:H27,">=4")=0,0,COUNTIF(H$10:H27,">=4")/$D27*100)) -> 88.888889 | I29: =IF(SUM(I$10:I27)=0,IF(COUNTA(I$10:I27)=0,"Очікую",0),IF(COUNTIF(I$10:I27,">=4")=0,0,COUNTIF(I$10:I27,">=4")/$D27*100)) -> 83.333333 | J29: =IF(SUM(J$10:J27)=0,IF(COUNTA(J$10:J27)=0,"Очікую",0),IF(COUNTIF(J$10:J27,">=4")=0,0,COUNTIF(J$10:J27,">=4")/$D27*100)) -> 94.444444 | K29: =IF(SUM(K$10:K27)=0,IF(COUNTA(K$10:K27)=0,"Очікую",0),IF(COUNTIF(K$10:K27,">=4")=0,0,COUNTIF(K$10:K27,">=4")/$D27*100)) -> 88.888889 | L29: =IF(SUM(L$10:L27)=0,IF(COUNTA(L$10:L27)=0,"Очікую",0),IF(COUNTIF(L$10:L27,">=4")=0,0,COUNTIF(L$10:L27,">=4")/$D27*100)) -> 100 | M29: =IF(SUM(M$10:M27)=0,IF(COUNTA(M$10:M27)=0,"Очікую",0),IF(COUNTIF(M$10:M27,">=4")=0,0,COUNTIF(M$10:M27,">=4")/$D27*100)) -> 88.888889 | ... S29: =IF(SUM(S$10:S27)=0,IF(COUNTA(S$10:S27)=0,"Очікую",0),IF(COUNTIF(S$10:S27,">=4")=0,0,COUNTIF(S$10:S27,">=4")/$D27*100)) -> 94.444444
E30: Якісна успішність | F30: =IF(SUM(F$10:F27)=0,IF(COUNTA(F$10:F27)=0,"Очікую",0),IF(COUNTIF(F$10:F27,">=7")=0,0,COUNTIF(F$10:F27,">=7")/$D27*100)) -> 66.666667 | G30: =IF(SUM(G$10:G27)=0,IF(COUNTA(G$10:G27)=0,"Очікую",0),IF(COUNTIF(G$10:G27,">=7")=0,0,COUNTIF(G$10:G27,">=7")/$D27*100)) -> 38.888889 | H30: =IF(SUM(H$10:H27)=0,IF(COUNTA(H$10:H27)=0,"Очікую",0),IF(COUNTIF(H$10:H27,">=7")=0,0,COUNTIF(H$10:H27,">=7")/$D27*100)) -> 50 | I30: =IF(SUM(I$10:I27)=0,IF(COUNTA(I$10:I27)=0,"Очікую",0),IF(COUNTIF(I$10:I27,">=7")=0,0,COUNTIF(I$10:I27,">=7")/$D27*100)) -> 66.666667 | J30: =IF(SUM(J$10:J27)=0,IF(COUNTA(J$10:J27)=0,"Очікую",0),IF(COUNTIF(J$10:J27,">=7")=0,0,COUNTIF(J$10:J27,">=7")/$D27*100)) -> 50 | K30: =IF(SUM(K$10:K27)=0,IF(COUNTA(K$10:K27)=0,"Очікую",0),IF(COUNTIF(K$10:K27,">=7")=0,0,COUNTIF(K$10:K27,">=7")/$D27*100)) -> 77.777778 | L30: =IF(SUM(L$10:L27)=0,IF(COUNTA(L$10:L27)=0,"Очікую",0),IF(COUNTIF(L$10:L27,">=7")=0,0,COUNTIF(L$10:L27,">=7")/$D27*100)) -> 72.222222 | M30: =IF(SUM(M$10:M27)=0,IF(COUNTA(M$10:M27)=0,"Очікую",0),IF(COUNTIF(M$10:M27,">=7")=0,0,COUNTIF(M$10:M27,">=7")/$D27*100)) -> 55.555556 | ... S30: =IF(SUM(S$10:S27)=0,IF(COUNTA(S$10:S27)=0,"Очікую",0),IF(COUNTIF(S$10:S27,">=7")=0,0,COUNTIF(S$10:S27,">=7")/$D27*100)) -> 66.666667
E31: Абсолютна успішність по групі | F31: =IFERROR(AVERAGE(F29:S29),"Очікую") -> 92.460317
E32: Якісна успішність по групі | F32: =IFERROR(AVERAGE($F30:S30),"Очікую") -> 64.68254
E33: Кількість бюджетників | F33: =IF(COUNTIF($C$10:$C27,"=Б")=0,IF(COUNTIF($C$10:$C27,"=К")=0,"Очікую",0),COUNTIF($C$10:$C27,"=Б")) -> 10
E34: Кількість контрактників | F34: =IF(COUNTIF($C$10:$C27,"=К")=0,IF(COUNTIF($C$10:$C27,"=Б")=0,"Очікую",0),COUNTIF($C$10:$C27,"=К")) -> 8 | H34: Класний керівник | P34: Ірина ДОПІРА
E35: Кількість соціального контингенту | F35: 0
E36: Вийшли на стипендію | F36: =IF(F33="Очікую","Очікую",IF(F33-COUNTIF($T$10:$T27," - ")<ROUNDDOWN(F33*0.4,0),F33-COUNTIF($T$10:$T27," - "),ROUNDDOWN(F33*0.4,0))) -> 3 | H36: Завідувач відділення ПЗСО | P36: Маргарита БРІТІКОВА

Sheet Зведена D7
A1: S
C3: ВІДОКРЕМЛЕНИЙ СТРУКТУРНИЙ ПІДРОЗДІЛ «ФАХОВИЙ КОЛЕДЖ НАФТОГАЗОВИХ ТЕХНОЛОГІЙ, ІНЖЕНЕРІЇ ТА ІНФРАСТРУКТУРИ СЕРВІСУ ОДЕСЬКОГО НАЦІОНАЛЬНОГО ТЕХНОЛОГІЧНОГО УНІВЕРСИТЕТУ»
C4: ЗВЕДЕНА ВІДОМІСТЬ
C5: Успішності студентів спеціальності D7 «Торгівля»
C6: За І семестр 2025-2026 н.р.
C7: Група 26-1 курс І
C8: Б/К | D8: № п/п | E8: Прізвище, ім’я, по батькові | F8: Підсумкові оцінки дисциплін | T8: Середній бал
F9: Біологія Богданенко О.В. | G9: Всесвітня історія Мельничук С.А. | H9: Географія Наговська Т.С. | I9: Зарубіжна література Сербулова Ю.А. | J9: Захист України Лазар В.І. | K9: Іноземна мова Сербулова Ю.А. | L9: Інформатика Бєльдюгіна С.С. | M9: Історія України Левчук Т.Г. | N9: Математика Бондаренко О.С. | O9: Українська література Антропова Л.І. | P9: Українська мова Антропова Л.І. | Q9: Фізика Калюта Н.М. | R9: Фізична культура Возіян О.Г. | S9: Хімія Сахно Н.О.
C10: Б | D10: 1 | E10: Безуглий Юрій Віталійович | F10: 10 | G10: 11 | H10: 6 | I10: 9 | J10: 4 | K10: 8 | L10: 5 | M10: 6 | N10: 6 | O10: 5 | P10: 9 | Q10: 8 | R10: 7 | S10: 5 | T10: =IF(COUNTIF($F10:S10,"=*")>0,IF($C10="К","-"," - "),IF(COUNTIF($F10:S10,"<4")>0,IF(C10="К","-"," - "),(IFERROR(AVERAGE($F10:S10),"Очікую")))) -> 7.0714286
C11: Б | D11: 2 | E11: Білан Інна Євгенівна | F11: 11 | G11: 8 | H11: 6 | I11: 6 | J11: 5 | K11: 6 | L11: 8 | M11: 10 | N11: 7 | O11: 5 | P11: 4 | Q11: 8 | R11: 4 | S11: 7 | T11: =IF(COUNTIF($F11:S11,"=*")>0,IF($C11="К","-"," - "),IF(COUNTIF($F11:S11,"<4")>0,IF(C11="К","-"," - "),(IFERROR(AVERAGE($F11:S11),"Очікую")))) -> 6.7857143
C12: К | D12: 3 | E12: Білик Анастасія Павлівна | F12: 6 | G12: 5 | H12: 8 | I12: н/а | J12: н/а | K12: 6 | L12: 7 | M12: 7 | N12: 10 | O12: 5 | P12: 9 | Q12: 6 | R12: 8 | S12: 7 | T12: =IF(COUNTIF($F12:S12,"=*")>0,IF($C12="К","-"," - "),IF(COUNTIF($F12:S12,"<4")>0,IF(C12="К","-"," - "),(IFERROR(AVERAGE($F12:S12),"Очікую")))) -> -
C13: К | D13: 4 | E13: Волошин Кирило Миколайович | F13: 9 | G13: 8 | H13: 8 | I13: 4 | J13: 4 | K13: 7 | L13: 9 | M13: 7 | N13: 4 | O13: 8 | P13: 8 | Q13: 5 | R13: 10 | S13: 8 | T13: =IF(COUNTIF($F13:S13,"=*")>0,IF($C13="К","-"," - "),IF(COUNTIF($F13:S13,"<4")>0,IF(C13="К","-"," - "),(IFERROR(AVERAGE($F13:S13),"Очікую")))) -> 7.0714286
C14: Б | D14: 5 | E14: Гаврилюк Маргарита Тимофіївна | F14: 4 | G14: 8 | H14: 8 | I14: 10 | J14: 6 | K14: 8 | L14: 10 | M14: 8 | N14: 8 | O14: 8 | P14: 4 | Q14: 8 | R14: 10 | S14: 8 | T14: =IF(COUNTIF($F14:S14,"=*")>0,IF($C14="К","-"," - "),IF(COUNTIF($F14:S14,"<4")>0,IF(C14="К","-"," - "),(IFERROR(AVERAGE($F14:S14),"Очікую")))) -> 7.7142857
C15: Б | D15: 6 | E15: Гончар Марія Сергіївна | F15: н/а | G15: 8 | H15: 4 | I15: 6 | J15: 4 | K15: 7 | L15: 9 | M15: 11 | N15: 7 | O15: 4 | P15: 5 | Q15: 6 | R15: 8 | S15: 8 | T15: =IF(COUNTIF($F15:S15,"=*")>0,IF($C15="К","-"," - "),IF(COUNTIF($F15:S15,"<4")>0,IF(C15="К","-"," - "),(IFERROR(AVERAGE($F15:S15),"Очікую")))) -> -
C16: Б | D16: 7 | E16: Дяченко Катерина Дмитрівна | F16: 8 | G16: 6 | H16: 5 | I16: 11 | J16: 7 | K16: 7 | L16: 6 | M16: 10 | N16: 7 | O16: 6 | P16: 6 | Q16: 4 | R16: 6 | S16: 6 | T16: =IF(COUNTIF($F16:S16,"=*")>0,IF($C16="К","-"," - "),IF(COUNTIF($F16:S16,"<4")>0,IF(C16="К","-"," - "),(IFERROR(AVERAGE($F16:S16),"Очікую")))) -> 6.7857143
C17: Б | D17: 8 | E17: Зінченко Богдан Романович | F17: 9 | G17: 9 | H17: 8 | I17: 6 | J17: 10 | K17: 11 | L17: 6 | M17: 11 | N17: 7 | O17: 7 | P17: 10 | Q17: 6 | R17: 7 | S17: 8 | T17: =IF(COUNTIF($F17:S17,"=*")>0,IF($C17="К","-"," - "),IF(COUNTIF($F17:S17,"<4")>0,IF(C17="К","-"," - "),(IFERROR(AVERAGE($F17:S17),"Очікую")))) -> 8.2142857
C18: Б | D18: 9 | E18: Клименко Алла Михайлівна | F18: 4 | G18: 4 | H18: 11 | I18: 8 | J18: 5 | K18: 10 | L18: 8 | M18: 5 | N18: 9 | O18: 6 | P18: 4 | Q18: 10 | R18: 8 | S18: 8 | T18: =IF(COUNTIF($F18:S18,"=*")>0,IF($C18="К","-"," - "),IF(COUNTIF($F18:S18,"<4")>0,IF(C18="К","-"," - "),(IFERROR(AVERAGE($F18:S18),"Очікую")))) -> 7.1428571
C19: К | D19: 10 | E19: Козак Дмитро Вікторович | F19: 9 | G19: 10 | H19: 8 | I19: 8 | J19: 4 | K19: 6 | L19: 8 | M19: 6 | N19: 6 | O19: 10 | P19: 6 | Q19: 6 | R19: 11 | S19: 7 | T19: =IF(COUNTIF($F19:S19,"=*")>0,IF($C19="К","-"," - "),IF(COUNTIF($F19:S19,"<4")>0,IF(C19="К","-"," - "),(IFERROR(AVERAGE($F19:S19),"Очікую")))) -> 7.5
C20: Б | D20: 11 | E20: Козаченко Роман Анатолійович | F20: 9 | G20: 9 | H20: 6 | I20: 5 | J20: 10 | K20: 6 | L20: 7 | M20: 7 | N20: 6 | O20: 7 | P20: 8 | Q20: 10 | R20: 6 | S20: 7 | T20: =IF(COUNTIF($F20:S20,"=*")>0,IF($C20="К","-"," - "),IF(COUNTIF($F20:S20,"<4")>0,IF(C20="К","-"," - "),(IFERROR(AVERAGE($F20:S20),"Очікую")))) -> 7.3571429
C21: Б | D21: 12 | E21: Корнієнко Владислава Іванівна | F21: 10 | G21: 6 | H21: 5 | I21: н/а | J21: 5 | K21: 8 | L21: 6 | M21: 7 | N21: 8 | O21: 10 | P21: 5 | Q21: 9 | R21: 8 | S21: 5 | T21: =IF(COUNTIF($F21:S21,"=*")>0,IF($C21="К","-"," - "),IF(COUNTIF($F21:S21,"<4")>0,IF(C21="К","-"," - "),(IFERROR(AVERAGE($F21:S21),"Очікую")))) -> -
C22: Б | D22: 13 | E22: Куліш Дарина Олегівна | F22: 7 | G22: 8 | H22: 11 | I22: 4 | J22: 9 | K22: 5 | L22: 8 | M22: 6 | N22: 8 | O22: 8 | P22: 11 | Q22: 7 | R22: 11 | S22: 8 | T22: =IF(COUNTIF($F22:S22,"=*")>0,IF($C22="К","-"," - "),IF(COUNTIF($F22:S22,"<4")>0,IF(C22="К","-"," - "),(IFERROR(AVERAGE($F22:S22),"Очікую")))) -> 7.9285714
C23: К | D23: 14 | E23: Левченко Вікторія Василівна | F23: 8 | G23: 8 | H23: 9 | I23: 6 | J23: 10 | K23: 10 | L23: 9 | M23: н/а | N23: 11 | O23: 11 | P23: 7 | Q23: 4 | R23: 10 | S23: 6 | T23: =IF(COUNTIF($F23:S23,"=*")>0,IF($C23="К","-"," - "),IF(COUNTIF($F23:S23,"<4")>0,IF(C23="К","-"," - "),(IFERROR(AVERAGE($F23:S23),"Очікую")))) -> -
C24: Б | D24: 15 | E24: Мельничук Людмила Петрівна | F24: 8 | G24: 7 | H24: 8 | I24: 8 | J24: 6 | K24: 7 | L24: 6 | M24: 7 | N24: 6 | O24: 9 | P24: 5 | Q24: 4 | R24: 5 | S24: 5 | T24: =IF(COUNTIF($F24:S24,"=*")>0,IF($C24="К","-"," - "),IF(COUNTIF($F24:S24,"<4")>0,IF(C24="К","-"," - "),(IFERROR(AVERAGE($F24:S24),"Очікую")))) -> 6.5
C25: К | D25: 16 | E25: Нікітенко Владислав Юрійович | F25: 8 | G25: 9 | H25: 9 | I25: 8 | J25: 8 | K25: 9 | L25: 10 | M25: 5 | N25: 10 | O25: 8 | P25: 5 | Q25: 5 | R25: 5 | S25: 6 | T25: =IF(COUNTIF($F25:S25,"=*")>0,IF($C25="К","-"," - "),IF(COUNTIF($F25:S25,"<4")>0,IF(C25="К","-"," - "),(IFERROR(AVERAGE($F25:S25),"Очікую")))) -> 7.5
C26: К | D26: 17 | E26: Орленко Арсен Романович | F26: 9 | G26: 7 | H26: 9 | I26: 8 | J26: 11 | K26: 8 | L26: 9 | M26: 6 | N26: 9 | O26: 6 | P26: 10 | Q26: 5 | R26: 11 | S26: 9 | T26: =IF(COUNTIF($F26:S26,"=*")>0,IF($C26="К","-"," - "),IF(COUNTIF($F26:S26,"<4")>0,IF(C26="К","-"," - "),(IFERROR(AVERAGE($F26:S26),"Очікую")))) -> 8.3571429
C27: Б | D27: 18 | E27: Остапчук Максим Олександрович | F27: 8 | G27: 6 | H27: 9 | I27: 11 | J27: 4 | K27: 4 | L27: 8 | M27: 11 | N27: 9 | O27: 10 | P27: 7 | Q27: 9 | R27: 10 | S27: 9 | T27: =IF(COUNTIF($F27:S27,"=*")>0,IF($C27="К","-"," - "),IF(COUNTIF($F27:S27,"<4")>0,IF(C27="К","-"," - "),(IFERROR(AVERAGE($F27:S27),"Очікую")))) -> 8.2142857
C28: К | D28: 19 | E28: Паламарчук Оксана Валентинівна | F28: 6 | G28: 9 | H28: 6 | I28: 8 | J28: 8 | K28: 5 | L28: 7 | M28: 8 | N28: 7 | O28: 9 | P28: 11 | Q28: 10 | R28: 7 | S28: н/а | T28: =IF(COUNTIF($F28:S28,"=*")>0,IF($C28="К","-"," - "),IF(COUNTIF($F28:S28,"<4")>0,IF(C28="К","-"," - "),(IFERROR(AVERAGE($F28:S28),"Очікую")))) -> -
C29: К | D29: 20 | E29: Панченко Тетяна Ігорівна | F29: 7 | G29: 10 | H29: 10 | I29: 4 | J29: 8 | K29: 7 | L29: 8 | M29: 5 | N29: 10 | O29: 10 | P29: 9 | Q29: 6 | R29: 11 | S29: 6 | T29: =IF(COUNTIF($F29:S29,"=*")>0,IF($C29="К","-"," - "),IF(COUNTIF($F29:S29,"<4")>0,IF(C29="К","-"," - "),(IFERROR(AVERAGE($F29:S29),"Очікую")))) -> 7.9285714
C30: К | D30: 21 | E30: Петренко Назар Борисович | F30: 8 | G30: 5 | H30: 7 | I30: 10 | J30: 7 | K30: 8 | L30: 6 | M30: 5 | N30: 8 | O30: 5 | P30: 10 | Q30: 11 | R30: 10 | S30: 10 | T30: =IF(COUNTIF($F30:S30,"=*")>0,IF($C30="К","-"," - "),IF(COUNTIF($F30:S30,"<4")>0,IF(C30="К","-"," - "),(IFERROR(AVERAGE($F30:S30),"Очікую")))) -> 7.8571429
C31: К | D31: 22 | E31: Романенко Юлія Андріївна | F31: 4 | G31: 4 | H31: н/а | I31: 4 | J31: 8 | K31: н/а | L31: 6 | M31: 7 | N31: 10 | O31: 8 | P31: н/а | Q31: 7 | R31: 10 | S31: 11 | T31: =IF(COUNTIF($F31:S31,"=*")>0,IF($C31="К","-"," - "),IF(COUNTIF($F31:S31,"<4")>0,IF(C31="К","-"," - "),(IFERROR(AVERAGE($F31:S31),"Очікую")))) -> -
C32: Б | D32: 23 | E32: Семенюк Марина Григорівна | F32: 5 | G32: 9 | H32: 10 | I32: 9 | J32: 5 | K32: 4 | L32: 6 | M32: 9 | N32: 8 | O32: 8 | P32: 7 | Q32: 7 | R32: 9 | S32: 9 | T32: =IF(COUNTIF($F32:S32,"=*")>0,IF($C32="К","-"," - "),IF(COUNTIF($F32:S32,"<4")>0,IF(C32="К","-"," - "),(IFERROR(AVERAGE($F32:S32),"Очікую")))) -> 7.5
C33: Б | D33: 24 | E33: Сидоренко Ілля Артемович | F33: 8 | G33: 9 | H33: 9 | I33: 8 | J33: 10 | K33: 5 | L33: 10 | M33: 8 | N33: 10 | O33: 10 | P33: 8 | Q33: 8 | R33: 10 | S33: 10 | T33: =IF(COUNTIF($F33:S33,"=*")>0,IF($C33="К","-"," - "),IF(COUNTIF($F33:S33,"<4")>0,IF(C33="К","-"," - "),(IFERROR(AVERAGE($F33:S33),"Очікую")))) -> 8.7857143
C34: К | D34: 25 | E34: Тимченко Олексій Вікторович | F34: н/а | G34: 9 | H34: 11 | I34: н/а | J34: 11 | K34: 6 | L34: 10 | M34: 5 | N34: 8 | O34: 8 | P34: 9 | Q34: 5 | R34: н/а | S34: 9 | T34: =IF(COUNTIF($F34:S34,"=*")>0,IF($C34="К","-"," - "),IF(COUNTIF($F34:S34,"<4")>0,IF(C34="К","-"," - "),(IFERROR(AVERAGE($F34:S34),"Очікую")))) -> -
C35: К | D35: 26 | E35: Харченко Ганна Олексіївна | F35: 8 | G35: 4 | H35: 4 | I35: 9 | J35: 6 | K35: 10 | L35: н/а | M35: 5 | N35: 6 | O35: 10 | P35: 10 | Q35: н/а | R35: 11 | S35: 8 | T35: =IF(COUNTIF($F35:S35,"=*")>0,IF($C35="К","-"," - "),IF(COUNTIF($F35:S35,"<4")>0,IF(C35="К","-"," - "),(IFERROR(AVERAGE($F35:S35),"Очікую")))) -> -
C36: К | D36: 27 | E36: Черненко Вадим Павлович | F36: 8 | G36: 7 | H36: 8 | I36: 8 | J36: 6 | K36: 4 | L36: 5 | M36: 5 | N36: 8 | O36: 6 | P36: 6 | Q36: 5 | R36: 7 | S36: 10 | T36: =IF(COUNTIF($F36:S36,"=*")>0,IF($C36="К","-"," - "),IF(COUNTIF($F36:S36,"<4")>0,IF(C36="К","-"," - "),(IFERROR(AVERAGE($F36:S36),"Очікую")))) -> 6.6428571
C37: К | D37: 28 | E37: Чорний Степан Ігорович | F37: 9 | G37: 6 | H37: 11 | I37: 8 | J37: 11 | K37: 8 | L37: 5 | M37: 5 | N37: 10 | O37: 8 | P37: 10 | Q37: 7 | R37: 7 | S37: 10 | T37: =IF(COUNTIF($F37:S37,"=*")>0,IF($C37="К","-"," - "),IF(COUNTIF($F37:S37,"<4")>0,IF(C37="К","-"," - "),(IFERROR(AVERAGE($F37:S37),"Очікую")))) -> 8.2142857
C38: К | D38: 29 | E38: Шаповал Аліна Сергіївна | F38: 11 | G38: 6 | H38: 8 | I38: 11 | J38: 6 | K38: 9 | L38: 8 | M38: 6 | N38: 9 | O38: 8 | P38: 10 | Q38: 8 | R38: 8 | S38: 11 | T38: =IF(COUNTIF($F38:S38,"=*")>0,IF($C38="К","-"," - "),IF(COUNTIF($F38:S38,"<4")>0,IF(C38="К","-"," - "),(IFERROR(AVERAGE($F38:S38),"Очікую")))) -> 8.5
C39: К | D39: 30 | E39: Яремчук Євген Степанович | F39: н/а | G39: 5 | H39: 4 | I39: 8 | J39: 7 | K39: 8 | L39: 7 | M39: 10 | N39: 7 | O39: 11 | P39: 11 | Q39: 6 | R39: 11 | S39: 8 | T39: =IF(COUNTIF($F39:S39,"=*")>0,IF($C39="К","-"," - "),IF(COUNTIF($F39:S39,"<4")>0,IF(C39="К","-"," - "),(IFERROR(AVERAGE($F39:S39),"Очікую")))) -> -
E40: Середній бал успішності з дисципліни | F40: =IF(SUM(F$10:F39)=0,IF(COUNTA(F$10:F39)=0,"Очікую",0),SUM(F$10:F39)/$D39) -> 7.0333333 | G40: =IF(SUM(G$10:G39)=0,IF(COUNTA(G$10:G39)=0,"Очікую",0),SUM(G$10:G39)/$D39) -> 7.3333333 | H40: =IF(SUM(H$10:H39)=0,IF(COUNTA(H$10:H39)=0,"Очікую",0),SUM(H$10:H39)/$D39) -> 7.5333333 | I40: =IF(SUM(I$10:I39)=0,IF(COUNTA(I$10:I39)=0,"Очікую",0),SUM(I$10:I39)/$D39) -> 6.8333333 | J40: =IF(SUM(J$10:J39)=0,IF(COUNTA(J$10:J39)=0,"Очікую",0),SUM(J$10:J39)/$D39) -> 6.8333333 | K40: =IF(SUM(K$10:K39)=0,IF(COUNTA(K$10:K39)=0,"Очікую",0),SUM(K$10:K39)/$D39) -> 6.9 | L40: =IF(SUM(L$10:L39)=0,IF(COUNTA(L$10:L39)=0,"Очікую",0),SUM(L$10:L39)/$D39) -> 7.2333333 | M40: =IF(SUM(M$10:M39)=0,IF(COUNTA(M$10:M39)=0,"Очікую",0),SUM(M$10:M39)/$D39) -> 6.9333333 | ... S40: =IF(SUM(S$10:S39)=0,IF(COUNTA(S$10:S39)=0,"Очікую",0),SUM(S$10:S39)/$D39) -> 7.6333333 | T40: =IFERROR(AVERAGE($F40:S40),"Очікую") -> 7.3119048
E41: Абсолютна успішність | F41: =IF(SUM(F$10:F39)=0,IF(COUNTA(F$10:F39)=0,"Очікую",0),IF(COUNTIF(F$10:F39,">=4")=0,0,COUNTIF(F$10:F39,">=4")/$D39*100)) -> 90 | G41: =IF(SUM(G$10:G39)=0,IF(COUNTA(G$10:G39)=0,"Очікую",0),IF(COUNTIF(G$10:G39,">=4")=0,0,COUNTIF(G$10:G39,">=4")/$D39*100)) -> 100 | H41: =IF(SUM(H$10:H39)=0,IF(COUNTA(H$10:H39)=0,"Очікую",0),IF(COUNTIF(H$10:H39,">=4")=0,0,COUNTIF(H$10:H39,">=4")/$D39*100)) -> 96.666667 | I41: =IF(SUM(I$10:I39)=0,IF(COUNTA(I$10:I39)=0,"Очікую",0),IF(COUNTIF(I$10:I39,">=4")=0,0,COUNTIF(I$10:I39,">=4")/$D39*100)) -> 90 | J41: =IF(SUM(J$10:J39)=0,IF(COUNTA(J$10:J39)=0,"Очікую",0),IF(COUNTIF(J$10:J39,">=4")=0,0,COUNTIF(J$10:J39,">=4")/$D39*100)) -> 96.666667 | K41: =IF(SUM(K$10:K39)=0,IF(COUNTA(K$10:K39)=0,"Очікую",0),IF(COUNTIF(K$10:K39,">=4")=0,0,COUNTIF(K$10:K39,">=4")/$D39*100)) -> 96.666667 | L41: =IF(SUM(L$10:L39)=0,IF(COUNTA(L$10:L39)=0,"Очікую",0),IF(COUNTIF(L$10:L39,">=4")=0,0,COUNTIF(L$10:L39,">=4")/$D39*100)) -> 96.666667 | M41: =IF(SUM(M$10:M39)=0,IF(COUNTA(M$10:M39)=0,"Очікую",0),IF(COUNTIF(M$10:M39,">=4")=0,0,COUNTIF(M$10:M39,">=4")/$D39*100)) -> 96.666667 | ... S41: =IF(SUM(S$10:S39)=0,IF(COUNTA(S$10:S39)=0,"Очікую",0),IF(COUNTIF(S$10:S39,">=4")=0,0,COUNTIF(S$10:S39,">=4")/$D39*100)) -> 96.666667
...

Sheet Зведена G1
A1: S
C3: ВІДОКРЕМЛЕНИЙ СТРУКТУРНИЙ ПІДРОЗДІЛ «ФАХОВИЙ КОЛЕДЖ НАФТОГАЗОВИХ ТЕХНОЛОГІЙ, ІНЖЕНЕРІЇ ТА ІНФРАСТРУКТУРИ СЕРВІСУ ОДЕСЬКОГО НАЦІОНАЛЬНОГО ТЕХНОЛОГІЧНОГО УНІВЕРСИТЕТУ»
C4: ЗВЕДЕНА ВІДОМІСТЬ
C5: Успішності студентів спеціальності G1 «Хімічні технології та інженерія»
C6: За І семестр 2025-2026 н.р.
C7: Група 26-1 курс І
C8: Б/К | D8: № п/п | E8: Прізвище, ім’я, по батькові | F8: Підсумкові оцінки дисциплін | T8: Середній бал
F9: Біологія Богданенко О.В. | G9: Всесвітня історія Мельничук С.А. | H9: Географія Наговська Т.С. | I9: Зарубіжна література Сербулова Ю.А. | J9: Захист України Лазар В.І. | K9: Іноземна мова Сербулова Ю.А. | L9: Інформатика Бєльдюгіна С.С. | M9: Історія України Левчук Т.Г. | N9: Математика Бондаренко О.С. | O9: Українська література Антропова Л.І. | P9: Українська мова Антропова Л.І. | Q9: Фізика Калюта Н.М. | R9: Фізична культура Возіян О.Г. | S9: Хімія Сахно Н.О.
C10: К | D10: 1 | E10: Бондарчук Ніна Григорівна | F10: 8 | G10: 7 | H10: 8 | I10: 8 | J10: 6 | K10: 4 | L10: 5 | M10: 5 | N10: 8 | O10: 6 | P10: 6 | Q10: 5 | R10: 7 | S10: 10 | T10: =IF(COUNTIF($F10:S10,"=*")>0,IF($C10="К","-"," - "),IF(COUNTIF($F10:S10,"<4")>0,IF(C10="К","-"," - "),(IFERROR(AVERAGE($F10:S10),"Очікую")))) -> 6.6428571
C11: К | D11: 2 | E11: Дубовик Віра Михайлівна | F11: 8 | G11: 6 | H11: 9 | I11: 11 | J11: 4 | K11: 4 | L11: 8 | M11: 11 | N11: 9 | O11: 10 | P11: 7 | Q11: 9 | R11: 10 | S11: 9 | T11: =IF(COUNTIF($F11:S11,"=*")>0,IF($C11="К","-"," - "),IF(COUNTIF($F11:S11,"<4")>0,IF(C11="К","-"," - "),(IFERROR(AVERAGE($F11:S11),"Очікую")))) -> 8.2142857
C12: К | D12: 3 | E12: Кушніренко Артем Олександрович | F12: 8 | G12: 6 | H12: 5 | I12: 11 | J12: 7 | K12: 7 | L12: 6 | M12: 10 | N12: 7 | O12: 6 | P12: 6 | Q12: 4 | R12: 6 | S12: 6 | T12: =IF(COUNTIF($F12:S12,"=*")>0,IF($C12="К","-"," - "),IF(COUNTIF($F12:S12,"<4")>0,IF(C12="К","-"," - "),(IFERROR(AVERAGE($F12:S12),"Очікую")))) -> 6.7857143
C13: К | D13: 4 | E13: Назаренко Єгор Віталійович | F13: 7 | G13: 10 | H13: 10 | I13: 4 | J13: 8 | K13: 7 | L13: 8 | M13: 5 | N13: 10 | O13: 10 | P13: 9 | Q13: 6 | R13: 11 | S13: 6 | T13: =IF(COUNTIF($F13:S13,"=*")>0,IF($C13="К","-"," - "),IF(COUNTIF($F13:S13,"<4")>0,IF(C13="К","-"," - "),(IFERROR(AVERAGE($F13:S13),"Очікую")))) -> 7.9285714
C14: К | D14: 5 | E14: Рябоконь Софія Юріївна | F14: 9 | G14: 9 | H14: 8 | I14: 6 | J14: 10 | K14: 11 | L14: 6 | M14: 11 | N14: 7 | O14: 7 | P14: 10 | Q14: 6 | R14: 7 | S14: 8 | T14: =IF(COUNTIF($F14:S14,"=*")>0,IF($C14="К","-"," - "),IF(COUNTIF($F14:S14,"<4")>0,IF(C14="К","-"," - "),(IFERROR(AVERAGE($F14:S14),"Очікую")))) -> 8.2142857
C15: К | D15: 6 | E15: Соловей Микита Ігорович | F15: 4 | G15: 4 | H15: 11 | I15: 8 | J15: 5 | K15: 10 | L15: 8 | M15: 5 | N15: 9 | O15: 6 | P15: 4 | Q15: 10 | R15: 8 | S15: 8 | T15: =IF(COUNTIF($F15:S15,"=*")>0,IF($C15="К","-"," - "),IF(COUNTIF($F15:S15,"<4")>0,IF(C15="К","-"," - "),(IFERROR(AVERAGE($F15:S15),"Очікую")))) -> 7.1428571
C16: К | D16: 7 | E16: Тарасенко Леонід Степанович | F16: 4 | G16: 4 | H16: н/а | I16: 4 | J16: 8 | K16: н/а | L16: 6 | M16: 7 | N16: 10 | O16: 8 | P16: н/а | Q16: 7 | R16: 10 | S16: 11 | T16: =IF(COUNTIF($F16:S16,"=*")>0,IF($C16="К","-"," - "),IF(COUNTIF($F16:S16,"<4")>0,IF(C16="К","-"," - "),(IFERROR(AVERAGE($F16:S16),"Очікую")))) -> -
E17: Середній бал успішності з дисципліни | F17: =IF(SUM(F$10:F16)=0,IF(COUNTA(F$10:F16)=0,"Очікую",0),SUM(F$10:F16)/$D16) -> 6.8571429 | G17: =IF(SUM(G$10:G16)=0,IF(COUNTA(G$10:G16)=0,"Очікую",0),SUM(G$10:G16)/$D16) -> 6.5714286 | H17: =IF(SUM(H$10:H16)=0,IF(COUNTA(H$10:H16)=0,"Очікую",0),SUM(H$10:H16)/$D16) -> 7.2857143 | I17: =IF(SUM(I$10:I16)=0,IF(COUNTA(I$10:I16)=0,"Очікую",0),SUM(I$10:I16)/$D16) -> 7.4285714 | J17: =IF(SUM(J$10:J16)=0,IF(COUNTA(J$10:J16)=0,"Очікую",0),SUM(J$10:J16)/$D16) -> 6.8571429 | K17: =IF(SUM(K$10:K16)=0,IF(COUNTA(K$10:K16)=0,"Очікую",0),SUM(K$10:K16)/$D16) -> 6.1428571 | L17: =IF(SUM(L$10:L16)=0,IF(COUNTA(L$10:L16)=0,"Очікую",0),SUM(L$10:L16)/$D16) -> 6.7142857 | M17: =IF(SUM(M$10:M16)=0,IF(COUNTA(M$10:M16)=0,"Очікую",0),SUM(M$10:M16)/$D16) -> 7.7142857 | ... S17: =IF(SUM(S$10:S16)=0,IF(COUNTA(S$10:S16)=0,"Очікую",0),SUM(S$10:S16)/$D16) -> 8.2857143 | T17: =IFERROR(AVERAGE($F17:S17),"Очікую") -> 7.2244898
E18: Абсолютна успішність | F18: =IF(SUM(F$10:F16)=0,IF(COUNTA(F$10:F16)=0,"Очікую",0),IF(COUNTIF(F$10:F16,">=4")=0,0,COUNTIF(F$10:F16,">=4")/$D16*100)) -> 100 | G18: =IF(SUM(G$10:G16)=0,IF(COUNTA(G$10:G16)=0,"Очікую",0),IF(COUNTIF(G$10:G16,">=4")=0,0,COUNTIF(G$10:G16,">=4")/$D16*100)) -> 100 | H18: =IF(SUM(H$10:H16)=0,IF(COUNTA(H$10:H16)=0,"Очікую",0),IF(COUNTIF(H$10:H16,">=4")=0,0,COUNTIF(H$10:H16,">=4")/$D16*100)) -> 85.714286 | I18: =IF(SUM(I$10:I16)=0,IF(COUNTA(I$10:I16)=0,"Очікую",0),IF(COUNTIF(I$10:I16,">=4")=0,0,COUNTIF(I$10:I16,">=4")/$D16*100)) -> 100 | J18: =IF(SUM(J$10:J16)=0,IF(COUNTA(J$10:J16)=0,"Очікую",0),IF(COUNTIF(J$10:J16,">=4")=0,0,COUNTIF(J$10:J16,">=4")/$D16*100)) -> 100 | K18: =IF(SUM(K$10:K16)=0,IF(COUNTA(K$10:K16)=0,"Очікую",0),IF(COUNTIF(K$10:K16,">=4")=0,0,COUNTIF(K$10:K16,">=4")/$D16*100)) -> 85.714286 | L18: =IF(SUM(L$10:L16)=0,IF(COUNTA(L$10:L16)=0,"Очікую",0),IF(COUNTIF(L$10:L16,">=4")=0,0,COUNTIF(L$10:L16,">=4")/$D16*100)) -> 100 | M18: =IF(SUM(M$10:M16)=0,IF(COUNTA(M$10:M16)=0,"Очікую",0),IF(COUNTIF(M$10:M16,">=4")=0,0,COUNTIF(M$10:M16,">=4")/$D16*100)) -> 100 | ... S18: =IF(SUM(S$10:S16)=0,IF(COUNTA(S$10:S16)=0,"Очікую",0),IF(COUNTIF(S$10:S16,">=4")=0,0,COUNTIF(S$10:S16,">=4")/$D16*100)) -> 100
E19: Якісна успішність | F19: =IF(SUM(F$10:F16)=0,IF(COUNTA(F$10:F16)=0,"Очікую",0),IF(COUNTIF(F$10:F16,">=7")=0,0,COUNTIF(F$10:F16,">=7")/$D16*100)) -> 71.428571 | G19: =IF(SUM(G$10:G16)=0,IF(COUNTA(G$10:G16)=0,"Очікую",0),IF(COUNTIF(G$10:G16,">=7")=0,0,COUNTIF(G$10:G16,">=7")/$D16*100)) -> 42.857143 | H19: =IF(SUM(H$10:H16)=0,IF(COUNTA(H$10:H16)=0,"Очікую",0),IF(COUNTIF(H$10:H16,">=7")=0,0,COUNTIF(H$10:H16,">=7")/$D16*100)) -> 71.428571 | I19: =IF(SUM(I$10:I16)=0,IF(COUNTA(I$10:I16)=0,"Очікую",0),IF(COUNTIF(I$10:I16,">=7")=0,0,COUNTIF(I$10:I16,">=7")/$D16*100)) -> 57.142857 | J19: =IF(SUM(J$10:J16)=0,IF(COUNTA(J$10:J16)=0,"Очікую",0),IF(COUNTIF(J$10:J16,">=7")=0,0,COUNTIF(J$10:J16,">=7")/$D16*100)) -> 57.142857 | K19: =IF(SUM(K$10:K16)=0,IF(COUNTA(K$10:K16)=0,"Очікую",0),IF(COUNTIF(K$10:K16,">=7")=0,0,COUNTIF(K$10:K16,">=7")/$D16*100)) -> 57.142857 | L19: =IF(SUM(L$10:L16)=0,IF(COUNTA(L$10:L16)=0,"Очікую",0),IF(COUNTIF(L$10:L16,">=7")=0,0,COUNTIF(L$10:L16,">=7")/$D16*100)) -> 42.857143 | M19: =IF(SUM(M$10:M16)=0,IF(COUNTA(M$10:M16)=0,"Очікую",0),IF(COUNTIF(M$10:M16,">=7")=0,0,COUNTIF(M$10:M16,">=7")/$D16*100)) -> 57.142857 | ... S19: =IF(SUM(S$10:S16)=0,IF(COUNTA(S$10:S16)=0,"Очікую",0),IF(COUNTIF(S$10:S16,">=7")=0,0,COUNTIF(S$10:S16,">=7")/$D16*100)) -> 71.428571
E20: Абсолютна успішність по групі | F20: =IFERROR(AVERAGE(F18:S18),"Очікую") -> 96.938776
E21: Якісна успішність по групі | F21: =IFERROR(AVERAGE($F19:S19),"Очікую") -> 61.22449
E22: Кількість бюджетників | F22: =IF(COUNTIF($C$10:$C16,"=Б")=0,IF(COUNTIF($C$10:$C16,"=К")=0,"Очікую",0),COUNTIF($C$10:$C16,"=Б")) -> 0
E23: Кількість контрактників | F23: =IF(COUNTIF($C$10:$C16,"=К")=0,IF(COUNTIF($C$10:$C16,"=Б")=0,"Очікую",0),COUNTIF($C$10:$C16,"=К")) -> 7 | H23: Класний керівник | P23: Ірина ДОПІРА
E24: Кількість соціального контингенту | F24: 0
E25: Вийшли на стипендію | F25: =IF(F22="Очікую","Очікую",IF(F22-COUNTIF($T$10:$T16," - ")<ROUNDDOWN(F22*0.4,0),F22-COUNTIF($T$10:$T16," - "),ROUNDDOWN(F22*0.4,0))) -> 0 | H25: Завідувач відділення ПЗСО | P25: Маргарита БРІТІКОВА

Sheet Рейтингова D5
A1: S
C3: ВІДОКРЕМЛЕНИЙ СТРУКТУРНИЙ ПІДРОЗДІЛ «ФАХОВИЙ КОЛЕДЖ НАФТОГАЗОВИХ ТЕХНОЛОГІЙ, ІНЖЕНЕРІЇ ТА ІНФРАСТРУКТУРИ СЕРВІСУ ОДЕСЬКОГО НАЦІОНАЛЬНОГО ТЕХНОЛОГІЧНОГО УНІВЕРСИТЕТУ»
C4: РЕЙТИНГОВА ВІДОМІСТЬ
C5: ='Зведена D5'!C5 -> Успішності студентів спеціальності D5 «Маркетинг»
C6: ='Зведена D5'!C6 -> За І семестр 2025-2026 н.р.
C7: ='Зведена D5'!C7 -> Група 26-1 курс І
C8: Б/К | D8: № п/п | E8: Прізвище, ім’я, по батькові | F8: Підсумкові оцінки дисциплін | T8: Середній бал | U8: Рейтинговий бал
F9: ='Зведена D5'!F9 -> Біологія Богданенко О.В. | G9: ='Зведена D5'!G9 -> Всесвітня історія Мельничук С.А. | H9: ='Зведена D5'!H9 -> Географія Наговська Т.С. | I9: ='Зведена D5'!I9 -> Зарубіжна література Сербулова Ю.А. | J9: ='Зведена D5'!J9 -> Захист України Лазар В.І. | K9: ='Зведена D5'!K9 -> Іноземна мова Сербулова Ю.А. | L9: ='Зведена D5'!L9 -> Інформатика Бєльдюгіна С.С. | M9: ='Зведена D5'!M9 -> Історія України Левчук Т.Г. | ... S9: ='Зведена D5'!S9 -> Хімія Сахно Н.О.
C10: ='Зведена D5'!C19 -> Б | D10: 1 | E10: ='Зведена D5'!E19 -> Поліщук Артем Валерійович | F10: ='Зведена D5'!F19 -> 4 | G10: ='Зведена D5'!G19 -> 7 | H10: ='Зведена D5'!H19 -> 9 | I10: ='Зведена D5'!I19 -> 9 | J10: ='Зведена D5'!J19 -> 6 | K10: ='Зведена D5'!K19 -> 8 | L10: ='Зведена D5'!L19 -> 8 | ... S10: ='Зведена D5'!S19 -> 8 | T10: =IF(COUNTIF($F10:S10,"=*")>0,IF($C10="К","-"," - "),IF(COUNTIF($F10:S10,"<4")>0,IF(C10="К","-"," - "),(IFERROR(AVERAGE($F10:S10),"Очікую")))) -> 7.7857143 | U10: =IFERROR(T10/12*90,"Очікую") -> 58.392857
C11: ='Зведена D5'!C20 -> Б | D11: 2 | E11: ='Зведена D5'!E20 -> Присяжнюк Аміна Михайлівна | F11: ='Зведена D5'!F20 -> 11 | G11: ='Зведена D5'!G20 -> 4 | H11: ='Зведена D5'!H20 -> 10 | I11: ='Зведена D5'!I20 -> 5 | J11: ='Зведена D5'!J20 -> 8 | K11: ='Зведена D5'!K20 -> 11 | L11: ='Зведена D5'!L20 -> 9 | ... S11: ='Зведена D5'!S20 -> 5 | T11: =IF(COUNTIF($F11:S11,"=*")>0,IF($C11="К","-"," - "),IF(COUNTIF($F11:S11,"<4")>0,IF(C11="К","-"," - "),(IFERROR(AVERAGE($F11:S11),"Очікую")))) -> 7.5714286 | U11: =IFERROR(T11/12*90,"Очікую") -> 56.785714
C12: ='Зведена D5'!C23 -> Б | D12: 3 | E12: ='Зведена D5'!E23 -> Самойлова Яна Вячеславівна | F12: ='Зведена D5'!F23 -> 8 | G12: ='Зведена D5'!G23 -> 4 | H12: ='Зведена D5'!H23 -> 9 | I12: ='Зведена D5'!I23 -> 7 | J12: ='Зведена D5'!J23 -> 5 | K12: ='Зведена D5'!K23 -> 8 | L12: ='Зведена D5'!L23 -> 5 | ... S12: ='Зведена D5'!S23 -> 9 | T12: =IF(COUNTIF($F12:S12,"=*")>0,IF($C12="К","-"," - "),IF(COUNTIF($F12:S12,"<4")>0,IF(C12="К","-"," - "),(IFERROR(AVERAGE($F12:S12),"Очікую")))) -> 7.0714286 | U12: =IFERROR(T12/12*90,"Очікую") -> 53.035714
E13: Кількість бюджетників | F13: ='Зведена D5'!F33 -> 10
E14: Кількість контрактників | F14: ='Зведена D5'!F34 -> 8 | H14: Класний керівник | P14: ='Зведена D5'!P34 -> Ірина ДОПІРА
E15: Кількість соціального контингенту | F15: ='Зведена D5'!F35 -> 0
E16: Вийшли на стипендію | F16: ='Зведена D5'!F36 -> 3 | H16: Завідувач відділення ПЗСО | P16: Маргарита БРІТІКОВА

Sheet Рейтингова D7
A1: S
C3: ВІДОКРЕМЛЕНИЙ СТРУКТУРНИЙ ПІДРОЗДІЛ «ФАХОВИЙ КОЛЕДЖ НАФТОГАЗОВИХ ТЕХНОЛОГІЙ, ІНЖЕНЕРІЇ ТА ІНФРАСТРУКТУРИ СЕРВІСУ ОДЕСЬКОГО НАЦІОНАЛЬНОГО ТЕХНОЛОГІЧНОГО УНІВЕРСИТЕТУ»
C4: РЕЙТИНГОВА ВІДОМІСТЬ
C5: ='Зведена D7'!C5 -> Успішності студентів спеціальності D7 «Торгівля»
C6: ='Зведена D7'!C6 -> За І семестр 2025-2026 н.р.
C7: ='Зведена D7'!C7 -> Група 26-1 курс І
C8: Б/К | D8: № п/п | E8: Прізвище, ім’я, по батькові | F8: Підсумкові оцінки дисциплін | T8: Середній бал | U8: Рейтинговий бал
F9: ='Зведена D7'!F9 -> Біологія Богданенко О.В. | G9: ='Зведена D7'!G9 -> Всесвітня історія Мельничук С.А. | H9: ='Зведена D7'!H9 -> Географія Наговська Т.С. | I9: ='Зведена D7'!I9 -> Зарубіжна література Сербулова Ю.А. | J9: ='Зведена D7'!J9 -> Захист України Лазар В.І. | K9: ='Зведена D7'!K9 -> Іноземна мова Сербулова Ю.А. | L9: ='Зведена D7'!L9 -> Інформатика Бєльдюгіна С.С. | M9: ='Зведена D7'!M9 -> Історія України Левчук Т.Г. | ... S9: ='Зведена D7'!S9 -> Хімія Сахно Н.О.
C10: ='Зведена D7'!C33 -> Б | D10: 1 | E10: ='Зведена D7'!E33 -> Сидоренко Ілля Артемович | F10: ='Зведена D7'!F33 -> 8 | G10: ='Зведена D7'!G33 -> 9 | H10: ='Зведена D7'!H33 -> 9 | I10: ='Зведена D7'!I33 -> 8 | J10: ='Зведена D7'!J33 -> 10 | K10: ='Зведена D7'!K33 -> 5 | L10: ='Зведена D7'!L33 -> 10 | ... S10: ='Зведена D7'!S33 -> 10 | T10: =IF(COUNTIF($F10:S10,"=*")>0,IF($C10="К","-"," - "),IF(COUNTIF($F10:S10,"<4")>0,IF(C10="К","-"," - "),(IFERROR(AVERAGE($F10:S10),"Очікую")))) -> 8.7857143 | U10: =IFERROR(T10/12*90,"Очікую") -> 65.892857
C11: ='Зведена D7'!C17 -> Б | D11: 2 | E11: ='Зведена D7'!E17 -> Зінченко Богдан Романович | F11: ='Зведена D7'!F17 -> 9 | G11: ='Зведена D7'!G17 -> 9 | H11: ='Зведена D7'!H17 -> 8 | I11: ='Зведена D7'!I17 -> 6 | J11: ='Зведена D7'!J17 -> 10 | K11: ='Зведена D7'!K17 -> 11 | L11: ='Зведена D7'!L17 -> 6 | ... S11: ='Зведена D7'!S17 -> 8 | T11: =IF(COUNTIF($F11:S11,"=*")>0,IF($C11="К","-"," - "),IF(COUNTIF($F11:S11,"<4")>0,IF(C11="К","-"," - "),(IFERROR(AVERAGE($F11:S11),"Очікую")))) -> 8.2142857 | U11: =IFERROR(T11/12*90,"Очікую") -> 61.607143
C12: ='Зведена D7'!C27 -> Б | D12: 3 | E12: ='Зведена D7'!E27 -> Остапчук Максим Олександрович | F12: ='Зведена D7'!F27 -> 8 | G12: ='Зведена D7'!G27 -> 6 | H12: ='Зведена D7'!H27 -> 9 | I12: ='Зведена D7'!I27 -> 11 | J12: ='Зведена D7'!J27 -> 4 | K12: ='Зведена D7'!K27 -> 4 | L12: ='Зведена D7'!L27 -> 8 | ... S12: ='Зведена D7'!S27 -> 9 | T12: =IF(COUNTIF($F12:S12,"=*")>0,IF($C12="К","-"," - "),IF(COUNTIF($F12:S12,"<4")>0,IF(C12="К","-"," - "),(IFERROR(AVERAGE($F12:S12),"Очікую")))) -> 8.2142857 | U12: =IFERROR(T12/12*90,"Очікую") -> 61.607143
C13: ='Зведена D7'!C22 -> Б | D13: 4 | E13: ='Зведена D7'!E22 -> Куліш Дарина Олегівна | F13: ='Зведена D7'!F22 -> 7 | G13: ='Зведена D7'!G22 -> 8 | H13: ='Зведена D7'!H22 -> 11 | I13: ='Зведена D7'!I22 -> 4 | J13: ='Зведена D7'!J22 -> 9 | K13: ='Зведена D7'!K22 -> 5 | L13: ='Зведена D7'!L22 -> 8 | ... S13: ='Зведена D7'!S22 -> 8 | T13: =IF(COUNTIF($F13:S13,"=*")>0,IF($C13="К","-"," - "),IF(COUNTIF($F13:S13,"<4")>0,IF(C13="К","-"," - "),(IFERROR(AVERAGE($F13:S13),"Очікую")))) -> 7.9285714 | U13: =IFERROR(T13/12*90,"Очікую") -> 59.464286
C14: ='Зведена D7'!C14 -> Б | D14: 5 | E14: ='Зведена D7'!E14 -> Гаврилюк Маргарита Тимофіївна | F14: ='Зведена D7'!F14 -> 4 | G14: ='Зведена D7'!G14 -> 8 | H14: ='Зведена D7'!H14 -> 8 | I14: ='Зведена D7'!I14 -> 10 | J14: ='Зведена D7'!J14 -> 6 | K14: ='Зведена D7'!K14 -> 8 | L14: ='Зведена D7'!L14 -> 10 | ... S14: ='Зведена D7'!S14 -> 8 | T14: =IF(COUNTIF($F14:S14,"=*")>0,IF($C14="К","-"," - "),IF(COUNTIF($F14:S14,"<4")>0,IF(C14="К","-"," - "),(IFERROR(AVERAGE($F14:S14),"Очікую")))) -> 7.7142857 | U14: =IFERROR(T14/12*90,"Очікую") -> 57.857143
C15: ='Зведена D7'!C32 -> Б | D15: 6 | E15: ='Зведена D7'!E32 -> Семенюк Марина Григорівна | F15: ='Зведена D7'!F32 -> 5 | G15: ='Зведена D7'!G32 -> 9 | H15: ='Зведена D7'!H32 -> 10 | I15: ='Зведена D7'!I32 -> 9 | J15: ='Зведена D7'!J32 -> 5 | K15: ='Зведена D7'!K32 -> 4 | L15: ='Зведена D7'!L32 -> 6 | ... S15: ='Зведена D7'!S32 -> 9 | T15: =IF(COUNTIF($F15:S15,"=*")>0,IF($C15="К","-"," - "),IF(COUNTIF($F15:S15,"<4")>0,IF(C15="К","-"," - "),(IFERROR(AVERAGE($F15:S15),"Очікую")))) -> 7.5 | U15: =IFERROR(T15/12*90,"Очікую") -> 56.25
C16: ='Зведена D7'!C20 -> Б | D16: 7 | E16: ='Зведена D7'!E20 -> Козаченко Роман Анатолійович | F16: ='Зведена D7'!F20 -> 9 | G16: ='Зведена D7'!G20 -> 9 | H16: ='Зведена D7'!H20 -> 6 | I16: ='Зведена D7'!I20 -> 5 | J16: ='Зведена D7'!J20 -> 10 | K16: ='Зведена D7'!K20 -> 6 | L16: ='Зведена D7'!L20 -> 7 | ... S16: ='Зведена D7'!S20 -> 7 | T16: =IF(COUNTIF($F16:S16,"=*")>0,IF($C16="К","-"," - "),IF(COUNTIF($F16:S16,"<4")>0,IF(C16="К","-"," - "),(IFERROR(AVERAGE($F16:S16),"Очікую")))) -> 7.3571429 | U16: =IFERROR(T16/12*90,"Очікую") -> 55.178571
C17: ='Зведена D7'!C18 -> Б | D17: 8 | E17: ='Зведена D7'!E18 -> Клименко Алла Михайлівна | F17: ='Зведена D7'!F18 -> 4 | G17: ='Зведена D7'!G18 -> 4 | H17: ='Зведена D7'!H18 -> 11 | I17: ='Зведена D7'!I18 -> 8 | J17: ='Зведена D7'!J18 -> 5 | K17: ='Зведена D7'!K18 -> 10 | L17: ='Зведена D7'!L18 -> 8 | ... S17: ='Зведена D7'!S18 -> 8 | T17: =IF(COUNTIF($F17:S17,"=*")>0,IF($C17="К","-"," - "),IF(COUNTIF($F17:S17,"<4")>0,IF(C17="К","-"," - "),(IFERROR(AVERAGE($F17:S17),"Очікую")))) -> 7.1428571 | U17: =IFERROR(T17/12*90,"Очікую") -> 53.571429
C18: ='Зведена D7'!C10 -> Б | D18: 9 | E18: ='Зведена D7'!E10 -> Безуглий Юрій Віталійович | F18: ='Зведена D7'!F10 -> 10 | G18: ='Зведена D7'!G10 -> 11 | H18: ='Зведена D7'!H10 -> 6 | I18: ='Зведена D7'!I10 -> 9 | J18: ='Зведена D7'!J10 -> 4 | K18: ='Зведена D7'!K10 -> 8 | L18: ='Зведена D7'!L10 -> 5 | ... S18: ='Зведена D7'!S10 -> 5 | T18: =IF(COUNTIF($F18:S18,"=*")>0,IF($C18="К","-"," - "),IF(COUNTIF($F18:S18,"<4")>0,IF(C18="К","-"," - "),(IFERROR(AVERAGE($F18:S18),"Очікую")))) -> 7.0714286 | U18: =IFERROR(T18/12*90,"Очікую") -> 53.035714
C19: ='Зведена D7'!C11 -> Б | D19: 10 | E19: ='Зведена D7'!E11 -> Білан Інна Євгенівна | F19: ='Зведена D7'!F11 -> 11 | G19: ='Зведена D7'!G11 -> 8 | H19: ='Зведена D7'!H11 -> 6 | I19: ='Зведена D7'!I11 -> 6 | J19: ='Зведена D7'!J11 -> 5 | K19: ='Зведена D7'!K11 -> 6 | L19: ='Зведена D7'!L11 -> 8 | ... S19: ='Зведена D7'!S11 -> 7 | T19: =IF(COUNTIF($F19:S19,"=*")>0,IF($C19="К","-"," - "),IF(COUNTIF($F19:S19,"<4")>0,IF(C19="К","-"," - "),(IFERROR(AVERAGE($F19:S19),"Очікую")))) -> 6.7857143 | U19: =IFERROR(T19/12*90,"Очікую") -> 50.892857
C20: ='Зведена D7'!C16 -> Б | D20: 11 | E20: ='Зведена D7'!E16 -> Дяченко Катерина Дмитрівна | F20: ='Зведена D7'!F16 -> 8 | G20: ='Зведена D7'!G16 -> 6 | H20: ='Зведена D7'!H16 -> 5 | I20: ='Зведена D7'!I16 -> 11 | J20: ='Зведена D7'!J16 -> 7 | K20: ='Зведена D7'!K16 -> 7 | L20: ='Зведена D7'!L16 -> 6 | ... S20: ='Зведена D7'!S16 -> 6 | T20: =IF(COUNTIF($F20:S20,"=*")>0,IF($C20="К","-"," - "),IF(COUNTIF($F20:S20,"<4")>0,IF(C20="К","-"," - "),(IFERROR(AVERAGE($F20:S20),"Очікую")))) -> 6.7857143 | U20: =IFERROR(T20/12*90,"Очікую") -> 50.892857
C21: ='Зведена D7'!C24 -> Б | D21: 12 | E21: ='Зведена D7'!E24 -> Мельничук Людмила Петрівна | F21: ='Зведена D7'!F24 -> 8 | G21: ='Зведена D7'!G24 -> 7 | H21: ='Зведена D7'!H24 -> 8 | I21: ='Зведена D7'!I24 -> 8 | J21: ='Зведена D7'!J24 -> 6 | K21: ='Зведена D7'!K24 -> 7 | L21: ='Зведена D7'!L24 -> 6 | ... S21: ='Зведена D7'!S24 -> 5 | T21: =IF(COUNTIF($F21:S21,"=*")>0,IF($C21="К","-"," - "),IF(COUNTIF($F21:S21,"<4")>0,IF(C21="К","-"," - "),(IFERROR(AVERAGE($F21:S21),"Очікую")))) -> 6.5 | U21: =IFERROR(T21/12*90,"Очікую") -> 48.75
E22: Кількість бюджетників | F22: ='Зведена D7'!F45 -> 14
E23: Кількість контрактників | F23: ='Зведена D7'!F46 -> 16 | H23: Класний керівник | P23: ='Зведена D7'!P46 -> Ірина ДОПІРА
E24: Кількість соціального контингенту | F24: ='Зведена D7'!F47 -> 2
E25: Вийшли на стипендію | F25: ='Зведена D7'!F48 -> 5 | H25: Завідувач відділення ПЗСО | P25: Маргарита БРІТІКОВА
