Workbook
Name A1048577: #REF!
Name Ф80: #REF!
Name A1048577: #REF!
Name Ф80: #REF!
Name A1048577: #REF!
Name Ф80: #REF!
Name A1048577: #REF!
Name Ф80: #REF!
Name A1048577: #REF!
Name Ф80: #REF!
Name A1048577: #REF!
Name Ф80: #REF!

Sheet Зведена D5
A1: S
C3: ВІДОКРЕМЛЕНИЙ СТРУКТУРНИЙ ПІДРОЗДІЛ «ФАХОВИЙ КОЛЕДЖ НАФТОГАЗОВИХ ТЕХНОЛОГІЙ, ІНЖЕНЕРІЇ ТА ІНФРАСТРУКТУРИ СЕРВІСУ ОДЕСЬКОГО НАЦІОНАЛЬНОГО ТЕХНОЛОГІЧНОГО УНІВЕРСИТЕТУ»
C4: ЗВЕДЕНА ВІДОМІСТЬ
C5: Успішності студентів спеціальності D5 «Маркетинг»
C6: За ІІ семестр 2025-2026 н.р.
C7: Група 26-1 курс І
C8: Б/К | D8: № п/п | E8: Прізвище, ім’я, по батькові | F8: Підсумкові оцінки дисциплін | U8: Середній бал
F9: Астрономія Наговська Т.С. | G9: Біологія Богданенко О.В. | H9: Всесвітня історія Мельничук С.А. | I9: Географія Наговська Т.С. | J9: Зарубіжна література Сербулова Ю.А. | K9: Захист України Лазар В.І. | L9: Іноземна мова Сербулова Ю.А. | M9: Інформатика Бєльдюгіна С.С. | N9: Історія України Левчук Т.Г. | O9: Математика Бондаренко О.С. | P9: Українська література Антропова Л.І. | Q9: Українська мова Антропова Л.І. | R9: Фізика Калюта Н.М. | S9: Фізична культура Возіян О.Г. | T9: Хімія Сахно Н.О.
C10: Б | D10: 1 | E10: Бондаренко Андрій Миколайович | F10: 6 | G10: 4 | H10: 5 | I10: 9 | J10: 4 | K10: 5 | L10: 7 | M10: 8 | N10: н/а | O10: 10 | P10: 8 | Q10: 7 | R10: 8 | S10: 9 | T10: 5 | U10: =IF(COUNTIF($F10:T10,"=*")>0,IF($C10="К","-"," - "),IF(COUNTIF($F10:T10,"<4")>0,IF(C10="К","-"," - "),(IFERROR(AVERAGE($F10:T10),"Очікую"))))
C11: Б | D11: 2 | E11: Гриценко Світлана Анатоліївна | F11: 7 | G11: 8 | H11: 5 | I11: 7 | J11: 9 | K11: 6 | L11: 9 | M11: 11 | N11: н/а | O11: 8 | P11: 7 | Q11: 7 | R11: 11 | S11: 4 | T11: 5 | U11: =IF(COUNTIF($F11:T11,"=*")>0,IF($C11="К","-"," - "),IF(COUNTIF($F11:T11,"<4")>0,IF(C11="К","-"," - "),(IFERROR(AVERAGE($F11:T11),"Очікую"))))
C12: К | D12: 3 | E12: Карєва Анастасія Сергіївна | F12: 4 | G12: 11 | H12: 5 | I12: 4 | J12: н/а | K12: 4 | L12: 10 | M12: 11 | N12: 6 | O12: 8 | P12: 9 | Q12: 10 | R12: 10 | S12: н/а | T12: 9 | U12: =IF(COUNTIF($F12:T12,"=*")>0,IF($C12="К","-"," - "),IF(COUNTIF($F12:T12,"<4")>0,IF(C12="К","-"," - "),(IFERROR(AVERAGE($F12:T12),"Очікую"))))
C13: К | D13: 4 | E13: Ковальчук Наталія Петрівна | F13: 8 | G13: 5 | H13: 6 | I13: 6 | J13: 10 | K13: 7 | L13: 9 | M13: 5 | N13: 8 | O13: 10 | P13: 5 | Q13: 8 | R13: 6 | S13: 11 | T13: 11 | U13: =IF(COUNTIF($F13:T13,"=*")>0,IF($C13="К","-"," - "),IF(COUNTIF($F13:T13,"<4")>0,IF(C13="К","-"," - "),(IFERROR(AVERAGE($F13:T13),"Очікую"))))
C14: Б | D14: 5 | E14: Кравченко Денис Юрійович | F14: 9 | G14: 6 | H14: 7 | I14: 4 | J14: 6 | K14: 7 | L14: н/а | M14: 6 | N14: 11 | O14: 10 | P14: н/а | Q14: 5 | R14: 10 | S14: 10 | T14: 5 | U14: =IF(COUNTIF($F14:T14,"=*")>0,IF($C14="К","-"," - "),IF(COUNTIF($F14:T14,"<4")>0,IF(C14="К","-"," - "),(IFERROR(AVERAGE($F14:T14),"Очікую"))))
C15: К | D15: 6 | E15: Лєрманова Олена Євгенівна | F15: 4 | G15: 8 | H15: 4 | I15: 5 | J15: 11 | K15: 6 | L15: 8 | M15: 8 | N15: 10 | O15: 7 | P15: н/а | Q15: 5 | R15: н/а | S15: 11 | T15: н/а | U15: =IF(COUNTIF($F15:T15,"=*")>0,IF($C15="К","-"," - "),IF(COUNTIF($F15:T15,"<4")>0,IF(C15="К","-"," - "),(IFERROR(AVERAGE($F15:T15),"Очікую"))))
C16: Б | D16: 7 | E16: Лисенко Олена Володимирівна | F16: 8 | G16: 8 | H16: 8 | I16: н/а | J16: 10 | K16: 8 | L16: 8 | M16: 4 | N16: 8 | O16: 8 | P16: н/а | Q16: н/а | R16: 5 | S16: 10 | T16: 10 | U16: =IF(COUNTIF($F16:T16,"=*")>0,IF($C16="К","-"," - "),IF(COUNTIF($F16:T16,"<4")>0,IF(C16="К","-"," - "),(IFERROR(AVERAGE($F16:T16),"Очікую"))))
C17: К | D17: 8 | E17: Мельниченко Софія Ігорівна | F17: 10 | G17: 8 | H17: 7 | I17: 8 | J17: 11 | K17: 9 | L17: 10 | M17: 10 | N17: 9 | O17: 6 | P17: 5 | Q17: 7 | R17: 8 | S17: 10 | T17: 4 | U17: =IF(COUNTIF($F17:T17,"=*")>0,IF($C17="К","-"," - "),IF(COUNTIF($F17:T17,"<4")>0,IF(C17="К","-"," - "),(IFERROR(AVERAGE($F17:T17),"Очікую"))))
C18: К | D18: 9 | E18: Мороз Віктор Васильович | F18: 4 | G18: 9 | H18: 4 | I18: н/а | J18: 9 | K18: 6 | L18: н/а | M18: 11 | N18: 11 | O18: 10 | P18: 8 | Q18: 11 | R18: 9 | S18: 7 | T18: 11 | U18: =IF(COUNTIF($F18:T18,"=*")>0,IF($C18="К","-"," - "),IF(COUNTIF($F18:T18,"<4")>0,IF(C18="К","-"," - "),(IFERROR(AVERAGE($F18:T18),"Очікую"))))
C19: Б | D19: 10 | E19: Поліщук Артем Валерійович | F19: 4 | G19: 4 | H19: 7 | I19: 9 | J19: 9 | K19: 6 | L19: 8 | M19: 8 | N19: 10 | O19: 4 | P19: 11 | Q19: 7 | R19: 8 | S19: 10 | T19: 8 | U19: =IF(COUNTIF($F19:T19,"=*")>0,IF($C19="К","-"," - "),IF(COUNTIF($F19:T19,"<4")>0,IF(C19="К","-"," - "),(IFERROR(AVERAGE($F19:T19),"Очікую"))))
C20: Б | D20: 11 | E20: Присяжнюк Аміна Михайлівна | F20: 8 | G20: 11 | H20: 4 | I20: 10 | J20: 5 | K20: 8 | L20: 11 | M20: 9 | N20: 5 | O20: 8 | P20: 4 | Q20: 7 | R20: 11 | S20: 8 | T20: 5 | U20: =IF(COUNTIF($F20:T20,"=*")>0,IF($C20="К","-"," - "),IF(COUNTIF($F20:T20,"<4")>0,IF(C20="К","-"," - "),(IFERROR(AVERAGE($F20:T20),"Очікую"))))
C21: К | D21: 12 | E21: Савельєв Олександр Вячеславович | F21: 9 | G21: 8 | H21: 11 | I21: 5 | J21: 8 | K21: 5 | L21: 5 | M21: 8 | N21: 6 | O21: 11 | P21: 9 | Q21: 8 | R21: 8 | S21: 8 | T21: 8 | U21: =IF(COUNTIF($F21:T21,"=*")>0,IF($C21="К","-"," - "),IF(COUNTIF($F21:T21,"<4")>0,IF(C21="К","-"," - "),(IFERROR(AVERAGE($F21:T21),"Очікую"))))
C22: К | D22: 13 | E22: Савченко Марія Олегівна | F22: 11 | G22: 6 | H22: н/а | I22: 9 | J22: 9 | K22: н/а | L22: 8 | M22: 11 | N22: 5 | O22: 6 | P22: 4 | Q22: 11 | R22: 9 | S22: 6 | T22: 8 | U22: =IF(COUNTIF($F22:T22,"=*")>0,IF($C22="К","-"," - "),IF(COUNTIF($F22:T22,"<4")>0,IF(C22="К","-"," - "),(IFERROR(AVERAGE($F22:T22),"Очікую"))))
C23: Б | D23: 14 | E23: Самойлова Яна Вячеславівна | F23: 11 | G23: 8 | H23: 4 | I23: 9 | J23: 7 | K23: 5 | L23: 8 | M23: 5 | N23: 9 | O23: 4 | P23: 8 | Q23: 8 | R23: 6 | S23: 9 | T23: 9 | U23: =IF(COUNTIF($F23:T23,"=*")>0,IF($C23="К","-"," - "),IF(COUNTIF($F23:T23,"<4")>0,IF(C23="К","-"," - "),(IFERROR(AVERAGE($F23:T23),"Очікую"))))
C24: Б | D24: 15 | E24: Стегарь Евеліна Сергіївна | F24: 11 | G24: 5 | H24: 6 | I24: 6 | J24: н/а | K24: 10 | L24: 9 | M24: 11 | N24: 11 | O24: 11 | P24: 10 | Q24: 11 | R24: 10 | S24: 11 | T24: 8 | U24: =IF(COUNTIF($F24:T24,"=*")>0,IF($C24="К","-"," - "),IF(COUNTIF($F24:T24,"<4")>0,IF(C24="К","-"," - "),(IFERROR(AVERAGE($F24:T24),"Очікую"))))
C25: К | D25: 16 | E25: Ткаченко Ірина Сергіївна | F25: 5 | G25: 10 | H25: 10 | I25: 8 | J25: 9 | K25: 9 | L25: 9 | M25: 4 | N25: 9 | O25: 8 | P25: 10 | Q25: 8 | R25: 11 | S25: 8 | T25: 8 | U25: =IF(COUNTIF($F25:T25,"=*")>0,IF($C25="К","-"," - "),IF(COUNTIF($F25:T25,"<4")>0,IF(C25="К","-"," - "),(IFERROR(AVERAGE($F25:T25),"Очікую"))))
C26: Б | D26: 17 | E26: Цвєтков Андрій Геннадійович | F26: 8 | G26: 7 | H26: н/а | I26: 4 | J26: 7 | K26: 8 | L26: 5 | M26: 10 | N26: 4 | O26: 8 | P26: 8 | Q26: 6 | R26: 4 | S26: 7 | T26: 10 | U26: =IF(COUNTIF($F26:T26,"=*")>0,IF($C26="К","-"," - "),IF(COUNTIF($F26:T26,"<4")>0,IF(C26="К","-"," - "),(IFERROR(AVERAGE($F26:T26),"Очікую"))))
C27: Б | D27: 18 | E27: Шевченко Олександр Іванович | F27: 9 | G27: 9 | H27: 7 | I27: 11 | J27: н/а | K27: 10 | L27: 8 | M27: 8 | N27: 5 | O27: 7 | P27: 7 | Q27: 4 | R27: 8 | S27: 4 | T27: 8 | U27: =IF(COUNTIF($F27:T27,"=*")>0,IF($C27="К","-"," - "),IF(COUNTIF($F27:T27,"<4")>0,IF(C27="К","-"," - "),(IFERROR(AVERAGE($F27:T27),"Очікую"))))
E28: Середній бал успішності з дисципліни | F28: =IF(SUM(F$10:F27)=0,IF(COUNTA(F$10:F27)=0,"Очікую",0),SUM(F$10:F27)/$D27) | G28: =IF(SUM(G$10:G27)=0,IF(COUNTA(G$10:G27)=0,"Очікую",0),SUM(G$10:G27)/$D27) | H28: =IF(SUM(H$10:H27)=0,IF(COUNTA(H$10:H27)=0,"Очікую",0),SUM(H$10:H27)/$D27) | I28: =IF(SUM(I$10:I27)=0,IF(COUNTA(I$10:I27)=0,"Очікую",0),SUM(I$10:I27)/$D27) | J28: =IF(SUM(J$10:J27)=0,IF(COUNTA(J$10:J27)=0,"Очікую",0),SUM(J$10:J27)/$D27) | K28: =IF(SUM(K$10:K27)=0,IF(COUNTA(K$10:K27)=0,"Очікую",0),SUM(K$10:K27)/$D27) | L28: =IF(SUM(L$10:L27)=0,IF(COUNTA(L$10:L27)=0,"Очікую",0),SUM(L$10:L27)/$D27) | M28: =IF(SUM(M$10:M27)=0,IF(COUNTA(M$10:M27)=0,"Очікую",0),SUM(M$10:M27)/$D27) | ... T28: =IF(SUM(T$10:T27)=0,IF(COUNTA(T$10:T27)=0,"Очікую",0),SUM(T$10:T27)/$D27) | U28: =IFERROR(AVERAGE($F28:T28),"Очікую")
E29: Абсолютна успішність | F29: =IF(SUM(F$10:F27)=0,IF(COUNTA(F$10:F27)=0,"Очікую",0),IF(COUNTIF(F$10:F27,">=4")=0,0,COUNTIF(F$10:F27,">=4")/$D27*100)) | G29: =IF(SUM(G$10:G27)=0,IF(COUNTA(G$10:G27)=0,"Очікую",0),IF(COUNTIF(G$10:G27,">=4")=0,0,COUNTIF(G$10:G27,">=4")/$D27*100)) | H29: =IF(SUM(H$10:H27)=0,IF(COUNTA(H$10:H27)=0,"Очікую",0),IF(COUNTIF(H$10:H27,">=4")=0,0,COUNTIF(H$10:H27,">=4")/$D27*100)) | I29: =IF(SUM(I$10:I27)=0,IF(COUNTA(I$10:I27)=0,"Очікую",0),IF(COUNTIF(I$10:I27,">=4")=0,0,COUNTIF(I$10:I27,">=4")/$D27*100)) | J29: =IF(SUM(J$10:J27)=0,IF(COUNTA(J$10:J27)=0,"Очікую",0),IF(COUNTIF(J$10:J27,">=4")=0,0,COUNTIF(J$10:J27,">=4")/$D27*100)) | K29: =IF(SUM(K$10:K27)=0,IF(COUNTA(K$10:K27)=0,"Очікую",0),IF(COUNTIF(K$10:K27,">=4")=0,0,COUNTIF(K$10:K27,">=4")/$D27*100)) | L29: =IF(SUM(L$10:L27)=0,IF(COUNTA(L$10:L27)=0,"Очікую",0),IF(COUNTIF(L$10:L27,">=4")=0,0,COUNTIF(L$10:L27,">=4")/$D27*100)) | M29: =IF(SUM(M$10:M27)=0,IF(COUNTA(M$10:M27)=0,"Очікую",0),IF(COUNTIF(M$10:M27,">=4")=0,0,COUNTIF(M$10:M27,">=4")/$D27*100)) | ... T29: =IF(SUM(T$10:T27)=0,IF(COUNTA(T$10:T27)=0,"Очікую",0),IF(COUNTIF(T$10:T27,">=4")=0,0,COUNTIF(T$10:T27,">=4")/$D27*100))
E30: Якісна успішність | F30: =IF(SUM(F$10:F27)=0,IF(COUNTA(F$10:F27)=0,"Очікую",0),IF(COUNTIF(F$10:F27,">=7")=0,0,COUNTIF(F$10:F27,">=7")/$D27*100)) | G30: =IF(SUM(G$10:G27)=0,IF(COUNTA(G$10:G27)=0,"Очікую",0),IF(COUNTIF(G$10:G27,">=7")=0,0,COUNTIF(G$10:G27,">=7")/$D27*100)) | H30: =IF(SUM(H$10:H27)=0,IF(COUNTA(H$10:H27)=0,"Очікую",0),IF(COUNTIF(H$10:H27,">=7")=0,0,COUNTIF(H$10:H27,">=7")/$D27*100)) | I30: =IF(SUM(I$10:I27)=0,IF(COUNTA(I$10:I27)=0,"Очікую",0),IF(COUNTIF(I$10:I27,">=7")=0,0,COUNTIF(I$10:I27,">=7")/$D27*100)) | J30: =IF(SUM(J$10:J27)=0,IF(COUNTA(J$10:J27)=0,"Очікую",0),IF(COUNTIF(J$10:J27,">=7")=0,0,COUNTIF(J$10:J27,">=7")/$D27*100)) | K30: =IF(SUM(K$10:K27)=0,IF(COUNTA(K$10:K27)=0,"Очікую",0),IF(COUNTIF(K$10:K27,">=7")=0,0,COUNTIF(K$10:K27,">=7")/$D27*100)) | L30: =IF(SUM(L$10:L27)=0,IF(COUNTA(L$10:L27)=0,"Очікую",0),IF(COUNTIF(L$10:L27,">=7")=0,0,COUNTIF(L$10:L27,">=7")/$D27*100)) | M30: =IF(SUM(M$10:M27)=0,IF(COUNTA(M$10:M27)=0,"Очікую",0),IF(COUNTIF(M$10:M27,">=7")=0,0,COUNTIF(M$10:M27,">=7")/$D27*100)) | ... T30: =IF(SUM(T$10:T27)=0,IF(COUNTA(T$10:T27)=0,"Очікую",0),IF(COUNTIF(T$10:T27,">=7")=0,0,COUNTIF(T$10:T27,">=7")/$D27*100))
E31: Абсолютна успішність по групі | F31: =IFERROR(AVERAGE(F29:T29),"Очікую")
E32: Якісна успішність по групі | F32: =IFERROR(AVERAGE($F30:T30),"Очікую")
E33: Кількість бюджетників | F33: =IF(COUNTIF($C$10:$C27,"=Б")=0,IF(COUNTIF($C$10:$C27,"=К")=0,"Очікую",0),COUNTIF($C$10:$C27,"=Б"))
E34: Кількість контрактників | F34: =IF(COUNTIF($C$10:$C27,"=К")=0,IF(COUNTIF($C$10:$C27,"=Б")=0,"Очікую",0),COUNTIF($C$10:$C27,"=К")) | H34: Класний керівник | P34: Ірина ДОПІРА
E35: Кількість соціального контингенту | F35: 0
E36: Вийшли на стипендію | F36: =IF(F33="Очікую","Очікую",IF(F33-COUNTIF($U$10:$U27," - ")<ROUNDDOWN(F33*0.4,0),F33-COUNTIF($U$10:$U27," - "),ROUNDDOWN(F33*0.4,0))) | H36: Завідувач відділення ПЗСО | P36: Маргарита БРІТІКОВА

Sheet Зведена D7
A1: S
C3: ВІДОКРЕМЛЕНИЙ СТРУКТУРНИЙ ПІДРОЗДІЛ «ФАХОВИЙ КОЛЕДЖ НАФТОГАЗОВИХ ТЕХНОЛОГІЙ, ІНЖЕНЕРІЇ ТА ІНФРАСТРУКТУРИ СЕРВІСУ ОДЕСЬКОГО НАЦІОНАЛЬНОГО ТЕХНОЛОГІЧНОГО УНІВЕРСИТЕТУ»
C4: ЗВЕДЕНА ВІДОМІСТЬ
C5: Успішності студентів спеціальності D7 «Торгівля»
C6: За ІІ семестр 2025-2026 н.р.
C7: Група 26-1 курс І
C8: Б/К | D8: № п/п | E8: Прізвище, ім’я, по батькові | F8: Підсумкові оцінки дисциплін | U8: Середній бал
F9: Астрономія Наговська Т.С. | G9: Біологія Богданенко О.В. | H9: Всесвітня історія Мельничук С.А. | I9: Географія Наговська Т.С. | J9: Зарубіжна література Сербулова Ю.А. | K9: Захист України Лазар В.І. | L9: Іноземна мова Сербулова Ю.А. | M9: Інформатика Бєльдюгіна С.С. | N9: Історія України Левчук Т.Г. | O9: Математика Бондаренко О.С. | P9: Українська література Антропова Л.І. | Q9: Українська мова Антропова Л.І. | R9: Фізика Калюта Н.М. | S9: Фізична культура Возіян О.Г. | T9: Хімія Сахно Н.О.
C10: Б | D10: 1 | E10: Безуглий Юрій Віталійович | F10: 6 | G10: 10 | H10: 11 | I10: 6 | J10: 9 | K10: 4 | L10: 8 | M10: 5 | N10: 6 | O10: 6 | P10: 5 | Q10: 9 | R10: 8 | S10: 7 | T10: 5 | U10: =IF(COUNTIF($F10:T10,"=*")>0,IF($C10="К","-"," - "),IF(COUNTIF($F10:T10,"<4")>0,IF(C10="К","-"," - "),(IFERROR(AVERAGE($F10:T10),"Очікую"))))
C11: Б | D11: 2 | E11: Білан Інна Євгенівна | F11: 4 | G11: 11 | H11: 8 | I11: 6 | J11: 6 | K11: 5 | L11: 6 | M11: 8 | N11: 10 | O11: 7 | P11: 5 | Q11: 4 | R11: 8 | S11: 4 | T11: 7 | U11: =IF(COUNTIF($F11:T11,"=*")>0,IF($C11="К","-"," - "),IF(COUNTIF($F11:T11,"<4")>0,IF(C11="К","-"," - "),(IFERROR(AVERAGE($F11:T11),"Очікую"))))
C12: К | D12: 3 | E12: Білик Анастасія Павлівна | F12: 7 | G12: 6 | H12: 5 | I12: 8 | J12: н/а | K12: н/а | L12: 6 | M12: 7 | N12: 7 | O12: 10 | P12: 5 | Q12: 9 | R12: 6 | S12: 8 | T12: 7 | U12: =IF(COUNTIF($F12:T12,"=*")>0,IF($C12="К","-"," - "),IF(COUNTIF($F12:T12,"<4")>0,IF(C12="К","-"," - "),(IFERROR(AVERAGE($F12:T12),"Очікую"))))
C13: К | D13: 4 | E13: Волошин Кирило Миколайович | F13: 4 | G13: 9 | H13: 8 | I13: 8 | J13: 4 | K13: 4 | L13: 7 | M13: 9 | N13: 7 | O13: 4 | P13: 8 | Q13: 8 | R13: 5 | S13: 10 | T13: 8 | U13: =IF(COUNTIF($F13:T13,"=*")>0,IF($C13="К","-"," - "),IF(COUNTIF($F13:T13,"<4")>0,IF(C13="К","-"," - "),(IFERROR(AVERAGE($F13:T13),"Очікую"))))
C14: Б | D14: 5 | E14: Гаврилюк Маргарита Тимофіївна | F14: 7 | G14: 4 | H14: 8 | I14: 8 | J14: 10 | K14: 6 | L14: 8 | M14: 10 | N14: 8 | O14: 8 | P14: 8 | Q14: 4 | R14: 8 | S14: 10 | T14: 8 | U14: =IF(COUNTIF($F14:T14,"=*")>0,IF($C14="К","-"," - "),IF(COUNTIF($F14:T14,"<4")>0,IF(C14="К","-"," - "),(IFERROR(AVERAGE($F14:T14),"Очікую"))))
C15: Б | D15: 6 | E15: Гончар Марія Сергіївна | F15: 4 | G15: н/а | H15: 8 | I15: 4 | J15: 6 | K15: 4 | L15: 7 | M15: 9 | N15: 11 | O15: 7 | P15: 4 | Q15: 5 | R15: 6 | S15: 8 | T15: 8 | U15: =IF(COUNTIF($F15:T15,"=*")>0,IF($C15="К","-"," - "),IF(COUNTIF($F15:T15,"<4")>0,IF(C15="К","-"," - "),(IFERROR(AVERAGE($F15:T15),"Очікую"))))
C16: Б | D16: 7 | E16: Дяченко Катерина Дмитрівна | F16: 4 | G16: 8 | H16: 6 | I16: 5 | J16: 11 | K16: 7 | L16: 7 | M16: 6 | N16: 10 | O16: 7 | P16: 6 | Q16: 6 | R16: 4 | S16: 6 | T16: 6 | U16: =IF(COUNTIF($F16:T16,"=*")>0,IF($C16="К","-"," - "),IF(COUNTIF($F16:T16,"<4")>0,IF(C16="К","-"," - "),(IFERROR(AVERAGE($F16:T16),"Очікую"))))
C17: Б | D17: 8 | E17: Зінченко Богдан Романович | F17: 6 | G17: 9 | H17: 9 | I17: 8 | J17: 6 | K17: 10 | L17: 11 | M17: 6 | N17: 11 | O17: 7 | P17: 7 | Q17: 10 | R17: 6 | S17: 7 | T17: 8 | U17: =IF(COUNTIF($F17:T17,"=*")>0,IF($C17="К","-"," - "),IF(COUNTIF($F17:T17,"<4")>0,IF(C17="К","-"," - "),(IFERROR(AVERAGE($F17:T17),"Очікую"))))
C18: Б | D18: 9 | E18: Клименко Алла Михайлівна | F18: 11 | G18: 4 | H18: 4 | I18: 11 | J18: 8 | K18: 5 | L18: 10 | M18: 8 | N18: 5 | O18: 9 | P18: 6 | Q18: 4 | R18: 10 | S18: 8 | T18: 8 | U18: =IF(COUNTIF($F18:T18,"=*")>0,IF($C18="К","-"," - "),IF(COUNTIF($F18:T18,"<4")>0,IF(C18="К","-"," - "),(IFERROR(AVERAGE($F18:T18),"Очікую"))))
C19: К | D19: 10 | E19: Козак Дмитро Вікторович | F19: 11 | G19: 9 | H19: 10 | I19: 8 | J19: 8 | K19: 4 | L19: 6 | M19: 8 | N19: 6 | O19: 6 | P19: 10 | Q19: 6 | R19: 6 | S19: 11 | T19: 7 | U19: =IF(COUNTIF($F19:T19,"=*")>0,IF($C19="К","-"," - "),IF(COUNTIF($F19:T19,"<4")>0,IF(C19="К","-"," - "),(IFERROR(AVERAGE($F19:T19),"Очікую"))))
C20: Б | D20: 11 | E20: Козаченко Роман Анатолійович | F20: 5 | G20: 9 | H20: 9 | I20: 6 | J20: 5 | K20: 10 | L20: 6 | M20: 7 | N20: 7 | O20: 6 | P20: 7 | Q20: 8 | R20: 10 | S20: 6 | T20: 7 | U20: =IF(COUNTIF($F20:T20,"=*")>0,IF($C20="К","-"," - "),IF(COUNTIF($F20:T20,"<4")>0,IF(C20="К","-"," - "),(IFERROR(AVERAGE($F20:T20),"Очікую"))))
C21: Б | D21: 12 | E21: Корнієнко Владислава Іванівна | F21: 5 | G21: 10 | H21: 6 | I21: 5 | J21: н/а | K21: 5 | L21: 8 | M21: 6 | N21: 7 | O21: 8 | P21: 10 | Q21: 5 | R21: 9 | S21: 8 | T21: 5 | U21: =IF(COUNTIF($F21:T21,"=*")>0,IF($C21="К","-"," - "),IF(COUNTIF($F21:T21,"<4")>0,IF(C21="К","-"," - "),(IFERROR(AVERAGE($F21:T21),"Очікую"))))
C22: Б | D22: 13 | E22: Куліш Дарина Олегівна | F22: 4 | G22: 7 | H22: 8 | I22: 11 | J22: 4 | K22: 9 | L22: 5 | M22: 8 | N22: 6 | O22: 8 | P22: 8 | Q22: 11 | R22: 7 | S22: 11 | T22: 8 | U22: =IF(COUNTIF($F22:T22,"=*")>0,IF($C22="К","-"," - "),IF(COUNTIF($F22:T22,"<4")>0,IF(C22="К","-"," - "),(IFERROR(AVERAGE($F22:T22),"Очікую"))))
C23: К | D23: 14 | E23: Левченко Вікторія Василівна | F23: 7 | G23: 8 | H23: 8 | I23: 9 | J23: 6 | K23: 10 | L23: 10 | M23: 9 | N23: н/а | O23: 11 | P23: 11 | Q23: 7 | R23: 4 | S23: 10 | T23: 6 | U23: =IF(COUNTIF($F23:T23,"=*")>0,IF($C23="К","-"," - "),IF(COUNTIF($F23:T23,"<4")>0,IF(C23="К","-"," - "),(IFERROR(AVERAGE($F23:T23),"Очікую"))))
C24: Б | D24: 15 | E24: Мельничук Людмила Петрівна | F24: 8 | G24: 8 | H24: 7 | I24: 8 | J24: 8 | K24: 6 | L24: 7 | M24: 6 | N24: 7 | O24: 6 | P24: 9 | Q24: 5 | R24: 4 | S24: 5 | T24: 5 | U24: =IF(COUNTIF($F24:T24,"=*")>0,IF($C24="К","-"," - "),IF(COUNTIF($F24:T24,"<4")>0,IF(C24="К","-"," - "),(IFERROR(AVERAGE($F24:T24),"Очікую"))))
C25: К | D25: 16 | E25: Нікітенко Владислав Юрійович | F25: 10 | G25: 8 | H25: 9 | I25: 9 | J25: 8 | K25: 8 | L25: 9 | M25: 10 | N25: 5 | O25: 10 | P25: 8 | Q25: 5 | R25: 5 | S25: 5 | T25: 6 | U25: =IF(COUNTIF($F25:T25,"=*")>0,IF($C25="К","-"," - "),IF(COUNTIF($F25:T25,"<4")>0,IF(C25="К","-"," - "),(IFERROR(AVERAGE($F25:T25),"Очікую"))))
C26: К | D26: 17 | E26: Орленко Арсен Романович | F26: 5 | G26: 9 | H26: 7 | I26: 9 | J26: 8 | K26: 11 | L26: 8 | M26: 9 | N26: 6 | O26: 9 | P26: 6 | Q26: 10 | R26: 5 | S26: 11 | T26: 9 | U26: =IF(COUNTIF($F26:T26,"=*")>0,IF($C26="К","-"," - "),IF(COUNTIF($F26:T26,"<4")>0,IF(C26="К","-"," - "),(IFERROR(AVERAGE($F26:T26),"Очікую"))))
C27: Б | D27: 18 | E27: Остапчук Максим Олександрович | F27: 11 | G27: 8 | H27: 6 | I27: 9 | J27: 11 | K27: 4 | L27: 4 | M27: 8 | N27: 11 | O27: 9 | P27: 10 | Q27: 7 | R27: 9 | S27: 10 | T27: 9 | U27: =IF(COUNTIF($F27:T27,"=*")>0,IF($C27="К","-"," - "),IF(COUNTIF($F27:T27,"<4")>0,IF(C27="К","-"," - "),(IFERROR(AVERAGE($F27:T27),"Очікую"))))
C28: К | D28: 19 | E28: Паламарчук Оксана Валентинівна | F28: 9 | G28: 6 | H28: 9 | I28: 6 | J28: 8 | K28: 8 | L28: 5 | M28: 7 | N28: 8 | O28: 7 | P28: 9 | Q28: 11 | R28: 10 | S28: 7 | T28: н/а | U28: =IF(COUNTIF($F28:T28,"=*")>0,IF($C28="К","-"," - "),IF(COUNTIF($F28:T28,"<4")>0,IF(C28="К","-"," - "),(IFERROR(AVERAGE($F28:T28),"Очікую"))))
C29: К | D29: 20 | E29: Панченко Тетяна Ігорівна | F29: 8 | G29: 7 | H29: 10 | I29: 10 | J29: 4 | K29: 8 | L29: 7 | M29: 8 | N29: 5 | O29: 10 | P29: 10 | Q29: 9 | R29: 6 | S29: 11 | T29: 6 | U29: =IF(COUNTIF($F29:T29,"=*")>0,IF($C29="К","-"," - "),IF(COUNTIF($F29:T29,"<4")>0,IF(C29="К","-"," - "),(IFERROR(AVERAGE($F29:T29),"Очікую"))))
C30: К | D30: 21 | E30: Петренко Назар Борисович | F30: 8 | G30: 8 | H30: 5 | I30: 7 | J30: 10 | K30: 7 | L30: 8 | M30: 6 | N30: 5 | O30: 8 | P30: 5 | Q30: 10 | R30: 11 | S30: 10 | T30: 10 | U30: =IF(COUNTIF($F30:T30,"=*")>0,IF($C30="К","-"," - "),IF(COUNTIF($F30:T30,"<4")>0,IF(C30="К","-"," - "),(IFERROR(AVERAGE($F30:T30),"Очікую"))))
C31: К | D31: 22 | E31: Романенко Юлія Андріївна | F31: 11 | G31: 4 | H31: 4 | I31: н/а | J31: 4 | K31: 8 | L31: н/а | M31: 6 | N31: 7 | O31: 10 | P31: 8 | Q31: н/а | R31: 7 | S31: 10 | T31: 11 | U31: =IF(COUNTIF($F31:T31,"=*")>0,IF($C31="К","-"," - "),IF(COUNTIF($F31:T31,"<4")>0,IF(C31="К","-"," - "),(IFERROR(AVERAGE($F31:T31),"Очікую"))))
C32: Б | D32: 23 | E32: Семенюк Марина Григорівна | F32: 6 | G32: 5 | H32: 9 | I32: 10 | J32: 9 | K32: 5 | L32: 4 | M32: 6 | N32: 9 | O32: 8 | P32: 8 | Q32: 7 | R32: 7 | S32: 9 | T32: 9 | U32: =IF(COUNTIF($F32:T32,"=*")>0,IF($C32="К","-"," - "),IF(COUNTIF($F32:T32,"<4")>0,IF(C32="К","-"," - "),(IFERROR(AVERAGE($F32:T32),"Очікую"))))
C33: Б | D33: 24 | E33: Сидоренко Ілля Артемович | F33: 10 | G33: 8 | H33: 9 | I33: 9 | J33: 8 | K33: 10 | L33: 5 | M33: 10 | N33: 8 | O33: 10 | P33: 10 | Q33: 8 | R33: 8 | S33: 10 | T33: 10 | U33: =IF(COUNTIF($F33:T33,"=*")>0,IF($C33="К","-"," - "),IF(COUNTIF($F33:T33,"<4")>0,IF(C33="К","-"," - "),(IFERROR(AVERAGE($F33:T33),"Очікую"))))
C34: К | D34: 25 | E34: Тимченко Олексій Вікторович | F34: 11 | G34: н/а | H34: 9 | I34: 11 | J34: н/а | K34: 11 | L34: 6 | M34: 10 | N34: 5 | O34: 8 | P34: 8 | Q34: 9 | R34: 5 | S34: н/а | T34: 9 | U34: =IF(COUNTIF($F34:T34,"=*")>0,IF($C34="К","-"," - "),IF(COUNTIF($F34:T34,"<4")>0,IF(C34="К","-"," - "),(IFERROR(AVERAGE($F34:T34),"Очікую"))))
C35: К | D35: 26 | E35: Харченко Ганна Олексіївна | F35: 8 | G35: 8 | H35: 4 | I35: 4 | J35: 9 | K35: 6 | L35: 10 | M35: н/а | N35: 5 | O35: 6 | P35: 10 | Q35: 10 | R35: н/а | S35: 11 | T35: 8 | U35: =IF(COUNTIF($F35:T35,"=*")>0,IF($C35="К","-"," - "),IF(COUNTIF($F35:T35,"<4")>0,IF(C35="К","-"," - "),(IFERROR(AVERAGE($F35:T35),"Очікую"))))
C36: К | D36: 27 | E36: Черненко Вадим Павлович | F36: 8 | G36: 8 | H36: 7 | I36: 8 | J36: 8 | K36: 6 | L36: 4 | M36: 5 | N36: 5 | O36: 8 | P36: 6 | Q36: 6 | R36: 5 | S36: 7 | T36: 10 | U36: =IF(COUNTIF($F36:T36,"=*")>0,IF($C36="К","-"," - "),IF(COUNTIF($F36:T36,"<4")>0,IF(C36="К","-"," - "),(IFERROR(AVERAGE($F36:T36),"Очікую"))))
C37: К | D37: 28 | E37: Чорний Степан Ігорович | F37: 9 | G37: 9 | H37: 6 | I37: 11 | J37: 8 | K37: 11 | L37: 8 | M37: 5 | N37: 5 | O37: 10 | P37: 8 | Q37: 10 | R37: 7 | S37: 7 | T37: 10 | U37: =IF(COUNTIF($F37:T37,"=*")>0,IF($C37="К","-"," - "),IF(COUNTIF($F37:T37,"<4")>0,IF(C37="К","-"," - "),(IFERROR(AVERAGE($F37:T37),"Очікую"))))
C38: К | D38: 29 | E38: Шаповал Аліна Сергіївна | F38: 5 | G38: 11 | H38: 6 | I38: 8 | J38: 11 | K38: 6 | L38: 9 | M38: 8 | N38: 6 | O38: 9 | P38: 8 | Q38: 10 | R38: 8 | S38: 8 | T38: 11 | U38: =IF(COUNTIF($F38:T38,"=*")>0,IF($C38="К","-"," - "),IF(COUNTIF($F38:T38,"<4")>0,IF(C38="К","-"," - "),(IFERROR(AVERAGE($F38:T38),"Очікую"))))
C39: К | D39: 30 | E39: Яремчук Євген Степанович | F39: 8 | G39: н/а | H39: 5 | I39: 4 | J39: 8 | K39: 7 | L39: 8 | M39: 7 | N39: 10 | O39: 7 | P39: 11 | Q39: 11 | R39: 6 | S39: 11 | T39: 8 | U39: =IF(COUNTIF($F39:T39,"=*")>0,IF($C39="К","-"," - "),IF(COUNTIF($F39:T39,"<4")>0,IF(C39="К","-"," - "),(IFERROR(AVERAGE($F39:T39),"Очікую"))))
E40: Середній бал успішності з дисципліни | F40: =IF(SUM(F$10:F39)=0,IF(COUNTA(F$10:F39)=0,"Очікую",0),SUM(F$10:F39)/$D39) | G40: =IF(SUM(G$10:G39)=0,IF(COUNTA(G$10:G39)=0,"Очікую",0),SUM(G$10:G39)/$D39) | H40: =IF(SUM(H$10:H39)=0,IF(COUNTA(H$10:H39)=0,"Очікую",0),SUM(H$10:H39)/$D39) | I40: =IF(SUM(I$10:I39)=0,IF(COUNTA(I$10:I39)=0,"Очікую",0),SUM(I$10:I39)/$D39) | J40: =IF(SUM(J$10:J39)=0,IF(COUNTA(J$10:J39)=0,"Очікую",0),SUM(J$10:J39)/$D39) | K40: =IF(SUM(K$10:K39)=0,IF(COUNTA(K$10:K39)=0,"Очікую",0),SUM(K$10:K39)/$D39) | L40: =IF(SUM(L$10:L39)=0,IF(COUNTA(L$10:L39)=0,"Очікую",0),SUM(L$10:L39)/$D39) | M40: =IF(SUM(M$10:M39)=0,IF(COUNTA(M$10:M39)=0,"Очікую",0),SUM(M$10:M39)/$D39) | ... T40: =IF(SUM(T$10:T39)=0,IF(COUNTA(T$10:T39)=0,"Очікую",0),SUM(T$10:T39)/$D39) | U40: =IFERROR(AVERAGE($F40:T40),"Очікую")
E41: Абсолютна успішність | F41: =IF(SUM(F$10:F39)=0,IF(COUNTA(F$10:F39)=0,"Очікую",0),IF(COUNTIF(F$10:F39,">=4")=0,0,COUNTIF(F$10:F39,">=4")/$D39*100)) | G41: =IF(SUM(G$10:G39)=0,IF(COUNTA(G$10:G39)=0,"Очікую",0),IF(COUNTIF(G$10:G39,">=4")=0,0,COUNTIF(G$10:G39,">=4")/$D39*100)) | H41: =IF(SUM(H$10:H39)=0,IF(COUNTA(H$10:H39)=0,"Очікую",0),IF(COUNTIF(H$10:H39,">=4")=0,0,COUNTIF(H$10:H39,">=4")/$D39*100)) | I41: =IF(SUM(I$10:I39)=0,IF(COUNTA(I$10:I39)=0,"Очікую",0),IF(COUNTIF(I$10:I39,">=4")=0,0,COUNTIF(I$10:I39,">=4")/$D39*100)) | J41: =IF(SUM(J$10:J39)=0,IF(COUNTA(J$10:J39)=0,"Очікую",0),IF(COUNTIF(J$10:J39,">=4")=0,0,COUNTIF(J$10:J39,">=4")/$D39*100)) | K41: =IF(SUM(K$10:K39)=0,IF(COUNTA(K$10:K39)=0,"Очікую",0),IF(COUNTIF(K$10:K39,">=4")=0,0,COUNTIF(K$10:K39,">=4")/$D39*100)) | L41: =IF(SUM(L$10:L39)=0,IF(COUNTA(L$10:L39)=0,"Очікую",0),IF(COUNTIF(L$10:L39,">=4")=0,0,COUNTIF(L$10:L39,">=4")/$D39*100)) | M41: =IF(SUM(M$10:M39)=0,IF(COUNTA(M$10:M39)=0,"Очікую",0),IF(COUNTIF(M$10:M39,">=4")=0,0,COUNTIF(M$10:M39,">=4")/$D39*100)) | ... T41: =IF(SUM(T$10:T39)=0,IF(COUNTA(T$10:T39)=0,"Очікую",0),IF(COUNTIF(T$10:T39,">=4")=0,0,COUNTIF(T$10:T39,">=4")/$D39*100))
...

Sheet Зведена G1
A1: S
C3: ВІДОКРЕМЛЕНИЙ СТРУКТУРНИЙ ПІДРОЗДІЛ «ФАХОВИЙ КОЛЕДЖ НАФТОГАЗОВИХ ТЕХНОЛОГІЙ, ІНЖЕНЕРІЇ ТА ІНФРАСТРУКТУРИ СЕРВІСУ ОДЕСЬКОГО НАЦІОНАЛЬНОГО ТЕХНОЛОГІЧНОГО УНІВЕРСИТЕТУ»
C4: ЗВЕДЕНА ВІДОМІСТЬ
C5: Успішності студентів спеціальності G1 «Хімічні технології та інженерія»
C6: За ІІ семестр 2025-2026 н.р.
C7: Група 26-1 курс І
C8: Б/К | D8: № п/п | E8: Прізвище, ім’я, по батькові | F8: Підсумкові оцінки дисциплін | U8: Середній бал
F9: Астрономія Наговська Т.С. | G9: Біологія Богданенко О.В. | H9: Всесвітня історія Мельничук С.А. | I9: Географія Наговська Т.С. | J9: Зарубіжна література Сербулова Ю.А. | K9: Захист України Лазар В.І. | L9: Іноземна мова Сербулова Ю.А. | M9: Інформатика Бєльдюгіна С.С. | N9: Історія України Левчук Т.Г. | O9: Математика Бондаренко О.С. | P9: Українська література Антропова Л.І. | Q9: Українська мова Антропова Л.І. | R9: Фізика Калюта Н.М. | S9: Фізична культура Возіян О.Г. | T9: Хімія Сахно Н.О.
C10: К | D10: 1 | E10: Бондарчук Ніна Григорівна | F10: 8 | G10: 8 | H10: 7 | I10: 8 | J10: 8 | K10: 6 | L10: 4 | M10: 5 | N10: 5 | O10: 8 | P10: 6 | Q10: 6 | R10: 5 | S10: 7 | T10: 10 | U10: =IF(COUNTIF($F10:T10,"=*")>0,IF($C10="К","-"," - "),IF(COUNTIF($F10:T10,"<4")>0,IF(C10="К","-"," - "),(IFERROR(AVERAGE($F10:T10),"Очікую"))))
C11: К | D11: 2 | E11: Дубовик Віра Михайлівна | F11: 11 | G11: 8 | H11: 6 | I11: 9 | J11: 11 | K11: 4 | L11: 4 | M11: 8 | N11: 11 | O11: 9 | P11: 10 | Q11: 7 | R11: 9 | S11: 10 | T11: 9 | U11: =IF(COUNTIF($F11:T11,"=*")>0,IF($C11="К","-"," - "),IF(COUNTIF($F11:T11,"<4")>0,IF(C11="К","-"," - "),(IFERROR(AVERAGE($F11:T11),"Очікую"))))
C12: К | D12: 3 | E12: Кушніренко Артем Олександрович | F12: 4 | G12: 8 | H12: 6 | I12: 5 | J12: 11 | K12: 7 | L12: 7 | M12: 6 | N12: 10 | O12: 7 | P12: 6 | Q12: 6 | R12: 4 | S12: 6 | T12: 6 | U12: =IF(COUNTIF($F12:T12,"=*")>0,IF($C12="К","-"," - "),IF(COUNTIF($F12:T12,"<4")>0,IF(C12="К","-"," - "),(IFERROR(AVERAGE($F12:T12),"Очікую"))))
C13: К | D13: 4 | E13: Назаренко Єгор Віталійович | F13: 8 | G13: 7 | H13: 10 | I13: 10 | J13: 4 | K13: 8 | L13: 7 | M13: 8 | N13: 5 | O13: 10 | P13: 10 | Q13: 9 | R13: 6 | S13: 11 | T13: 6 | U13: =IF(COUNTIF($F13:T13,"=*")>0,IF($C13="К","-"," - "),IF(COUNTIF($F13:T13,"<4")>0,IF(C13="К","-"," - "),(IFERROR(AVERAGE($F13:T13),"Очікую"))))
C14: К | D14: 5 | E14: Рябоконь Софія Юріївна | F14: 6 | G14: 9 | H14: 9 | I14: 8 | J14: 6 | K14: 10 | L14: 11 | M14: 6 | N14: 11 | O14: 7 | P14: 7 | Q14: 10 | R14: 6 | S14: 7 | T14: 8 | U14: =IF(COUNTIF($F14:T14,"=*")>0,IF($C14="К","-"," - "),IF(COUNTIF($F14:T14,"<4")>0,IF(C14="К","-"," - "),(IFERROR(AVERAGE($F14:T14),"Очікую"))))
C15: К | D15: 6 | E15: Соловей Микита Ігорович | F15: 11 | G15: 4 | H15: 4 | I15: 11 | J15: 8 | K15: 5 | L15: 10 | M15: 8 | N15: 5 | O15: 9 | P15: 6 | Q15: 4 | R15: 10 | S15: 8 | T15: 8 | U15: =IF(COUNTIF($F15:T15,"=*")>0,IF($C15="К","-"," - "),IF(COUNTIF($F15:T15,"<4")>0,IF(C15="К","-"," - "),(IFERROR(AVERAGE($F15:T15),"Очікую"))))
C16: К | D16: 7 | E16: Тарасенко Леонід Степанович | F16: 11 | G16: 4 | H16: 4 | I16: н/а | J16: 4 | K16: 8 | L16: н/а | M16: 6 | N16: 7 | O16: 10 | P16: 8 | Q16: н/а | R16: 7 | S16: 10 | T16: 11 | U16: =IF(COUNTIF($F16:T16,"=*")>0,IF($C16="К","-"," - "),IF(COUNTIF($F16:T16,"<4")>0,IF(C16="К","-"," - "),(IFERROR(AVERAGE($F16:T16),"Очікую"))))
E17: Середній бал успішності з дисципліни | F17: =IF(SUM(F$10:F16)=0,IF(COUNTA(F$10:F16)=0,"Очікую",0),SUM(F$10:F16)/$D16) | G17: =IF(SUM(G$10:G16)=0,IF(COUNTA(G$10:G16)=0,"Очікую",0),SUM(G$10:G16)/$D16) | H17: =IF(SUM(H$10:H16)=0,IF(COUNTA(H$10:H16)=0,"Очікую",0),SUM(H$10:H16)/$D16) | I17: =IF(SUM(I$10:I16)=0,IF(COUNTA(I$10:I16)=0,"Очікую",0),SUM(I$10:I16)/$D16) | J17: =IF(SUM(J$10:J16)=0,IF(COUNTA(J$10:J16)=0,"Очікую",0),SUM(J$10:J16)/$D16) | K17: =IF(SUM(K$10:K16)=0,IF(COUNTA(K$10:K16)=0,"Очікую",0),SUM(K$10:K16)/$D16) | L17: =IF(SUM(L$10:L16)=0,IF(COUNTA(L$10:L16)=0,"Очікую",0),SUM(L$10:L16)/$D16) | M17: =IF(SUM(M$10:M16)=0,IF(COUNTA(M$10:M16)=0,"Очікую",0),SUM(M$10:M16)/$D16) | ... T17: =IF(SUM(T$10:T16)=0,IF(COUNTA(T$10:T16)=0,"Очікую",0),SUM(T$10:T16)/$D16) | U17: =IFERROR(AVERAGE($F17:T17),"Очікую")
E18: Абсолютна успішність | F18: =IF(SUM(F$10:F16)=0,IF(COUNTA(F$10:F16)=0,"Очікую",0),IF(COUNTIF(F$10:F16,">=4")=0,0,COUNTIF(F$10:F16,">=4")/$D16*100)) | G18: =IF(SUM(G$10:G16)=0,IF(COUNTA(G$10:G16)=0,"Очікую",0),IF(COUNTIF(G$10:G16,">=4")=0,0,COUNTIF(G$10:G16,">=4")/$D16*100)) | H18: =IF(SUM(H$10:H16)=0,IF(COUNTA(H$10:H16)=0,"Очікую",0),IF(COUNTIF(H$10:H16,">=4")=0,0,COUNTIF(H$10:H16,">=4")/$D16*100)) | I18: =IF(SUM(I$10:I16)=0,IF(COUNTA(I$10:I16)=0,"Очікую",0),IF(COUNTIF(I$10:I16,">=4")=0,0,COUNTIF(I$10:I16,">=4")/$D16*100)) | J18: =IF(SUM(J$10:J16)=0,IF(COUNTA(J$10:J16)=0,"Очікую",0),IF(COUNTIF(J$10:J16,">=4")=0,0,COUNTIF(J$10:J16,">=4")/$D16*100)) | K18: =IF(SUM(K$10:K16)=0,IF(COUNTA(K$10:K16)=0,"Очікую",0),IF(COUNTIF(K$10:K16,">=4")=0,0,COUNTIF(K$10:K16,">=4")/$D16*100)) | L18: =IF(SUM(L$10:L16)=0,IF(COUNTA(L$10:L16)=0,"Очікую",0),IF(COUNTIF(L$10:L16,">=4")=0,0,COUNTIF(L$10:L16,">=4")/$D16*100)) | M18: =IF(SUM(M$10:M16)=0,IF(COUNTA(M$10:M16)=0,"Очікую",0),IF(COUNTIF(M$10:M16,">=4")=0,0,COUNTIF(M$10:M16,">=4")/$D16*100)) | ... T18: =IF(SUM(T$10:T16)=0,IF(COUNTA(T$10:T16)=0,"Очікую",0),IF(COUNTIF(T$10:T16,">=4")=0,0,COUNTIF(T$10:T16,">=4")/$D16*100))
E19: Якісна успішність | F19: =IF(SUM(F$10:F16)=0,IF(COUNTA(F$10:F16)=0,"Очікую",0),IF(COUNTIF(F$10:F16,">=7")=0,0,COUNTIF(F$10:F16,">=7")/$D16*100)) | G19: =IF(SUM(G$10:G16)=0,IF(COUNTA(G$10:G16)=0,"Очікую",0),IF(COUNTIF(G$10:G16,">=7")=0,0,COUNTIF(G$10:G16,">=7")/$D16*100)) | H19: =IF(SUM(H$10:H16)=0,IF(COUNTA(H$10:H16)=0,"Очікую",0),IF(COUNTIF(H$10:H16,">=7")=0,0,COUNTIF(H$10:H16,">=7")/$D16*100)) | I19: =IF(SUM(I$10:I16)=0,IF(COUNTA(I$10:I16)=0,"Очікую",0),IF(COUNTIF(I$10:I16,">=7")=0,0,COUNTIF(I$10:I16,">=7")/$D16*100)) | J19: =IF(SUM(J$10:J16)=0,IF(COUNTA(J$10:J16)=0,"Очікую",0),IF(COUNTIF(J$10:J16,">=7")=0,0,COUNTIF(J$10:J16,">=7")/$D16*100)) | K19: =IF(SUM(K$10:K16)=0,IF(COUNTA(K$10:K16)=0,"Очікую",0),IF(COUNTIF(K$10:K16,">=7")=0,0,COUNTIF(K$10:K16,">=7")/$D16*100)) | L19: =IF(SUM(L$10:L16)=0,IF(COUNTA(L$10:L16)=0,"Очікую",0),IF(COUNTIF(L$10:L16,">=7")=0,0,COUNTIF(L$10:L16,">=7")/$D16*100)) | M19: =IF(SUM(M$10:M16)=0,IF(COUNTA(M$10:M16)=0,"Очікую",0),IF(COUNTIF(M$10:M16,">=7")=0,0,COUNTIF(M$10:M16,">=7")/$D16*100)) | ... T19: =IF(SUM(T$10:T16)=0,IF(COUNTA(T$10:T16)=0,"Очікую",0),IF(COUNTIF(T$10:T16,">=7")=0,0,COUNTIF(T$10:T16,">=7")/$D16*100))
E20: Абсолютна успішність по групі | F20: =IFERROR(AVERAGE(F18:T18),"Очікую")
E21: Якісна успішність по групі | F21: =IFERROR(AVERAGE($F19:T19),"Очікую")
E22: Кількість бюджетників | F22: =IF(COUNTIF($C$10:$C16,"=Б")=0,IF(COUNTIF($C$10:$C16,"=К")=0,"Очікую",0),COUNTIF($C$10:$C16,"=Б"))
E23: Кількість контрактників | F23: =IF(COUNTIF($C$10:$C16,"=К")=0,IF(COUNTIF($C$10:$C16,"=Б")=0,"Очікую",0),COUNTIF($C$10:$C16,"=К")) | H23: Класний керівник | P23: Ірина ДОПІРА
E24: Кількість соціального контингенту | F24: 0
E25: Вийшли на стипендію | F25: =IF(F22="Очікую","Очікую",IF(F22-COUNTIF($U$10:$U16," - ")<ROUNDDOWN(F22*0.4,0),F22-COUNTIF($U$10:$U16," - "),ROUNDDOWN(F22*0.4,0))) | H25: Завідувач відділення ПЗСО | P25: Маргарита БРІТІКОВА

Sheet Рейтингова D5
A1: S
C3: ВІДОКРЕМЛЕНИЙ СТРУКТУРНИЙ ПІДРОЗДІЛ «ФАХОВИЙ КОЛЕДЖ НАФТОГАЗОВИХ ТЕХНОЛОГІЙ, ІНЖЕНЕРІЇ ТА ІНФРАСТРУКТУРИ СЕРВІСУ ОДЕСЬКОГО НАЦІОНАЛЬНОГО ТЕХНОЛОГІЧНОГО УНІВЕРСИТЕТУ»
C4: РЕЙТИНГОВА ВІДОМІСТЬ
C5: ='Зведена D5'!C5
C6: ='Зведена D5'!C6
C7: ='Зведена D5'!C7
C8: Б/К | D8: № п/п | E8: Прізвище, ім’я, по батькові | F8: Підсумкові оцінки дисциплін | U8: Середній бал | V8: Рейтинговий бал
F9: ='Зведена D5'!F9 | G9: ='Зведена D5'!G9 | H9: ='Зведена D5'!H9 | I9: ='Зведена D5'!I9 | J9: ='Зведена D5'!J9 | K9: ='Зведена D5'!K9 | L9: ='Зведена D5'!L9 | M9: ='Зведена D5'!M9 | ... T9: ='Зведена D5'!T9
C10: ='Зведена D5'!C20 | D10: 1 | E10: ='Зведена D5'!E20 | F10: ='Зведена D5'!F20 | G10: ='Зведена D5'!G20 | H10: ='Зведена D5'!H20 | I10: ='Зведена D5'!I20 | J10: ='Зведена D5'!J20 | K10: ='Зведена D5'!K20 | L10: ='Зведена D5'!L20 | ... T10: ='Зведена D5'!T20 | U10: =IF(COUNTIF($F10:T10,"=*")>0,IF($C10="К","-"," - "),IF(COUNTIF($F10:T10,"<4")>0,IF(C10="К","-"," - "),(IFERROR(AVERAGE($F10:T10),"Очікую")))) | V10: =IFERROR(U10/12*90,"Очікую")
C11: ='Зведена D5'!C19 | D11: 2 | E11: ='Зведена D5'!E19 | F11: ='Зведена D5'!F19 | G11: ='Зведена D5'!G19 | H11: ='Зведена D5'!H19 | I11: ='Зведена D5'!I19 | J11: ='Зведена D5'!J19 | K11: ='Зведена D5'!K19 | L11: ='Зведена D5'!L19 | ... T11: ='Зведена D5'!T19 | U11: =IF(COUNTIF($F11:T11,"=*")>0,IF($C11="К","-"," - "),IF(COUNTIF($F11:T11,"<4")>0,IF(C11="К","-"," - "),(IFERROR(AVERAGE($F11:T11),"Очікую")))) | V11: =IFERROR(U11/12*90,"Очікую")
C12: ='Зведена D5'!C23 | D12: 3 | E12: ='Зведена D5'!E23 | F12: ='Зведена D5'!F23 | G12: ='Зведена D5'!G23 | H12: ='Зведена D5'!H23 | I12: ='Зведена D5'!I23 | J12: ='Зведена D5'!J23 | K12: ='Зведена D5'!K23 | L12: ='Зведена D5'!L23 | ... T12: ='Зведена D5'!T23 | U12: =IF(COUNTIF($F12:T12,"=*")>0,IF($C12="К","-"," - "),IF(COUNTIF($F12:T12,"<4")>0,IF(C12="К","-"," - "),(IFERROR(AVERAGE($F12:T12),"Очікую")))) | V12: =IFERROR(U12/12*90,"Очікую")
E13: Кількість бюджетників | F13: ='Зведена D5'!F33
E14: Кількість контрактників | F14: ='Зведена D5'!F34 | H14: Класний керівник | P14: ='Зведена D5'!P34
E15: Кількість соціального контингенту | F15: ='Зведена D5'!F35
E16: Вийшли на стипендію | F16: ='Зведена D5'!F36 | H16: Завідувач відділення ПЗСО | P16: Маргарита БРІТІКОВА

Sheet Рейтингова D7
A1: S
C3: ВІДОКРЕМЛЕНИЙ СТРУКТУРНИЙ ПІДРОЗДІЛ «ФАХОВИЙ КОЛЕДЖ НАФТОГАЗОВИХ ТЕХНОЛОГІЙ, ІНЖЕНЕРІЇ ТА ІНФРАСТРУКТУРИ СЕРВІСУ ОДЕСЬКОГО НАЦІОНАЛЬНОГО ТЕХНОЛОГІЧНОГО УНІВЕРСИТЕТУ»
C4: РЕЙТИНГОВА ВІДОМІСТЬ
C5: ='Зведена D7'!C5
C6: ='Зведена D7'!C6
C7: ='Зведена D7'!C7
C8: Б/К | D8: № п/п | E8: Прізвище, ім’я, по батькові | F8: Підсумкові оцінки дисциплін | U8: Середній бал | V8: Рейтинговий бал
F9: ='Зведена D7'!F9 | G9: ='Зведена D7'!G9 | H9: ='Зведена D7'!H9 | I9: ='Зведена D7'!I9 | J9: ='Зведена D7'!J9 | K9: ='Зведена D7'!K9 | L9: ='Зведена D7'!L9 | M9: ='Зведена D7'!M9 | ... T9: ='Зведена D7'!T9
C10: ='Зведена D7'!C33 | D10: 1 | E10: ='Зведена D7'!E33 | F10: ='Зведена D7'!F33 | G10: ='Зведена D7'!G33 | H10: ='Зведена D7'!H33 | I10: ='Зведена D7'!I33 | J10: ='Зведена D7'!J33 | K10: ='Зведена D7'!K33 | L10: ='Зведена D7'!L33 | ... T10: ='Зведена D7'!T33 | U10: =IF(COUNTIF($F10:T10,"=*")>0,IF($C10="К","-"," - "),IF(COUNTIF($F10:T10,"<4")>0,IF(C10="К","-"," - "),(IFERROR(AVERAGE($F10:T10),"Очікую")))) | V10: =IFERROR(U10/12*90,"Очікую")
C11: ='Зведена D7'!C27 | D11: 2 | E11: ='Зведена D7'!E27 | F11: ='Зведена D7'!F27 | G11: ='Зведена D7'!G27 | H11: ='Зведена D7'!H27 | I11: ='Зведена D7'!I27 | J11: ='Зведена D7'!J27 | K11: ='Зведена D7'!K27 | L11: ='Зведена D7'!L27 | ... T11: ='Зведена D7'!T27 | U11: =IF(COUNTIF($F11:T11,"=*")>0,IF($C11="К","-"," - "),IF(COUNTIF($F11:T11,"<4")>0,IF(C11="К","-"," - "),(IFERROR(AVERAGE($F11:T11),"Очікую")))) | V11: =IFERROR(U11/12*90,"Очікую")
C12: ='Зведена D7'!C17 | D12: 3 | E12: ='Зведена D7'!E17 | F12: ='Зведена D7'!F17 | G12: ='Зведена D7'!G17 | H12: ='Зведена D7'!H17 | I12: ='Зведена D7'!I17 | J12: ='Зведена D7'!J17 | K12: ='Зведена D7'!K17 | L12: ='Зведена D7'!L17 | ... T12: ='Зведена D7'!T17 | U12: =IF(COUNTIF($F12:T12,"=*")>0,IF($C12="К","-"," - "),IF(COUNTIF($F12:T12,"<4")>0,IF(C12="К","-"," - "),(IFERROR(AVERAGE($F12:T12),"Очікую")))) | V12: =IFERROR(U12/12*90,"Очікую")
C13: ='Зведена D7'!C14 | D13: 4 | E13: ='Зведена D7'!E14 | F13: ='Зведена D7'!F14 | G13: ='Зведена D7'!G14 | H13: ='Зведена D7'!H14 | I13: ='Зведена D7'!I14 | J13: ='Зведена D7'!J14 | K13: ='Зведена D7'!K14 | L13: ='Зведена D7'!L14 | ... T13: ='Зведена D7'!T14 | U13: =IF(COUNTIF($F13:T13,"=*")>0,IF($C13="К","-"," - "),IF(COUNTIF($F13:T13,"<4")>0,IF(C13="К","-"," - "),(IFERROR(AVERAGE($F13:T13),"Очікую")))) | V13: =IFERROR(U13/12*90,"Очікую")
C14: ='Зведена D7'!C22 | D14: 5 | E14: ='Зведена D7'!E22 | F14: ='Зведена D7'!F22 | G14: ='Зведена D7'!G22 | H14: ='Зведена D7'!H22 | I14: ='Зведена D7'!I22 | J14: ='Зведена D7'!J22 | K14: ='Зведена D7'!K22 | L14: ='Зведена D7'!L22 | ... T14: ='Зведена D7'!T22 | U14: =IF(COUNTIF($F14:T14,"=*")>0,IF($C14="К","-"," - "),IF(COUNTIF($F14:T14,"<4")>0,IF(C14="К","-"," - "),(IFERROR(AVERAGE($F14:T14),"Очікую")))) | V14: =IFERROR(U14/12*90,"Очікую")
C15: ='Зведена D7'!C18 | D15: 6 | E15: ='Зведена D7'!E18 | F15: ='Зведена D7'!F18 | G15: ='Зведена D7'!G18 | H15: ='Зведена D7'!H18 | I15: ='Зведена D7'!I18 | J15: ='Зведена D7'!J18 | K15: ='Зведена D7'!K18 | L15: ='Зведена D7'!L18 | ... T15: ='Зведена D7'!T18 | U15: =IF(COUNTIF($F15:T15,"=*")>0,IF($C15="К","-"," - "),IF(COUNTIF($F15:T15,"<4")>0,IF(C15="К","-"," - "),(IFERROR(AVERAGE($F15:T15),"Очікую")))) | V15: =IFERROR(U15/12*90,"Очікую")
C16: ='Зведена D7'!C32 | D16: 7 | E16: ='Зведена D7'!E32 | F16: ='Зведена D7'!F32 | G16: ='Зведена D7'!G32 | H16: ='Зведена D7'!H32 | I16: ='Зведена D7'!I32 | J16: ='Зведена D7'!J32 | K16: ='Зведена D7'!K32 | L16: ='Зведена D7'!L32 | ... T16: ='Зведена D7'!T32 | U16: =IF(COUNTIF($F16:T16,"=*")>0,IF($C16="К","-"," - "),IF(COUNTIF($F16:T16,"<4")>0,IF(C16="К","-"," - "),(IFERROR(AVERAGE($F16:T16),"Очікую")))) | V16: =IFERROR(U16/12*90,"Очікую")
C17: ='Зведена D7'!C20 | D17: 8 | E17: ='Зведена D7'!E20 | F17: ='Зведена D7'!F20 | G17: ='Зведена D7'!G20 | H17: ='Зведена D7'!H20 | I17: ='Зведена D7'!I20 | J17: ='Зведена D7'!J20 | K17: ='Зведена D7'!K20 | L17: ='Зведена D7'!L20 | ... T17: ='Зведена D7'!T20 | U17: =IF(COUNTIF($F17:T17,"=*")>0,IF($C17="К","-"," - "),IF(COUNTIF($F17:T17,"<4")>0,IF(C17="К","-"," - "),(IFERROR(AVERAGE($F17:T17),"Очікую")))) | V17: =IFERROR(U17/12*90,"Очікую")
C18: ='Зведена D7'!C10 | D18: 9 | E18: ='Зведена D7'!E10 | F18: ='Зведена D7'!F10 | G18: ='Зведена D7'!G10 | H18: ='Зведена D7'!H10 | I18: ='Зведена D7'!I10 | J18: ='Зведена D7'!J10 | K18: ='Зведена D7'!K10 | L18: ='Зведена D7'!L10 | ... T18: ='Зведена D7'!T10 | U18: =IF(COUNTIF($F18:T18,"=*")>0,IF($C18="К","-"," - "),IF(COUNTIF($F18:T18,"<4")>0,IF(C18="К","-"," - "),(IFERROR(AVERAGE($F18:T18),"Очікую")))) | V18: =IFERROR(U18/12*90,"Очікую")
C19: ='Зведена D7'!C11 | D19: 10 | E19: ='Зведена D7'!E11 | F19: ='Зведена D7'!F11 | G19: ='Зведена D7'!G11 | H19: ='Зведена D7'!H11 | I19: ='Зведена D7'!I11 | J19: ='Зведена D7'!J11 | K19: ='Зведена D7'!K11 | L19: ='Зведена D7'!L11 | ... T19: ='Зведена D7'!T11 | U19: =IF(COUNTIF($F19:T19,"=*")>0,IF($C19="К","-"," - "),IF(COUNTIF($F19:T19,"<4")>0,IF(C19="К","-"," - "),(IFERROR(AVERAGE($F19:T19),"Очікую")))) | V19: =IFERROR(U19/12*90,"Очікую")
C20: ='Зведена D7'!C16 | D20: 11 | E20: ='Зведена D7'!E16 | F20: ='Зведена D7'!F16 | G20: ='Зведена D7'!G16 | H20: ='Зведена D7'!H16 | I20: ='Зведена D7'!I16 | J20: ='Зведена D7'!J16 | K20: ='Зведена D7'!K16 | L20: ='Зведена D7'!L16 | ... T20: ='Зведена D7'!T16 | U20: =IF(COUNTIF($F20:T20,"=*")>0,IF($C20="К","-"," - "),IF(COUNTIF($F20:T20,"<4")>0,IF(C20="К","-"," - "),(IFERROR(AVERAGE($F20:T20),"Очікую")))) | V20: =IFERROR(U20/12*90,"Очікую")
C21: ='Зведена D7'!C24 | D21: 12 | E21: ='Зведена D7'!E24 | F21: ='Зведена D7'!F24 | G21: ='Зведена D7'!G24 | H21: ='Зведена D7'!H24 | I21: ='Зведена D7'!I24 | J21: ='Зведена D7'!J24 | K21: ='Зведена D7'!K24 | L21: ='Зведена D7'!L24 | ... T21: ='Зведена D7'!T24 | U21: =IF(COUNTIF($F21:T21,"=*")>0,IF($C21="К","-"," - "),IF(COUNTIF($F21:T21,"<4")>0,IF(C21="К","-"," - "),(IFERROR(AVERAGE($F21:T21),"Очікую")))) | V21: =IFERROR(U21/12*90,"Очікую")
E22: Кількість бюджетників | F22: ='Зведена D7'!F45
E23: Кількість контрактників | F23: ='Зведена D7'!F46 | H23: Класний керівник | P23: ='Зведена D7'!P46
E24: Кількість соціального контингенту | F24: ='Зведена D7'!F47
E25: Вийшли на стипендію | F25: ='Зведена D7'!F48 | H25: Завідувач відділення ПЗСО | P25: Маргарита БРІТІКОВА
