Workbook
Name A1048577: #REF!
Name A1048577: #REF!
Name A1048577: #REF!
Name A1048577: #REF!
Name A1048577: #REF!
Name A1048577: #REF!
Name A1048577: #REF!
Name A1048577: #REF!
Name A1048577: #REF!
Name A1048577: #REF!
Name A1048577: #REF!
Name A1048577: #REF!
Name A1048577: #REF!
Name A1048577: #REF!
Name A1048577: #REF!
Name A1048577: #REF!
Name A1048577: #REF!
Name A1048577: #REF!
Name A1048577: #REF!
Name A1048577: #REF!
Name A1048577: #REF!
Name Ф80: #REF!
Name Ф80: #REF!
Name Ф80: #REF!
Name Ф80: #REF!
Name Ф80: #REF!
Name Ф80: #REF!
Name Ф80: #REF!
Name Ф80: #REF!
Name Ф80: #REF!
Name Ф80: #REF!
Name Ф80: #REF!
Name Ф80: #REF!
Name Ф80: #REF!
Name Ф80: #REF!
Name Ф80: #REF!
Name Ф80: #REF!
Name Ф80: #REF!
Name Ф80: #REF!
Name Ф80: #REF!
Name Ф80: #REF!
Name Ф80: #REF!

Sheet Приклад
A1: S | B1: Для роботи програми Sonata У цьому документі повинні бути ТІЛЬКИ зведені відомості усіх спеціальностей в межах однієї групи Назви листів повинні бути "Зведена ХХХ", де ХХХ - шифр спеціальності (075 або D5 та інші) Порядок предметів повинен бути однаковим на всіх листах (окрім листа "Приклад") Значення, де записано ікси (Х) потрібно заповнювати Формули не чипати. Текст "Очікую" говорить про те, що формула очікує значення для рахунку Лист "Приклад" можна не видаляти але йому неможна змінювати назву
C3: ВІДОКРЕМЛЕНИЙ СТРУКТУРНИЙ ПІДРОЗДІЛ «ФАХОВИЙ КОЛЕДЖ НАФТОГАЗОВИХ ТЕХНОЛОГІЙ, ІНЖЕНЕРІЇ ТА ІНФРАСТРУКТУРИ СЕРВІСУ ОДЕСЬКОГО НАЦІОНАЛЬНОГО ТЕХНОЛОГІЧНОГО УНІВЕРСИТЕТУ»
C4: ЗВЕДЕНА ВІДОМІСТЬ
C5: Успішності студентів спеціальності D5 «Маркетинг»
C6: За ІІ семестр 2025-2026 н.р.
C7: Група 26-1 курс І
C8: Б/К | D8: № п/п | E8: Прізвище, ім’я, по батькові | F8: Підсумкові оцінки дисциплін | U8: Середній бал
F9: Астрономія Наговська Т.С. | G9: Біологія Богданенко О.В. | H9: Всесвітня історія Мельничук С.А. | I9: Географія Наговська Т.С. | J9: Зарубіжна література Сербулова Ю.А. | K9: Захист України Лазар В.І. | L9: Іноземна мова Сербулова Ю.А. | M9: Інформатика Бєльдюгіна С.С. | N9: Історія України Левчук Т.Г. | O9: Математика Бондаренко О.С. | P9: Українська література Антропова Л.І. | Q9: Українська мова Антропова Л.І. | R9: Фізика Калюта Н.М. | S9: Фізична культура Возіян О.Г. | T9: Хімія Сахно Н.О.
C10: Б | D10: 1 | E10: Бондаренко Андрій Миколайович | F10: 6 | G10: 4 | H10: 5 | I10: 9 | J10: 4 | K10: 5 | L10: 7 | M10: 8 | N10: н/а | O10: 10 | P10: 8 | Q10: 7 | R10: 8 | S10: 9 | T10: 5 | U10: =IF(COUNTIF(F10:T10,"=*")>0,IF($C10="К","-"," - "),IF(COUNTIF(F10:T10,"<4")>0,IF(C10="К","-"," - "),(IFERROR(AVERAGE(F10:T10),"Очікую")))) -> -
C11: Б | D11: 2 | E11: Гриценко Світлана Анатоліївна | F11: 7 | G11: 8 | H11: 5 | I11: 7 | J11: 9 | K11: 6 | L11: 9 | M11: 11 | N11: н/а | O11: 8 | P11: 7 | Q11: 7 | R11: 11 | S11: 4 | T11: 5 | U11: =IF(COUNTIF(F11:T11,"=*")>0,IF($C11="К","-"," - "),IF(COUNTIF(F11:T11,"<4")>0,IF(C11="К","-"," - "),(IFERROR(AVERAGE(F11:T11),"Очікую")))) -> -
C12: К | D12: 3 | E12: Карєва Анастасія Сергіївна | F12: 4 | G12: 11 | H12: 5 | I12: 4 | J12: н/а | K12: 4 | L12: 10 | M12: 11 | N12: 6 | O12: 8 | P12: 9 | Q12: 10 | R12: 10 | S12: н/а | T12: 9 | U12: =IF(COUNTIF(F12:T12,"=*")>0,IF($C12="К","-"," - "),IF(COUNTIF(F12:T12,"<4")>0,IF(C12="К","-"," - "),(IFERROR(AVERAGE(F12:T12),"Очікую")))) -> -
C13: К | D13: 4 | E13: Ковальчук Наталія Петрівна | F13: 8 | G13: 5 | H13: 6 | I13: 6 | J13: 10 | K13: 7 | L13: 9 | M13: 5 | N13: 8 | O13: 10 | P13: 5 | Q13: 8 | R13: 6 | S13: 11 | T13: 11 | U13: =IF(COUNTIF(F13:T13,"=*")>0,IF($C13="К","-"," - "),IF(COUNTIF(F13:T13,"<4")>0,IF(C13="К","-"," - "),(IFERROR(AVERAGE(F13:T13),"Очікую")))) -> 7.6666667
C14: Б | D14: 5 | E14: Кравченко Денис Юрійович | F14: 9 | G14: 6 | H14: 7 | I14: 4 | J14: 6 | K14: 7 | L14: н/а | M14: 6 | N14: 11 | O14: 10 | P14: н/а | Q14: 5 | R14: 10 | S14: 10 | T14: 5 | U14: =IF(COUNTIF(F14:T14,"=*")>0,IF($C14="К","-"," - "),IF(COUNTIF(F14:T14,"<4")>0,IF(C14="К","-"," - "),(IFERROR(AVERAGE(F14:T14),"Очікую")))) -> -
C15: К | D15: 6 | E15: Лєрманова Олена Євгенівна | F15: 4 | G15: 8 | H15: 4 | I15: 5 | J15: 11 | K15: 6 | L15: 8 | M15: 8 | N15: 10 | O15: 7 | P15: н/а | Q15: 5 | R15: н/а | S15: 11 | T15: н/а | U15: =IF(COUNTIF(F15:T15,"=*")>0,IF($C15="К","-"," - "),IF(COUNTIF(F15:T15,"<4")>0,IF(C15="К","-"," - "),(IFERROR(AVERAGE(F15:T15),"Очікую")))) -> -
C16: Б | D16: 7 | E16: Лисенко Олена Володимирівна | F16: 8 | G16: 8 | H16: 8 | I16: н/а | J16: 10 | K16: 8 | L16: 8 | M16: 4 | N16: 8 | O16: 8 | P16: н/а | Q16: н/а | R16: 5 | S16: 10 | T16: 10 | U16: =IF(COUNTIF(F16:T16,"=*")>0,IF($C16="К","-"," - "),IF(COUNTIF(F16:T16,"<4")>0,IF(C16="К","-"," - "),(IFERROR(AVERAGE(F16:T16),"Очікую")))) -> -
C17: К | D17: 8 | E17: Мельниченко Софія Ігорівна | F17: 10 | G17: 8 | H17: 7 | I17: 8 | J17: 11 | K17: 9 | L17: 10 | M17: 10 | N17: 9 | O17: 6 | P17: 5 | Q17: 7 | R17: 8 | S17: 10 | T17: 4 | U17: =IF(COUNTIF(F17:T17,"=*")>0,IF($C17="К","-"," - "),IF(COUNTIF(F17:T17,"<4")>0,IF(C17="К","-"," - "),(IFERROR(AVERAGE(F17:T17),"Очікую")))) -> 8.1333333
C18: К | D18: 9 | E18: Мороз Віктор Васильович | F18: 4 | G18: 9 | H18: 4 | I18: н/а | J18: 9 | K18: 6 | L18: н/а | M18: 11 | N18: 11 | O18: 10 | P18: 8 | Q18: 11 | R18: 9 | S18: 7 | T18: 11 | U18: =IF(COUNTIF(F18:T18,"=*")>0,IF($C18="К","-"," - "),IF(COUNTIF(F18:T18,"<4")>0,IF(C18="К","-"," - "),(IFERROR(AVERAGE(F18:T18),"Очікую")))) -> -
C19: Б | D19: 10 | E19: Поліщук Артем Валерійович | F19: 4 | G19: 4 | H19: 7 | I19: 9 | J19: 9 | K19: 6 | L19: 8 | M19: 8 | N19: 10 | O19: 4 | P19: 11 | Q19: 7 | R19: 8 | S19: 10 | T19: 8 | U19: =IF(COUNTIF(F19:T19,"=*")>0,IF($C19="К","-"," - "),IF(COUNTIF(F19:T19,"<4")>0,IF(C19="К","-"," - "),(IFERROR(AVERAGE(F19:T19),"Очікую")))) -> 7.5333333
C20: Б | D20: 11 | E20: Присяжнюк Аміна Михайлівна | F20: 8 | G20: 11 | H20: 4 | I20: 10 | J20: 5 | K20: 8 | L20: 11 | M20: 9 | N20: 5 | O20: 8 | P20: 4 | Q20: 7 | R20: 11 | S20: 8 | T20: 5 | U20: =IF(COUNTIF(F20:T20,"=*")>0,IF($C20="К","-"," - "),IF(COUNTIF(F20:T20,"<4")>0,IF(C20="К","-"," - "),(IFERROR(AVERAGE(F20:T20),"Очікую")))) -> 7.6
C21: К | D21: 12 | E21: Савельєв Олександр Вячеславович | F21: 9 | G21: 8 | H21: 11 | I21: 5 | J21: 8 | K21: 5 | L21: 5 | M21: 8 | N21: 6 | O21: 11 | P21: 9 | Q21: 8 | R21: 8 | S21: 8 | T21: 8 | U21: =IF(COUNTIF(F21:T21,"=*")>0,IF($C21="К","-"," - "),IF(COUNTIF(F21:T21,"<4")>0,IF(C21="К","-"," - "),(IFERROR(AVERAGE(F21:T21),"Очікую")))) -> 7.8
C22: К | D22: 13 | E22: Савченко Марія Олегівна | F22: 11 | G22: 6 | H22: н/а | I22: 9 | J22: 9 | K22: н/а | L22: 8 | M22: 11 | N22: 5 | O22: 6 | P22: 4 | Q22: 11 | R22: 9 | S22: 6 | T22: 8 | U22: =IF(COUNTIF(F22:T22,"=*")>0,IF($C22="К","-"," - "),IF(COUNTIF(F22:T22,"<4")>0,IF(C22="К","-"," - "),(IFERROR(AVERAGE(F22:T22),"Очікую")))) -> -
C23: Б | D23: 14 | E23: Самойлова Яна Вячеславівна | F23: 11 | G23: 8 | H23: 4 | I23: 9 | J23: 7 | K23: 5 | L23: 8 | M23: 5 | N23: 9 | O23: 4 | P23: 8 | Q23: 8 | R23: 6 | S23: 9 | T23: 9 | U23: =IF(COUNTIF(F23:T23,"=*")>0,IF($C23="К","-"," - "),IF(COUNTIF(F23:T23,"<4")>0,IF(C23="К","-"," - "),(IFERROR(AVERAGE(F23:T23),"Очікую")))) -> 7.3333333
C24: Б | D24: 15 | E24: Стегарь Евеліна Сергіївна | F24: 11 | G24: 5 | H24: 6 | I24: 6 | J24: н/а | K24: 10 | L24: 9 | M24: 11 | N24: 11 | O24: 11 | P24: 10 | Q24: 11 | R24: 10 | S24: 11 | T24: 8 | U24: =IF(COUNTIF(F24:T24,"=*")>0,IF($C24="К","-"," - "),IF(COUNTIF(F24:T24,"<4")>0,IF(C24="К","-"," - "),(IFERROR(AVERAGE(F24:T24),"Очікую")))) -> -
C25: К | D25: 16 | E25: Ткаченко Ірина Сергіївна | F25: 5 | G25: 10 | H25: 10 | I25: 8 | J25: 9 | K25: 9 | L25: 9 | M25: 4 | N25: 9 | O25: 8 | P25: 10 | Q25: 8 | R25: 11 | S25: 8 | T25: 8 | U25: =IF(COUNTIF(F25:T25,"=*")>0,IF($C25="К","-"," - "),IF(COUNTIF(F25:T25,"<4")>0,IF(C25="К","-"," - "),(IFERROR(AVERAGE(F25:T25),"Очікую")))) -> 8.4
C26: Б | D26: 17 | E26: Цвєтков Андрій Геннадійович | F26: 8 | G26: 7 | H26: н/а | I26: 4 | J26: 7 | K26: 8 | L26: 5 | M26: 10 | N26: 4 | O26: 8 | P26: 8 | Q26: 6 | R26: 4 | S26: 7 | T26: 10 | U26: =IF(COUNTIF(F26:T26,"=*")>0,IF($C26="К","-"," - "),IF(COUNTIF(F26:T26,"<4")>0,IF(C26="К","-"," - "),(IFERROR(AVERAGE(F26:T26),"Очікую")))) -> -
C27: Б | D27: 18 | E27: Шевченко Олександр Іванович | F27: 9 | G27: 9 | H27: 7 | I27: 11 | J27: н/а | K27: 10 | L27: 8 | M27: 8 | N27: 5 | O27: 7 | P27: 7 | Q27: 4 | R27: 8 | S27: 4 | T27: 8 | U27: =IF(COUNTIF(F27:T27,"=*")>0,IF($C27="К","-"," - "),IF(COUNTIF(F27:T27,"<4")>0,IF(C27="К","-"," - "),(IFERROR(AVERAGE(F27:T27),"Очікую")))) -> -
E28: Середній бал успішності з дисципліни | F28: =IF(SUM(F10:F27)=0,IF(COUNTA(F10:F27)=0,"Очікую",0),SUM(F10:F27)/$D27) -> 7.5555556 | G28: =IF(SUM(G10:G27)=0,IF(COUNTA(G10:G27)=0,"Очікую",0),SUM(G10:G27)/$D27) -> 7.5 | H28: =IF(SUM(H10:H27)=0,IF(COUNTA(H10:H27)=0,"Очікую",0),SUM(H10:H27)/$D27) -> 5.5555556 | I28: =IF(SUM(I10:I27)=0,IF(COUNTA(I10:I27)=0,"Очікую",0),SUM(I10:I27)/$D27) -> 6.3333333 | J28: =IF(SUM(J10:J27)=0,IF(COUNTA(J10:J27)=0,"Очікую",0),SUM(J10:J27)/$D27) -> 6.8888889 | K28: =IF(SUM(K10:K27)=0,IF(COUNTA(K10:K27)=0,"Очікую",0),SUM(K10:K27)/$D27) -> 6.6111111 | L28: =IF(SUM(L10:L27)=0,IF(COUNTA(L10:L27)=0,"Очікую",0),SUM(L10:L27)/$D27) -> 7.3333333 | M28: =IF(SUM(M10:M27)=0,IF(COUNTA(M10:M27)=0,"Очікую",0),SUM(M10:M27)/$D27) -> 8.2222222 | ... T28: =IF(SUM(T10:T27)=0,IF(COUNTA(T10:T27)=0,"Очікую",0),SUM(T10:T27)/$D27) -> 7.3333333 | U28: =IFERROR(AVERAGE(F28:T28),"Очікую") -> 7.1814815
E29: Абсолютна успішність | F29: =IF(SUM(F10:F27)=0,IF(COUNTA(F10:F27)=0,"Очікую",0),IF(COUNTIF(F10:F27,">=4")=0,0,COUNTIF(F10:F27,">=4")/$D27*100)) -> 100 | G29: =IF(SUM(G10:G27)=0,IF(COUNTA(G10:G27)=0,"Очікую",0),IF(COUNTIF(G10:G27,">=4")=0,0,COUNTIF(G10:G27,">=4")/$D27*100)) -> 100 | H29: =IF(SUM(H10:H27)=0,IF(COUNTA(H10:H27)=0,"Очікую",0),IF(COUNTIF(H10:H27,">=4")=0,0,COUNTIF(H10:H27,">=4")/$D27*100)) -> 88.888889 | I29: =IF(SUM(I10:I27)=0,IF(COUNTA(I10:I27)=0,"Очікую",0),IF(COUNTIF(I10:I27,">=4")=0,0,COUNTIF(I10:I27,">=4")/$D27*100)) -> 88.888889 | J29: =IF(SUM(J10:J27)=0,IF(COUNTA(J10:J27)=0,"Очікую",0),IF(COUNTIF(J10:J27,">=4")=0,0,COUNTIF(J10:J27,">=4")/$D27*100)) -> 83.333333 | K29: =IF(SUM(K10:K27)=0,IF(COUNTA(K10:K27)=0,"Очікую",0),IF(COUNTIF(K10:K27,">=4")=0,0,COUNTIF(K10:K27,">=4")/$D27*100)) -> 94.444444 | L29: =IF(SUM(L10:L27)=0,IF(COUNTA(L10:L27)=0,"Очікую",0),IF(COUNTIF(L10:L27,">=4")=0,0,COUNTIF(L10:L27,">=4")/$D27*100)) -> 88.888889 | M29: =IF(SUM(M10:M27)=0,IF(COUNTA(M10:M27)=0,"Очікую",0),IF(COUNTIF(M10:M27,">=4")=0,0,COUNTIF(M10:M27,">=4")/$D27*100)) -> 100 | ... T29: =IF(SUM(T10:T27)=0,IF(COUNTA(T10:T27)=0,"Очікую",0),IF(COUNTIF(T10:T27,">=4")=0,0,COUNTIF(T10:T27,">=4")/$D27*100)) -> 94.444444
E30: Якісна успішність | F30: =IF(SUM(F10:F27)=0,IF(COUNTA(F10:F27)=0,"Очікую",0),IF(COUNTIF(F10:F27,">=7")=0,0,COUNTIF(F10:F27,">=7")/$D27*100)) -> 66.666667 | G30: =IF(SUM(G10:G27)=0,IF(COUNTA(G10:G27)=0,"Очікую",0),IF(COUNTIF(G10:G27,">=7")=0,0,COUNTIF(G10:G27,">=7")/$D27*100)) -> 66.666667 | H30: =IF(SUM(H10:H27)=0,IF(COUNTA(H10:H27)=0,"Очікую",0),IF(COUNTIF(H10:H27,">=7")=0,0,COUNTIF(H10:H27,">=7")/$D27*100)) -> 38.888889 | I30: =IF(SUM(I10:I27)=0,IF(COUNTA(I10:I27)=0,"Очікую",0),IF(COUNTIF(I10:I27,">=7")=0,0,COUNTIF(I10:I27,">=7")/$D27*100)) -> 50 | J30: =IF(SUM(J10:J27)=0,IF(COUNTA(J10:J27)=0,"Очікую",0),IF(COUNTIF(J10:J27,">=7")=0,0,COUNTIF(J10:J27,">=7")/$D27*100)) -> 66.666667 | K30: =IF(SUM(K10:K27)=0,IF(COUNTA(K10:K27)=0,"Очікую",0),IF(COUNTIF(K10:K27,">=7")=0,0,COUNTIF(K10:K27,">=7")/$D27*100)) -> 50 | L30: =IF(SUM(L10:L27)=0,IF(COUNTA(L10:L27)=0,"Очікую",0),IF(COUNTIF(L10:L27,">=7")=0,0,COUNTIF(L10:L27,">=7")/$D27*100)) -> 77.777778 | M30: =IF(SUM(M10:M27)=0,IF(COUNTA(M10:M27)=0,"Очікую",0),IF(COUNTIF(M10:M27,">=7")=0,0,COUNTIF(M10:M27,">=7")/$D27*100)) -> 72.222222 | ... T30: =IF(SUM(T10:T27)=0,IF(COUNTA(T10:T27)=0,"Очікую",0),IF(COUNTIF(T10:T27,">=7")=0,0,COUNTIF(T10:T27,">=7")/$D27*100)) -> 66.666667
E31: Абсолютна успішність по групі | F31: =IFERROR(AVERAGE(F29:T29),"Очікую") -> 92.962963
E32: Якісна успішність по групі | F32: =IFERROR(AVERAGE(F30:T30),"Очікую") -> 64.814815
E33: Кількість бюджетників | F33: =IF(COUNTIF(C10:C27,"=Б")=0,IF(COUNTIF(C10:C27,"=К")=0,"Очікую",0),COUNTIF(C10:C27,"=Б")) -> 10
E34: Кількість контрактників | F34: =IF(COUNTIF(C10:C27,"=К")=0,IF(COUNTIF(C10:C27,"=Б")=0,"Очікую",0),COUNTIF(C10:C27,"=К")) -> 8 | H34: Класний керівник | P34: Ірина ДОПІРА
E35: Кількість соціального контингенту
E36: Вийшли на стипендію | F36: =IF(F33="Очікую","Очікую",IF(F33-COUNTIF(U10:U27," - ")<ROUNDDOWN(F33*0.4,0),F33-COUNTIF(U10:U27," - "),ROUNDDOWN(F33*0.4,0))) -> 3 | H36: Завідувач відділення ПЗСО | P36: Маргарита БРІТІКОВА

Sheet Л_Загальна
A1: S
C3: ЗАГАЛЬНА ВІДОМІСТЬ З УСІМА СПЕЦІАЛЬНОСТЯМИ. НЕ ДЛЯ ДРУКУ. ЗВІДСИ ОЦІНКИ АВТОМАТИЧНО ПЕРЕНОСЯТЬСЯ ДО ВІДОМОСТЕЙ. СТВОРЕНО ДЛЯ ЛЕГШОГО ЗАПОВНЕННЯ ОЦІНОК
C8: Б/К | D8: № п/п | E8: Прізвище, ім’я, по батькові | F8: Підсумкові оцінки дисциплін | Z8: Середній бал
F9: 1 | G9: 2 | H9: 3 | I9: 4 | J9: 5 | K9: 6 | L9: 7 | M9: 8 | N9: 9 | O9: 10 | P9: 11 | Q9: 12 | R9: 13 | S9: 14 | T9: 15 | U9: 16 | V9: 17 | W9: 18 | X9: 19 | Y9: 20
D10: 1 | Z10: =IF(COUNTIF(F10:Y10,"=*")>0,IF($C10="К","-"," - "),IF(COUNTIF(F10:Y10,"<4")>0,IF(C10="К","-"," - "),(IFERROR(AVERAGE(F10:Y10),"Очікую")))) -> Очікую
D11: 2 | Z11: =IF(COUNTIF(F11:Y11,"=*")>0,IF($C11="К","-"," - "),IF(COUNTIF(F11:Y11,"<4")>0,IF(C11="К","-"," - "),(IFERROR(AVERAGE(F11:Y11),"Очікую")))) -> Очікую
D12: 3 | Z12: =IF(COUNTIF(F12:Y12,"=*")>0,IF($C12="К","-"," - "),IF(COUNTIF(F12:Y12,"<4")>0,IF(C12="К","-"," - "),(IFERROR(AVERAGE(F12:Y12),"Очікую")))) -> Очікую
D13: 4 | Z13: =IF(COUNTIF(F13:Y13,"=*")>0,IF($C13="К","-"," - "),IF(COUNTIF(F13:Y13,"<4")>0,IF(C13="К","-"," - "),(IFERROR(AVERAGE(F13:Y13),"Очікую")))) -> Очікую
D14: 5 | Z14: =IF(COUNTIF(F14:Y14,"=*")>0,IF($C14="К","-"," - "),IF(COUNTIF(F14:Y14,"<4")>0,IF(C14="К","-"," - "),(IFERROR(AVERAGE(F14:Y14),"Очікую")))) -> Очікую
D15: 6 | Z15: =IF(COUNTIF(F15:Y15,"=*")>0,IF($C15="К","-"," - "),IF(COUNTIF(F15:Y15,"<4")>0,IF(C15="К","-"," - "),(IFERROR(AVERAGE(F15:Y15),"Очікую")))) -> Очікую
D16: 7 | Z16: =IF(COUNTIF(F16:Y16,"=*")>0,IF($C16="К","-"," - "),IF(COUNTIF(F16:Y16,"<4")>0,IF(C16="К","-"," - "),(IFERROR(AVERAGE(F16:Y16),"Очікую")))) -> Очікую
D17: 8 | Z17: =IF(COUNTIF(F17:Y17,"=*")>0,IF($C17="К","-"," - "),IF(COUNTIF(F17:Y17,"<4")>0,IF(C17="К","-"," - "),(IFERROR(AVERAGE(F17:Y17),"Очікую")))) -> Очікую
D18: 9 | Z18: =IF(COUNTIF(F18:Y18,"=*")>0,IF($C18="К","-"," - "),IF(COUNTIF(F18:Y18,"<4")>0,IF(C18="К","-"," - "),(IFERROR(AVERAGE(F18:Y18),"Очікую")))) -> Очікую
D19: 10 | Z19: =IF(COUNTIF(F19:Y19,"=*")>0,IF($C19="К","-"," - "),IF(COUNTIF(F19:Y19,"<4")>0,IF(C19="К","-"," - "),(IFERROR(AVERAGE(F19:Y19),"Очікую")))) -> Очікую
D20: 11 | Z20: =IF(COUNTIF(F20:Y20,"=*")>0,IF($C20="К","-"," - "),IF(COUNTIF(F20:Y20,"<4")>0,IF(C20="К","-"," - "),(IFERROR(AVERAGE(F20:Y20),"Очікую")))) -> Очікую
D21: 12 | Z21: =IF(COUNTIF(F21:Y21,"=*")>0,IF($C21="К","-"," - "),IF(COUNTIF(F21:Y21,"<4")>0,IF(C21="К","-"," - "),(IFERROR(AVERAGE(F21:Y21),"Очікую")))) -> Очікую
... D109: 100 | Z109: =IF(COUNTIF(F109:Y109,"=*")>0,IF($C109="К","-"," - "),IF(COUNTIF(F109:Y109,"<4")>0,IF(C109="К","-"," - "),(IFERROR(AVERAGE(F109:Y109),"Очікую")))) -> Очікую
E110: Середній бал успішності з дисципліни | F110: =IF(SUM(F10:F109)=0,IF(COUNTA(F10:F109)=0,"Очікую",0),SUM(F10:F109)/$D109) -> Очікую | G110: =IF(SUM(G10:G109)=0,IF(COUNTA(G10:G109)=0,"Очікую",0),SUM(G10:G109)/$D109) -> Очікую | H110: =IF(SUM(H10:H109)=0,IF(COUNTA(H10:H109)=0,"Очікую",0),SUM(H10:H109)/$D109) -> Очікую | I110: =IF(SUM(I10:I109)=0,IF(COUNTA(I10:I109)=0,"Очікую",0),SUM(I10:I109)/$D109) -> Очікую | J110: =IF(SUM(J10:J109)=0,IF(COUNTA(J10:J109)=0,"Очікую",0),SUM(J10:J109)/$D109) -> Очікую | K110: =IF(SUM(K10:K109)=0,IF(COUNTA(K10:K109)=0,"Очікую",0),SUM(K10:K109)/$D109) -> Очікую | L110: =IF(SUM(L10:L109)=0,IF(COUNTA(L10:L109)=0,"Очікую",0),SUM(L10:L109)/$D109) -> Очікую | M110: =IF(SUM(M10:M109)=0,IF(COUNTA(M10:M109)=0,"Очікую",0),SUM(M10:M109)/$D109) -> Очікую | ... Y110: =IF(SUM(Y10:Y109)=0,IF(COUNTA(Y10:Y109)=0,"Очікую",0),SUM(Y10:Y109)/$D109) -> Очікую | Z110: =IFERROR(AVERAGE(F110:Y110),"Очікую") -> Очікую
E111: Абсолютна успішність | F111: =IF(SUM(F10:F109)=0,IF(COUNTA(F10:F109)=0,"Очікую",0),IF(COUNTIF(F10:F109,">=4")=0,0,COUNTIF(F10:F109,">=4")/$D109*100)) -> Очікую | G111: =IF(SUM(G10:G109)=0,IF(COUNTA(G10:G109)=0,"Очікую",0),IF(COUNTIF(G10:G109,">=4")=0,0,COUNTIF(G10:G109,">=4")/$D109*100)) -> Очікую | H111: =IF(SUM(H10:H109)=0,IF(COUNTA(H10:H109)=0,"Очікую",0),IF(COUNTIF(H10:H109,">=4")=0,0,COUNTIF(H10:H109,">=4")/$D109*100)) -> Очікую | I111: =IF(SUM(I10:I109)=0,IF(COUNTA(I10:I109)=0,"Очікую",0),IF(COUNTIF(I10:I109,">=4")=0,0,COUNTIF(I10:I109,">=4")/$D109*100)) -> Очікую | J111: =IF(SUM(J10:J109)=0,IF(COUNTA(J10:J109)=0,"Очікую",0),IF(COUNTIF(J10:J109,">=4")=0,0,COUNTIF(J10:J109,">=4")/$D109*100)) -> Очікую | K111: =IF(SUM(K10:K109)=0,IF(COUNTA(K10:K109)=0,"Очікую",0),IF(COUNTIF(K10:K109,">=4")=0,0,COUNTIF(K10:K109,">=4")/$D109*100)) -> Очікую | L111: =IF(SUM(L10:L109)=0,IF(COUNTA(L10:L109)=0,"Очікую",0),IF(COUNTIF(L10:L109,">=4")=0,0,COUNTIF(L10:L109,">=4")/$D109*100)) -> Очікую | M111: =IF(SUM(M10:M109)=0,IF(COUNTA(M10:M109)=0,"Очікую",0),IF(COUNTIF(M10:M109,">=4")=0,0,COUNTIF(M10:M109,">=4")/$D109*100)) -> Очікую | ... Y111: =IF(SUM(Y10:Y109)=0,IF(COUNTA(Y10:Y109)=0,"Очікую",0),IF(COUNTIF(Y10:Y109,">=4")=0,0,COUNTIF(Y10:Y109,">=4")/$D109*100)) -> Очікую
E112: Якісна успішність | F112: =IF(SUM(F10:F109)=0,IF(COUNTA(F10:F109)=0,"Очікую",0),IF(COUNTIF(F10:F109,">=7")=0,0,COUNTIF(F10:F109,">=7")/$D109*100)) -> Очікую | G112: =IF(SUM(G10:G109)=0,IF(COUNTA(G10:G109)=0,"Очікую",0),IF(COUNTIF(G10:G109,">=7")=0,0,COUNTIF(G10:G109,">=7")/$D109*100)) -> Очікую | H112: =IF(SUM(H10:H109)=0,IF(COUNTA(H10:H109)=0,"Очікую",0),IF(COUNTIF(H10:H109,">=7")=0,0,COUNTIF(H10:H109,">=7")/$D109*100)) -> Очікую | I112: =IF(SUM(I10:I109)=0,IF(COUNTA(I10:I109)=0,"Очікую",0),IF(COUNTIF(I10:I109,">=7")=0,0,COUNTIF(I10:I109,">=7")/$D109*100)) -> Очікую | J112: =IF(SUM(J10:J109)=0,IF(COUNTA(J10:J109)=0,"Очікую",0),IF(COUNTIF(J10:J109,">=7")=0,0,COUNTIF(J10:J109,">=7")/$D109*100)) -> Очікую | K112: =IF(SUM(K10:K109)=0,IF(COUNTA(K10:K109)=0,"Очікую",0),IF(COUNTIF(K10:K109,">=7")=0,0,COUNTIF(K10:K109,">=7")/$D109*100)) -> Очікую | L112: =IF(SUM(L10:L109)=0,IF(COUNTA(L10:L109)=0,"Очікую",0),IF(COUNTIF(L10:L109,">=7")=0,0,COUNTIF(L10:L109,">=7")/$D109*100)) -> Очікую | M112: =IF(SUM(M10:M109)=0,IF(COUNTA(M10:M109)=0,"Очікую",0),IF(COUNTIF(M10:M109,">=7")=0,0,COUNTIF(M10:M109,">=7")/$D109*100)) -> Очікую | ... Y112: =IF(SUM(Y10:Y109)=0,IF(COUNTA(Y10:Y109)=0,"Очікую",0),IF(COUNTIF(Y10:Y109,">=7")=0,0,COUNTIF(Y10:Y109,">=7")/$D109*100)) -> Очікую
E113: Абсолютна успішність по групі | F113: =IFERROR(AVERAGE(F111:Y111),"Очікую") -> Очікую
E114: Якісна успішність по групі | F114: =IFERROR(AVERAGE(F112:Y112),"Очікую") -> Очікую
E115: Кількість бюджетників | F115: =IF(COUNTIF(C10:C109,"=Б")=0,IF(COUNTIF(C10:C109,"=К")=0,"Очікую",0),COUNTIF(C10:C109,"=Б")) -> Очікую
E116: Кількість контрактників | F116: =IF(COUNTIF(C10:C109,"=К")=0,IF(COUNTIF(C10:C109,"=Б")=0,"Очікую",0),COUNTIF(C10:C109,"=К")) -> Очікую | H116: Класний керівник
E117: Кількість соціального контингенту
E118: Вийшли на стипендію | F118: =IF(F115="Очікую","Очікую",IF(F115-COUNTIF(Z10:Z109," - ")<ROUNDDOWN(F115*0.4,0),F115-COUNTIF(Z10:Z109," - "),ROUNDDOWN(F115*0.4,0))) -> Очікую | H118: Завідувач відділення ПЗСО

Sheet ЛЗ1
A1: S
C3: ВІДОКРЕМЛЕНИЙ СТРУКТУРНИЙ ПІДРОЗДІЛ «ФАХОВИЙ КОЛЕДЖ НАФТОГАЗОВИХ ТЕХНОЛОГІЙ, ІНЖЕНЕРІЇ ТА ІНФРАСТРУКТУРИ СЕРВІСУ ОДЕСЬКОГО НАЦІОНАЛЬНОГО ТЕХНОЛОГІЧНОГО УНІВЕРСИТЕТУ»
C4: ЗВЕДЕНА ВІДОМІСТЬ
C5: Успішності студентів спеціальності XXX «XXXXX»
C6: За X семестр XXXX-XXXX н.р.
C7: Група XXXX курс X
C8: Б/К | D8: № п/п | E8: Прізвище, ім’я, по батькові | F8: Підсумкові оцінки дисциплін | Z8: Середній бал
F9: 1 | G9: 2 | H9: 3 | I9: 4 | J9: 5 | K9: 6 | L9: 7 | M9: 8 | N9: 9 | O9: 10 | P9: 11 | Q9: 12 | R9: 13 | S9: 14 | T9: 15 | U9: 16 | V9: 17 | W9: 18 | X9: 19 | Y9: 20
D10: 1 | Z10: =IF(COUNTIF(F10:Y10,"=*")>0,IF($C10="К","-"," - "),IF(COUNTIF(F10:Y10,"<4")>0,IF(C10="К","-"," - "),(IFERROR(AVERAGE(F10:Y10),"Очікую")))) -> Очікую
D11: 2 | Z11: =IF(COUNTIF(F11:Y11,"=*")>0,IF($C11="К","-"," - "),IF(COUNTIF(F11:Y11,"<4")>0,IF(C11="К","-"," - "),(IFERROR(AVERAGE(F11:Y11),"Очікую")))) -> Очікую
D12: 3 | Z12: =IF(COUNTIF(F12:Y12,"=*")>0,IF($C12="К","-"," - "),IF(COUNTIF(F12:Y12,"<4")>0,IF(C12="К","-"," - "),(IFERROR(AVERAGE(F12:Y12),"Очікую")))) -> Очікую
D13: 4 | Z13: =IF(COUNTIF(F13:Y13,"=*")>0,IF($C13="К","-"," - "),IF(COUNTIF(F13:Y13,"<4")>0,IF(C13="К","-"," - "),(IFERROR(AVERAGE(F13:Y13),"Очікую")))) -> Очікую
D14: 5 | Z14: =IF(COUNTIF(F14:Y14,"=*")>0,IF($C14="К","-"," - "),IF(COUNTIF(F14:Y14,"<4")>0,IF(C14="К","-"," - "),(IFERROR(AVERAGE(F14:Y14),"Очікую")))) -> Очікую
D15: 6 | Z15: =IF(COUNTIF(F15:Y15,"=*")>0,IF($C15="К","-"," - "),IF(COUNTIF(F15:Y15,"<4")>0,IF(C15="К","-"," - "),(IFERROR(AVERAGE(F15:Y15),"Очікую")))) -> Очікую
D16: 7 | Z16: =IF(COUNTIF(F16:Y16,"=*")>0,IF($C16="К","-"," - "),IF(COUNTIF(F16:Y16,"<4")>0,IF(C16="К","-"," - "),(IFERROR(AVERAGE(F16:Y16),"Очікую")))) -> Очікую
D17: 8 | Z17: =IF(COUNTIF(F17:Y17,"=*")>0,IF($C17="К","-"," - "),IF(COUNTIF(F17:Y17,"<4")>0,IF(C17="К","-"," - "),(IFERROR(AVERAGE(F17:Y17),"Очікую")))) -> Очікую
D18: 9 | Z18: =IF(COUNTIF(F18:Y18,"=*")>0,IF($C18="К","-"," - "),IF(COUNTIF(F18:Y18,"<4")>0,IF(C18="К","-"," - "),(IFERROR(AVERAGE(F18:Y18),"Очікую")))) -> Очікую
D19: 10 | Z19: =IF(COUNTIF(F19:Y19,"=*")>0,IF($C19="К","-"," - "),IF(COUNTIF(F19:Y19,"<4")>0,IF(C19="К","-"," - "),(IFERROR(AVERAGE(F19:Y19),"Очікую")))) -> Очікую
D20: 11 | Z20: =IF(COUNTIF(F20:Y20,"=*")>0,IF($C20="К","-"," - "),IF(COUNTIF(F20:Y20,"<4")>0,IF(C20="К","-"," - "),(IFERROR(AVERAGE(F20:Y20),"Очікую")))) -> Очікую
D21: 12 | Z21: =IF(COUNTIF(F21:Y21,"=*")>0,IF($C21="К","-"," - "),IF(COUNTIF(F21:Y21,"<4")>0,IF(C21="К","-"," - "),(IFERROR(AVERAGE(F21:Y21),"Очікую")))) -> Очікую
... D109: 100 | Z109: =IF(COUNTIF(F109:Y109,"=*")>0,IF($C109="К","-"," - "),IF(COUNTIF(F109:Y109,"<4")>0,IF(C109="К","-"," - "),(IFERROR(AVERAGE(F109:Y109),"Очікую")))) -> Очікую
E110: Середній бал успішності з дисципліни | F110: =IF(SUM(F10:F109)=0,IF(COUNTA(F10:F109)=0,"Очікую",0),SUM(F10:F109)/$D109) -> Очікую | G110: =IF(SUM(G10:G109)=0,IF(COUNTA(G10:G109)=0,"Очікую",0),SUM(G10:G109)/$D109) -> Очікую | H110: =IF(SUM(H10:H109)=0,IF(COUNTA(H10:H109)=0,"Очікую",0),SUM(H10:H109)/$D109) -> Очікую | I110: =IF(SUM(I10:I109)=0,IF(COUNTA(I10:I109)=0,"Очікую",0),SUM(I10:I109)/$D109) -> Очікую | J110: =IF(SUM(J10:J109)=0,IF(COUNTA(J10:J109)=0,"Очікую",0),SUM(J10:J109)/$D109) -> Очікую | K110: =IF(SUM(K10:K109)=0,IF(COUNTA(K10:K109)=0,"Очікую",0),SUM(K10:K109)/$D109) -> Очікую | L110: =IF(SUM(L10:L109)=0,IF(COUNTA(L10:L109)=0,"Очікую",0),SUM(L10:L109)/$D109) -> Очікую | M110: =IF(SUM(M10:M109)=0,IF(COUNTA(M10:M109)=0,"Очікую",0),SUM(M10:M109)/$D109) -> Очікую | ... Y110: =IF(SUM(Y10:Y109)=0,IF(COUNTA(Y10:Y109)=0,"Очікую",0),SUM(Y10:Y109)/$D109) -> Очікую | Z110: =IFERROR(AVERAGE(F110:Y110),"Очікую") -> Очікую
E111: Абсолютна успішність | F111: =IF(SUM(F10:F109)=0,IF(COUNTA(F10:F109)=0,"Очікую",0),IF(COUNTIF(F10:F109,">=4")=0,0,COUNTIF(F10:F109,">=4")/$D109*100)) -> Очікую | G111: =IF(SUM(G10:G109)=0,IF(COUNTA(G10:G109)=0,"Очікую",0),IF(COUNTIF(G10:G109,">=4")=0,0,COUNTIF(G10:G109,">=4")/$D109*100)) -> Очікую | H111: =IF(SUM(H10:H109)=0,IF(COUNTA(H10:H109)=0,"Очікую",0),IF(COUNTIF(H10:H109,">=4")=0,0,COUNTIF(H10:H109,">=4")/$D109*100)) -> Очікую | I111: =IF(SUM(I10:I109)=0,IF(COUNTA(I10:I109)=0,"Очікую",0),IF(COUNTIF(I10:I109,">=4")=0,0,COUNTIF(I10:I109,">=4")/$D109*100)) -> Очікую | J111: =IF(SUM(J10:J109)=0,IF(COUNTA(J10:J109)=0,"Очікую",0),IF(COUNTIF(J10:J109,">=4")=0,0,COUNTIF(J10:J109,">=4")/$D109*100)) -> Очікую | K111: =IF(SUM(K10:K109)=0,IF(COUNTA(K10:K109)=0,"Очікую",0),IF(COUNTIF(K10:K109,">=4")=0,0,COUNTIF(K10:K109,">=4")/$D109*100)) -> Очікую | L111: =IF(SUM(L10:L109)=0,IF(COUNTA(L10:L109)=0,"Очікую",0),IF(COUNTIF(L10:L109,">=4")=0,0,COUNTIF(L10:L109,">=4")/$D109*100)) -> Очікую | M111: =IF(SUM(M10:M109)=0,IF(COUNTA(M10:M109)=0,"Очікую",0),IF(COUNTIF(M10:M109,">=4")=0,0,COUNTIF(M10:M109,">=4")/$D109*100)) -> Очікую | ... Y111: =IF(SUM(Y10:Y109)=0,IF(COUNTA(Y10:Y109)=0,"Очікую",0),IF(COUNTIF(Y10:Y109,">=4")=0,0,COUNTIF(Y10:Y109,">=4")/$D109*100)) -> Очікую
E112: Якісна успішність | F112: =IF(SUM(F10:F109)=0,IF(COUNTA(F10:F109)=0,"Очікую",0),IF(COUNTIF(F10:F109,">=7")=0,0,COUNTIF(F10:F109,">=7")/$D109*100)) -> Очікую | G112: =IF(SUM(G10:G109)=0,IF(COUNTA(G10:G109)=0,"Очікую",0),IF(COUNTIF(G10:G109,">=7")=0,0,COUNTIF(G10:G109,">=7")/$D109*100)) -> Очікую | H112: =IF(SUM(H10:H109)=0,IF(COUNTA(H10:H109)=0,"Очікую",0),IF(COUNTIF(H10:H109,">=7")=0,0,COUNTIF(H10:H109,">=7")/$D109*100)) -> Очікую | I112: =IF(SUM(I10:I109)=0,IF(COUNTA(I10:I109)=0,"Очікую",0),IF(COUNTIF(I10:I109,">=7")=0,0,COUNTIF(I10:I109,">=7")/$D109*100)) -> Очікую | J112: =IF(SUM(J10:J109)=0,IF(COUNTA(J10:J109)=0,"Очікую",0),IF(COUNTIF(J10:J109,">=7")=0,0,COUNTIF(J10:J109,">=7")/$D109*100)) -> Очікую | K112: =IF(SUM(K10:K109)=0,IF(COUNTA(K10:K109)=0,"Очікую",0),IF(COUNTIF(K10:K109,">=7")=0,0,COUNTIF(K10:K109,">=7")/$D109*100)) -> Очікую | L112: =IF(SUM(L10:L109)=0,IF(COUNTA(L10:L109)=0,"Очікую",0),IF(COUNTIF(L10:L109,">=7")=0,0,COUNTIF(L10:L109,">=7")/$D109*100)) -> Очікую | M112: =IF(SUM(M10:M109)=0,IF(COUNTA(M10:M109)=0,"Очікую",0),IF(COUNTIF(M10:M109,">=7")=0,0,COUNTIF(M10:M109,">=7")/$D109*100)) -> Очікую | ... Y112: =IF(SUM(Y10:Y109)=0,IF(COUNTA(Y10:Y109)=0,"Очікую",0),IF(COUNTIF(Y10:Y109,">=7")=0,0,COUNTIF(Y10:Y109,">=7")/$D109*100)) -> Очікую
E113: Абсолютна успішність по групі | F113: =IFERROR(AVERAGE(F111:Y111),"Очікую") -> Очікую
E114: Якісна успішність по групі | F114: =IFERROR(AVERAGE(F112:Y112),"Очікую") -> Очікую
E115: Кількість бюджетників | F115: =IF(COUNTIF(C10:C109,"=Б")=0,IF(COUNTIF(C10:C109,"=К")=0,"Очікую",0),COUNTIF(C10:C109,"=Б")) -> Очікую
E116: Кількість контрактників | F116: =IF(COUNTIF(C10:C109,"=К")=0,IF(COUNTIF(C10:C109,"=Б")=0,"Очікую",0),COUNTIF(C10:C109,"=К")) -> Очікую | H116: Класний керівник
E117: Кількість соціального контингенту
E118: Вийшли на стипендію | F118: =IF(F115="Очікую","Очікую",IF(F115-COUNTIF(Z10:Z109," - ")<ROUNDDOWN(F115*0.4,0),F115-COUNTIF(Z10:Z109," - "),ROUNDDOWN(F115*0.4,0))) -> Очікую | H118: Завідувач відділення ПЗСО

Sheet ЛЗ2
A1: S
C3: ВІДОКРЕМЛЕНИЙ СТРУКТУРНИЙ ПІДРОЗДІЛ «ФАХОВИЙ КОЛЕДЖ НАФТОГАЗОВИХ ТЕХНОЛОГІЙ, ІНЖЕНЕРІЇ ТА ІНФРАСТРУКТУРИ СЕРВІСУ ОДЕСЬКОГО НАЦІОНАЛЬНОГО ТЕХНОЛОГІЧНОГО УНІВЕРСИТЕТУ»
C4: ЗВЕДЕНА ВІДОМІСТЬ
C5: Успішності студентів спеціальності XXX «XXXXX»
C6: За X семестр XXXX-XXXX н.р.
C7: Група XXXX курс X
C8: Б/К | D8: № п/п | E8: Прізвище, ім’я, по батькові | F8: Підсумкові оцінки дисциплін | Z8: Середній бал
F9: 1 | G9: 2 | H9: 3 | I9: 4 | J9: 5 | K9: 6 | L9: 7 | M9: 8 | N9: 9 | O9: 10 | P9: 11 | Q9: 12 | R9: 13 | S9: 14 | T9: 15 | U9: 16 | V9: 17 | W9: 18 | X9: 19 | Y9: 20
D10: 1 | Z10: =IF(COUNTIF(F10:Y10,"=*")>0,IF($C10="К","-"," - "),IF(COUNTIF(F10:Y10,"<4")>0,IF(C10="К","-"," - "),(IFERROR(AVERAGE(F10:Y10),"Очікую")))) -> Очікую
D11: 2 | Z11: =IF(COUNTIF(F11:Y11,"=*")>0,IF($C11="К","-"," - "),IF(COUNTIF(F11:Y11,"<4")>0,IF(C11="К","-"," - "),(IFERROR(AVERAGE(F11:Y11),"Очікую")))) -> Очікую
D12: 3 | Z12: =IF(COUNTIF(F12:Y12,"=*")>0,IF($C12="К","-"," - "),IF(COUNTIF(F12:Y12,"<4")>0,IF(C12="К","-"," - "),(IFERROR(AVERAGE(F12:Y12),"Очікую")))) -> Очікую
D13: 4 | Z13: =IF(COUNTIF(F13:Y13,"=*")>0,IF($C13="К","-"," - "),IF(COUNTIF(F13:Y13,"<4")>0,IF(C13="К","-"," - "),(IFERROR(AVERAGE(F13:Y13),"Очікую")))) -> Очікую
D14: 5 | Z14: =IF(COUNTIF(F14:Y14,"=*")>0,IF($C14="К","-"," - "),IF(COUNTIF(F14:Y14,"<4")>0,IF(C14="К","-"," - "),(IFERROR(AVERAGE(F14:Y14),"Очікую")))) -> Очікую
D15: 6 | Z15: =IF(COUNTIF(F15:Y15,"=*")>0,IF($C15="К","-"," - "),IF(COUNTIF(F15:Y15,"<4")>0,IF(C15="К","-"," - "),(IFERROR(AVERAGE(F15:Y15),"Очікую")))) -> Очікую
D16: 7 | Z16: =IF(COUNTIF(F16:Y16,"=*")>0,IF($C16="К","-"," - "),IF(COUNTIF(F16:Y16,"<4")>0,IF(C16="К","-"," - "),(IFERROR(AVERAGE(F16:Y16),"Очікую")))) -> Очікую
D17: 8 | Z17: =IF(COUNTIF(F17:Y17,"=*")>0,IF($C17="К","-"," - "),IF(COUNTIF(F17:Y17,"<4")>0,IF(C17="К","-"," - "),(IFERROR(AVERAGE(F17:Y17),"Очікую")))) -> Очікую
D18: 9 | Z18: =IF(COUNTIF(F18:Y18,"=*")>0,IF($C18="К","-"," - "),IF(COUNTIF(F18:Y18,"<4")>0,IF(C18="К","-"," - "),(IFERROR(AVERAGE(F18:Y18),"Очікую")))) -> Очікую
D19: 10 | Z19: =IF(COUNTIF(F19:Y19,"=*")>0,IF($C19="К","-"," - "),IF(COUNTIF(F19:Y19,"<4")>0,IF(C19="К","-"," - "),(IFERROR(AVERAGE(F19:Y19),"Очікую")))) -> Очікую
D20: 11 | Z20: =IF(COUNTIF(F20:Y20,"=*")>0,IF($C20="К","-"," - "),IF(COUNTIF(F20:Y20,"<4")>0,IF(C20="К","-"," - "),(IFERROR(AVERAGE(F20:Y20),"Очікую")))) -> Очікую
D21: 12 | Z21: =IF(COUNTIF(F21:Y21,"=*")>0,IF($C21="К","-"," - "),IF(COUNTIF(F21:Y21,"<4")>0,IF(C21="К","-"," - "),(IFERROR(AVERAGE(F21:Y21),"Очікую")))) -> Очікую
... D109: 100 | Z109: =IF(COUNTIF(F109:Y109,"=*")>0,IF($C109="К","-"," - "),IF(COUNTIF(F109:Y109,"<4")>0,IF(C109="К","-"," - "),(IFERROR(AVERAGE(F109:Y109),"Очікую")))) -> Очікую
E110: Середній бал успішності з дисципліни | F110: =IF(SUM(F10:F109)=0,IF(COUNTA(F10:F109)=0,"Очікую",0),SUM(F10:F109)/$D109) -> Очікую | G110: =IF(SUM(G10:G109)=0,IF(COUNTA(G10:G109)=0,"Очікую",0),SUM(G10:G109)/$D109) -> Очікую | H110: =IF(SUM(H10:H109)=0,IF(COUNTA(H10:H109)=0,"Очікую",0),SUM(H10:H109)/$D109) -> Очікую | I110: =IF(SUM(I10:I109)=0,IF(COUNTA(I10:I109)=0,"Очікую",0),SUM(I10:I109)/$D109) -> Очікую | J110: =IF(SUM(J10:J109)=0,IF(COUNTA(J10:J109)=0,"Очікую",0),SUM(J10:J109)/$D109) -> Очікую | K110: =IF(SUM(K10:K109)=0,IF(COUNTA(K10:K109)=0,"Очікую",0),SUM(K10:K109)/$D109) -> Очікую | L110: =IF(SUM(L10:L109)=0,IF(COUNTA(L10:L109)=0,"Очікую",0),SUM(L10:L109)/$D109) -> Очікую | M110: =IF(SUM(M10:M109)=0,IF(COUNTA(M10:M109)=0,"Очікую",0),SUM(M10:M109)/$D109) -> Очікую | ... Y110: =IF(SUM(Y10:Y109)=0,IF(COUNTA(Y10:Y109)=0,"Очікую",0),SUM(Y10:Y109)/$D109) -> Очікую | Z110: =IFERROR(AVERAGE(F110:Y110),"Очікую") -> Очікую
E111: Абсолютна успішність | F111: =IF(SUM(F10:F109)=0,IF(COUNTA(F10:F109)=0,"Очікую",0),IF(COUNTIF(F10:F109,">=4")=0,0,COUNTIF(F10:F109,">=4")/$D109*100)) -> Очікую | G111: =IF(SUM(G10:G109)=0,IF(COUNTA(G10:G109)=0,"Очікую",0),IF(COUNTIF(G10:G109,">=4")=0,0,COUNTIF(G10:G109,">=4")/$D109*100)) -> Очікую | H111: =IF(SUM(H10:H109)=0,IF(COUNTA(H10:H109)=0,"Очікую",0),IF(COUNTIF(H10:H109,">=4")=0,0,COUNTIF(H10:H109,">=4")/$D109*100)) -> Очікую | I111: =IF(SUM(I10:I109)=0,IF(COUNTA(I10:I109)=0,"Очікую",0),IF(COUNTIF(I10:I109,">=4")=0,0,COUNTIF(I10:I109,">=4")/$D109*100)) -> Очікую | J111: =IF(SUM(J10:J109)=0,IF(COUNTA(J10:J109)=0,"Очікую",0),IF(COUNTIF(J10:J109,">=4")=0,0,COUNTIF(J10:J109,">=4")/$D109*100)) -> Очікую | K111: =IF(SUM(K10:K109)=0,IF(COUNTA(K10:K109)=0,"Очікую",0),IF(COUNTIF(K10:K109,">=4")=0,0,COUNTIF(K10:K109,">=4")/$D109*100)) -> Очікую | L111: =IF(SUM(L10:L109)=0,IF(COUNTA(L10:L109)=0,"Очікую",0),IF(COUNTIF(L10:L109,">=4")=0,0,COUNTIF(L10:L109,">=4")/$D109*100)) -> Очікую | M111: =IF(SUM(M10:M109)=0,IF(COUNTA(M10:M109)=0,"Очікую",0),IF(COUNTIF(M10:M109,">=4")=0,0,COUNTIF(M10:M109,">=4")/$D109*100)) -> Очікую | ... Y111: =IF(SUM(Y10:Y109)=0,IF(COUNTA(Y10:Y109)=0,"Очікую",0),IF(COUNTIF(Y10:Y109,">=4")=0,0,COUNTIF(Y10:Y109,">=4")/$D109*100)) -> Очікую
E112: Якісна успішність | F112: =IF(SUM(F10:F109)=0,IF(COUNTA(F10:F109)=0,"Очікую",0),IF(COUNTIF(F10:F109,">=7")=0,0,COUNTIF(F10:F109,">=7")/$D109*100)) -> Очікую | G112: =IF(SUM(G10:G109)=0,IF(COUNTA(G10:G109)=0,"Очікую",0),IF(COUNTIF(G10:G109,">=7")=0,0,COUNTIF(G10:G109,">=7")/$D109*100)) -> Очікую | H112: =IF(SUM(H10:H109)=0,IF(COUNTA(H10:H109)=0,"Очікую",0),IF(COUNTIF(H10:H109,">=7")=0,0,COUNTIF(H10:H109,">=7")/$D109*100)) -> Очікую | I112: =IF(SUM(I10:I109)=0,IF(COUNTA(I10:I109)=0,"Очікую",0),IF(COUNTIF(I10:I109,">=7")=0,0,COUNTIF(I10:I109,">=7")/$D109*100)) -> Очікую | J112: =IF(SUM(J10:J109)=0,IF(COUNTA(J10:J109)=0,"Очікую",0),IF(COUNTIF(J10:J109,">=7")=0,0,COUNTIF(J10:J109,">=7")/$D109*100)) -> Очікую | K112: =IF(SUM(K10:K109)=0,IF(COUNTA(K10:K109)=0,"Очікую",0),IF(COUNTIF(K10:K109,">=7")=0,0,COUNTIF(K10:K109,">=7")/$D109*100)) -> Очікую | L112: =IF(SUM(L10:L109)=0,IF(COUNTA(L10:L109)=0,"Очікую",0),IF(COUNTIF(L10:L109,">=7")=0,0,COUNTIF(L10:L109,">=7")/$D109*100)) -> Очікую | M112: =IF(SUM(M10:M109)=0,IF(COUNTA(M10:M109)=0,"Очікую",0),IF(COUNTIF(M10:M109,">=7")=0,0,COUNTIF(M10:M109,">=7")/$D109*100)) -> Очікую | ... Y112: =IF(SUM(Y10:Y109)=0,IF(COUNTA(Y10:Y109)=0,"Очікую",0),IF(COUNTIF(Y10:Y109,">=7")=0,0,COUNTIF(Y10:Y109,">=7")/$D109*100)) -> Очікую
E113: Абсолютна успішність по групі | F113: =IFERROR(AVERAGE(F111:Y111),"Очікую") -> Очікую
E114: Якісна успішність по групі | F114: =IFERROR(AVERAGE(F112:Y112),"Очікую") -> Очікую
E115: Кількість бюджетників | F115: =IF(COUNTIF(C10:C109,"=Б")=0,IF(COUNTIF(C10:C109,"=К")=0,"Очікую",0),COUNTIF(C10:C109,"=Б")) -> Очікую
E116: Кількість контрактників | F116: =IF(COUNTIF(C10:C109,"=К")=0,IF(COUNTIF(C10:C109,"=Б")=0,"Очікую",0),COUNTIF(C10:C109,"=К")) -> Очікую | H116: Класний керівник
E117: Кількість соціального контингенту
E118: Вийшли на стипендію | F118: =IF(F115="Очікую","Очікую",IF(F115-COUNTIF(Z10:Z109," - ")<ROUNDDOWN(F115*0.4,0),F115-COUNTIF(Z10:Z109," - "),ROUNDDOWN(F115*0.4,0))) -> Очікую | H118: Завідувач відділення ПЗСО

Sheet ЛЗ3
A1: S
C3: ВІДОКРЕМЛЕНИЙ СТРУКТУРНИЙ ПІДРОЗДІЛ «ФАХОВИЙ КОЛЕДЖ НАФТОГАЗОВИХ ТЕХНОЛОГІЙ, ІНЖЕНЕРІЇ ТА ІНФРАСТРУКТУРИ СЕРВІСУ ОДЕСЬКОГО НАЦІОНАЛЬНОГО ТЕХНОЛОГІЧНОГО УНІВЕРСИТЕТУ»
C4: ЗВЕДЕНА ВІДОМІСТЬ
C5: Успішності студентів спеціальності XXX «XXXXX»
C6: За X семестр XXXX-XXXX н.р.
C7: Група XXXX курс X
C8: Б/К | D8: № п/п | E8: Прізвище, ім’я, по батькові | F8: Підсумкові оцінки дисциплін | Z8: Середній бал
F9: 1 | G9: 2 | H9: 3 | I9: 4 | J9: 5 | K9: 6 | L9: 7 | M9: 8 | N9: 9 | O9: 10 | P9: 11 | Q9: 12 | R9: 13 | S9: 14 | T9: 15 | U9: 16 | V9: 17 | W9: 18 | X9: 19 | Y9: 20
D10: 1 | Z10: =IF(COUNTIF(F10:Y10,"=*")>0,IF($C10="К","-"," - "),IF(COUNTIF(F10:Y10,"<4")>0,IF(C10="К","-"," - "),(IFERROR(AVERAGE(F10:Y10),"Очікую")))) -> Очікую
D11: 2 | Z11: =IF(COUNTIF(F11:Y11,"=*")>0,IF($C11="К","-"," - "),IF(COUNTIF(F11:Y11,"<4")>0,IF(C11="К","-"," - "),(IFERROR(AVERAGE(F11:Y11),"Очікую")))) -> Очікую
D12: 3 | Z12: =IF(COUNTIF(F12:Y12,"=*")>0,IF($C12="К","-"," - "),IF(COUNTIF(F12:Y12,"<4")>0,IF(C12="К","-"," - "),(IFERROR(AVERAGE(F12:Y12),"Очікую")))) -> Очікую
D13: 4 | Z13: =IF(COUNTIF(F13:Y13,"=*")>0,IF($C13="К","-"," - "),IF(COUNTIF(F13:Y13,"<4")>0,IF(C13="К","-"," - "),(IFERROR(AVERAGE(F13:Y13),"Очікую")))) -> Очікую
D14: 5 | Z14: =IF(COUNTIF(F14:Y14,"=*")>0,IF($C14="К","-"," - "),IF(COUNTIF(F14:Y14,"<4")>0,IF(C14="К","-"," - "),(IFERROR(AVERAGE(F14:Y14),"Очікую")))) -> Очікую
D15: 6 | Z15: =IF(COUNTIF(F15:Y15,"=*")>0,IF($C15="К","-"," - "),IF(COUNTIF(F15:Y15,"<4")>0,IF(C15="К","-"," - "),(IFERROR(AVERAGE(F15:Y15),"Очікую")))) -> Очікую
D16: 7 | Z16: =IF(COUNTIF(F16:Y16,"=*")>0,IF($C16="К","-"," - "),IF(COUNTIF(F16:Y16,"<4")>0,IF(C16="К","-"," - "),(IFERROR(AVERAGE(F16:Y16),"Очікую")))) -> Очікую
D17: 8 | Z17: =IF(COUNTIF(F17:Y17,"=*")>0,IF($C17="К","-"," - "),IF(COUNTIF(F17:Y17,"<4")>0,IF(C17="К","-"," - "),(IFERROR(AVERAGE(F17:Y17),"Очікую")))) -> Очікую
D18: 9 | Z18: =IF(COUNTIF(F18:Y18,"=*")>0,IF($C18="К","-"," - "),IF(COUNTIF(F18:Y18,"<4")>0,IF(C18="К","-"," - "),(IFERROR(AVERAGE(F18:Y18),"Очікую")))) -> Очікую
D19: 10 | Z19: =IF(COUNTIF(F19:Y19,"=*")>0,IF($C19="К","-"," - "),IF(COUNTIF(F19:Y19,"<4")>0,IF(C19="К","-"," - "),(IFERROR(AVERAGE(F19:Y19),"Очікую")))) -> Очікую
D20: 11 | Z20: =IF(COUNTIF(F20:Y20,"=*")>0,IF($C20="К","-"," - "),IF(COUNTIF(F20:Y20,"<4")>0,IF(C20="К","-"," - "),(IFERROR(AVERAGE(F20:Y20),"Очікую")))) -> Очікую
D21: 12 | Z21: =IF(COUNTIF(F21:Y21,"=*")>0,IF($C21="К","-"," - "),IF(COUNTIF(F21:Y21,"<4")>0,IF(C21="К","-"," - "),(IFERROR(AVERAGE(F21:Y21),"Очікую")))) -> Очікую
... D109: 100 | Z109: =IF(COUNTIF(F109:Y109,"=*")>0,IF($C109="К","-"," - "),IF(COUNTIF(F109:Y109,"<4")>0,IF(C109="К","-"," - "),(IFERROR(AVERAGE(F109:Y109),"Очікую")))) -> Очікую
E110: Середній бал успішності з дисципліни | F110: =IF(SUM(F10:F109)=0,IF(COUNTA(F10:F109)=0,"Очікую",0),SUM(F10:F109)/$D109) -> Очікую | G110: =IF(SUM(G10:G109)=0,IF(COUNTA(G10:G109)=0,"Очікую",0),SUM(G10:G109)/$D109) -> Очікую | H110: =IF(SUM(H10:H109)=0,IF(COUNTA(H10:H109)=0,"Очікую",0),SUM(H10:H109)/$D109) -> Очікую | I110: =IF(SUM(I10:I109)=0,IF(COUNTA(I10:I109)=0,"Очікую",0),SUM(I10:I109)/$D109) -> Очікую | J110: =IF(SUM(J10:J109)=0,IF(COUNTA(J10:J109)=0,"Очікую",0),SUM(J10:J109)/$D109) -> Очікую | K110: =IF(SUM(K10:K109)=0,IF(COUNTA(K10:K109)=0,"Очікую",0),SUM(K10:K109)/$D109) -> Очікую | L110: =IF(SUM(L10:L109)=0,IF(COUNTA(L10:L109)=0,"Очікую",0),SUM(L10:L109)/$D109) -> Очікую | M110: =IF(SUM(M10:M109)=0,IF(COUNTA(M10:M109)=0,"Очікую",0),SUM(M10:M109)/$D109) -> Очікую | ... Y110: =IF(SUM(Y10:Y109)=0,IF(COUNTA(Y10:Y109)=0,"Очікую",0),SUM(Y10:Y109)/$D109) -> Очікую | Z110: =IFERROR(AVERAGE(F110:Y110),"Очікую") -> Очікую
E111: Абсолютна успішність | F111: =IF(SUM(F10:F109)=0,IF(COUNTA(F10:F109)=0,"Очікую",0),IF(COUNTIF(F10:F109,">=4")=0,0,COUNTIF(F10:F109,">=4")/$D109*100)) -> Очікую | G111: =IF(SUM(G10:G109)=0,IF(COUNTA(G10:G109)=0,"Очікую",0),IF(COUNTIF(G10:G109,">=4")=0,0,COUNTIF(G10:G109,">=4")/$D109*100)) -> Очікую | H111: =IF(SUM(H10:H109)=0,IF(COUNTA(H10:H109)=0,"Очікую",0),IF(COUNTIF(H10:H109,">=4")=0,0,COUNTIF(H10:H109,">=4")/$D109*100)) -> Очікую | I111: =IF(SUM(I10:I109)=0,IF(COUNTA(I10:I109)=0,"Очікую",0),IF(COUNTIF(I10:I109,">=4")=0,0,COUNTIF(I10:I109,">=4")/$D109*100)) -> Очікую | J111: =IF(SUM(J10:J109)=0,IF(COUNTA(J10:J109)=0,"Очікую",0),IF(COUNTIF(J10:J109,">=4")=0,0,COUNTIF(J10:J109,">=4")/$D109*100)) -> Очікую | K111: =IF(SUM(K10:K109)=0,IF(COUNTA(K10:K109)=0,"Очікую",0),IF(COUNTIF(K10:K109,">=4")=0,0,COUNTIF(K10:K109,">=4")/$D109*100)) -> Очікую | L111: =IF(SUM(L10:L109)=0,IF(COUNTA(L10:L109)=0,"Очікую",0),IF(COUNTIF(L10:L109,">=4")=0,0,COUNTIF(L10:L109,">=4")/$D109*100)) -> Очікую | M111: =IF(SUM(M10:M109)=0,IF(COUNTA(M10:M109)=0,"Очікую",0),IF(COUNTIF(M10:M109,">=4")=0,0,COUNTIF(M10:M109,">=4")/$D109*100)) -> Очікую | ... Y111: =IF(SUM(Y10:Y109)=0,IF(COUNTA(Y10:Y109)=0,"Очікую",0),IF(COUNTIF(Y10:Y109,">=4")=0,0,COUNTIF(Y10:Y109,">=4")/$D109*100)) -> Очікую
E112: Якісна успішність | F112: =IF(SUM(F10:F109)=0,IF(COUNTA(F10:F109)=0,"Очікую",0),IF(COUNTIF(F10:F109,">=7")=0,0,COUNTIF(F10:F109,">=7")/$D109*100)) -> Очікую | G112: =IF(SUM(G10:G109)=0,IF(COUNTA(G10:G109)=0,"Очікую",0),IF(COUNTIF(G10:G109,">=7")=0,0,COUNTIF(G10:G109,">=7")/$D109*100)) -> Очікую | H112: =IF(SUM(H10:H109)=0,IF(COUNTA(H10:H109)=0,"Очікую",0),IF(COUNTIF(H10:H109,">=7")=0,0,COUNTIF(H10:H109,">=7")/$D109*100)) -> Очікую | I112: =IF(SUM(I10:I109)=0,IF(COUNTA(I10:I109)=0,"Очікую",0),IF(COUNTIF(I10:I109,">=7")=0,0,COUNTIF(I10:I109,">=7")/$D109*100)) -> Очікую | J112: =IF(SUM(J10:J109)=0,IF(COUNTA(J10:J109)=0,"Очікую",0),IF(COUNTIF(J10:J109,">=7")=0,0,COUNTIF(J10:J109,">=7")/$D109*100)) -> Очікую | K112: =IF(SUM(K10:K109)=0,IF(COUNTA(K10:K109)=0,"Очікую",0),IF(COUNTIF(K10:K109,">=7")=0,0,COUNTIF(K10:K109,">=7")/$D109*100)) -> Очікую | L112: =IF(SUM(L10:L109)=0,IF(COUNTA(L10:L109)=0,"Очікую",0),IF(COUNTIF(L10:L109,">=7")=0,0,COUNTIF(L10:L109,">=7")/$D109*100)) -> Очікую | M112: =IF(SUM(M10:M109)=0,IF(COUNTA(M10:M109)=0,"Очікую",0),IF(COUNTIF(M10:M109,">=7")=0,0,COUNTIF(M10:M109,">=7")/$D109*100)) -> Очікую | ... Y112: =IF(SUM(Y10:Y109)=0,IF(COUNTA(Y10:Y109)=0,"Очікую",0),IF(COUNTIF(Y10:Y109,">=7")=0,0,COUNTIF(Y10:Y109,">=7")/$D109*100)) -> Очікую
E113: Абсолютна успішність по групі | F113: =IFERROR(AVERAGE(F111:Y111),"Очікую") -> Очікую
E114: Якісна успішність по групі | F114: =IFERROR(AVERAGE(F112:Y112),"Очікую") -> Очікую
E115: Кількість бюджетників | F115: =IF(COUNTIF(C10:C109,"=Б")=0,IF(COUNTIF(C10:C109,"=К")=0,"Очікую",0),COUNTIF(C10:C109,"=Б")) -> Очікую
E116: Кількість контрактників | F116: =IF(COUNTIF(C10:C109,"=К")=0,IF(COUNTIF(C10:C109,"=Б")=0,"Очікую",0),COUNTIF(C10:C109,"=К")) -> Очікую | H116: Класний керівник
E117: Кількість соціального контингенту
E118: Вийшли на стипендію | F118: =IF(F115="Очікую","Очікую",IF(F115-COUNTIF(Z10:Z109," - ")<ROUNDDOWN(F115*0.4,0),F115-COUNTIF(Z10:Z109," - "),ROUNDDOWN(F115*0.4,0))) -> Очікую | H118: Завідувач відділення ПЗСО

Sheet ЛЗ4
A1: S
C3: ВІДОКРЕМЛЕНИЙ СТРУКТУРНИЙ ПІДРОЗДІЛ «ФАХОВИЙ КОЛЕДЖ НАФТОГАЗОВИХ ТЕХНОЛОГІЙ, ІНЖЕНЕРІЇ ТА ІНФРАСТРУКТУРИ СЕРВІСУ ОДЕСЬКОГО НАЦІОНАЛЬНОГО ТЕХНОЛОГІЧНОГО УНІВЕРСИТЕТУ»
C4: ЗВЕДЕНА ВІДОМІСТЬ
C5: Успішності студентів спеціальності XXX «XXXXX»
C6: За X семестр XXXX-XXXX н.р.
C7: Група XXXX курс X
C8: Б/К | D8: № п/п | E8: Прізвище, ім’я, по батькові | F8: Підсумкові оцінки дисциплін | Z8: Середній бал
F9: 1 | G9: 2 | H9: 3 | I9: 4 | J9: 5 | K9: 6 | L9: 7 | M9: 8 | N9: 9 | O9: 10 | P9: 11 | Q9: 12 | R9: 13 | S9: 14 | T9: 15 | U9: 16 | V9: 17 | W9: 18 | X9: 19 | Y9: 20
D10: 1 | Z10: =IF(COUNTIF(F10:Y10,"=*")>0,IF($C10="К","-"," - "),IF(COUNTIF(F10:Y10,"<4")>0,IF(C10="К","-"," - "),(IFERROR(AVERAGE(F10:Y10),"Очікую")))) -> Очікую
D11: 2 | Z11: =IF(COUNTIF(F11:Y11,"=*")>0,IF($C11="К","-"," - "),IF(COUNTIF(F11:Y11,"<4")>0,IF(C11="К","-"," - "),(IFERROR(AVERAGE(F11:Y11),"Очікую")))) -> Очікую
D12: 3 | Z12: =IF(COUNTIF(F12:Y12,"=*")>0,IF($C12="К","-"," - "),IF(COUNTIF(F12:Y12,"<4")>0,IF(C12="К","-"," - "),(IFERROR(AVERAGE(F12:Y12),"Очікую")))) -> Очікую
D13: 4 | Z13: =IF(COUNTIF(F13:Y13,"=*")>0,IF($C13="К","-"," - "),IF(COUNTIF(F13:Y13,"<4")>0,IF(C13="К","-"," - "),(IFERROR(AVERAGE(F13:Y13),"Очікую")))) -> Очікую
D14: 5 | Z14: =IF(COUNTIF(F14:Y14,"=*")>0,IF($C14="К","-"," - "),IF(COUNTIF(F14:Y14,"<4")>0,IF(C14="К","-"," - "),(IFERROR(AVERAGE(F14:Y14),"Очікую")))) -> Очікую
D15: 6 | Z15: =IF(COUNTIF(F15:Y15,"=*")>0,IF($C15="К","-"," - "),IF(COUNTIF(F15:Y15,"<4")>0,IF(C15="К","-"," - "),(IFERROR(AVERAGE(F15:Y15),"Очікую")))) -> Очікую
D16: 7 | Z16: =IF(COUNTIF(F16:Y16,"=*")>0,IF($C16="К","-"," - "),IF(COUNTIF(F16:Y16,"<4")>0,IF(C16="К","-"," - "),(IFERROR(AVERAGE(F16:Y16),"Очікую")))) -> Очікую
D17: 8 | Z17: =IF(COUNTIF(F17:Y17,"=*")>0,IF($C17="К","-"," - "),IF(COUNTIF(F17:Y17,"<4")>0,IF(C17="К","-"," - "),(IFERROR(AVERAGE(F17:Y17),"Очікую")))) -> Очікую
D18: 9 | Z18: =IF(COUNTIF(F18:Y18,"=*")>0,IF($C18="К","-"," - "),IF(COUNTIF(F18:Y18,"<4")>0,IF(C18="К","-"," - "),(IFERROR(AVERAGE(F18:Y18),"Очікую")))) -> Очікую
D19: 10 | Z19: =IF(COUNTIF(F19:Y19,"=*")>0,IF($C19="К","-"," - "),IF(COUNTIF(F19:Y19,"<4")>0,IF(C19="К","-"," - "),(IFERROR(AVERAGE(F19:Y19),"Очікую")))) -> Очікую
D20: 11 | Z20: =IF(COUNTIF(F20:Y20,"=*")>0,IF($C20="К","-"," - "),IF(COUNTIF(F20:Y20,"<4")>0,IF(C20="К","-"," - "),(IFERROR(AVERAGE(F20:Y20),"Очікую")))) -> Очікую
D21: 12 | Z21: =IF(COUNTIF(F21:Y21,"=*")>0,IF($C21="К","-"," - "),IF(COUNTIF(F21:Y21,"<4")>0,IF(C21="К","-"," - "),(IFERROR(AVERAGE(F21:Y21),"Очікую")))) -> Очікую
... D109: 100 | Z109: =IF(COUNTIF(F109:Y109,"=*")>0,IF($C109="К","-"," - "),IF(COUNTIF(F109:Y109,"<4")>0,IF(C109="К","-"," - "),(IFERROR(AVERAGE(F109:Y109),"Очікую")))) -> Очікую
E110: Середній бал успішності з дисципліни | F110: =IF(SUM(F10:F109)=0,IF(COUNTA(F10:F109)=0,"Очікую",0),SUM(F10:F109)/$D109) -> Очікую | G110: =IF(SUM(G10:G109)=0,IF(COUNTA(G10:G109)=0,"Очікую",0),SUM(G10:G109)/$D109) -> Очікую | H110: =IF(SUM(H10:H109)=0,IF(COUNTA(H10:H109)=0,"Очікую",0),SUM(H10:H109)/$D109) -> Очікую | I110: =IF(SUM(I10:I109)=0,IF(COUNTA(I10:I109)=0,"Очікую",0),SUM(I10:I109)/$D109) -> Очікую | J110: =IF(SUM(J10:J109)=0,IF(COUNTA(J10:J109)=0,"Очікую",0),SUM(J10:J109)/$D109) -> Очікую | K110: =IF(SUM(K10:K109)=0,IF(COUNTA(K10:K109)=0,"Очікую",0),SUM(K10:K109)/$D109) -> Очікую | L110: =IF(SUM(L10:L109)=0,IF(COUNTA(L10:L109)=0,"Очікую",0),SUM(L10:L109)/$D109) -> Очікую | M110: =IF(SUM(M10:M109)=0,IF(COUNTA(M10:M109)=0,"Очікую",0),SUM(M10:M109)/$D109) -> Очікую | ... Y110: =IF(SUM(Y10:Y109)=0,IF(COUNTA(Y10:Y109)=0,"Очікую",0),SUM(Y10:Y109)/$D109) -> Очікую | Z110: =IFERROR(AVERAGE(F110:Y110),"Очікую") -> Очікую
E111: Абсолютна успішність | F111: =IF(SUM(F10:F109)=0,IF(COUNTA(F10:F109)=0,"Очікую",0),IF(COUNTIF(F10:F109,">=4")=0,0,COUNTIF(F10:F109,">=4")/$D109*100)) -> Очікую | G111: =IF(SUM(G10:G109)=0,IF(COUNTA(G10:G109)=0,"Очікую",0),IF(COUNTIF(G10:G109,">=4")=0,0,COUNTIF(G10:G109,">=4")/$D109*100)) -> Очікую | H111: =IF(SUM(H10:H109)=0,IF(COUNTA(H10:H109)=0,"Очікую",0),IF(COUNTIF(H10:H109,">=4")=0,0,COUNTIF(H10:H109,">=4")/$D109*100)) -> Очікую | I111: =IF(SUM(I10:I109)=0,IF(COUNTA(I10:I109)=0,"Очікую",0),IF(COUNTIF(I10:I109,">=4")=0,0,COUNTIF(I10:I109,">=4")/$D109*100)) -> Очікую | J111: =IF(SUM(J10:J109)=0,IF(COUNTA(J10:J109)=0,"Очікую",0),IF(COUNTIF(J10:J109,">=4")=0,0,COUNTIF(J10:J109,">=4")/$D109*100)) -> Очікую | K111: =IF(SUM(K10:K109)=0,IF(COUNTA(K10:K109)=0,"Очікую",0),IF(COUNTIF(K10:K109,">=4")=0,0,COUNTIF(K10:K109,">=4")/$D109*100)) -> Очікую | L111: =IF(SUM(L10:L109)=0,IF(COUNTA(L10:L109)=0,"Очікую",0),IF(COUNTIF(L10:L109,">=4")=0,0,COUNTIF(L10:L109,">=4")/$D109*100)) -> Очікую | M111: =IF(SUM(M10:M109)=0,IF(COUNTA(M10:M109)=0,"Очікую",0),IF(COUNTIF(M10:M109,">=4")=0,0,COUNTIF(M10:M109,">=4")/$D109*100)) -> Очікую | ... Y111: =IF(SUM(Y10:Y109)=0,IF(COUNTA(Y10:Y109)=0,"Очікую",0),IF(COUNTIF(Y10:Y109,">=4")=0,0,COUNTIF(Y10:Y109,">=4")/$D109*100)) -> Очікую
E112: Якісна успішність | F112: =IF(SUM(F10:F109)=0,IF(COUNTA(F10:F109)=0,"Очікую",0),IF(COUNTIF(F10:F109,">=7")=0,0,COUNTIF(F10:F109,">=7")/$D109*100)) -> Очікую | G112: =IF(SUM(G10:G109)=0,IF(COUNTA(G10:G109)=0,"Очікую",0),IF(COUNTIF(G10:G109,">=7")=0,0,COUNTIF(G10:G109,">=7")/$D109*100)) -> Очікую | H112: =IF(SUM(H10:H109)=0,IF(COUNTA(H10:H109)=0,"Очікую",0),IF(COUNTIF(H10:H109,">=7")=0,0,COUNTIF(H10:H109,">=7")/$D109*100)) -> Очікую | I112: =IF(SUM(I10:I109)=0,IF(COUNTA(I10:I109)=0,"Очікую",0),IF(COUNTIF(I10:I109,">=7")=0,0,COUNTIF(I10:I109,">=7")/$D109*100)) -> Очікую | J112: =IF(SUM(J10:J109)=0,IF(COUNTA(J10:J109)=0,"Очікую",0),IF(COUNTIF(J10:J109,">=7")=0,0,COUNTIF(J10:J109,">=7")/$D109*100)) -> Очікую | K112: =IF(SUM(K10:K109)=0,IF(COUNTA(K10:K109)=0,"Очікую",0),IF(COUNTIF(K10:K109,">=7")=0,0,COUNTIF(K10:K109,">=7")/$D109*100)) -> Очікую | L112: =IF(SUM(L10:L109)=0,IF(COUNTA(L10:L109)=0,"Очікую",0),IF(COUNTIF(L10:L109,">=7")=0,0,COUNTIF(L10:L109,">=7")/$D109*100)) -> Очікую | M112: =IF(SUM(M10:M109)=0,IF(COUNTA(M10:M109)=0,"Очікую",0),IF(COUNTIF(M10:M109,">=7")=0,0,COUNTIF(M10:M109,">=7")/$D109*100)) -> Очікую | ... Y112: =IF(SUM(Y10:Y109)=0,IF(COUNTA(Y10:Y109)=0,"Очікую",0),IF(COUNTIF(Y10:Y109,">=7")=0,0,COUNTIF(Y10:Y109,">=7")/$D109*100)) -> Очікую
E113: Абсолютна успішність по групі | F113: =IFERROR(AVERAGE(F111:Y111),"Очікую") -> Очікую
E114: Якісна успішність по групі | F114: =IFERROR(AVERAGE(F112:Y112),"Очікую") -> Очікую
E115: Кількість бюджетників | F115: =IF(COUNTIF(C10:C109,"=Б")=0,IF(COUNTIF(C10:C109,"=К")=0,"Очікую",0),COUNTIF(C10:C109,"=Б")) -> Очікую
E116: Кількість контрактників | F116: =IF(COUNTIF(C10:C109,"=К")=0,IF(COUNTIF(C10:C109,"=Б")=0,"Очікую",0),COUNTIF(C10:C109,"=К")) -> Очікую | H116: Класний керівник
E117: Кількість соціального контингенту
E118: Вийшли на стипендію | F118: =IF(F115="Очікую","Очікую",IF(F115-COUNTIF(Z10:Z109," - ")<ROUNDDOWN(F115*0.4,0),F115-COUNTIF(Z10:Z109," - "),ROUNDDOWN(F115*0.4,0))) -> Очікую | H118: Завідувач відділення ПЗСО

Sheet ЛЗ5
A1: S
C3: ВІДОКРЕМЛЕНИЙ СТРУКТУРНИЙ ПІДРОЗДІЛ «ФАХОВИЙ КОЛЕДЖ НАФТОГАЗОВИХ ТЕХНОЛОГІЙ, ІНЖЕНЕРІЇ ТА ІНФРАСТРУКТУРИ СЕРВІСУ ОДЕСЬКОГО НАЦІОНАЛЬНОГО ТЕХНОЛОГІЧНОГО УНІВЕРСИТЕТУ»
C4: ЗВЕДЕНА ВІДОМІСТЬ
C5: Успішності студентів спеціальності XXX «XXXXX»
C6: За X семестр XXXX-XXXX н.р.
C7: Група XXXX курс X
C8: Б/К | D8: № п/п | E8: Прізвище, ім’я, по батькові | F8: Підсумкові оцінки дисциплін | Z8: Середній бал
F9: 1 | G9: 2 | H9: 3 | I9: 4 | J9: 5 | K9: 6 | L9: 7 | M9: 8 | N9: 9 | O9: 10 | P9: 11 | Q9: 12 | R9: 13 | S9: 14 | T9: 15 | U9: 16 | V9: 17 | W9: 18 | X9: 19 | Y9: 20
D10: 1 | Z10: =IF(COUNTIF(F10:Y10,"=*")>0,IF($C10="К","-"," - "),IF(COUNTIF(F10:Y10,"<4")>0,IF(C10="К","-"," - "),(IFERROR(AVERAGE(F10:Y10),"Очікую")))) -> Очікую
D11: 2 | Z11: =IF(COUNTIF(F11:Y11,"=*")>0,IF($C11="К","-"," - "),IF(COUNTIF(F11:Y11,"<4")>0,IF(C11="К","-"," - "),(IFERROR(AVERAGE(F11:Y11),"Очікую")))) -> Очікую
D12: 3 | Z12: =IF(COUNTIF(F12:Y12,"=*")>0,IF($C12="К","-"," - "),IF(COUNTIF(F12:Y12,"<4")>0,IF(C12="К","-"," - "),(IFERROR(AVERAGE(F12:Y12),"Очікую")))) -> Очікую
D13: 4 | Z13: =IF(COUNTIF(F13:Y13,"=*")>0,IF($C13="К","-"," - "),IF(COUNTIF(F13:Y13,"<4")>0,IF(C13="К","-"," - "),(IFERROR(AVERAGE(F13:Y13),"Очікую")))) -> Очікую
D14: 5 | Z14: =IF(COUNTIF(F14:Y14,"=*")>0,IF($C14="К","-"," - "),IF(COUNTIF(F14:Y14,"<4")>0,IF(C14="К","-"," - "),(IFERROR(AVERAGE(F14:Y14),"Очікую")))) -> Очікую
D15: 6 | Z15: =IF(COUNTIF(F15:Y15,"=*")>0,IF($C15="К","-"," - "),IF(COUNTIF(F15:Y15,"<4")>0,IF(C15="К","-"," - "),(IFERROR(AVERAGE(F15:Y15),"Очікую")))) -> Очікую
D16: 7 | Z16: =IF(COUNTIF(F16:Y16,"=*")>0,IF($C16="К","-"," - "),IF(COUNTIF(F16:Y16,"<4")>0,IF(C16="К","-"," - "),(IFERROR(AVERAGE(F16:Y16),"Очікую")))) -> Очікую
D17: 8 | Z17: =IF(COUNTIF(F17:Y17,"=*")>0,IF($C17="К","-"," - "),IF(COUNTIF(F17:Y17,"<4")>0,IF(C17="К","-"," - "),(IFERROR(AVERAGE(F17:Y17),"Очікую")))) -> Очікую
D18: 9 | Z18: =IF(COUNTIF(F18:Y18,"=*")>0,IF($C18="К","-"," - "),IF(COUNTIF(F18:Y18,"<4")>0,IF(C18="К","-"," - "),(IFERROR(AVERAGE(F18:Y18),"Очікую")))) -> Очікую
D19: 10 | Z19: =IF(COUNTIF(F19:Y19,"=*")>0,IF($C19="К","-"," - "),IF(COUNTIF(F19:Y19,"<4")>0,IF(C19="К","-"," - "),(IFERROR(AVERAGE(F19:Y19),"Очікую")))) -> Очікую
D20: 11 | Z20: =IF(COUNTIF(F20:Y20,"=*")>0,IF($C20="К","-"," - "),IF(COUNTIF(F20:Y20,"<4")>0,IF(C20="К","-"," - "),(IFERROR(AVERAGE(F20:Y20),"Очікую")))) -> Очікую
D21: 12 | Z21: =IF(COUNTIF(F21:Y21,"=*")>0,IF($C21="К","-"," - "),IF(COUNTIF(F21:Y21,"<4")>0,IF(C21="К","-"," - "),(IFERROR(AVERAGE(F21:Y21),"Очікую")))) -> Очікую
... D109: 100 | Z109: =IF(COUNTIF(F109:Y109,"=*")>0,IF($C109="К","-"," - "),IF(COUNTIF(F109:Y109,"<4")>0,IF(C109="К","-"," - "),(IFERROR(AVERAGE(F109:Y109),"Очікую")))) -> Очікую
E110: Середній бал успішності з дисципліни | F110: =IF(SUM(F10:F109)=0,IF(COUNTA(F10:F109)=0,"Очікую",0),SUM(F10:F109)/$D109) -> Очікую | G110: =IF(SUM(G10:G109)=0,IF(COUNTA(G10:G109)=0,"Очікую",0),SUM(G10:G109)/$D109) -> Очікую | H110: =IF(SUM(H10:H109)=0,IF(COUNTA(H10:H109)=0,"Очікую",0),SUM(H10:H109)/$D109) -> Очікую | I110: =IF(SUM(I10:I109)=0,IF(COUNTA(I10:I109)=0,"Очікую",0),SUM(I10:I109)/$D109) -> Очікую | J110: =IF(SUM(J10:J109)=0,IF(COUNTA(J10:J109)=0,"Очікую",0),SUM(J10:J109)/$D109) -> Очікую | K110: =IF(SUM(K10:K109)=0,IF(COUNTA(K10:K109)=0,"Очікую",0),SUM(K10:K109)/$D109) -> Очікую | L110: =IF(SUM(L10:L109)=0,IF(COUNTA(L10:L109)=0,"Очікую",0),SUM(L10:L109)/$D109) -> Очікую | M110: =IF(SUM(M10:M109)=0,IF(COUNTA(M10:M109)=0,"Очікую",0),SUM(M10:M109)/$D109) -> Очікую | ... Y110: =IF(SUM(Y10:Y109)=0,IF(COUNTA(Y10:Y109)=0,"Очікую",0),SUM(Y10:Y109)/$D109) -> Очікую | Z110: =IFERROR(AVERAGE(F110:Y110),"Очікую") -> Очікую
E111: Абсолютна успішність | F111: =IF(SUM(F10:F109)=0,IF(COUNTA(F10:F109)=0,"Очікую",0),IF(COUNTIF(F10:F109,">=4")=0,0,COUNTIF(F10:F109,">=4")/$D109*100)) -> Очікую | G111: =IF(SUM(G10:G109)=0,IF(COUNTA(G10:G109)=0,"Очікую",0),IF(COUNTIF(G10:G109,">=4")=0,0,COUNTIF(G10:G109,">=4")/$D109*100)) -> Очікую | H111: =IF(SUM(H10:H109)=0,IF(COUNTA(H10:H109)=0,"Очікую",0),IF(COUNTIF(H10:H109,">=4")=0,0,COUNTIF(H10:H109,">=4")/$D109*100)) -> Очікую | I111: =IF(SUM(I10:I109)=0,IF(COUNTA(I10:I109)=0,"Очікую",0),IF(COUNTIF(I10:I109,">=4")=0,0,COUNTIF(I10:I109,">=4")/$D109*100)) -> Очікую | J111: =IF(SUM(J10:J109)=0,IF(COUNTA(J10:J109)=0,"Очікую",0),IF(COUNTIF(J10:J109,">=4")=0,0,COUNTIF(J10:J109,">=4")/$D109*100)) -> Очікую | K111: =IF(SUM(K10:K109)=0,IF(COUNTA(K10:K109)=0,"Очікую",0),IF(COUNTIF(K10:K109,">=4")=0,0,COUNTIF(K10:K109,">=4")/$D109*100)) -> Очікую | L111: =IF(SUM(L10:L109)=0,IF(COUNTA(L10:L109)=0,"Очікую",0),IF(COUNTIF(L10:L109,">=4")=0,0,COUNTIF(L10:L109,">=4")/$D109*100)) -> Очікую | M111: =IF(SUM(M10:M109)=0,IF(COUNTA(M10:M109)=0,"Очікую",0),IF(COUNTIF(M10:M109,">=4")=0,0,COUNTIF(M10:M109,">=4")/$D109*100)) -> Очікую | ... Y111: =IF(SUM(Y10:Y109)=0,IF(COUNTA(Y10:Y109)=0,"Очікую",0),IF(COUNTIF(Y10:Y109,">=4")=0,0,COUNTIF(Y10:Y109,">=4")/$D109*100)) -> Очікую
E112: Якісна успішність | F112: =IF(SUM(F10:F109)=0,IF(COUNTA(F10:F109)=0,"Очікую",0),IF(COUNTIF(F10:F109,">=7")=0,0,COUNTIF(F10:F109,">=7")/$D109*100)) -> Очікую | G112: =IF(SUM(G10:G109)=0,IF(COUNTA(G10:G109)=0,"Очікую",0),IF(COUNTIF(G10:G109,">=7")=0,0,COUNTIF(G10:G109,">=7")/$D109*100)) -> Очікую | H112: =IF(SUM(H10:H109)=0,IF(COUNTA(H10:H109)=0,"Очікую",0),IF(COUNTIF(H10:H109,">=7")=0,0,COUNTIF(H10:H109,">=7")/$D109*100)) -> Очікую | I112: =IF(SUM(I10:I109)=0,IF(COUNTA(I10:I109)=0,"Очікую",0),IF(COUNTIF(I10:I109,">=7")=0,0,COUNTIF(I10:I109,">=7")/$D109*100)) -> Очікую | J112: =IF(SUM(J10:J109)=0,IF(COUNTA(J10:J109)=0,"Очікую",0),IF(COUNTIF(J10:J109,">=7")=0,0,COUNTIF(J10:J109,">=7")/$D109*100)) -> Очікую | K112: =IF(SUM(K10:K109)=0,IF(COUNTA(K10:K109)=0,"Очікую",0),IF(COUNTIF(K10:K109,">=7")=0,0,COUNTIF(K10:K109,">=7")/$D109*100)) -> Очікую | L112: =IF(SUM(L10:L109)=0,IF(COUNTA(L10:L109)=0,"Очікую",0),IF(COUNTIF(L10:L109,">=7")=0,0,COUNTIF(L10:L109,">=7")/$D109*100)) -> Очікую | M112: =IF(SUM(M10:M109)=0,IF(COUNTA(M10:M109)=0,"Очікую",0),IF(COUNTIF(M10:M109,">=7")=0,0,COUNTIF(M10:M109,">=7")/$D109*100)) -> Очікую | ... Y112: =IF(SUM(Y10:Y109)=0,IF(COUNTA(Y10:Y109)=0,"Очікую",0),IF(COUNTIF(Y10:Y109,">=7")=0,0,COUNTIF(Y10:Y109,">=7")/$D109*100)) -> Очікую
E113: Абсолютна успішність по групі | F113: =IFERROR(AVERAGE(F111:Y111),"Очікую") -> Очікую
E114: Якісна успішність по групі | F114: =IFERROR(AVERAGE(F112:Y112),"Очікую") -> Очікую
E115: Кількість бюджетників | F115: =IF(COUNTIF(C10:C109,"=Б")=0,IF(COUNTIF(C10:C109,"=К")=0,"Очікую",0),COUNTIF(C10:C109,"=Б")) -> Очікую
E116: Кількість контрактників | F116: =IF(COUNTIF(C10:C109,"=К")=0,IF(COUNTIF(C10:C109,"=Б")=0,"Очікую",0),COUNTIF(C10:C109,"=К")) -> Очікую | H116: Класний керівник
E117: Кількість соціального контингенту
E118: Вийшли на стипендію | F118: =IF(F115="Очікую","Очікую",IF(F115-COUNTIF(Z10:Z109," - ")<ROUNDDOWN(F115*0.4,0),F115-COUNTIF(Z10:Z109," - "),ROUNDDOWN(F115*0.4,0))) -> Очікую | H118: Завідувач відділення ПЗСО

Sheet ЛЗ6
A1: S
C3: ВІДОКРЕМЛЕНИЙ СТРУКТУРНИЙ ПІДРОЗДІЛ «ФАХОВИЙ КОЛЕДЖ НАФТОГАЗОВИХ ТЕХНОЛОГІЙ, ІНЖЕНЕРІЇ ТА ІНФРАСТРУКТУРИ СЕРВІСУ ОДЕСЬКОГО НАЦІОНАЛЬНОГО ТЕХНОЛОГІЧНОГО УНІВЕРСИТЕТУ»
C4: ЗВЕДЕНА ВІДОМІСТЬ
C5: Успішності студентів спеціальності XXX «XXXXX»
C6: За X семестр XXXX-XXXX н.р.
C7: Група XXXX курс X
C8: Б/К | D8: № п/п | E8: Прізвище, ім’я, по батькові | F8: Підсумкові оцінки дисциплін | Z8: Середній бал
F9: 1 | G9: 2 | H9: 3 | I9: 4 | J9: 5 | K9: 6 | L9: 7 | M9: 8 | N9: 9 | O9: 10 | P9: 11 | Q9: 12 | R9: 13 | S9: 14 | T9: 15 | U9: 16 | V9: 17 | W9: 18 | X9: 19 | Y9: 20
D10: 1 | Z10: =IF(COUNTIF(F10:Y10,"=*")>0,IF($C10="К","-"," - "),IF(COUNTIF(F10:Y10,"<4")>0,IF(C10="К","-"," - "),(IFERROR(AVERAGE(F10:Y10),"Очікую")))) -> Очікую
D11: 2 | Z11: =IF(COUNTIF(F11:Y11,"=*")>0,IF($C11="К","-"," - "),IF(COUNTIF(F11:Y11,"<4")>0,IF(C11="К","-"," - "),(IFERROR(AVERAGE(F11:Y11),"Очікую")))) -> Очікую
D12: 3 | Z12: =IF(COUNTIF(F12:Y12,"=*")>0,IF($C12="К","-"," - "),IF(COUNTIF(F12:Y12,"<4")>0,IF(C12="К","-"," - "),(IFERROR(AVERAGE(F12:Y12),"Очікую")))) -> Очікую
D13: 4 | Z13: =IF(COUNTIF(F13:Y13,"=*")>0,IF($C13="К","-"," - "),IF(COUNTIF(F13:Y13,"<4")>0,IF(C13="К","-"," - "),(IFERROR(AVERAGE(F13:Y13),"Очікую")))) -> Очікую
D14: 5 | Z14: =IF(COUNTIF(F14:Y14,"=*")>0,IF($C14="К","-"," - "),IF(COUNTIF(F14:Y14,"<4")>0,IF(C14="К","-"," - "),(IFERROR(AVERAGE(F14:Y14),"Очікую")))) -> Очікую
D15: 6 | Z15: =IF(COUNTIF(F15:Y15,"=*")>0,IF($C15="К","-"," - "),IF(COUNTIF(F15:Y15,"<4")>0,IF(C15="К","-"," - "),(IFERROR(AVERAGE(F15:Y15),"Очікую")))) -> Очікую
D16: 7 | Z16: =IF(COUNTIF(F16:Y16,"=*")>0,IF($C16="К","-"," - "),IF(COUNTIF(F16:Y16,"<4")>0,IF(C16="К","-"," - "),(IFERROR(AVERAGE(F16:Y16),"Очікую")))) -> Очікую
D17: 8 | Z17: =IF(COUNTIF(F17:Y17,"=*")>0,IF($C17="К","-"," - "),IF(COUNTIF(F17:Y17,"<4")>0,IF(C17="К","-"," - "),(IFERROR(AVERAGE(F17:Y17),"Очікую")))) -> Очікую
D18: 9 | Z18: =IF(COUNTIF(F18:Y18,"=*")>0,IF($C18="К","-"," - "),IF(COUNTIF(F18:Y18,"<4")>0,IF(C18="К","-"," - "),(IFERROR(AVERAGE(F18:Y18),"Очікую")))) -> Очікую
D19: 10 | Z19: =IF(COUNTIF(F19:Y19,"=*")>0,IF($C19="К","-"," - "),IF(COUNTIF(F19:Y19,"<4")>0,IF(C19="К","-"," - "),(IFERROR(AVERAGE(F19:Y19),"Очікую")))) -> Очікую
D20: 11 | Z20: =IF(COUNTIF(F20:Y20,"=*")>0,IF($C20="К","-"," - "),IF(COUNTIF(F20:Y20,"<4")>0,IF(C20="К","-"," - "),(IFERROR(AVERAGE(F20:Y20),"Очікую")))) -> Очікую
D21: 12 | Z21: =IF(COUNTIF(F21:Y21,"=*")>0,IF($C21="К","-"," - "),IF(COUNTIF(F21:Y21,"<4")>0,IF(C21="К","-"," - "),(IFERROR(AVERAGE(F21:Y21),"Очікую")))) -> Очікую
... D109: 100 | Z109: =IF(COUNTIF(F109:Y109,"=*")>0,IF($C109="К","-"," - "),IF(COUNTIF(F109:Y109,"<4")>0,IF(C109="К","-"," - "),(IFERROR(AVERAGE(F109:Y109),"Очікую")))) -> Очікую
E110: Середній бал успішності з дисципліни | F110: =IF(SUM(F10:F109)=0,IF(COUNTA(F10:F109)=0,"Очікую",0),SUM(F10:F109)/$D109) -> Очікую | G110: =IF(SUM(G10:G109)=0,IF(COUNTA(G10:G109)=0,"Очікую",0),SUM(G10:G109)/$D109) -> Очікую | H110: =IF(SUM(H10:H109)=0,IF(COUNTA(H10:H109)=0,"Очікую",0),SUM(H10:H109)/$D109) -> Очікую | I110: =IF(SUM(I10:I109)=0,IF(COUNTA(I10:I109)=0,"Очікую",0),SUM(I10:I109)/$D109) -> Очікую | J110: =IF(SUM(J10:J109)=0,IF(COUNTA(J10:J109)=0,"Очікую",0),SUM(J10:J109)/$D109) -> Очікую | K110: =IF(SUM(K10:K109)=0,IF(COUNTA(K10:K109)=0,"Очікую",0),SUM(K10:K109)/$D109) -> Очікую | L110: =IF(SUM(L10:L109)=0,IF(COUNTA(L10:L109)=0,"Очікую",0),SUM(L10:L109)/$D109) -> Очікую | M110: =IF(SUM(M10:M109)=0,IF(COUNTA(M10:M109)=0,"Очікую",0),SUM(M10:M109)/$D109) -> Очікую | ... Y110: =IF(SUM(Y10:Y109)=0,IF(COUNTA(Y10:Y109)=0,"Очікую",0),SUM(Y10:Y109)/$D109) -> Очікую | Z110: =IFERROR(AVERAGE(F110:Y110),"Очікую") -> Очікую
E111: Абсолютна успішність | F111: =IF(SUM(F10:F109)=0,IF(COUNTA(F10:F109)=0,"Очікую",0),IF(COUNTIF(F10:F109,">=4")=0,0,COUNTIF(F10:F109,">=4")/$D109*100)) -> Очікую | G111: =IF(SUM(G10:G109)=0,IF(COUNTA(G10:G109)=0,"Очікую",0),IF(COUNTIF(G10:G109,">=4")=0,0,COUNTIF(G10:G109,">=4")/$D109*100)) -> Очікую | H111: =IF(SUM(H10:H109)=0,IF(COUNTA(H10:H109)=0,"Очікую",0),IF(COUNTIF(H10:H109,">=4")=0,0,COUNTIF(H10:H109,">=4")/$D109*100)) -> Очікую | I111: =IF(SUM(I10:I109)=0,IF(COUNTA(I10:I109)=0,"Очікую",0),IF(COUNTIF(I10:I109,">=4")=0,0,COUNTIF(I10:I109,">=4")/$D109*100)) -> Очікую | J111: =IF(SUM(J10:J109)=0,IF(COUNTA(J10:J109)=0,"Очікую",0),IF(COUNTIF(J10:J109,">=4")=0,0,COUNTIF(J10:J109,">=4")/$D109*100)) -> Очікую | K111: =IF(SUM(K10:K109)=0,IF(COUNTA(K10:K109)=0,"Очікую",0),IF(COUNTIF(K10:K109,">=4")=0,0,COUNTIF(K10:K109,">=4")/$D109*100)) -> Очікую | L111: =IF(SUM(L10:L109)=0,IF(COUNTA(L10:L109)=0,"Очікую",0),IF(COUNTIF(L10:L109,">=4")=0,0,COUNTIF(L10:L109,">=4")/$D109*100)) -> Очікую | M111: =IF(SUM(M10:M109)=0,IF(COUNTA(M10:M109)=0,"Очікую",0),IF(COUNTIF(M10:M109,">=4")=0,0,COUNTIF(M10:M109,">=4")/$D109*100)) -> Очікую | ... Y111: =IF(SUM(Y10:Y109)=0,IF(COUNTA(Y10:Y109)=0,"Очікую",0),IF(COUNTIF(Y10:Y109,">=4")=0,0,COUNTIF(Y10:Y109,">=4")/$D109*100)) -> Очікую
