Workbook
Name A1048577: #REF!
Name A1048577: #REF!
Name A1048577: #REF!
Name A1048577: #REF!
Name A1048577: #REF!
Name A1048577: #REF!
Name Ф80: #REF!
Name Ф80: #REF!
Name Ф80: #REF!
Name Ф80: #REF!
Name Ф80: #REF!
Name Ф80: #REF!

Sheet Зведена 141
C3: ВІДОКРЕМЛЕНИЙ СТРУКТУРНИЙ ПІДРОЗДІЛ «ФАХОВИЙ КОЛЕДЖ НАФТОГАЗОВИХ ТЕХНОЛОГІЙ, ІНЖЕНЕРІЇ ТА ІНФРАСТРУКТУРИ СЕРВІСУ
C4: ОДЕСЬКОГО НАЦІОНАЛЬНОГО ТЕХНОЛОГІЧНОГО УНІВЕРСИТЕТУ»
C5: ЗВЕДЕНА ВІДОМІСТЬ
C6: Успішності студентів спеціальності 141 «Електроенергетика, електротехніка та електромеханіка»
C7: За IІ семестр 2024-2025 н.р.
C8: Група 24-4 курс І
C9: Б/К | D9: № п/п | E9: Прізвище, ім’я, по батькові | G9: Підсумкові оцінки дисциплін
F10: Астрономія Наговська Т.С. | G10: Біологія Богданенко О.В. | H10: Всесвітня історія Мельничук С.А. | I10: Географія Наговська Т.С. | J10: Зарубіжна література Сербулова Ю.А. | K10: Захист України Лазар В.І. | L10: Іноземна мова Нічик Н.О. | M10: Інформатика Бєльдюгіна С.С. | N10: Історія України Левчук Т.Г. | O10: Математика Ромчук В.В. | P10: Українська література Юрченко О.Б. | Q10: Українська мова Юрченко О.Б. | R10: Фізика Калюта Н.М. | S10: Фізична культура Галеніна І.С. | T10: Хімія Сахно Н.О. | U10: Середній бал
C11: К | D11: 1 | E11: Аман Святослав Вікторович | F11: 5 | G11: 6 | H11: 5 | I11: 5 | J11: 6 | K11: 4 | L11: 4 | M11: н/а | N11: н/а | O11: н/а | P11: 4 | Q11: 4 | R11: 4 | S11: 4 | T11: н/а | U11: =IF(COUNTIF(F11:T11,"=*")>0,"-",IF(COUNTIF(F11:T11,"<4")>0,"-",(IFERROR(AVERAGE(F11:T11),"")))) -> -
C12: Б | D12: 2 | E12: Артюхін Родіон Костянтинович | F12: 10 | G12: 11 | H12: 10 | I12: 11 | J12: 10 | K12: 11 | L12: 10 | M12: 10 | N12: 10 | O12: 10 | P12: 10 | Q12: 10 | R12: 10 | S12: 11 | T12: 10 | U12: =IF(COUNTIF(F12:T12,"=*")>0,"-",IF(COUNTIF(F12:T12,"<4")>0,"-",(IFERROR(AVERAGE(F12:T12),"")))) -> 10.266667
C13: К | D13: 3 | E13: Бужор Михайло Федорович | F13: 8 | G13: 7 | H13: 6 | I13: 8 | J13: 5 | K13: 4 | L13: 4 | M13: 8 | N13: 7 | O13: 6 | P13: 7 | Q13: 7 | R13: 7 | S13: 7 | T13: 7 | U13: =IF(COUNTIF(F13:T13,"=*")>0,"-",IF(COUNTIF(F13:T13,"<4")>0,"-",(IFERROR(AVERAGE(F13:T13),"")))) -> 6.5333333
C14: К | D14: 4 | E14: Воскобойнік Богдан Ігорович | F14: 7 | G14: 7 | H14: 9 | I14: 7 | J14: 8 | K14: 5 | L14: 4 | M14: 6 | N14: 4 | O14: 4 | P14: 4 | Q14: 4 | R14: 4 | S14: 8 | T14: 4 | U14: =IF(COUNTIF(F14:T14,"=*")>0,"-",IF(COUNTIF(F14:T14,"<4")>0,"-",(IFERROR(AVERAGE(F14:T14),"")))) -> 5.6666667
C15: Б | D15: 5 | E15: Демінський Кирило Вячеславович | F15: 10 | G15: 11 | H15: 10 | I15: 11 | J15: 10 | K15: 11 | L15: 10 | M15: 10 | N15: 10 | O15: 10 | P15: 10 | Q15: 10 | R15: 10 | S15: 11 | T15: 10 | U15: =IF(COUNTIF(F15:T15,"=*")>0,"-",IF(COUNTIF(F15:T15,"<4")>0,"-",(IFERROR(AVERAGE(F15:T15),"")))) -> 10.266667
C16: К | D16: 6 | E16: Дрига Олександр Артемович | F16: 8 | G16: 10 | H16: 8 | I16: 9 | J16: 6 | K16: 7 | L16: 4 | M16: 4 | N16: 7 | O16: 6 | P16: 8 | Q16: 7 | R16: 6 | S16: 7 | T16: 6 | U16: =IF(COUNTIF(F16:T16,"=*")>0,"-",IF(COUNTIF(F16:T16,"<4")>0,"-",(IFERROR(AVERAGE(F16:T16),"")))) -> 6.8666667
C17: К | D17: 7 | E17: Іхтіар Ігор Петрович | F17: 7 | G17: 6 | H17: 9 | I17: 7 | J17: 9 | K17: н/а | L17: 5 | M17: 6 | N17: н/а | O17: 5 | P17: 4 | Q17: 4 | R17: 4 | S17: 8 | T17: 4 | U17: =IF(COUNTIF(F17:T17,"=*")>0,"-",IF(COUNTIF(F17:T17,"<4")>0,"-",(IFERROR(AVERAGE(F17:T17),"")))) -> -
C18: Б | D18: 8 | E18: Кихтенко Тимофій Вячеславович | F18: 10 | G18: 11 | H18: 10 | I18: 11 | J18: 10 | K18: 9 | L18: 9 | M18: 10 | N18: 7 | O18: 7 | P18: 11 | Q18: 8 | R18: 9 | S18: 10 | T18: 8 | U18: =IF(COUNTIF(F18:T18,"=*")>0,"-",IF(COUNTIF(F18:T18,"<4")>0,"-",(IFERROR(AVERAGE(F18:T18),"")))) -> 9.3333333
C19: Б | D19: 9 | E19: Комарницький Олександр Вячеславович | F19: 6 | G19: 8 | H19: 9 | I19: 6 | J19: 7 | K19: 8 | L19: 7 | M19: 8 | N19: 7 | O19: 4 | P19: 4 | Q19: 4 | R19: 4 | S19: 9 | T19: 4 | U19: =IF(COUNTIF(F19:T19,"=*")>0,"-",IF(COUNTIF(F19:T19,"<4")>0,"-",(IFERROR(AVERAGE(F19:T19),"")))) -> 6.3333333
C20: Б | D20: 10 | E20: Кравець Олексій Олександрович | F20: 10 | G20: 11 | H20: 11 | I20: 10 | J20: 10 | K20: 10 | L20: 11 | M20: 11 | N20: 10 | O20: 10 | P20: 11 | Q20: 10 | R20: 11 | S20: 11 | T20: 10 | U20: =IF(COUNTIF(F20:T20,"=*")>0,"-",IF(COUNTIF(F20:T20,"<4")>0,"-",(IFERROR(AVERAGE(F20:T20),"")))) -> 10.466667
C21: К | D21: 11 | E21: Кулиш Вадім Вячеславович | F21: 4 | G21: 6 | H21: 5 | I21: 4 | J21: 5 | K21: 4 | L21: 4 | M21: 8 | N21: 4 | O21: 6 | P21: 7 | Q21: 7 | R21: 4 | S21: 4 | T21: 7 | U21: =IF(COUNTIF(F21:T21,"=*")>0,"-",IF(COUNTIF(F21:T21,"<4")>0,"-",(IFERROR(AVERAGE(F21:T21),"")))) -> 5.2666667
C22: Б | D22: 12 | E22: Кушмунс Максим Сергійович | F22: 9 | G22: 10 | H22: 10 | I22: 9 | J22: 9 | K22: 9 | L22: 8 | M22: 9 | N22: 8 | O22: 8 | P22: 9 | Q22: 8 | R22: 9 | S22: 10 | T22: 8 | U22: =IF(COUNTIF(F22:T22,"=*")>0,"-",IF(COUNTIF(F22:T22,"<4")>0,"-",(IFERROR(AVERAGE(F22:T22),"")))) -> 8.8666667
C23: К | D23: 13 | E23: Матура Кирило Сергійович | F23: 4 | G23: 5 | H23: 5 | I23: 4 | J23: 5 | K23: н/а | L23: 4 | M23: н/а | N23: 4 | O23: 7 | P23: 7 | Q23: 7 | R23: н/а | S23: 5 | T23: н/а | U23: =IF(COUNTIF(F23:T23,"=*")>0,"-",IF(COUNTIF(F23:T23,"<4")>0,"-",(IFERROR(AVERAGE(F23:T23),"")))) -> -
C24: Б | D24: 14 | E24: Михайлов Олег Григорійович | F24: 10 | G24: 10 | H24: 10 | I24: 11 | J24: 10 | K24: 8 | L24: 9 | M24: 10 | N24: 10 | O24: 9 | P24: 9 | Q24: 9 | R24: 8 | S24: 11 | T24: 9 | U24: =IF(COUNTIF(F24:T24,"=*")>0,"-",IF(COUNTIF(F24:T24,"<4")>0,"-",(IFERROR(AVERAGE(F24:T24),"")))) -> 9.5333333
C25: Б | D25: 15 | E25: Нагорняк Ростислав Вадимович | F25: 4 | G25: 5 | H25: 5 | I25: 4 | J25: 5 | K25: н/а | L25: 4 | M25: н/а | N25: н/а | O25: н/а | P25: 4 | Q25: 4 | R25: н/а | S25: 4 | T25: н/а | U25: =IF(COUNTIF(F25:T25,"=*")>0,"-",IF(COUNTIF(F25:T25,"<4")>0,"-",(IFERROR(AVERAGE(F25:T25),"")))) -> -
C26: Б | D26: 16 | E26: Полянський Кирило Володимирович | F26: 9 | G26: 9 | H26: 10 | I26: 9 | J26: 8 | K26: 7 | L26: 7 | M26: 8 | N26: 6 | O26: 7 | P26: 6 | Q26: 7 | R26: 8 | S26: 7 | T26: 7 | U26: =IF(COUNTIF(F26:T26,"=*")>0,"-",IF(COUNTIF(F26:T26,"<4")>0,"-",(IFERROR(AVERAGE(F26:T26),"")))) -> 7.6666667
C27: Б | D27: 17 | E27: Прутьян Кирило Сергійович | F27: 8 | G27: 7 | H27: 9 | I27: 8 | J27: 5 | K27: 4 | L27: 7 | M27: 6 | N27: 4 | O27: 6 | P27: 4 | Q27: 4 | R27: 5 | S27: 8 | T27: 5 | U27: =IF(COUNTIF(F27:T27,"=*")>0,"-",IF(COUNTIF(F27:T27,"<4")>0,"-",(IFERROR(AVERAGE(F27:T27),"")))) -> 6
C28: К | D28: 18 | E28: Савіцький Олександр Васильович | F28: 4 | G28: 5 | H28: 5 | I28: 4 | J28: 5 | K28: 4 | L28: 4 | M28: 8 | N28: 4 | O28: 7 | P28: 7 | Q28: 7 | R28: 7 | S28: 7 | T28: 7 | U28: =IF(COUNTIF(F28:T28,"=*")>0,"-",IF(COUNTIF(F28:T28,"<4")>0,"-",(IFERROR(AVERAGE(F28:T28),"")))) -> 5.6666667
C29: Б | D29: 19 | E29: Топалов Владислав Євгенович | F29: 10 | G29: 9 | H29: 9 | I29: 10 | J29: 9 | K29: 10 | L29: 10 | M29: 8 | N29: 8 | O29: 6 | P29: 10 | Q29: 9 | R29: 9 | S29: 10 | T29: 8 | U29: =IF(COUNTIF(F29:T29,"=*")>0,"-",IF(COUNTIF(F29:T29,"<4")>0,"-",(IFERROR(AVERAGE(F29:T29),"")))) -> 9
C30: Б | D30: 20 | E30: Унгурян Владислав Юрійович | F30: 10 | G30: 11 | H30: 10 | I30: 10 | J30: 9 | K30: 10 | L30: 10 | M30: 11 | N30: 10 | O30: 10 | P30: 11 | Q30: 10 | R30: 10 | S30: 10 | T30: 10 | U30: =IF(COUNTIF(F30:T30,"=*")>0,"-",IF(COUNTIF(F30:T30,"<4")>0,"-",(IFERROR(AVERAGE(F30:T30),"")))) -> 10.133333
C31: Б | D31: 21 | E31: Усанов Ілля Андрійович | F31: 8 | G31: 8 | H31: 10 | I31: 8 | J31: 9 | K31: 6 | L31: 4 | M31: 10 | N31: 6 | O31: 4 | P31: 6 | Q31: 4 | R31: 5 | S31: 10 | T31: 6 | U31: =IF(COUNTIF(F31:T31,"=*")>0,"-",IF(COUNTIF(F31:T31,"<4")>0,"-",(IFERROR(AVERAGE(F31:T31),"")))) -> 6.9333333
C32: К | D32: 22 | E32: Цитлідзе Руслан Нойович | F32: 8 | G32: 5 | H32: 5 | I32: 8 | J32: 5 | K32: 7 | L32: 4 | M32: 7 | N32: 4 | O32: 7 | P32: 7 | Q32: 7 | R32: 4 | S32: 6 | T32: 7 | U32: =IF(COUNTIF(F32:T32,"=*")>0,"-",IF(COUNTIF(F32:T32,"<4")>0,"-",(IFERROR(AVERAGE(F32:T32),"")))) -> 6.0666667
C33: Б | D33: 23 | E33: Шинкаренко Олександр Сергійович | F33: 8 | G33: 9 | H33: 8 | I33: 8 | J33: 8 | K33: 7 | L33: 7 | M33: 7 | N33: 7 | O33: 6 | P33: 8 | Q33: 7 | R33: 4 | S33: 9 | T33: 5 | U33: =IF(COUNTIF(F33:T33,"=*")>0,"-",IF(COUNTIF(F33:T33,"<4")>0,"-",(IFERROR(AVERAGE(F33:T33),"")))) -> 7.2
C34: К | D34: 24 | E34: Якубович Микола Миколайович | F34: 6 | G34: 8 | H34: 8 | I34: 7 | J34: 8 | K34: 5 | L34: 6 | M34: 7 | N34: 8 | O34: 4 | P34: 5 | Q34: 5 | R34: 4 | S34: 9 | T34: 6 | U34: =IF(COUNTIF(F34:T34,"=*")>0,"-",IF(COUNTIF(F34:T34,"<4")>0,"-",(IFERROR(AVERAGE(F34:T34),"")))) -> 6.4
C35: Б | D35: 25 | E35: Янчук Максим Дмитрович | F35: 4 | G35: 5 | H35: 5 | I35: 4 | J35: 5 | K35: н/а | L35: 4 | M35: н/а | N35: н/а | O35: н/а | P35: 4 | Q35: 4 | R35: н/а | S35: 4 | T35: н/а | U35: =IF(COUNTIF(F35:T35,"=*")>0,"-",IF(COUNTIF(F35:T35,"<4")>0,"-",(IFERROR(AVERAGE(F35:T35),"")))) -> -
E36: Середній бал успішності з дисципліни | F36: =IF(SUM(F11:F35)=0,"",SUM(F11:F35)/$D35) -> 7.48 | G36: =IF(SUM(G11:G35)=0,"",SUM(G11:G35)/$D35) -> 8 | H36: =IF(SUM(H11:H35)=0,"",SUM(H11:H35)/$D35) -> 8.04 | I36: =IF(SUM(I11:I35)=0,"",SUM(I11:I35)/$D35) -> 7.72 | J36: =IF(SUM(J11:J35)=0,"",SUM(J11:J35)/$D35) -> 7.44 | K36: =IF(SUM(K11:K35)=0,"",SUM(K11:K35)/$D35) -> 6 | L36: =IF(SUM(L11:L35)=0,"",SUM(L11:L35)/$D35) -> 6.4 | M36: =IF(SUM(M11:M35)=0,"",SUM(M11:M35)/$D35) -> 6.88 | ... T36: =IF(SUM(T11:T35)=0,"",SUM(T11:T35)/$D35) -> 5.92 | U36: =IFERROR(AVERAGE(F36:T36),"") -> 6.8826667
E37: Абсолютна успішність | F37: =IF(SUM(F11:F35)=0,"",IF(COUNTIF(F11:F35,">=4")=0,0,COUNTIF(F11:F35,">=4")/$D35*100)) -> 100 | G37: =IF(SUM(G11:G35)=0,"",IF(COUNTIF(G11:G35,">=4")=0,0,COUNTIF(G11:G35,">=4")/$D35*100)) -> 100 | H37: =IF(SUM(H11:H35)=0,"",IF(COUNTIF(H11:H35,">=4")=0,0,COUNTIF(H11:H35,">=4")/$D35*100)) -> 100 | I37: =IF(SUM(I11:I35)=0,"",IF(COUNTIF(I11:I35,">=4")=0,0,COUNTIF(I11:I35,">=4")/$D35*100)) -> 100 | J37: =IF(SUM(J11:J35)=0,"",IF(COUNTIF(J11:J35,">=4")=0,0,COUNTIF(J11:J35,">=4")/$D35*100)) -> 100 | K37: =IF(SUM(K11:K35)=0,"",IF(COUNTIF(K11:K35,">=4")=0,0,COUNTIF(K11:K35,">=4")/$D35*100)) -> 84 | L37: =IF(SUM(L11:L35)=0,"",IF(COUNTIF(L11:L35,">=4")=0,0,COUNTIF(L11:L35,">=4")/$D35*100)) -> 100 | M37: =IF(SUM(M11:M35)=0,"",IF(COUNTIF(M11:M35,">=4")=0,0,COUNTIF(M11:M35,">=4")/$D35*100)) -> 84 | ... T37: =IF(SUM(T11:T35)=0,"",IF(COUNTIF(T11:T35,">=4")=0,0,COUNTIF(T11:T35,">=4")/$D35*100)) -> 84
E38: Якісна успішність | F38: =IF(SUM(F11:F35)=0,"",IF(COUNTIF(F11:F35,">=7")=0,0,COUNTIF(F11:F35,">=7")/$D35*100)) -> 68 | G38: =IF(SUM(G11:G35)=0,"",IF(COUNTIF(G11:G35,">=7")=0,0,COUNTIF(G11:G35,">=7")/$D35*100)) -> 68 | H38: =IF(SUM(H11:H35)=0,"",IF(COUNTIF(H11:H35,">=7")=0,0,COUNTIF(H11:H35,">=7")/$D35*100)) -> 68 | I38: =IF(SUM(I11:I35)=0,"",IF(COUNTIF(I11:I35,">=7")=0,0,COUNTIF(I11:I35,">=7")/$D35*100)) -> 72 | J38: =IF(SUM(J11:J35)=0,"",IF(COUNTIF(J11:J35,">=7")=0,0,COUNTIF(J11:J35,">=7")/$D35*100)) -> 60 | K38: =IF(SUM(K11:K35)=0,"",IF(COUNTIF(K11:K35,">=7")=0,0,COUNTIF(K11:K35,">=7")/$D35*100)) -> 52 | L38: =IF(SUM(L11:L35)=0,"",IF(COUNTIF(L11:L35,">=7")=0,0,COUNTIF(L11:L35,">=7")/$D35*100)) -> 48 | M38: =IF(SUM(M11:M35)=0,"",IF(COUNTIF(M11:M35,">=7")=0,0,COUNTIF(M11:M35,">=7")/$D35*100)) -> 68 | ... T38: =IF(SUM(T11:T35)=0,"",IF(COUNTIF(T11:T35,">=7")=0,0,COUNTIF(T11:T35,">=7")/$D35*100)) -> 52
E39: Абсолютна успішність по групі | F39: =IFERROR(AVERAGE(F37:T37),"") -> 94.133333
E40: Якісна успішність по групі | F40: =IFERROR(AVERAGE(F38:T38),"") -> 59.733333
E41: Кількість бюджетників | F41: =IF(COUNTIF(C11:C35,"=Б")=0,IF(COUNTIF(C11:C35,"=К")=0,"",0),COUNTIF(C11:C35,"=Б")) -> 15
E42: Кількість контрактників | F42: =IF(COUNTIF(C11:C35,"=К")=0,IF(COUNTIF(C11:C35,"=Б")=0,"",0),COUNTIF(C11:C35,"=К")) -> 10 | H42: Класний керівник | O42: Ірина ГАЛЕНІНА
...

Sheet Рейтингова 141
C3: ВІДОКРЕМЛЕНИЙ СТРУКТУРНИЙ ПІДРОЗДІЛ «ФАХОВИЙ КОЛЕДЖ НАФТОГАЗОВИХ ТЕХНОЛОГІЙ, ІНЖЕНЕРІЇ ТА ІНФРАСТРУКТУРИ СЕРВІСУ
C4: ОДЕСЬКОГО НАЦІОНАЛЬНОГО ТЕХНОЛОГІЧНОГО УНІВЕРСИТЕТУ»
C5: РЕЙТИНГОВА ВІДОМІСТЬ
C6: Успішності студентів спеціальності 141 «Електроенергетика, електротехніка та електромеханіка»
C7: За IІ семестр 2024-2025 н.р.
C8: Група 24-4 курс І
C9: Б/К | D9: № п/п | E9: Прізвище, ім’я, по батькові | G9: Підсумкові оцінки дисциплін
F10: Астрономія Наговська Т.С. | G10: Біологія Богданенко О.В. | H10: Всесвітня історія Мельничук С.А. | I10: Географія Наговська Т.С. | J10: Зарубіжна література Сербулова Ю.А. | K10: Захист України Лазар В.І. | L10: Іноземна мова Нічик Н.О. | M10: Інформатика Бєльдюгіна С.С. | N10: Історія України Левчук Т.Г. | O10: Математика Ромчук В.В. | P10: Українська література Юрченко О.Б. | Q10: Українська мова Юрченко О.Б. | R10: Фізика Калюта Н.М. | S10: Фізична культура Галеніна І.С. | T10: Хімія Сахно Н.О. | U10: Середній бал | V10: Рейтинговий бал
C11: Б | D11: 1 | E11: Кравець Олексій Олександрович | F11: 10 | G11: 11 | H11: 11 | I11: 10 | J11: 10 | K11: 10 | L11: 11 | M11: 11 | N11: 10 | O11: 10 | P11: 11 | Q11: 10 | R11: 11 | S11: 11 | T11: 10 | U11: =IF(COUNTIF(F11:T11,"=*")>0,"-",IF(COUNTIF(F11:T11,"<4")>0,"-",(IFERROR(AVERAGE(F11:T11),"")))) -> 10.466667 | V11: =U11/12*90 -> 78.5
C12: Б | D12: 2 | E12: Артюхін Родіон Костянтинович | F12: 10 | G12: 11 | H12: 10 | I12: 11 | J12: 10 | K12: 11 | L12: 10 | M12: 10 | N12: 10 | O12: 10 | P12: 10 | Q12: 10 | R12: 10 | S12: 11 | T12: 10 | U12: =IF(COUNTIF(F12:T12,"=*")>0,"-",IF(COUNTIF(F12:T12,"<4")>0,"-",(IFERROR(AVERAGE(F12:T12),"")))) -> 10.266667 | V12: =U12/12*90 -> 77
C13: Б | D13: 3 | E13: Демінський Кирило Вячеславович | F13: 10 | G13: 11 | H13: 10 | I13: 11 | J13: 10 | K13: 11 | L13: 10 | M13: 10 | N13: 10 | O13: 10 | P13: 10 | Q13: 10 | R13: 10 | S13: 11 | T13: 10 | U13: =IF(COUNTIF(F13:T13,"=*")>0,"-",IF(COUNTIF(F13:T13,"<4")>0,"-",(IFERROR(AVERAGE(F13:T13),"")))) -> 10.266667 | V13: =U13/12*90 -> 77
C14: Б | D14: 4 | E14: Унгурян Владислав Юрійович | F14: 10 | G14: 11 | H14: 10 | I14: 10 | J14: 9 | K14: 10 | L14: 10 | M14: 11 | N14: 10 | O14: 10 | P14: 11 | Q14: 10 | R14: 10 | S14: 10 | T14: 10 | U14: =IF(COUNTIF(F14:T14,"=*")>0,"-",IF(COUNTIF(F14:T14,"<4")>0,"-",(IFERROR(AVERAGE(F14:T14),"")))) -> 10.133333 | V14: =U14/12*90 -> 76
C15: Б | D15: 5 | E15: Михайлов Олег Григорійович | F15: 10 | G15: 10 | H15: 10 | I15: 11 | J15: 10 | K15: 8 | L15: 9 | M15: 10 | N15: 10 | O15: 9 | P15: 9 | Q15: 9 | R15: 8 | S15: 11 | T15: 9 | U15: =IF(COUNTIF(F15:T15,"=*")>0,"-",IF(COUNTIF(F15:T15,"<4")>0,"-",(IFERROR(AVERAGE(F15:T15),"")))) -> 9.5333333 | V15: =U15/12*90 -> 71.5
C16: Б | D16: 6 | E16: Кихтенко Тимофій Вячеславович | F16: 10 | G16: 11 | H16: 10 | I16: 11 | J16: 10 | K16: 9 | L16: 9 | M16: 10 | N16: 7 | O16: 7 | P16: 11 | Q16: 8 | R16: 9 | S16: 10 | T16: 8 | U16: =IF(COUNTIF(F16:T16,"=*")>0,"-",IF(COUNTIF(F16:T16,"<4")>0,"-",(IFERROR(AVERAGE(F16:T16),"")))) -> 9.3333333 | V16: =U16/12*90 -> 70
C17: Б | D17: 7 | E17: Топалов Владислав Євгенович | F17: 10 | G17: 9 | H17: 9 | I17: 10 | J17: 9 | K17: 10 | L17: 10 | M17: 8 | N17: 8 | O17: 6 | P17: 10 | Q17: 9 | R17: 9 | S17: 10 | T17: 8 | U17: =IF(COUNTIF(F17:T17,"=*")>0,"-",IF(COUNTIF(F17:T17,"<4")>0,"-",(IFERROR(AVERAGE(F17:T17),"")))) -> 9 | V17: =U17/12*90 -> 67.5
C18: Б | D18: 8 | E18: Кушмунс Максим Сергійович | F18: 9 | G18: 10 | H18: 10 | I18: 9 | J18: 9 | K18: 9 | L18: 8 | M18: 9 | N18: 8 | O18: 8 | P18: 9 | Q18: 8 | R18: 9 | S18: 10 | T18: 8 | U18: =IF(COUNTIF(F18:T18,"=*")>0,"-",IF(COUNTIF(F18:T18,"<4")>0,"-",(IFERROR(AVERAGE(F18:T18),"")))) -> 8.8666667 | V18: =U18/12*90 -> 66.5
C19: Б | D19: 9 | E19: Полянський Кирило Володимирович | F19: 9 | G19: 9 | H19: 10 | I19: 9 | J19: 8 | K19: 7 | L19: 7 | M19: 8 | N19: 6 | O19: 7 | P19: 6 | Q19: 7 | R19: 8 | S19: 7 | T19: 7 | U19: =IF(COUNTIF(F19:T19,"=*")>0,"-",IF(COUNTIF(F19:T19,"<4")>0,"-",(IFERROR(AVERAGE(F19:T19),"")))) -> 7.6666667 | V19: =U19/12*90 -> 57.5
C20: Б | D20: 10 | E20: Шинкаренко Олександр Сергійович | F20: 8 | G20: 9 | H20: 8 | I20: 8 | J20: 8 | K20: 7 | L20: 7 | M20: 7 | N20: 7 | O20: 6 | P20: 8 | Q20: 7 | R20: 4 | S20: 9 | T20: 5 | U20: =IF(COUNTIF(F20:T20,"=*")>0,"-",IF(COUNTIF(F20:T20,"<4")>0,"-",(IFERROR(AVERAGE(F20:T20),"")))) -> 7.2 | V20: =U20/12*90 -> 54
C21: Б | D21: 11 | E21: Усанов Ілля Андрійович | F21: 8 | G21: 8 | H21: 10 | I21: 8 | J21: 9 | K21: 6 | L21: 4 | M21: 10 | N21: 6 | O21: 4 | P21: 6 | Q21: 4 | R21: 5 | S21: 10 | T21: 6 | U21: =IF(COUNTIF(F21:T21,"=*")>0,"-",IF(COUNTIF(F21:T21,"<4")>0,"-",(IFERROR(AVERAGE(F21:T21),"")))) -> 6.9333333 | V21: =U21/12*90 -> 52
C22: Б | D22: 12 | E22: Комарницький Олександр Вячеславович | F22: 6 | G22: 8 | H22: 9 | I22: 6 | J22: 7 | K22: 8 | L22: 7 | M22: 8 | N22: 7 | O22: 4 | P22: 4 | Q22: 4 | R22: 4 | S22: 9 | T22: 4 | U22: =IF(COUNTIF(F22:T22,"=*")>0,"-",IF(COUNTIF(F22:T22,"<4")>0,"-",(IFERROR(AVERAGE(F22:T22),"")))) -> 6.3333333 | V22: =U22/12*90 -> 47.5
C23: Б | D23: 13 | E23: Прутьян Кирило Сергійович | F23: 8 | G23: 7 | H23: 9 | I23: 8 | J23: 5 | K23: 4 | L23: 7 | M23: 6 | N23: 4 | O23: 6 | P23: 4 | Q23: 4 | R23: 5 | S23: 8 | T23: 5 | U23: =IF(COUNTIF(F23:T23,"=*")>0,"-",IF(COUNTIF(F23:T23,"<4")>0,"-",(IFERROR(AVERAGE(F23:T23),"")))) -> 6 | V23: =U23/12*90 -> 45
E24: Кількість бюджетників | F24: ='Зведена 141'!F41 -> 15
E25: Кількість контрактників | F25: ='Зведена 141'!F42 -> 10 | H25: Класний керівник | O25: Ірина ГАЛЕНІНА
E26: Кількість соціального контингенту | F26: ='Зведена 141'!F43 -> 1
E27: Вийшли на стипендію | F27: ='Зведена 141'!F44 -> 6 | H27: Завідувач відділення ПЗСО | O27: Маргарита БРІТІКОВА

Sheet Зведена 161
C3: ВІДОКРЕМЛЕНИЙ СТРУКТУРНИЙ ПІДРОЗДІЛ «ФАХОВИЙ КОЛЕДЖ НАФТОГАЗОВИХ ТЕХНОЛОГІЙ, ІНЖЕНЕРІЇ ТА ІНФРАСТРУКТУРИ СЕРВІСУ
C4: ОДЕСЬКОГО НАЦІОНАЛЬНОГО ТЕХНОЛОГІЧНОГО УНІВЕРСИТЕТУ»
C5: ЗВЕДЕНА ВІДОМІСТЬ
C6: Успішності студентів спеціальності 161 «Хімічні технології та інженерія»
C7: За IІ семестр 2024-2025 н.р.
C8: Група 24-4 курс І
C9: Б/К | D9: № п/п | E9: Прізвище, ім’я, по батькові | G9: Підсумкові оцінки дисциплін
F10: Астрономія Наговська Т.С. | G10: Біологія Богданенко О.В. | H10: Всесвітня історія Мельничук С.А. | I10: Географія Наговська Т.С. | J10: Зарубіжна література Сербулова Ю.А. | K10: Захист України Лазар В.І. | L10: Іноземна мова Нічик Н.О. | M10: Інформатика Бєльдюгіна С.С. | N10: Історія України Левчук Т.Г. | O10: Математика Ромчук В.В. | P10: Українська література Юрченко О.Б. | Q10: Українська мова Юрченко О.Б. | R10: Фізика Калюта Н.М. | S10: Фізична культура Галеніна І.С. | T10: Хімія Сахно Н.О. | U10: Середній бал
C11: Б | D11: 1 | E11: Бєляєв Іван Олександрович | F11: 9 | G11: 8 | H11: 9 | I11: 9 | J11: 9 | K11: 4 | L11: 4 | M11: 4 | N11: 5 | O11: 4 | P11: 4 | Q11: 4 | R11: 4 | S11: 5 | T11: 6 | U11: =IF(COUNTIF(F11:T11,"=*")>0,"-",IF(COUNTIF(F11:T11,"<4")>0,"-",(IFERROR(AVERAGE(F11:T11),"")))) -> 5.8666667
C12: Б | D12: 2 | E12: Бєріл Євген Сергійович | F12: 8 | G12: 9 | H12: 10 | I12: 8 | J12: 9 | K12: 4 | L12: 8 | M12: 7 | N12: 6 | O12: 6 | P12: 7 | Q12: 7 | R12: 4 | S12: 10 | T12: 5 | U12: =IF(COUNTIF(F12:T12,"=*")>0,"-",IF(COUNTIF(F12:T12,"<4")>0,"-",(IFERROR(AVERAGE(F12:T12),"")))) -> 7.2
C13: Б | D13: 3 | E13: Білецький Александр Олегович | F13: 9 | G13: 10 | H13: 9 | I13: 9 | J13: 8 | K13: н/а | L13: 9 | M13: 8 | N13: 7 | O13: 6 | P13: 7 | Q13: 5 | R13: 6 | S13: 10 | T13: 7 | U13: =IF(COUNTIF(F13:T13,"=*")>0,"-",IF(COUNTIF(F13:T13,"<4")>0,"-",(IFERROR(AVERAGE(F13:T13),"")))) -> -
C14: Б | D14: 4 | E14: Босенко Єлизавета Олексіївна | F14: 4 | G14: 4 | H14: 5 | I14: 4 | J14: 4 | K14: 4 | L14: 4 | M14: 4 | N14: 5 | O14: 4 | P14: 4 | Q14: 4 | R14: 4 | S14: 4 | T14: 4 | U14: =IF(COUNTIF(F14:T14,"=*")>0,"-",IF(COUNTIF(F14:T14,"<4")>0,"-",(IFERROR(AVERAGE(F14:T14),"")))) -> 4.1333333
C15: Б | D15: 5 | E15: Гринько Євген Ігорович | F15: 8 | G15: 7 | H15: 7 | I15: 8 | J15: 7 | K15: 4 | L15: 4 | M15: 10 | N15: 7 | O15: 7 | P15: 7 | Q15: 7 | R15: 4 | S15: 8 | T15: 7 | U15: =IF(COUNTIF(F15:T15,"=*")>0,"-",IF(COUNTIF(F15:T15,"<4")>0,"-",(IFERROR(AVERAGE(F15:T15),"")))) -> 6.8
C16: Б | D16: 6 | E16: Дурбайлов Олександр Денисович | F16: 5 | G16: 7 | H16: 7 | I16: 5 | J16: 9 | K16: н/а | L16: 4 | M16: 4 | N16: 4 | O16: 6 | P16: 4 | Q16: 4 | R16: 4 | S16: 7 | T16: 4 | U16: =IF(COUNTIF(F16:T16,"=*")>0,"-",IF(COUNTIF(F16:T16,"<4")>0,"-",(IFERROR(AVERAGE(F16:T16),"")))) -> -
C17: Б | D17: 7 | E17: Лавріненко Марко Павлович | F17: 8 | G17: 10 | H17: 5 | I17: 8 | J17: 8 | K17: 4 | L17: 4 | M17: 6 | N17: 7 | O17: 6 | P17: 6 | Q17: 8 | R17: 5 | S17: 8 | T17: 5 | U17: =IF(COUNTIF(F17:T17,"=*")>0,"-",IF(COUNTIF(F17:T17,"<4")>0,"-",(IFERROR(AVERAGE(F17:T17),"")))) -> 6.5333333
C18: Б | D18: 8 | E18: Лобода Олександр Олександрович | F18: 7 | G18: 7 | H18: 9 | I18: 8 | J18: 10 | K18: 7 | L18: 4 | M18: 7 | N18: 5 | O18: 7 | P18: 7 | Q18: 7 | R18: 4 | S18: 8 | T18: 5 | U18: =IF(COUNTIF(F18:T18,"=*")>0,"-",IF(COUNTIF(F18:T18,"<4")>0,"-",(IFERROR(AVERAGE(F18:T18),"")))) -> 6.8
C19: Б | D19: 9 | E19: Сіньковська Ганна Миколаївна | F19: 8 | G19: 6 | H19: 7 | I19: 8 | J19: 5 | K19: 4 | L19: 4 | M19: 8 | N19: 4 | O19: 7 | P19: 7 | Q19: 7 | R19: 7 | S19: 6 | T19: 7 | U19: =IF(COUNTIF(F19:T19,"=*")>0,"-",IF(COUNTIF(F19:T19,"<4")>0,"-",(IFERROR(AVERAGE(F19:T19),"")))) -> 6.3333333
C20: Б | D20: 10 | E20: Старовойтов Андрій Петрович | F20: 4 | G20: 6 | H20: 5 | I20: 4 | J20: 5 | K20: 4 | L20: 4 | M20: 8 | N20: 4 | O20: 7 | P20: 7 | Q20: 7 | R20: 7 | S20: 6 | T20: 7 | U20: =IF(COUNTIF(F20:T20,"=*")>0,"-",IF(COUNTIF(F20:T20,"<4")>0,"-",(IFERROR(AVERAGE(F20:T20),"")))) -> 5.6666667
E21: Середній бал успішності з дисципліни | F21: =IF(SUM(F11:F20)=0,"",SUM(F11:F20)/$D20) -> 7 | G21: =IF(SUM(G11:G20)=0,"",SUM(G11:G20)/$D20) -> 7.4 | H21: =IF(SUM(H11:H20)=0,"",SUM(H11:H20)/$D20) -> 7.3 | I21: =IF(SUM(I11:I20)=0,"",SUM(I11:I20)/$D20) -> 7.1 | J21: =IF(SUM(J11:J20)=0,"",SUM(J11:J20)/$D20) -> 7.4 | K21: =IF(SUM(K11:K20)=0,"",SUM(K11:K20)/$D20) -> 3.5 | L21: =IF(SUM(L11:L20)=0,"",SUM(L11:L20)/$D20) -> 4.9 | M21: =IF(SUM(M11:M20)=0,"",SUM(M11:M20)/$D20) -> 6.6 | ... T21: =IF(SUM(T11:T20)=0,"",SUM(T11:T20)/$D20) -> 5.7 | U21: =IFERROR(AVERAGE(F21:T21),"") -> 6.16
E22: Абсолютна успішність | F22: =IF(SUM(F11:F20)=0,"",IF(COUNTIF(F11:F20,">=4")=0,0,COUNTIF(F11:F20,">=4")/$D20*100)) -> 100 | G22: =IF(SUM(G11:G20)=0,"",IF(COUNTIF(G11:G20,">=4")=0,0,COUNTIF(G11:G20,">=4")/$D20*100)) -> 100 | H22: =IF(SUM(H11:H20)=0,"",IF(COUNTIF(H11:H20,">=4")=0,0,COUNTIF(H11:H20,">=4")/$D20*100)) -> 100 | I22: =IF(SUM(I11:I20)=0,"",IF(COUNTIF(I11:I20,">=4")=0,0,COUNTIF(I11:I20,">=4")/$D20*100)) -> 100 | J22: =IF(SUM(J11:J20)=0,"",IF(COUNTIF(J11:J20,">=4")=0,0,COUNTIF(J11:J20,">=4")/$D20*100)) -> 100 | K22: =IF(SUM(K11:K20)=0,"",IF(COUNTIF(K11:K20,">=4")=0,0,COUNTIF(K11:K20,">=4")/$D20*100)) -> 80 | L22: =IF(SUM(L11:L20)=0,"",IF(COUNTIF(L11:L20,">=4")=0,0,COUNTIF(L11:L20,">=4")/$D20*100)) -> 100 | M22: =IF(SUM(M11:M20)=0,"",IF(COUNTIF(M11:M20,">=4")=0,0,COUNTIF(M11:M20,">=4")/$D20*100)) -> 100 | ... T22: =IF(SUM(T11:T20)=0,"",IF(COUNTIF(T11:T20,">=4")=0,0,COUNTIF(T11:T20,">=4")/$D20*100)) -> 100
E23: Якісна успішність | F23: =IF(SUM(F11:F20)=0,"",IF(COUNTIF(F11:F20,">=7")=0,0,COUNTIF(F11:F20,">=7")/$D20*100)) -> 70 | G23: =IF(SUM(G11:G20)=0,"",IF(COUNTIF(G11:G20,">=7")=0,0,COUNTIF(G11:G20,">=7")/$D20*100)) -> 70 | H23: =IF(SUM(H11:H20)=0,"",IF(COUNTIF(H11:H20,">=7")=0,0,COUNTIF(H11:H20,">=7")/$D20*100)) -> 70 | I23: =IF(SUM(I11:I20)=0,"",IF(COUNTIF(I11:I20,">=7")=0,0,COUNTIF(I11:I20,">=7")/$D20*100)) -> 70 | J23: =IF(SUM(J11:J20)=0,"",IF(COUNTIF(J11:J20,">=7")=0,0,COUNTIF(J11:J20,">=7")/$D20*100)) -> 70 | K23: =IF(SUM(K11:K20)=0,"",IF(COUNTIF(K11:K20,">=7")=0,0,COUNTIF(K11:K20,">=7")/$D20*100)) -> 10 | L23: =IF(SUM(L11:L20)=0,"",IF(COUNTIF(L11:L20,">=7")=0,0,COUNTIF(L11:L20,">=7")/$D20*100)) -> 20 | M23: =IF(SUM(M11:M20)=0,"",IF(COUNTIF(M11:M20,">=7")=0,0,COUNTIF(M11:M20,">=7")/$D20*100)) -> 60 | ... T23: =IF(SUM(T11:T20)=0,"",IF(COUNTIF(T11:T20,">=7")=0,0,COUNTIF(T11:T20,">=7")/$D20*100)) -> 40
E24: Абсолютна успішність по групі | F24: =IFERROR(AVERAGE(F22:T22),"") -> 98.666667
E25: Якісна успішність по групі | F25: =IFERROR(AVERAGE(F23:T23),"") -> 50
E26: Кількість бюджетників | F26: =IF(COUNTIF(C11:C20,"=Б")=0,IF(COUNTIF(C11:C20,"=К")=0,"",0),COUNTIF(C11:C20,"=Б")) -> 10
E27: Кількість контрактників | F27: =IF(COUNTIF(C11:C20,"=К")=0,IF(COUNTIF(C11:C20,"=Б")=0,"",0),COUNTIF(C11:C20,"=К")) -> 0 | H27: Класний керівник | O27: Ірина ГАЛЕНІНА
E28: Кількість соціального контингенту | F28: 0
E29: Вийшли на стипендію | F29: 4 | H29: Завідувач відділення ПЗСО | O29: Маргарита БРІТІКОВА

Sheet Рейтингова 161
C3: ВІДОКРЕМЛЕНИЙ СТРУКТУРНИЙ ПІДРОЗДІЛ «ФАХОВИЙ КОЛЕДЖ НАФТОГАЗОВИХ ТЕХНОЛОГІЙ, ІНЖЕНЕРІЇ ТА ІНФРАСТРУКТУРИ СЕРВІСУ
C4: ОДЕСЬКОГО НАЦІОНАЛЬНОГО ТЕХНОЛОГІЧНОГО УНІВЕРСИТЕТУ»
C5: РЕЙТИНГОВА ВІДОМІСТЬ
C6: Успішності студентів спеціальності 161 «Хімічні технології та інженерія»
C7: За IІ семестр 2024-2025 н.р.
C8: Група 24-4 курс І
C9: Б/К | D9: № п/п | E9: Прізвище, ім’я, по батькові | G9: Підсумкові оцінки дисциплін
F10: Астрономія Наговська Т.С. | G10: Біологія Богданенко О.В. | H10: Всесвітня історія Мельничук С.А. | I10: Географія Наговська Т.С. | J10: Зарубіжна література Сербулова Ю.А. | K10: Захист України Лазар В.І. | L10: Іноземна мова Нічик Н.О. | M10: Інформатика Бєльдюгіна С.С. | N10: Історія України Левчук Т.Г. | O10: Математика Ромчук В.В. | P10: Українська література Юрченко О.Б. | Q10: Українська мова Юрченко О.Б. | R10: Фізика Калюта Н.М. | S10: Фізична культура Галеніна І.С. | T10: Хімія Сахно Н.О. | U10: Середній бал | V10: Рейтинговий бал
C11: Б | D11: 1 | E11: Бєріл Євген Сергійович | F11: 8 | G11: 9 | H11: 10 | I11: 8 | J11: 9 | K11: 4 | L11: 8 | M11: 7 | N11: 6 | O11: 6 | P11: 7 | Q11: 7 | R11: 4 | S11: 10 | T11: 5 | U11: =IF(COUNTIF(F11:T11,"=*")>0,"-",IF(COUNTIF(F11:T11,"<4")>0,"-",(IFERROR(AVERAGE(F11:T11),"")))) -> 7.2 | V11: =U11/12*90 -> 54
C12: Б | D12: 2 | E12: Гринько Євген Ігорович | F12: 8 | G12: 7 | H12: 7 | I12: 8 | J12: 7 | K12: 4 | L12: 4 | M12: 10 | N12: 7 | O12: 7 | P12: 7 | Q12: 7 | R12: 4 | S12: 8 | T12: 7 | U12: =IF(COUNTIF(F12:T12,"=*")>0,"-",IF(COUNTIF(F12:T12,"<4")>0,"-",(IFERROR(AVERAGE(F12:T12),"")))) -> 6.8 | V12: =U12/12*90 -> 51
C13: Б | D13: 3 | E13: Лобода Олександр Олександрович | F13: 7 | G13: 7 | H13: 9 | I13: 8 | J13: 10 | K13: 7 | L13: 4 | M13: 7 | N13: 5 | O13: 7 | P13: 7 | Q13: 7 | R13: 4 | S13: 8 | T13: 5 | U13: =IF(COUNTIF(F13:T13,"=*")>0,"-",IF(COUNTIF(F13:T13,"<4")>0,"-",(IFERROR(AVERAGE(F13:T13),"")))) -> 6.8 | V13: =U13/12*90 -> 51
C14: Б | D14: 4 | E14: Лавріненко Марко Павлович | F14: 8 | G14: 10 | H14: 5 | I14: 8 | J14: 8 | K14: 4 | L14: 4 | M14: 6 | N14: 7 | O14: 6 | P14: 6 | Q14: 8 | R14: 5 | S14: 8 | T14: 5 | U14: =IF(COUNTIF(F14:T14,"=*")>0,"-",IF(COUNTIF(F14:T14,"<4")>0,"-",(IFERROR(AVERAGE(F14:T14),"")))) -> 6.5333333 | V14: =U14/12*90 -> 49
C15: Б | D15: 5 | E15: Сіньковська Ганна Миколаївна | F15: 8 | G15: 6 | H15: 7 | I15: 8 | J15: 5 | K15: 4 | L15: 4 | M15: 8 | N15: 4 | O15: 7 | P15: 7 | Q15: 7 | R15: 7 | S15: 6 | T15: 7 | U15: =IF(COUNTIF(F15:T15,"=*")>0,"-",IF(COUNTIF(F15:T15,"<4")>0,"-",(IFERROR(AVERAGE(F15:T15),"")))) -> 6.3333333 | V15: =U15/12*90 -> 47.5
C16: Б | D16: 6 | E16: Бєляєв Іван Олександрович | F16: 9 | G16: 8 | H16: 9 | I16: 9 | J16: 9 | K16: 4 | L16: 4 | M16: 4 | N16: 5 | O16: 4 | P16: 4 | Q16: 4 | R16: 4 | S16: 5 | T16: 6 | U16: =IF(COUNTIF(F16:T16,"=*")>0,"-",IF(COUNTIF(F16:T16,"<4")>0,"-",(IFERROR(AVERAGE(F16:T16),"")))) -> 5.8666667 | V16: =U16/12*90 -> 44
C17: Б | D17: 7 | E17: Старовойтов Андрій Петрович | F17: 4 | G17: 6 | H17: 5 | I17: 4 | J17: 5 | K17: 4 | L17: 4 | M17: 8 | N17: 4 | O17: 7 | P17: 7 | Q17: 7 | R17: 7 | S17: 6 | T17: 7 | U17: =IF(COUNTIF(F17:T17,"=*")>0,"-",IF(COUNTIF(F17:T17,"<4")>0,"-",(IFERROR(AVERAGE(F17:T17),"")))) -> 5.6666667 | V17: =U17/12*90 -> 42.5
C18: Б | D18: 8 | E18: Босенко Єлизавета Олексіївна | F18: 4 | G18: 4 | H18: 5 | I18: 4 | J18: 4 | K18: 4 | L18: 4 | M18: 4 | N18: 5 | O18: 4 | P18: 4 | Q18: 4 | R18: 4 | S18: 4 | T18: 4 | U18: =IF(COUNTIF(F18:T18,"=*")>0,"-",IF(COUNTIF(F18:T18,"<4")>0,"-",(IFERROR(AVERAGE(F18:T18),"")))) -> 4.1333333 | V18: =U18/12*90 -> 31
E19: Кількість бюджетників | F19: ='Зведена 161'!F26 -> 10
E20: Кількість контрактників | F20: ='Зведена 161'!F27 -> 0 | H20: Класний керівник | O20: Ірина ГАЛЕНІНА
E21: Кількість соціального контингенту | F21: ='Зведена 161'!F28 -> 0
E22: Вийшли на стипендію | F22: ='Зведена 161'!F29 -> 4 | H22: Завідувач відділення ПЗСО | O22: Маргарита БРІТІКОВА

Sheet Зведена 241
C3: ВІДОКРЕМЛЕНИЙ СТРУКТУРНИЙ ПІДРОЗДІЛ «ФАХОВИЙ КОЛЕДЖ НАФТОГАЗОВИХ ТЕХНОЛОГІЙ, ІНЖЕНЕРІЇ ТА ІНФРАСТРУКТУРИ СЕРВІСУ
C4: ОДЕСЬКОГО НАЦІОНАЛЬНОГО ТЕХНОЛОГІЧНОГО УНІВЕРСИТЕТУ»
C5: ЗВЕДЕНА ВІДОМІСТЬ
C6: Успішності студентів спеціальності 241 «Готельно-ресторанна справа»
C7: За IІ семестр 2024-2025 н.р.
C8: Група 24-4 курс І
C9: Б/К | D9: № п/п | E9: Прізвище, ім’я, по батькові | G9: Підсумкові оцінки дисциплін
F10: Астрономія Наговська Т.С. | G10: Біологія Богданенко О.В. | H10: Всесвітня історія Мельничук С.А. | I10: Географія Наговська Т.С. | J10: Зарубіжна література Сербулова Ю.А. | K10: Захист України Лазар В.І. | L10: Іноземна мова Нічик Н.О. | M10: Інформатика Бєльдюгіна С.С. | N10: Історія України Левчук Т.Г. | O10: Математика Ромчук В.В. | P10: Українська література Юрченко О.Б. | Q10: Українська мова Юрченко О.Б. | R10: Фізика Калюта Н.М. | S10: Фізична культура Галеніна І.С. | T10: Хімія Сахно Н.О. | U10: Середній бал
C11: К | D11: 1 | E11: Городниченко Світлана Олександрівна | F11: 4 | G11: 6 | H11: 5 | I11: 4 | J11: 5 | K11: н/а | L11: 4 | M11: н/а | N11: н/а | O11: н/а | P11: 4 | Q11: 4 | R11: н/а | S11: 4 | T11: н/а | U11: =IF(COUNTIF(F11:T11,"=*")>0,"-",IF(COUNTIF(F11:T11,"<4")>0,"-",(IFERROR(AVERAGE(F11:T11),"")))) -> -
C12: К | D12: 2 | E12: Калін Сергій Омелянович | F12: 4 | G12: 5 | H12: 5 | I12: 4 | J12: 5 | K12: 4 | L12: 4 | M12: 7 | N12: 4 | O12: 7 | P12: 7 | Q12: 7 | R12: 4 | S12: 5 | T12: 7 | U12: =IF(COUNTIF(F12:T12,"=*")>0,"-",IF(COUNTIF(F12:T12,"<4")>0,"-",(IFERROR(AVERAGE(F12:T12),"")))) -> 5.2666667
C13: К | D13: 3 | E13: Кришмарел Сергій Андрійович | F13: 4 | G13: 6 | H13: 5 | I13: 4 | J13: 5 | K13: 4 | L13: 4 | M13: 8 | N13: 4 | O13: 7 | P13: 7 | Q13: 7 | R13: 4 | S13: 6 | T13: 7 | U13: =IF(COUNTIF(F13:T13,"=*")>0,"-",IF(COUNTIF(F13:T13,"<4")>0,"-",(IFERROR(AVERAGE(F13:T13),"")))) -> 5.4666667
C14: К | D14: 4 | E14: Сератський Максим Вікторович | F14: 4 | G14: 5 | H14: 5 | I14: 4 | J14: 4 | K14: 4 | L14: 4 | M14: 8 | N14: 4 | O14: 7 | P14: 7 | Q14: 7 | R14: 7 | S14: 5 | T14: 7 | U14: =IF(COUNTIF(F14:T14,"=*")>0,"-",IF(COUNTIF(F14:T14,"<4")>0,"-",(IFERROR(AVERAGE(F14:T14),"")))) -> 5.4666667
C15: К | D15: 5 | E15: Сорохан Поліна Андріївна | F15: 7 | G15: 6 | H15: 8 | I15: 6 | J15: 9 | K15: н/а | L15: 4 | M15: н/а | N15: 5 | O15: 4 | P15: 4 | Q15: 4 | R15: н/а | S15: 4 | T15: 2 | U15: =IF(COUNTIF(F15:T15,"=*")>0,"-",IF(COUNTIF(F15:T15,"<4")>0,"-",(IFERROR(AVERAGE(F15:T15),"")))) -> -
E16: Середній бал успішності з дисципліни | F16: =IF(SUM(F11:F15)=0,"",SUM(F11:F15)/$D15) -> 4.6 | G16: =IF(SUM(G11:G15)=0,"",SUM(G11:G15)/$D15) -> 5.6 | H16: =IF(SUM(H11:H15)=0,"",SUM(H11:H15)/$D15) -> 5.6 | I16: =IF(SUM(I11:I15)=0,"",SUM(I11:I15)/$D15) -> 4.4 | J16: =IF(SUM(J11:J15)=0,"",SUM(J11:J15)/$D15) -> 5.6 | K16: =IF(SUM(K11:K15)=0,"",SUM(K11:K15)/$D15) -> 2.4 | L16: =IF(SUM(L11:L15)=0,"",SUM(L11:L15)/$D15) -> 4 | M16: =IF(SUM(M11:M15)=0,"",SUM(M11:M15)/$D15) -> 4.6 | ... T16: =IF(SUM(T11:T15)=0,"",SUM(T11:T15)/$D15) -> 4.6 | U16: =IFERROR(AVERAGE(F16:T16),"") -> 4.6133333
E17: Абсолютна успішність | F17: =IF(SUM(F11:F15)=0,"",IF(COUNTIF(F11:F15,">=4")=0,0,COUNTIF(F11:F15,">=4")/$D15*100)) -> 100 | G17: =IF(SUM(G11:G15)=0,"",IF(COUNTIF(G11:G15,">=4")=0,0,COUNTIF(G11:G15,">=4")/$D15*100)) -> 100 | H17: =IF(SUM(H11:H15)=0,"",IF(COUNTIF(H11:H15,">=4")=0,0,COUNTIF(H11:H15,">=4")/$D15*100)) -> 100 | I17: =IF(SUM(I11:I15)=0,"",IF(COUNTIF(I11:I15,">=4")=0,0,COUNTIF(I11:I15,">=4")/$D15*100)) -> 100 | J17: =IF(SUM(J11:J15)=0,"",IF(COUNTIF(J11:J15,">=4")=0,0,COUNTIF(J11:J15,">=4")/$D15*100)) -> 100 | K17: =IF(SUM(K11:K15)=0,"",IF(COUNTIF(K11:K15,">=4")=0,0,COUNTIF(K11:K15,">=4")/$D15*100)) -> 60 | L17: =IF(SUM(L11:L15)=0,"",IF(COUNTIF(L11:L15,">=4")=0,0,COUNTIF(L11:L15,">=4")/$D15*100)) -> 100 | M17: =IF(SUM(M11:M15)=0,"",IF(COUNTIF(M11:M15,">=4")=0,0,COUNTIF(M11:M15,">=4")/$D15*100)) -> 60 | ... T17: =IF(SUM(T11:T15)=0,"",IF(COUNTIF(T11:T15,">=4")=0,0,COUNTIF(T11:T15,">=4")/$D15*100)) -> 60
E18: Якісна успішність | F18: =IF(SUM(F11:F15)=0,"",IF(COUNTIF(F11:F15,">=7")=0,0,COUNTIF(F11:F15,">=7")/$D15*100)) -> 20 | G18: =IF(SUM(G11:G15)=0,"",IF(COUNTIF(G11:G15,">=7")=0,0,COUNTIF(G11:G15,">=7")/$D15*100)) -> 0 | H18: =IF(SUM(H11:H15)=0,"",IF(COUNTIF(H11:H15,">=7")=0,0,COUNTIF(H11:H15,">=7")/$D15*100)) -> 20 | I18: =IF(SUM(I11:I15)=0,"",IF(COUNTIF(I11:I15,">=7")=0,0,COUNTIF(I11:I15,">=7")/$D15*100)) -> 0 | J18: =IF(SUM(J11:J15)=0,"",IF(COUNTIF(J11:J15,">=7")=0,0,COUNTIF(J11:J15,">=7")/$D15*100)) -> 20 | K18: =IF(SUM(K11:K15)=0,"",IF(COUNTIF(K11:K15,">=7")=0,0,COUNTIF(K11:K15,">=7")/$D15*100)) -> 0 | L18: =IF(SUM(L11:L15)=0,"",IF(COUNTIF(L11:L15,">=7")=0,0,COUNTIF(L11:L15,">=7")/$D15*100)) -> 0 | M18: =IF(SUM(M11:M15)=0,"",IF(COUNTIF(M11:M15,">=7")=0,0,COUNTIF(M11:M15,">=7")/$D15*100)) -> 60 | ... T18: =IF(SUM(T11:T15)=0,"",IF(COUNTIF(T11:T15,">=7")=0,0,COUNTIF(T11:T15,">=7")/$D15*100)) -> 60
E19: Абсолютна успішність по групі | F19: =IFERROR(AVERAGE(F17:T17),"") -> 86.666667
E20: Якісна успішність по групі | F20: =IFERROR(AVERAGE(F18:T18),"") -> 25.333333
E21: Кількість бюджетників | F21: =IF(COUNTIF(C11:C15,"=Б")=0,IF(COUNTIF(C11:C15,"=К")=0,"",0),COUNTIF(C11:C15,"=Б")) -> 0
E22: Кількість контрактників | F22: =IF(COUNTIF(C11:C15,"=К")=0,IF(COUNTIF(C11:C15,"=Б")=0,"",0),COUNTIF(C11:C15,"=К")) -> 5 | H22: Класний керівник | O22: Ірина ГАЛЕНІНА
E23: Кількість соціального контингенту | F23: 0
E24: Вийшли на стипендію | H24: Завідувач відділення ПЗСО | O24: Маргарита БРІТІКОВА
