Workbook
Name A1048577: #REF!
Name A1048577: #REF!
Name A1048577: #REF!
Name A1048577: #REF!
Name A1048577: #REF!
Name A1048577: #REF!
Name Ф80: #REF!
Name Ф80: #REF!
Name Ф80: #REF!
Name Ф80: #REF!
Name Ф80: #REF!
Name Ф80: #REF!

Sheet Зведена 076
C3: ВІДОКРЕМЛЕНИЙ СТРУКТУРНИЙ ПІДРОЗДІЛ «ФАХОВИЙ КОЛЕДЖ НАФТОГАЗОВИХ ТЕХНОЛОГІЙ, ІНЖЕНЕРІЇ ТА ІНФРАСТРУКТУРИ СЕРВІСУ
C4: ОДЕСЬКОГО НАЦІОНАЛЬНОГО ТЕХНОЛОГІЧНОГО УНІВЕРСИТЕТУ»
C5: ЗВЕДЕНА ВІДОМІСТЬ
C6: Успішності студентів спеціальності 076 «Підприємництво та торгівля»
C7: За IІ семестр 2024-2025 н.р.
C8: Група 24-2 курс І
C9: Б/К | D9: № п/п | E9: Прізвище, ім’я, по батькові | G9: Підсумкові оцінки дисциплін
F10: Астрономія Наговська Т.С. | G10: Біологія Богданенко О.В. | H10: Всесвітня історія Мельничук С.А. | I10: Географія Наговська Т.С. | J10: Зарубіжна література Сербулова Ю.А. | K10: Захист України Лазар В.І. | L10: Іноземна мова Сербулова Ю.А. | M10: Інформатика Бєльдюгіна С.С. | N10: Історія України Левчук Т.Г. | O10: Математика Земляна Т.М. | P10: Українська література Юрченко О.Б. | Q10: Українська мова Юрченко О.Б. | R10: Фізика Калюта Н.М. | S10: Фізична культура Возіян О.Г. | T10: Хімія Сахно Н.О. | U10: Середній бал
C11: Б | D11: 1 | E11: Адаменко Юлія Русланівна | F11: 4 | G11: 5 | H11: 5 | I11: 4 | J11: 4 | K11: 4 | L11: 4 | M11: 4 | N11: 4 | O11: 4 | P11: 4 | Q11: 4 | R11: 4 | S11: 4 | T11: 5 | U11: =IF(COUNTIF(F11:T11,"=*")>0,"-",IF(COUNTIF(F11:T11,"<4")>0,"-",(IFERROR(AVERAGE(F11:T11),"")))) -> 4.2
C12: Б | D12: 2 | E12: Гратій Олена Дмитрівна | F12: 11 | G12: 10 | H12: 11 | I12: 11 | J12: 10 | K12: 10 | L12: 10 | M12: 10 | N12: 10 | O12: 9 | P12: 10 | Q12: 10 | R12: 10 | S12: 11 | T12: 10 | U12: =IF(COUNTIF(F12:T12,"=*")>0,"-",IF(COUNTIF(F12:T12,"<4")>0,"-",(IFERROR(AVERAGE(F12:T12),"")))) -> 10.2
C13: Б | D13: 3 | E13: Давиденко Андрій Ілліч | F13: 4 | G13: 5 | H13: 4 | I13: 4 | J13: 5 | K13: н/а | L13: 5 | M13: 4 | N13: н/а | O13: н/а | P13: 4 | Q13: 4 | R13: н/а | S13: н/а | T13: 4 | U13: =IF(COUNTIF(F13:T13,"=*")>0,"-",IF(COUNTIF(F13:T13,"<4")>0,"-",(IFERROR(AVERAGE(F13:T13),"")))) -> -
C14: Б | D14: 4 | E14: Друмова Діана Олегівна | F14: 9 | G14: 10 | H14: 10 | I14: 9 | J14: 10 | K14: 4 | L14: 11 | M14: 8 | N14: 7 | O14: 6 | P14: 4 | Q14: 4 | R14: 7 | S14: 7 | T14: 7 | U14: =IF(COUNTIF(F14:T14,"=*")>0,"-",IF(COUNTIF(F14:T14,"<4")>0,"-",(IFERROR(AVERAGE(F14:T14),"")))) -> 7.5333333
C15: Б | D15: 5 | E15: Ізраєвський Артем Сергійович | F15: 9 | G15: 10 | H15: 10 | I15: 9 | J15: 9 | K15: 8 | L15: 9 | M15: 7 | N15: 9 | O15: 6 | P15: 7 | Q15: 7 | R15: 7 | S15: 10 | T15: 6 | U15: =IF(COUNTIF(F15:T15,"=*")>0,"-",IF(COUNTIF(F15:T15,"<4")>0,"-",(IFERROR(AVERAGE(F15:T15),"")))) -> 8.2
C16: Б | D16: 6 | E16: Кас`ян Андрій Андрійович | F16: 10 | G16: 9 | H16: 10 | I16: 10 | J16: 8 | K16: 8 | L16: 9 | M16: 6 | N16: 6 | O16: 6 | P16: 5 | Q16: 5 | R16: 7 | S16: 10 | T16: 8 | U16: =IF(COUNTIF(F16:T16,"=*")>0,"-",IF(COUNTIF(F16:T16,"<4")>0,"-",(IFERROR(AVERAGE(F16:T16),"")))) -> 7.8
C17: Б | D17: 7 | E17: Кіор Микола Миколайович | F17: 9 | G17: 9 | H17: 9 | I17: 9 | J17: 9 | K17: 7 | L17: 9 | M17: 5 | N17: 7 | O17: 7 | P17: 4 | Q17: 4 | R17: 8 | S17: 10 | T17: 8 | U17: =IF(COUNTIF(F17:T17,"=*")>0,"-",IF(COUNTIF(F17:T17,"<4")>0,"-",(IFERROR(AVERAGE(F17:T17),"")))) -> 7.6
C18: Б | D18: 8 | E18: Кіцул Гліб Олександрович | F18: 9 | G18: 8 | H18: 9 | I18: 9 | J18: 8 | K18: н/а | L18: 9 | M18: н/а | N18: 5 | O18: 4 | P18: 4 | Q18: 4 | R18: 2 | S18: 5 | T18: 5 | U18: =IF(COUNTIF(F18:T18,"=*")>0,"-",IF(COUNTIF(F18:T18,"<4")>0,"-",(IFERROR(AVERAGE(F18:T18),"")))) -> -
C19: Б | D19: 9 | E19: Кононенко Максим Костянтинович | F19: 8 | G19: 8 | H19: 8 | I19: 8 | J19: 10 | K19: 4 | L19: 10 | M19: 4 | N19: 6 | O19: 4 | P19: 4 | Q19: 4 | R19: 4 | S19: 4 | T19: 5 | U19: =IF(COUNTIF(F19:T19,"=*")>0,"-",IF(COUNTIF(F19:T19,"<4")>0,"-",(IFERROR(AVERAGE(F19:T19),"")))) -> 6.0666667
C20: Б | D20: 10 | E20: Кравцова Дар`я Сергіївна | F20: 10 | G20: 9 | H20: 10 | I20: 10 | J20: 9 | K20: 4 | L20: 9 | M20: 8 | N20: 6 | O20: 4 | P20: 4 | Q20: 4 | R20: 7 | S20: 7 | T20: 6 | U20: =IF(COUNTIF(F20:T20,"=*")>0,"-",IF(COUNTIF(F20:T20,"<4")>0,"-",(IFERROR(AVERAGE(F20:T20),"")))) -> 7.1333333
C21: К | D21: 11 | E21: Крепких Ольга Владиславівна | F21: 8 | G21: 8 | H21: 8 | I21: 8 | J21: 9 | K21: н/а | L21: 9 | M21: 4 | N21: 8 | O21: 4 | P21: 4 | Q21: 4 | R21: 4 | S21: 4 | T21: 5 | U21: =IF(COUNTIF(F21:T21,"=*")>0,"-",IF(COUNTIF(F21:T21,"<4")>0,"-",(IFERROR(AVERAGE(F21:T21),"")))) -> -
C22: Б | D22: 12 | E22: Кузьміна Дар`я Орестівна | F22: 10 | G22: 10 | H22: 11 | I22: 10 | J22: 10 | K22: 11 | L22: 9 | M22: 11 | N22: 9 | O22: 9 | P22: 9 | Q22: 9 | R22: 8 | S22: 9 | T22: 9 | U22: =IF(COUNTIF(F22:T22,"=*")>0,"-",IF(COUNTIF(F22:T22,"<4")>0,"-",(IFERROR(AVERAGE(F22:T22),"")))) -> 9.6
C23: Б | D23: 13 | E23: Кузьміна Марія Орестівна | F23: 10 | G23: 10 | H23: 11 | I23: 10 | J23: 10 | K23: 11 | L23: 9 | M23: 11 | N23: 9 | O23: 9 | P23: 9 | Q23: 9 | R23: 8 | S23: 9 | T23: 9 | U23: =IF(COUNTIF(F23:T23,"=*")>0,"-",IF(COUNTIF(F23:T23,"<4")>0,"-",(IFERROR(AVERAGE(F23:T23),"")))) -> 9.6
C24: Б | D24: 14 | E24: Кульчицька Марія Сергіївна | F24: 9 | G24: 9 | H24: 9 | I24: 9 | J24: 9 | K24: н/а | L24: 7 | M24: 8 | N24: 7 | O24: 4 | P24: 4 | Q24: 4 | R24: 5 | S24: 5 | T24: 8 | U24: =IF(COUNTIF(F24:T24,"=*")>0,"-",IF(COUNTIF(F24:T24,"<4")>0,"-",(IFERROR(AVERAGE(F24:T24),"")))) -> -
C25: Б | D25: 15 | E25: Лунгул Олексій Валерійович | F25: 8 | G25: 6 | H25: 5 | I25: 8 | J25: 5 | K25: 4 | L25: 6 | M25: 8 | N25: 4 | O25: 7 | P25: 7 | Q25: 7 | R25: 7 | S25: 5 | T25: 7 | U25: =IF(COUNTIF(F25:T25,"=*")>0,"-",IF(COUNTIF(F25:T25,"<4")>0,"-",(IFERROR(AVERAGE(F25:T25),"")))) -> 6.2666667
C26: Б | D26: 16 | E26: Мазур Ельвіра Владиславівна | F26: 11 | G26: 11 | H26: 11 | I26: 11 | J26: 10 | K26: 12 | L26: 11 | M26: 12 | N26: 11 | O26: 10 | P26: 11 | Q26: 11 | R26: 10 | S26: 11 | T26: 10 | U26: =IF(COUNTIF(F26:T26,"=*")>0,"-",IF(COUNTIF(F26:T26,"<4")>0,"-",(IFERROR(AVERAGE(F26:T26),"")))) -> 10.866667
C27: Б | D27: 17 | E27: Михайліченко Мілєна Ігорівна | F27: 11 | G27: 8 | H27: 10 | I27: 11 | J27: 10 | K27: 9 | L27: 9 | M27: 8 | N27: 7 | O27: 4 | P27: 9 | Q27: 9 | R27: 7 | S27: 10 | T27: 8 | U27: =IF(COUNTIF(F27:T27,"=*")>0,"-",IF(COUNTIF(F27:T27,"<4")>0,"-",(IFERROR(AVERAGE(F27:T27),"")))) -> 8.6666667
C28: Б | D28: 18 | E28: Моісєєва Діана Олександрівна | F28: 8 | G28: 7 | H28: 7 | I28: 8 | J28: 8 | K28: 4 | L28: 9 | M28: 4 | N28: 8 | O28: 4 | P28: 4 | Q28: 4 | R28: 4 | S28: 4 | T28: 4 | U28: =IF(COUNTIF(F28:T28,"=*")>0,"-",IF(COUNTIF(F28:T28,"<4")>0,"-",(IFERROR(AVERAGE(F28:T28),"")))) -> 5.8
C29: К | D29: 19 | E29: Пасхал Верджинія Ігорівна | F29: 8 | G29: 8 | H29: 7 | I29: 8 | J29: 6 | K29: 5 | L29: 8 | M29: 8 | N29: 5 | O29: 4 | P29: 4 | Q29: 4 | R29: 5 | S29: 5 | T29: 7 | U29: =IF(COUNTIF(F29:T29,"=*")>0,"-",IF(COUNTIF(F29:T29,"<4")>0,"-",(IFERROR(AVERAGE(F29:T29),"")))) -> 6.1333333
C30: К | D30: 20 | E30: Пінчуков Сергій Олексійович | F30: 4 | G30: 6 | H30: 7 | I30: 4 | J30: 4 | K30: 4 | L30: 7 | M30: 5 | N30: 6 | O30: 4 | P30: 4 | Q30: 4 | R30: 4 | S30: 8 | T30: 4 | U30: =IF(COUNTIF(F30:T30,"=*")>0,"-",IF(COUNTIF(F30:T30,"<4")>0,"-",(IFERROR(AVERAGE(F30:T30),"")))) -> 5
C31: Б | D31: 21 | E31: Попович Олексій Антонович | F31: 10 | G31: 10 | H31: 10 | I31: 10 | J31: 10 | K31: 10 | L31: 10 | M31: 10 | N31: 9 | O31: 6 | P31: 11 | Q31: 11 | R31: 10 | S31: 11 | T31: 9 | U31: =IF(COUNTIF(F31:T31,"=*")>0,"-",IF(COUNTIF(F31:T31,"<4")>0,"-",(IFERROR(AVERAGE(F31:T31),"")))) -> 9.8
C32: Б | D32: 22 | E32: Савченко Стефанія Андріївна | F32: 8 | G32: 6 | H32: 7 | I32: 8 | J32: 8 | K32: н/а | L32: 6 | M32: 4 | N32: 8 | O32: 4 | P32: 4 | Q32: 4 | R32: 4 | S32: 4 | T32: 6 | U32: =IF(COUNTIF(F32:T32,"=*")>0,"-",IF(COUNTIF(F32:T32,"<4")>0,"-",(IFERROR(AVERAGE(F32:T32),"")))) -> -
C33: Б | D33: 23 | E33: Фучеджи Андрій Вадимович | F33: 10 | G33: 8 | H33: 9 | I33: 10 | J33: 6 | K33: 5 | L33: 7 | M33: 10 | N33: 6 | O33: 4 | P33: 4 | Q33: 4 | R33: 5 | S33: 5 | T33: 8 | U33: =IF(COUNTIF(F33:T33,"=*")>0,"-",IF(COUNTIF(F33:T33,"<4")>0,"-",(IFERROR(AVERAGE(F33:T33),"")))) -> 6.7333333
C34: Б | D34: 24 | E34: Чувпило Владислав Олександрович | F34: 6 | G34: 5 | H34: 7 | I34: 6 | J34: 5 | K34: н/а | L34: 7 | M34: 4 | N34: 7 | O34: 4 | P34: 4 | Q34: 4 | R34: 4 | S34: 6 | T34: 6 | U34: =IF(COUNTIF(F34:T34,"=*")>0,"-",IF(COUNTIF(F34:T34,"<4")>0,"-",(IFERROR(AVERAGE(F34:T34),"")))) -> -
C35: К | D35: 25 | E35: Штанько Юрій Миколайович | F35: 4 | G35: 5 | H35: 5 | I35: 4 | J35: 4 | K35: 4 | L35: 5 | M35: 8 | N35: 4 | O35: 7 | P35: 7 | Q35: 7 | R35: 7 | S35: 4 | T35: 7 | U35: =IF(COUNTIF(F35:T35,"=*")>0,"-",IF(COUNTIF(F35:T35,"<4")>0,"-",(IFERROR(AVERAGE(F35:T35),"")))) -> 5.4666667
E36: Середній бал успішності з дисципліни | F36: =IF(SUM(F11:F35)=0,"",SUM(F11:F35)/$D35) -> 8.32 | G36: =IF(SUM(G11:G35)=0,"",SUM(G11:G35)/$D35) -> 8 | H36: =IF(SUM(H11:H35)=0,"",SUM(H11:H35)/$D35) -> 8.4 | I36: =IF(SUM(I11:I35)=0,"",SUM(I11:I35)/$D35) -> 8.32 | J36: =IF(SUM(J11:J35)=0,"",SUM(J11:J35)/$D35) -> 7.84 | K36: =IF(SUM(K11:K35)=0,"",SUM(K11:K35)/$D35) -> 5.12 | L36: =IF(SUM(L11:L35)=0,"",SUM(L11:L35)/$D35) -> 8.16 | M36: =IF(SUM(M11:M35)=0,"",SUM(M11:M35)/$D35) -> 6.84 | ... T36: =IF(SUM(T11:T35)=0,"",SUM(T11:T35)/$D35) -> 6.84 | U36: =IFERROR(AVERAGE(F36:T36),"") -> 6.944
E37: Абсолютна успішність | F37: =IF(SUM(F11:F35)=0,"",IF(COUNTIF(F11:F35,">=4")=0,0,COUNTIF(F11:F35,">=4")/$D35*100)) -> 100 | G37: =IF(SUM(G11:G35)=0,"",IF(COUNTIF(G11:G35,">=4")=0,0,COUNTIF(G11:G35,">=4")/$D35*100)) -> 100 | H37: =IF(SUM(H11:H35)=0,"",IF(COUNTIF(H11:H35,">=4")=0,0,COUNTIF(H11:H35,">=4")/$D35*100)) -> 100 | I37: =IF(SUM(I11:I35)=0,"",IF(COUNTIF(I11:I35,">=4")=0,0,COUNTIF(I11:I35,">=4")/$D35*100)) -> 100 | J37: =IF(SUM(J11:J35)=0,"",IF(COUNTIF(J11:J35,">=4")=0,0,COUNTIF(J11:J35,">=4")/$D35*100)) -> 100 | K37: =IF(SUM(K11:K35)=0,"",IF(COUNTIF(K11:K35,">=4")=0,0,COUNTIF(K11:K35,">=4")/$D35*100)) -> 76 | L37: =IF(SUM(L11:L35)=0,"",IF(COUNTIF(L11:L35,">=4")=0,0,COUNTIF(L11:L35,">=4")/$D35*100)) -> 100 | M37: =IF(SUM(M11:M35)=0,"",IF(COUNTIF(M11:M35,">=4")=0,0,COUNTIF(M11:M35,">=4")/$D35*100)) -> 96 | ... T37: =IF(SUM(T11:T35)=0,"",IF(COUNTIF(T11:T35,">=4")=0,0,COUNTIF(T11:T35,">=4")/$D35*100)) -> 100
E38: Якісна успішність | F38: =IF(SUM(F11:F35)=0,"",IF(COUNTIF(F11:F35,">=7")=0,0,COUNTIF(F11:F35,">=7")/$D35*100)) -> 80 | G38: =IF(SUM(G11:G35)=0,"",IF(COUNTIF(G11:G35,">=7")=0,0,COUNTIF(G11:G35,">=7")/$D35*100)) -> 72 | H38: =IF(SUM(H11:H35)=0,"",IF(COUNTIF(H11:H35,">=7")=0,0,COUNTIF(H11:H35,">=7")/$D35*100)) -> 84 | I38: =IF(SUM(I11:I35)=0,"",IF(COUNTIF(I11:I35,">=7")=0,0,COUNTIF(I11:I35,">=7")/$D35*100)) -> 80 | J38: =IF(SUM(J11:J35)=0,"",IF(COUNTIF(J11:J35,">=7")=0,0,COUNTIF(J11:J35,">=7")/$D35*100)) -> 68 | K38: =IF(SUM(K11:K35)=0,"",IF(COUNTIF(K11:K35,">=7")=0,0,COUNTIF(K11:K35,">=7")/$D35*100)) -> 36 | L38: =IF(SUM(L11:L35)=0,"",IF(COUNTIF(L11:L35,">=7")=0,0,COUNTIF(L11:L35,">=7")/$D35*100)) -> 80 | M38: =IF(SUM(M11:M35)=0,"",IF(COUNTIF(M11:M35,">=7")=0,0,COUNTIF(M11:M35,">=7")/$D35*100)) -> 56 | ... T38: =IF(SUM(T11:T35)=0,"",IF(COUNTIF(T11:T35,">=7")=0,0,COUNTIF(T11:T35,">=7")/$D35*100)) -> 56
E39: Абсолютна успішність по групі | F39: =IFERROR(AVERAGE(F37:T37),"") -> 96.8
E40: Якісна успішність по групі | F40: =IFERROR(AVERAGE(F38:T38),"") -> 57.866667
E41: Кількість бюджетників | F41: =IF(COUNTIF(C11:C35,"=Б")=0,IF(COUNTIF(C11:C35,"=К")=0,"",0),COUNTIF(C11:C35,"=Б")) -> 21
E42: Кількість контрактників | F42: =IF(COUNTIF(C11:C35,"=К")=0,IF(COUNTIF(C11:C35,"=Б")=0,"",0),COUNTIF(C11:C35,"=К")) -> 4 | H42: Класний керівник | O42: Тетяна НАГОВСЬКА
...

Sheet Рейтингова 076
C3: ВІДОКРЕМЛЕНИЙ СТРУКТУРНИЙ ПІДРОЗДІЛ «ФАХОВИЙ КОЛЕДЖ НАФТОГАЗОВИХ ТЕХНОЛОГІЙ, ІНЖЕНЕРІЇ ТА ІНФРАСТРУКТУРИ СЕРВІСУ
C4: ОДЕСЬКОГО НАЦІОНАЛЬНОГО ТЕХНОЛОГІЧНОГО УНІВЕРСИТЕТУ»
C5: РЕЙТИНГОВА ВІДОМІСТЬ
C6: Успішності студентів спеціальності 076 «Підприємництво та торгівля»
C7: За IІ семестр 2024-2025 н.р.
C8: Група 24-2 курс І
C9: Б/К | D9: № п/п | E9: Прізвище, ім’я, по батькові | G9: Підсумкові оцінки дисциплін
F10: Астрономія Наговська Т.С. | G10: Біологія Богданенко О.В. | H10: Всесвітня історія Мельничук С.А. | I10: Географія Наговська Т.С. | J10: Зарубіжна література Сербулова Ю.А. | K10: Захист України Лазар В.І. | L10: Іноземна мова Сербулова Ю.А. | M10: Інформатика Бєльдюгіна С.С. | N10: Історія України Левчук Т.Г. | O10: Математика Земляна Т.М. | P10: Українська література Юрченко О.Б. | Q10: Українська мова Юрченко О.Б. | R10: Фізика Калюта Н.М. | S10: Фізична культура Возіян О.Г. | T10: Хімія Сахно Н.О. | U10: Середній бал | V10: Рейтинговий бал
C11: Б | D11: 1 | E11: Мазур Ельвіра Владиславівна | F11: 11 | G11: 11 | H11: 11 | I11: 11 | J11: 10 | K11: 12 | L11: 11 | M11: 12 | N11: 11 | O11: 10 | P11: 11 | Q11: 11 | R11: 10 | S11: 11 | T11: 10 | U11: =IF(COUNTIF(F11:T11,"=*")>0,"-",IF(COUNTIF(F11:T11,"<4")>0,"-",(IFERROR(AVERAGE(F11:T11),"")))) -> 10.866667 | V11: =U11/12*90 -> 81.5
C12: Б | D12: 2 | E12: Гратій Олена Дмитрівна | F12: 11 | G12: 10 | H12: 11 | I12: 11 | J12: 10 | K12: 10 | L12: 10 | M12: 10 | N12: 10 | O12: 9 | P12: 10 | Q12: 10 | R12: 10 | S12: 11 | T12: 10 | U12: =IF(COUNTIF(F12:T12,"=*")>0,"-",IF(COUNTIF(F12:T12,"<4")>0,"-",(IFERROR(AVERAGE(F12:T12),"")))) -> 10.2 | V12: =U12/12*90 -> 76.5
C13: Б | D13: 3 | E13: Попович Олексій Антонович | F13: 10 | G13: 10 | H13: 10 | I13: 10 | J13: 10 | K13: 10 | L13: 10 | M13: 10 | N13: 9 | O13: 6 | P13: 11 | Q13: 11 | R13: 10 | S13: 11 | T13: 9 | U13: =IF(COUNTIF(F13:T13,"=*")>0,"-",IF(COUNTIF(F13:T13,"<4")>0,"-",(IFERROR(AVERAGE(F13:T13),"")))) -> 9.8 | V13: =U13/12*90 -> 73.5
C14: Б | D14: 4 | E14: Кузьміна Дар`я Орестівна | F14: 10 | G14: 10 | H14: 11 | I14: 10 | J14: 10 | K14: 11 | L14: 9 | M14: 11 | N14: 9 | O14: 9 | P14: 9 | Q14: 9 | R14: 8 | S14: 9 | T14: 9 | U14: =IF(COUNTIF(F14:T14,"=*")>0,"-",IF(COUNTIF(F14:T14,"<4")>0,"-",(IFERROR(AVERAGE(F14:T14),"")))) -> 9.6 | V14: =U14/12*90 -> 72
C15: Б | D15: 5 | E15: Кузьміна Марія Орестівна | F15: 10 | G15: 10 | H15: 11 | I15: 10 | J15: 10 | K15: 11 | L15: 9 | M15: 11 | N15: 9 | O15: 9 | P15: 9 | Q15: 9 | R15: 8 | S15: 9 | T15: 9 | U15: =IF(COUNTIF(F15:T15,"=*")>0,"-",IF(COUNTIF(F15:T15,"<4")>0,"-",(IFERROR(AVERAGE(F15:T15),"")))) -> 9.6 | V15: =U15/12*90 -> 72
C16: Б | D16: 6 | E16: Михайліченко Мілєна Ігорівна | F16: 11 | G16: 8 | H16: 10 | I16: 11 | J16: 10 | K16: 9 | L16: 9 | M16: 8 | N16: 7 | O16: 4 | P16: 9 | Q16: 9 | R16: 7 | S16: 10 | T16: 8 | U16: =IF(COUNTIF(F16:T16,"=*")>0,"-",IF(COUNTIF(F16:T16,"<4")>0,"-",(IFERROR(AVERAGE(F16:T16),"")))) -> 8.6666667 | V16: =U16/12*90 -> 65
C17: Б | D17: 7 | E17: Ізраєвський Артем Сергійович | F17: 9 | G17: 10 | H17: 10 | I17: 9 | J17: 9 | K17: 8 | L17: 9 | M17: 7 | N17: 9 | O17: 6 | P17: 7 | Q17: 7 | R17: 7 | S17: 10 | T17: 6 | U17: =IF(COUNTIF(F17:T17,"=*")>0,"-",IF(COUNTIF(F17:T17,"<4")>0,"-",(IFERROR(AVERAGE(F17:T17),"")))) -> 8.2 | V17: =U17/12*90 -> 61.5
C18: Б | D18: 8 | E18: Кас`ян Андрій Андрійович | F18: 10 | G18: 9 | H18: 10 | I18: 10 | J18: 8 | K18: 8 | L18: 9 | M18: 6 | N18: 6 | O18: 6 | P18: 5 | Q18: 5 | R18: 7 | S18: 10 | T18: 8 | U18: =IF(COUNTIF(F18:T18,"=*")>0,"-",IF(COUNTIF(F18:T18,"<4")>0,"-",(IFERROR(AVERAGE(F18:T18),"")))) -> 7.8 | V18: =U18/12*90 -> 58.5
C19: Б | D19: 9 | E19: Кіор Микола Миколайович | F19: 9 | G19: 9 | H19: 9 | I19: 9 | J19: 9 | K19: 7 | L19: 9 | M19: 5 | N19: 7 | O19: 7 | P19: 4 | Q19: 4 | R19: 8 | S19: 10 | T19: 8 | U19: =IF(COUNTIF(F19:T19,"=*")>0,"-",IF(COUNTIF(F19:T19,"<4")>0,"-",(IFERROR(AVERAGE(F19:T19),"")))) -> 7.6 | V19: =U19/12*90 -> 57
C20: Б | D20: 10 | E20: Друмова Діана Олегівна | F20: 9 | G20: 10 | H20: 10 | I20: 9 | J20: 10 | K20: 4 | L20: 11 | M20: 8 | N20: 7 | O20: 6 | P20: 4 | Q20: 4 | R20: 7 | S20: 7 | T20: 7 | U20: =IF(COUNTIF(F20:T20,"=*")>0,"-",IF(COUNTIF(F20:T20,"<4")>0,"-",(IFERROR(AVERAGE(F20:T20),"")))) -> 7.5333333 | V20: =U20/12*90 -> 56.5
C21: Б | D21: 11 | E21: Кравцова Дар`я Сергіївна | F21: 10 | G21: 9 | H21: 10 | I21: 10 | J21: 9 | K21: 4 | L21: 9 | M21: 8 | N21: 6 | O21: 4 | P21: 4 | Q21: 4 | R21: 7 | S21: 7 | T21: 6 | U21: =IF(COUNTIF(F21:T21,"=*")>0,"-",IF(COUNTIF(F21:T21,"<4")>0,"-",(IFERROR(AVERAGE(F21:T21),"")))) -> 7.1333333 | V21: =U21/12*90 -> 53.5
C22: Б | D22: 12 | E22: Фучеджи Андрій Вадимович | F22: 10 | G22: 8 | H22: 9 | I22: 10 | J22: 6 | K22: 5 | L22: 7 | M22: 10 | N22: 6 | O22: 4 | P22: 4 | Q22: 4 | R22: 5 | S22: 5 | T22: 8 | U22: =IF(COUNTIF(F22:T22,"=*")>0,"-",IF(COUNTIF(F22:T22,"<4")>0,"-",(IFERROR(AVERAGE(F22:T22),"")))) -> 6.7333333 | V22: =U22/12*90 -> 50.5
... C26: Б | D26: 16 | E26: Адаменко Юлія Русланівна | F26: 4 | G26: 5 | H26: 5 | I26: 4 | J26: 4 | K26: 4 | L26: 4 | M26: 4 | N26: 4 | O26: 4 | P26: 4 | Q26: 4 | R26: 4 | S26: 4 | T26: 5 | U26: =IF(COUNTIF(F26:T26,"=*")>0,"-",IF(COUNTIF(F26:T26,"<4")>0,"-",(IFERROR(AVERAGE(F26:T26),"")))) -> 4.2 | V26: =U26/12*90 -> 31.5
E27: Кількість бюджетників | F27: ='Зведена 076'!F41 -> 21
E28: Кількість контрактників | F28: ='Зведена 076'!F42 -> 4 | H28: Класний керівник | O28: Тетяна НАГОВСЬКА
E29: Кількість соціального контингенту | F29: ='Зведена 076'!F43 -> 6
E30: Вийшли на стипендію | F30: ='Зведена 076'!F44 -> 8 | H30: Завідувач відділення ПЗСО | O30: Маргарита БРІТІКОВА

Sheet Зведена 101
C3: ВІДОКРЕМЛЕНИЙ СТРУКТУРНИЙ ПІДРОЗДІЛ «ФАХОВИЙ КОЛЕДЖ НАФТОГАЗОВИХ ТЕХНОЛОГІЙ, ІНЖЕНЕРІЇ ТА ІНФРАСТРУКТУРИ СЕРВІСУ
C4: ОДЕСЬКОГО НАЦІОНАЛЬНОГО ТЕХНОЛОГІЧНОГО УНІВЕРСИТЕТУ»
C5: ЗВЕДЕНА ВІДОМІСТЬ
C6: Успішності студентів спеціальності 101 «Екологія»
C7: За IІ семестр 2024-2025 н.р.
C8: Група 24-2 курс І
C9: Б/К | D9: № п/п | E9: Прізвище, ім’я, по батькові | G9: Підсумкові оцінки дисциплін
F10: Астрономія Наговська Т.С. | G10: Біологія Богданенко О.В. | H10: Всесвітня історія Мельничук С.А. | I10: Географія Наговська Т.С. | J10: Зарубіжна література Сербулова Ю.А. | K10: Захист України Лазар В.І. | L10: Іноземна мова Сербулова Ю.А. | M10: Інформатика Бєльдюгіна С.С. | N10: Історія України Левчук Т.Г. | O10: Математика Земляна Т.М. | P10: Українська література Юрченко О.Б. | Q10: Українська мова Юрченко О.Б. | R10: Фізика Калюта Н.М. | S10: Фізична культура Возіян О.Г. | T10: Хімія Сахно Н.О. | U10: Середній бал
C11: Б | D11: 1 | E11: Гайдученко Катерина Дмитрівна | F11: 9 | G11: 9 | H11: 10 | I11: 9 | J11: 8 | K11: 5 | L11: 8 | M11: 8 | N11: 8 | O11: 7 | P11: 8 | Q11: 8 | R11: 7 | S11: 7 | T11: 7 | U11: =IF(COUNTIF(F11:T11,"=*")>0,"-",IF(COUNTIF(F11:T11,"<4")>0,"-",(IFERROR(AVERAGE(F11:T11),"")))) -> 7.8666667
C12: Б | D12: 2 | E12: Демовський Владислав Миколайович | F12: 8 | G12: 5 | H12: 7 | I12: 8 | J12: 7 | K12: 6 | L12: 7 | M12: 7 | N12: 5 | O12: 4 | P12: 4 | Q12: 4 | R12: 4 | S12: 4 | T12: 7 | U12: =IF(COUNTIF(F12:T12,"=*")>0,"-",IF(COUNTIF(F12:T12,"<4")>0,"-",(IFERROR(AVERAGE(F12:T12),"")))) -> 5.8
C13: К | D13: 3 | E13: Зубак Віталій Серафимович | F13: 4 | G13: 5 | H13: 5 | I13: 4 | J13: 5 | K13: 4 | L13: 5 | M13: 6 | N13: 4 | O13: 7 | P13: 7 | Q13: 7 | R13: 4 | S13: 4 | T13: 7 | U13: =IF(COUNTIF(F13:T13,"=*")>0,"-",IF(COUNTIF(F13:T13,"<4")>0,"-",(IFERROR(AVERAGE(F13:T13),"")))) -> 5.2
C14: К | D14: 4 | E14: Іванов Олександр Іванович | F14: 4 | G14: 5 | H14: 5 | I14: 4 | J14: 5 | K14: 4 | L14: 5 | M14: 8 | N14: 4 | O14: 7 | P14: 7 | Q14: 7 | R14: 7 | S14: 4 | T14: 7 | U14: =IF(COUNTIF(F14:T14,"=*")>0,"-",IF(COUNTIF(F14:T14,"<4")>0,"-",(IFERROR(AVERAGE(F14:T14),"")))) -> 5.5333333
C15: Б | D15: 5 | E15: Кольчак Артем Анатолійович | F15: 4 | G15: 6 | H15: 4 | I15: 4 | J15: 5 | K15: н/а | L15: 5 | M15: н/а | N15: н/а | O15: н/а | P15: 4 | Q15: 4 | R15: н/а | S15: 4 | T15: н/а | U15: =IF(COUNTIF(F15:T15,"=*")>0,"-",IF(COUNTIF(F15:T15,"<4")>0,"-",(IFERROR(AVERAGE(F15:T15),"")))) -> -
C16: К | D16: 6 | E16: Куняєв Олег Юрійович | F16: 4 | G16: 5 | H16: 5 | I16: 4 | J16: 5 | K16: 4 | L16: 5 | M16: 8 | N16: 4 | O16: 7 | P16: 7 | Q16: 7 | R16: 4 | S16: 4 | T16: 7 | U16: =IF(COUNTIF(F16:T16,"=*")>0,"-",IF(COUNTIF(F16:T16,"<4")>0,"-",(IFERROR(AVERAGE(F16:T16),"")))) -> 5.3333333
C17: Б | D17: 7 | E17: Лопатухіна Вікторія Анатоліївна | F17: 11 | G17: 10 | H17: 10 | I17: 11 | J17: 9 | K17: 10 | L17: 10 | M17: 10 | N17: 10 | O17: 7 | P17: 11 | Q17: 11 | R17: 8 | S17: 10 | T17: 9 | U17: =IF(COUNTIF(F17:T17,"=*")>0,"-",IF(COUNTIF(F17:T17,"<4")>0,"-",(IFERROR(AVERAGE(F17:T17),"")))) -> 9.8
C18: Б | D18: 8 | E18: Мокану Михайло Миколайович | F18: 4 | G18: 6 | H18: 5 | I18: 4 | J18: 5 | K18: 4 | L18: 5 | M18: 8 | N18: 4 | O18: 7 | P18: 7 | Q18: 7 | R18: 4 | S18: 4 | T18: 6 | U18: =IF(COUNTIF(F18:T18,"=*")>0,"-",IF(COUNTIF(F18:T18,"<4")>0,"-",(IFERROR(AVERAGE(F18:T18),"")))) -> 5.3333333
C19: Б | D19: 9 | E19: Нецеля Віра Петрівна | F19: 8 | G19: 8 | H19: 7 | I19: 8 | J19: 9 | K19: 7 | L19: 7 | M19: 7 | N19: 8 | O19: 4 | P19: 4 | Q19: 4 | R19: 4 | S19: 5 | T19: 7 | U19: =IF(COUNTIF(F19:T19,"=*")>0,"-",IF(COUNTIF(F19:T19,"<4")>0,"-",(IFERROR(AVERAGE(F19:T19),"")))) -> 6.4666667
C20: Б | D20: 10 | E20: Рачкован Олександр Сергійович | F20: 4 | G20: 6 | H20: 5 | I20: 4 | J20: 5 | K20: 4 | L20: 5 | M20: 8 | N20: 4 | O20: 7 | P20: 7 | Q20: 7 | R20: 7 | S20: 4 | T20: 7 | U20: =IF(COUNTIF(F20:T20,"=*")>0,"-",IF(COUNTIF(F20:T20,"<4")>0,"-",(IFERROR(AVERAGE(F20:T20),"")))) -> 5.6
C21: Б | D21: 11 | E21: Самойлова Софія Сергіївна | F21: 8 | G21: 8 | H21: 9 | I21: 8 | J21: 10 | K21: 7 | L21: 11 | M21: 8 | N21: 5 | O21: 4 | P21: 7 | Q21: 7 | R21: 6 | S21: 5 | T21: 5 | U21: =IF(COUNTIF(F21:T21,"=*")>0,"-",IF(COUNTIF(F21:T21,"<4")>0,"-",(IFERROR(AVERAGE(F21:T21),"")))) -> 7.2
C22: Б | D22: 12 | E22: Шаргородська Алла Сергіївна | F22: 7 | G22: 6 | H22: 6 | I22: 7 | J22: 5 | K22: н/а | L22: 5 | M22: н/а | N22: 6 | O22: 4 | P22: 4 | Q22: 4 | R22: 4 | S22: 4 | T22: 2 | U22: =IF(COUNTIF(F22:T22,"=*")>0,"-",IF(COUNTIF(F22:T22,"<4")>0,"-",(IFERROR(AVERAGE(F22:T22),"")))) -> -
C23: Б | D23: 13 | E23: Штєфан Даніїл Ігорович | F23: 8 | G23: 8 | H23: 6 | I23: 8 | J23: 5 | K23: н/а | L23: 6 | M23: 6 | N23: 7 | O23: 4 | P23: 4 | Q23: 4 | R23: 4 | S23: 4 | T23: 4 | U23: =IF(COUNTIF(F23:T23,"=*")>0,"-",IF(COUNTIF(F23:T23,"<4")>0,"-",(IFERROR(AVERAGE(F23:T23),"")))) -> -
E24: Середній бал успішності з дисципліни | F24: =IF(SUM(F11:F23)=0,"",SUM(F11:F23)/$D23) -> 6.3846154 | G24: =IF(SUM(G11:G23)=0,"",SUM(G11:G23)/$D23) -> 6.6923077 | H24: =IF(SUM(H11:H23)=0,"",SUM(H11:H23)/$D23) -> 6.4615385 | I24: =IF(SUM(I11:I23)=0,"",SUM(I11:I23)/$D23) -> 6.3846154 | J24: =IF(SUM(J11:J23)=0,"",SUM(J11:J23)/$D23) -> 6.3846154 | K24: =IF(SUM(K11:K23)=0,"",SUM(K11:K23)/$D23) -> 4.2307692 | L24: =IF(SUM(L11:L23)=0,"",SUM(L11:L23)/$D23) -> 6.4615385 | M24: =IF(SUM(M11:M23)=0,"",SUM(M11:M23)/$D23) -> 6.4615385 | ... T24: =IF(SUM(T11:T23)=0,"",SUM(T11:T23)/$D23) -> 5.7692308 | U24: =IFERROR(AVERAGE(F24:T24),"") -> 5.8666667
E25: Абсолютна успішність | F25: =IF(SUM(F11:F23)=0,"",IF(COUNTIF(F11:F23,">=4")=0,0,COUNTIF(F11:F23,">=4")/$D23*100)) -> 100 | G25: =IF(SUM(G11:G23)=0,"",IF(COUNTIF(G11:G23,">=4")=0,0,COUNTIF(G11:G23,">=4")/$D23*100)) -> 100 | H25: =IF(SUM(H11:H23)=0,"",IF(COUNTIF(H11:H23,">=4")=0,0,COUNTIF(H11:H23,">=4")/$D23*100)) -> 100 | I25: =IF(SUM(I11:I23)=0,"",IF(COUNTIF(I11:I23,">=4")=0,0,COUNTIF(I11:I23,">=4")/$D23*100)) -> 100 | J25: =IF(SUM(J11:J23)=0,"",IF(COUNTIF(J11:J23,">=4")=0,0,COUNTIF(J11:J23,">=4")/$D23*100)) -> 100 | K25: =IF(SUM(K11:K23)=0,"",IF(COUNTIF(K11:K23,">=4")=0,0,COUNTIF(K11:K23,">=4")/$D23*100)) -> 76.923077 | L25: =IF(SUM(L11:L23)=0,"",IF(COUNTIF(L11:L23,">=4")=0,0,COUNTIF(L11:L23,">=4")/$D23*100)) -> 100 | M25: =IF(SUM(M11:M23)=0,"",IF(COUNTIF(M11:M23,">=4")=0,0,COUNTIF(M11:M23,">=4")/$D23*100)) -> 84.615385 | ... T25: =IF(SUM(T11:T23)=0,"",IF(COUNTIF(T11:T23,">=4")=0,0,COUNTIF(T11:T23,">=4")/$D23*100)) -> 84.615385
E26: Якісна успішність | F26: =IF(SUM(F11:F23)=0,"",IF(COUNTIF(F11:F23,">=7")=0,0,COUNTIF(F11:F23,">=7")/$D23*100)) -> 53.846154 | G26: =IF(SUM(G11:G23)=0,"",IF(COUNTIF(G11:G23,">=7")=0,0,COUNTIF(G11:G23,">=7")/$D23*100)) -> 38.461538 | H26: =IF(SUM(H11:H23)=0,"",IF(COUNTIF(H11:H23,">=7")=0,0,COUNTIF(H11:H23,">=7")/$D23*100)) -> 38.461538 | I26: =IF(SUM(I11:I23)=0,"",IF(COUNTIF(I11:I23,">=7")=0,0,COUNTIF(I11:I23,">=7")/$D23*100)) -> 53.846154 | J26: =IF(SUM(J11:J23)=0,"",IF(COUNTIF(J11:J23,">=7")=0,0,COUNTIF(J11:J23,">=7")/$D23*100)) -> 38.461538 | K26: =IF(SUM(K11:K23)=0,"",IF(COUNTIF(K11:K23,">=7")=0,0,COUNTIF(K11:K23,">=7")/$D23*100)) -> 23.076923 | L26: =IF(SUM(L11:L23)=0,"",IF(COUNTIF(L11:L23,">=7")=0,0,COUNTIF(L11:L23,">=7")/$D23*100)) -> 38.461538 | M26: =IF(SUM(M11:M23)=0,"",IF(COUNTIF(M11:M23,">=7")=0,0,COUNTIF(M11:M23,">=7")/$D23*100)) -> 69.230769 | ... T26: =IF(SUM(T11:T23)=0,"",IF(COUNTIF(T11:T23,">=7")=0,0,COUNTIF(T11:T23,">=7")/$D23*100)) -> 61.538462
E27: Абсолютна успішність по групі | F27: =IFERROR(AVERAGE(F25:T25),"") -> 94.871795
E28: Якісна успішність по групі | F28: =IFERROR(AVERAGE(F26:T26),"") -> 44.615385
E29: Кількість бюджетників | F29: =IF(COUNTIF(C11:C23,"=Б")=0,IF(COUNTIF(C11:C23,"=К")=0,"",0),COUNTIF(C11:C23,"=Б")) -> 10
E30: Кількість контрактників | F30: =IF(COUNTIF(C11:C23,"=К")=0,IF(COUNTIF(C11:C23,"=Б")=0,"",0),COUNTIF(C11:C23,"=К")) -> 3 | H30: Класний керівник | O30: Тетяна НАГОВСЬКА
E31: Кількість соціального контингенту | F31: 0
E32: Вийшли на стипендію | F32: 4 | H32: Завідувач відділення ПЗСО | O32: Маргарита БРІТІКОВА

Sheet Рейтингова 101
C3: ВІДОКРЕМЛЕНИЙ СТРУКТУРНИЙ ПІДРОЗДІЛ «ФАХОВИЙ КОЛЕДЖ НАФТОГАЗОВИХ ТЕХНОЛОГІЙ, ІНЖЕНЕРІЇ ТА ІНФРАСТРУКТУРИ СЕРВІСУ
C4: ОДЕСЬКОГО НАЦІОНАЛЬНОГО ТЕХНОЛОГІЧНОГО УНІВЕРСИТЕТУ»
C5: РЕЙТИНГОВА ВІДОМІСТЬ
C6: Успішності студентів спеціальності 101 «Екологія»
C7: За IІ семестр 2024-2025 н.р.
C8: Група 24-2 курс І
C9: Б/К | D9: № п/п | E9: Прізвище, ім’я, по батькові | G9: Підсумкові оцінки дисциплін
F10: Астрономія Наговська Т.С. | G10: Біологія Богданенко О.В. | H10: Всесвітня історія Мельничук С.А. | I10: Географія Наговська Т.С. | J10: Зарубіжна література Сербулова Ю.А. | K10: Захист України Лазар В.І. | L10: Іноземна мова Сербулова Ю.А. | M10: Інформатика Бєльдюгіна С.С. | N10: Історія України Левчук Т.Г. | O10: Математика Земляна Т.М. | P10: Українська література Юрченко О.Б. | Q10: Українська мова Юрченко О.Б. | R10: Фізика Калюта Н.М. | S10: Фізична культура Возіян О.Г. | T10: Хімія Сахно Н.О. | U10: Середній бал | V10: Рейтинговий бал
C11: Б | D11: 1 | E11: Лопатухіна Вікторія Анатоліївна | F11: 11 | G11: 10 | H11: 10 | I11: 11 | J11: 9 | K11: 10 | L11: 10 | M11: 10 | N11: 10 | O11: 7 | P11: 11 | Q11: 11 | R11: 8 | S11: 10 | T11: 9 | U11: =IF(COUNTIF(F11:T11,"=*")>0,"-",IF(COUNTIF(F11:T11,"<4")>0,"-",(IFERROR(AVERAGE(F11:T11),"")))) -> 9.8 | V11: =U11/12*90 -> 73.5
C12: Б | D12: 2 | E12: Гайдученко Катерина Дмитрівна | F12: 9 | G12: 9 | H12: 10 | I12: 9 | J12: 8 | K12: 5 | L12: 8 | M12: 8 | N12: 8 | O12: 7 | P12: 8 | Q12: 8 | R12: 7 | S12: 7 | T12: 7 | U12: =IF(COUNTIF(F12:T12,"=*")>0,"-",IF(COUNTIF(F12:T12,"<4")>0,"-",(IFERROR(AVERAGE(F12:T12),"")))) -> 7.8666667 | V12: =U12/12*90 -> 59
C13: Б | D13: 3 | E13: Самойлова Софія Сергіївна | F13: 8 | G13: 8 | H13: 9 | I13: 8 | J13: 10 | K13: 7 | L13: 11 | M13: 8 | N13: 5 | O13: 4 | P13: 7 | Q13: 7 | R13: 6 | S13: 5 | T13: 5 | U13: =IF(COUNTIF(F13:T13,"=*")>0,"-",IF(COUNTIF(F13:T13,"<4")>0,"-",(IFERROR(AVERAGE(F13:T13),"")))) -> 7.2 | V13: =U13/12*90 -> 54
C14: Б | D14: 4 | E14: Нецеля Віра Петрівна | F14: 8 | G14: 8 | H14: 7 | I14: 8 | J14: 9 | K14: 7 | L14: 7 | M14: 7 | N14: 8 | O14: 4 | P14: 4 | Q14: 4 | R14: 4 | S14: 5 | T14: 7 | U14: =IF(COUNTIF(F14:T14,"=*")>0,"-",IF(COUNTIF(F14:T14,"<4")>0,"-",(IFERROR(AVERAGE(F14:T14),"")))) -> 6.4666667 | V14: =U14/12*90 -> 48.5
C15: Б | D15: 5 | E15: Демовський Владислав Миколайович | F15: 8 | G15: 5 | H15: 7 | I15: 8 | J15: 7 | K15: 6 | L15: 7 | M15: 7 | N15: 5 | O15: 4 | P15: 4 | Q15: 4 | R15: 4 | S15: 4 | T15: 7 | U15: =IF(COUNTIF(F15:T15,"=*")>0,"-",IF(COUNTIF(F15:T15,"<4")>0,"-",(IFERROR(AVERAGE(F15:T15),"")))) -> 5.8 | V15: =U15/12*90 -> 43.5
C16: Б | D16: 6 | E16: Рачкован Олександр Сергійович | F16: 4 | G16: 6 | H16: 5 | I16: 4 | J16: 5 | K16: 4 | L16: 5 | M16: 8 | N16: 4 | O16: 7 | P16: 7 | Q16: 7 | R16: 7 | S16: 4 | T16: 7 | U16: =IF(COUNTIF(F16:T16,"=*")>0,"-",IF(COUNTIF(F16:T16,"<4")>0,"-",(IFERROR(AVERAGE(F16:T16),"")))) -> 5.6 | V16: =U16/12*90 -> 42
C17: Б | D17: 7 | E17: Мокану Михайло Миколайович | F17: 4 | G17: 6 | H17: 5 | I17: 4 | J17: 5 | K17: 4 | L17: 5 | M17: 8 | N17: 4 | O17: 7 | P17: 7 | Q17: 7 | R17: 4 | S17: 4 | T17: 6 | U17: =IF(COUNTIF(F17:T17,"=*")>0,"-",IF(COUNTIF(F17:T17,"<4")>0,"-",(IFERROR(AVERAGE(F17:T17),"")))) -> 5.3333333 | V17: =U17/12*90 -> 40
E18: Кількість бюджетників | F18: ='Зведена 101'!F29 -> 10
E19: Кількість контрактників | F19: ='Зведена 101'!F30 -> 3 | H19: Класний керівник | O19: Тетяна НАГОВСЬКА
E20: Кількість соціального контингенту | F20: ='Зведена 101'!F31 -> 0
E21: Вийшли на стипендію | F21: ='Зведена 101'!F32 -> 4 | H21: Завідувач відділення ПЗСО | O21: Маргарита БРІТІКОВА

Sheet Зведена 185
C3: ВІДОКРЕМЛЕНИЙ СТРУКТУРНИЙ ПІДРОЗДІЛ «ФАХОВИЙ КОЛЕДЖ НАФТОГАЗОВИХ ТЕХНОЛОГІЙ, ІНЖЕНЕРІЇ ТА ІНФРАСТРУКТУРИ СЕРВІСУ
C4: ОДЕСЬКОГО НАЦІОНАЛЬНОГО ТЕХНОЛОГІЧНОГО УНІВЕРСИТЕТУ»
C5: ЗВЕДЕНА ВІДОМІСТЬ
C6: Успішності студентів спеціальності 185 «Нафтогазова інженерія та технології»
C7: За IІ семестр 2024-2025 н.р.
C8: Група 24-2 курс І
C9: Б/К | D9: № п/п | E9: Прізвище, ім’я, по батькові | G9: Підсумкові оцінки дисциплін
F10: Астрономія Наговська Т.С. | G10: Біологія Богданенко О.В. | H10: Всесвітня історія Мельничук С.А. | I10: Географія Наговська Т.С. | J10: Зарубіжна література Сербулова Ю.А. | K10: Захист України Лазар В.І. | L10: Іноземна мова Сербулова Ю.А. | M10: Інформатика Бєльдюгіна С.С. | N10: Історія України Левчук Т.Г. | O10: Математика Земляна Т.М. | P10: Українська література Юрченко О.Б. | Q10: Українська мова Юрченко О.Б. | R10: Фізика Калюта Н.М. | S10: Фізична культура Возіян О.Г. | T10: Хімія Сахно Н.О. | U10: Середній бал
C11: К | D11: 1 | E11: Греков Петро Іванович | F11: 4 | G11: 5 | H11: 5 | I11: 4 | J11: 5 | K11: 4 | L11: 5 | M11: 8 | N11: 4 | O11: 7 | P11: 7 | Q11: 7 | R11: 4 | S11: 4 | T11: 7 | U11: =IF(COUNTIF(F11:T11,"=*")>0,"-",IF(COUNTIF(F11:T11,"<4")>0,"-",(IFERROR(AVERAGE(F11:T11),"")))) -> 5.3333333
C12: К | D12: 2 | E12: Драган Сергій Сергійович | F12: 8 | G12: 5 | H12: 5 | I12: 8 | J12: 5 | K12: 4 | L12: 5 | M12: 8 | N12: 4 | O12: 7 | P12: 7 | Q12: 7 | R12: 4 | S12: 4 | T12: 7 | U12: =IF(COUNTIF(F12:T12,"=*")>0,"-",IF(COUNTIF(F12:T12,"<4")>0,"-",(IFERROR(AVERAGE(F12:T12),"")))) -> 5.8666667
E13: Середній бал успішності з дисципліни | F13: =IF(SUM(F11:F12)=0,"",SUM(F11:F12)/$D12) -> 6 | G13: =IF(SUM(G11:G12)=0,"",SUM(G11:G12)/D12) -> 5 | H13: =IF(SUM(H11:H12)=0,"",SUM(H11:H12)/D12) -> 5 | I13: =IF(SUM(I11:I12)=0,"",SUM(I11:I12)/D12) -> 6 | J13: =IF(SUM(J11:J12)=0,"",SUM(J11:J12)/D12) -> 5 | K13: =IF(SUM(K11:K12)=0,"",SUM(K11:K12)/D12) -> 4 | L13: =IF(SUM(L11:L12)=0,"",SUM(L11:L12)/D12) -> 5 | M13: =IF(SUM(M11:M12)=0,"",SUM(M11:M12)/D12) -> 8 | N13: =IF(SUM(N11:N12)=0,"",SUM(N11:N12)/D12) -> 4 | O13: =IF(SUM(O11:O12)=0,"",SUM(O11:O12)/D12) -> 7 | P13: =IF(SUM(P11:P12)=0,"",SUM(P11:P12)/D12) -> 7 | Q13: =IF(SUM(Q11:Q12)=0,"",SUM(Q11:Q12)/D12) -> 7 | R13: =IF(SUM(R11:R12)=0,"",SUM(R11:R12)/D12) -> 4 | S13: =IF(SUM(S11:S12)=0,"",SUM(S11:S12)/D12) -> 4 | T13: =IF(SUM(T11:T12)=0,"",SUM(T11:T12)/D12) -> 7 | U13: =IFERROR(AVERAGE(F13:T13),"") -> 5.6
E14: Абсолютна успішність | F14: =IF(SUM(F11:F12)=0,"",IF(COUNTIF(F11:F12,">=4")=0,0,COUNTIF(F11:F12,">=4")/$D12*100)) -> 100 | G14: =IF(SUM(G11:G12)=0,"",IF(COUNTIF(G11:G12,">=4")=0,0,COUNTIF(G11:G12,">=4")/D12*100)) -> 100 | H14: =IF(SUM(H11:H12)=0,"",IF(COUNTIF(H11:H12,">=4")=0,0,COUNTIF(H11:H12,">=4")/D12*100)) -> 100 | I14: =IF(SUM(I11:I12)=0,"",IF(COUNTIF(I11:I12,">=4")=0,0,COUNTIF(I11:I12,">=4")/D12*100)) -> 100 | J14: =IF(SUM(J11:J12)=0,"",IF(COUNTIF(J11:J12,">=4")=0,0,COUNTIF(J11:J12,">=4")/D12*100)) -> 100 | K14: =IF(SUM(K11:K12)=0,"",IF(COUNTIF(K11:K12,">=4")=0,0,COUNTIF(K11:K12,">=4")/D12*100)) -> 100 | L14: =IF(SUM(L11:L12)=0,"",IF(COUNTIF(L11:L12,">=4")=0,0,COUNTIF(L11:L12,">=4")/D12*100)) -> 100 | M14: =IF(SUM(M11:M12)=0,"",IF(COUNTIF(M11:M12,">=4")=0,0,COUNTIF(M11:M12,">=4")/D12*100)) -> 100 | N14: =IF(SUM(N11:N12)=0,"",IF(COUNTIF(N11:N12,">=4")=0,0,COUNTIF(N11:N12,">=4")/D12*100)) -> 100 | O14: =IF(SUM(O11:O12)=0,"",IF(COUNTIF(O11:O12,">=4")=0,0,COUNTIF(O11:O12,">=4")/D12*100)) -> 100 | P14: =IF(SUM(P11:P12)=0,"",IF(COUNTIF(P11:P12,">=4")=0,0,COUNTIF(P11:P12,">=4")/D12*100)) -> 100 | Q14: =IF(SUM(Q11:Q12)=0,"",IF(COUNTIF(Q11:Q12,">=4")=0,0,COUNTIF(Q11:Q12,">=4")/D12*100)) -> 100 | R14: =IF(SUM(R11:R12)=0,"",IF(COUNTIF(R11:R12,">=4")=0,0,COUNTIF(R11:R12,">=4")/D12*100)) -> 100 | S14: =IF(SUM(S11:S12)=0,"",IF(COUNTIF(S11:S12,">=4")=0,0,COUNTIF(S11:S12,">=4")/D12*100)) -> 100 | T14: =IF(SUM(T11:T12)=0,"",IF(COUNTIF(T11:T12,">=4")=0,0,COUNTIF(T11:T12,">=4")/D12*100)) -> 100
E15: Якісна успішність | F15: =IF(SUM(F11:F12)=0,"",IF(COUNTIF(F11:F12,">=7")=0,0,COUNTIF(F11:F12,">=7")/$D12*100)) -> 50 | G15: =IF(SUM(G11:G12)=0,"",IF(COUNTIF(G11:G12,">=7")=0,0,COUNTIF(G11:G12,">=7")/D12*100)) -> 0 | H15: =IF(SUM(H11:H12)=0,"",IF(COUNTIF(H11:H12,">=7")=0,0,COUNTIF(H11:H12,">=7")/D12*100)) -> 0 | I15: =IF(SUM(I11:I12)=0,"",IF(COUNTIF(I11:I12,">=7")=0,0,COUNTIF(I11:I12,">=7")/D12*100)) -> 50 | J15: =IF(SUM(J11:J12)=0,"",IF(COUNTIF(J11:J12,">=7")=0,0,COUNTIF(J11:J12,">=7")/D12*100)) -> 0 | K15: =IF(SUM(K11:K12)=0,"",IF(COUNTIF(K11:K12,">=7")=0,0,COUNTIF(K11:K12,">=7")/D12*100)) -> 0 | L15: =IF(SUM(L11:L12)=0,"",IF(COUNTIF(L11:L12,">=7")=0,0,COUNTIF(L11:L12,">=7")/D12*100)) -> 0 | M15: =IF(SUM(M11:M12)=0,"",IF(COUNTIF(M11:M12,">=7")=0,0,COUNTIF(M11:M12,">=7")/D12*100)) -> 100 | N15: =IF(SUM(N11:N12)=0,"",IF(COUNTIF(N11:N12,">=7")=0,0,COUNTIF(N11:N12,">=7")/D12*100)) -> 0 | O15: =IF(SUM(O11:O12)=0,"",IF(COUNTIF(O11:O12,">=7")=0,0,COUNTIF(O11:O12,">=7")/D12*100)) -> 100 | P15: =IF(SUM(P11:P12)=0,"",IF(COUNTIF(P11:P12,">=7")=0,0,COUNTIF(P11:P12,">=7")/D12*100)) -> 100 | Q15: =IF(SUM(Q11:Q12)=0,"",IF(COUNTIF(Q11:Q12,">=7")=0,0,COUNTIF(Q11:Q12,">=7")/D12*100)) -> 100 | R15: =IF(SUM(R11:R12)=0,"",IF(COUNTIF(R11:R12,">=7")=0,0,COUNTIF(R11:R12,">=7")/D12*100)) -> 0 | S15: =IF(SUM(S11:S12)=0,"",IF(COUNTIF(S11:S12,">=7")=0,0,COUNTIF(S11:S12,">=7")/D12*100)) -> 0 | T15: =IF(SUM(T11:T12)=0,"",IF(COUNTIF(T11:T12,">=7")=0,0,COUNTIF(T11:T12,">=7")/D12*100)) -> 100
E16: Абсолютна успішність по групі | F16: =IFERROR(AVERAGE(F14:T14),"") -> 100
E17: Якісна успішність по групі | F17: =IFERROR(AVERAGE(F15:T15),"") -> 40
E18: Кількість бюджетників | F18: =IF(COUNTIF(C11:C12,"=Б")=0,IF(COUNTIF(C11:C12,"=К")=0,"",0),COUNTIF(C11:C12,"=Б")) -> 0
E19: Кількість контрактників | F19: =IF(COUNTIF(C11:C12,"=К")=0,IF(COUNTIF(C11:C12,"=Б")=0,"",0),COUNTIF(C11:C12,"=К")) -> 2 | H19: Класний керівник | O19: Тетяна НАГОВСЬКА
E20: Кількість соціального контингенту
E21: Вийшли на стипендію | H21: Завідувач відділення ПЗСО | O21: Маргарита БРІТІКОВА
