Workbook
Name A1048577: #REF!
Name A1048577: #REF!
Name A1048577: #REF!
Name A1048577: #REF!
Name A1048577: #REF!
Name A1048577: #REF!
Name A1048577: #REF!
Name A1048577: #REF!
Name A1048577: #REF!
Name A1048577: #REF!
Name A1048577: #REF!
Name A1048577: #REF!
Name A1048577: #REF!
Name A1048577: #REF!
Name A1048577: #REF!
Name A1048577: #REF!
Name A1048577: #REF!
Name A1048577: #REF!
Name A1048577: #REF!
Name A1048577: #REF!
Name Ф80: #REF!
Name Ф80: #REF!
Name Ф80: #REF!
Name Ф80: #REF!
Name Ф80: #REF!
Name Ф80: #REF!
Name Ф80: #REF!
Name Ф80: #REF!
Name Ф80: #REF!
Name Ф80: #REF!
Name Ф80: #REF!
Name Ф80: #REF!
Name Ф80: #REF!
Name Ф80: #REF!
Name Ф80: #REF!
Name Ф80: #REF!
Name Ф80: #REF!
Name Ф80: #REF!
Name Ф80: #REF!
Name Ф80: #REF!

Sheet Л_Загальна
A1: S
C3: ЗАГАЛЬНА ВІДОМІСТЬ З УСІМА СПЕЦІАЛЬНОСТЯМИ. НЕ ДЛЯ ДРУКУ. ЗВІДСИ ОЦІНКИ АВТОМАТИЧНО ПЕРЕНОСЯТЬСЯ ДО ВІДОМОСТЕЙ. СТВОРЕНО ДЛЯ ЛЕГШОГО ЗАПОВНЕННЯ ОЦІНОК
C8: Б/К | D8: № п/п | E8: Прізвище, ім’я, по батькові | F8: Підсумкові оцінки дисциплін | Z8: Середній бал
F9: 1 | G9: 2 | H9: 3 | I9: 4 | J9: 5 | K9: 6 | L9: 7 | M9: 8 | N9: 9 | O9: 10 | P9: 11 | Q9: 12 | R9: 13 | S9: 14 | T9: 15 | U9: 16 | V9: 17 | W9: 18 | X9: 19 | Y9: 20
D10: 1 | Z10: =IF(COUNTIF(F10:Y10,"=*")>0,IF($C10="К","-"," - "),IF(COUNTIF(F10:Y10,"<4")>0,IF(C10="К","-"," - "),(IFERROR(AVERAGE(F10:Y10),"Очікую")))) -> Очікую
D11: 2 | Z11: =IF(COUNTIF(F11:Y11,"=*")>0,IF($C11="К","-"," - "),IF(COUNTIF(F11:Y11,"<4")>0,IF(C11="К","-"," - "),(IFERROR(AVERAGE(F11:Y11),"Очікую")))) -> Очікую
D12: 3 | Z12: =IF(COUNTIF(F12:Y12,"=*")>0,IF($C12="К","-"," - "),IF(COUNTIF(F12:Y12,"<4")>0,IF(C12="К","-"," - "),(IFERROR(AVERAGE(F12:Y12),"Очікую")))) -> Очікую
D13: 4 | Z13: =IF(COUNTIF(F13:Y13,"=*")>0,IF($C13="К","-"," - "),IF(COUNTIF(F13:Y13,"<4")>0,IF(C13="К","-"," - "),(IFERROR(AVERAGE(F13:Y13),"Очікую")))) -> Очікую
D14: 5 | Z14: =IF(COUNTIF(F14:Y14,"=*")>0,IF($C14="К","-"," - "),IF(COUNTIF(F14:Y14,"<4")>0,IF(C14="К","-"," - "),(IFERROR(AVERAGE(F14:Y14),"Очікую")))) -> Очікую
D15: 6 | Z15: =IF(COUNTIF(F15:Y15,"=*")>0,IF($C15="К","-"," - "),IF(COUNTIF(F15:Y15,"<4")>0,IF(C15="К","-"," - "),(IFERROR(AVERAGE(F15:Y15),"Очікую")))) -> Очікую
D16: 7 | Z16: =IF(COUNTIF(F16:Y16,"=*")>0,IF($C16="К","-"," - "),IF(COUNTIF(F16:Y16,"<4")>0,IF(C16="К","-"," - "),(IFERROR(AVERAGE(F16:Y16),"Очікую")))) -> Очікую
D17: 8 | Z17: =IF(COUNTIF(F17:Y17,"=*")>0,IF($C17="К","-"," - "),IF(COUNTIF(F17:Y17,"<4")>0,IF(C17="К","-"," - "),(IFERROR(AVERAGE(F17:Y17),"Очікую")))) -> Очікую
D18: 9 | Z18: =IF(COUNTIF(F18:Y18,"=*")>0,IF($C18="К","-"," - "),IF(COUNTIF(F18:Y18,"<4")>0,IF(C18="К","-"," - "),(IFERROR(AVERAGE(F18:Y18),"Очікую")))) -> Очікую
D19: 10 | Z19: =IF(COUNTIF(F19:Y19,"=*")>0,IF($C19="К","-"," - "),IF(COUNTIF(F19:Y19,"<4")>0,IF(C19="К","-"," - "),(IFERROR(AVERAGE(F19:Y19),"Очікую")))) -> Очікую
D20: 11 | Z20: =IF(COUNTIF(F20:Y20,"=*")>0,IF($C20="К","-"," - "),IF(COUNTIF(F20:Y20,"<4")>0,IF(C20="К","-"," - "),(IFERROR(AVERAGE(F20:Y20),"Очікую")))) -> Очікую
D21: 12 | Z21: =IF(COUNTIF(F21:Y21,"=*")>0,IF($C21="К","-"," - "),IF(COUNTIF(F21:Y21,"<4")>0,IF(C21="К","-"," - "),(IFERROR(AVERAGE(F21:Y21),"Очікую")))) -> Очікую
... D109: 100 | Z109: =IF(COUNTIF(F109:Y109,"=*")>0,IF($C109="К","-"," - "),IF(COUNTIF(F109:Y109,"<4")>0,IF(C109="К","-"," - "),(IFERROR(AVERAGE(F109:Y109),"Очікую")))) -> Очікую
E110: Середній бал успішності з дисципліни | F110: =IF(SUM(F10:F109)=0,IF(COUNTA(F10:F109)=0,"Очікую",0),SUM(F10:F109)/$D109) -> Очікую | G110: =IF(SUM(G10:G109)=0,IF(COUNTA(G10:G109)=0,"Очікую",0),SUM(G10:G109)/$D109) -> Очікую | H110: =IF(SUM(H10:H109)=0,IF(COUNTA(H10:H109)=0,"Очікую",0),SUM(H10:H109)/$D109) -> Очікую | I110: =IF(SUM(I10:I109)=0,IF(COUNTA(I10:I109)=0,"Очікую",0),SUM(I10:I109)/$D109) -> Очікую | J110: =IF(SUM(J10:J109)=0,IF(COUNTA(J10:J109)=0,"Очікую",0),SUM(J10:J109)/$D109) -> Очікую | K110: =IF(SUM(K10:K109)=0,IF(COUNTA(K10:K109)=0,"Очікую",0),SUM(K10:K109)/$D109) -> Очікую | L110: =IF(SUM(L10:L109)=0,IF(COUNTA(L10:L109)=0,"Очікую",0),SUM(L10:L109)/$D109) -> Очікую | M110: =IF(SUM(M10:M109)=0,IF(COUNTA(M10:M109)=0,"Очікую",0),SUM(M10:M109)/$D109) -> Очікую | ... Y110: =IF(SUM(Y10:Y109)=0,IF(COUNTA(Y10:Y109)=0,"Очікую",0),SUM(Y10:Y109)/$D109) -> Очікую | Z110: =IFERROR(AVERAGE(F110:Y110),"Очікую") -> Очікую
E111: Абсолютна успішність | F111: =IF(SUM(F10:F109)=0,IF(COUNTA(F10:F109)=0,"Очікую",0),IF(COUNTIF(F10:F109,">=4")=0,0,COUNTIF(F10:F109,">=4")/$D109*100)) -> Очікую | G111: =IF(SUM(G10:G109)=0,IF(COUNTA(G10:G109)=0,"Очікую",0),IF(COUNTIF(G10:G109,">=4")=0,0,COUNTIF(G10:G109,">=4")/$D109*100)) -> Очікую | H111: =IF(SUM(H10:H109)=0,IF(COUNTA(H10:H109)=0,"Очікую",0),IF(COUNTIF(H10:H109,">=4")=0,0,COUNTIF(H10:H109,">=4")/$D109*100)) -> Очікую | I111: =IF(SUM(I10:I109)=0,IF(COUNTA(I10:I109)=0,"Очікую",0),IF(COUNTIF(I10:I109,">=4")=0,0,COUNTIF(I10:I109,">=4")/$D109*100)) -> Очікую | J111: =IF(SUM(J10:J109)=0,IF(COUNTA(J10:J109)=0,"Очікую",0),IF(COUNTIF(J10:J109,">=4")=0,0,COUNTIF(J10:J109,">=4")/$D109*100)) -> Очікую | K111: =IF(SUM(K10:K109)=0,IF(COUNTA(K10:K109)=0,"Очікую",0),IF(COUNTIF(K10:K109,">=4")=0,0,COUNTIF(K10:K109,">=4")/$D109*100)) -> Очікую | L111: =IF(SUM(L10:L109)=0,IF(COUNTA(L10:L109)=0,"Очікую",0),IF(COUNTIF(L10:L109,">=4")=0,0,COUNTIF(L10:L109,">=4")/$D109*100)) -> Очікую | M111: =IF(SUM(M10:M109)=0,IF(COUNTA(M10:M109)=0,"Очікую",0),IF(COUNTIF(M10:M109,">=4")=0,0,COUNTIF(M10:M109,">=4")/$D109*100)) -> Очікую | ... Y111: =IF(SUM(Y10:Y109)=0,IF(COUNTA(Y10:Y109)=0,"Очікую",0),IF(COUNTIF(Y10:Y109,">=4")=0,0,COUNTIF(Y10:Y109,">=4")/$D109*100)) -> Очікую
E112: Якісна успішність | F112: =IF(SUM(F10:F109)=0,IF(COUNTA(F10:F109)=0,"Очікую",0),IF(COUNTIF(F10:F109,">=7")=0,0,COUNTIF(F10:F109,">=7")/$D109*100)) -> Очікую | G112: =IF(SUM(G10:G109)=0,IF(COUNTA(G10:G109)=0,"Очікую",0),IF(COUNTIF(G10:G109,">=7")=0,0,COUNTIF(G10:G109,">=7")/$D109*100)) -> Очікую | H112: =IF(SUM(H10:H109)=0,IF(COUNTA(H10:H109)=0,"Очікую",0),IF(COUNTIF(H10:H109,">=7")=0,0,COUNTIF(H10:H109,">=7")/$D109*100)) -> Очікую | I112: =IF(SUM(I10:I109)=0,IF(COUNTA(I10:I109)=0,"Очікую",0),IF(COUNTIF(I10:I109,">=7")=0,0,COUNTIF(I10:I109,">=7")/$D109*100)) -> Очікую | J112: =IF(SUM(J10:J109)=0,IF(COUNTA(J10:J109)=0,"Очікую",0),IF(COUNTIF(J10:J109,">=7")=0,0,COUNTIF(J10:J109,">=7")/$D109*100)) -> Очікую | K112: =IF(SUM(K10:K109)=0,IF(COUNTA(K10:K109)=0,"Очікую",0),IF(COUNTIF(K10:K109,">=7")=0,0,COUNTIF(K10:K109,">=7")/$D109*100)) -> Очікую | L112: =IF(SUM(L10:L109)=0,IF(COUNTA(L10:L109)=0,"Очікую",0),IF(COUNTIF(L10:L109,">=7")=0,0,COUNTIF(L10:L109,">=7")/$D109*100)) -> Очікую | M112: =IF(SUM(M10:M109)=0,IF(COUNTA(M10:M109)=0,"Очікую",0),IF(COUNTIF(M10:M109,">=7")=0,0,COUNTIF(M10:M109,">=7")/$D109*100)) -> Очікую | ... Y112: =IF(SUM(Y10:Y109)=0,IF(COUNTA(Y10:Y109)=0,"Очікую",0),IF(COUNTIF(Y10:Y109,">=7")=0,0,COUNTIF(Y10:Y109,">=7")/$D109*100)) -> Очікую
E113: Абсолютна успішність по групі | F113: =IFERROR(AVERAGE(F111:Y111),"Очікую") -> Очікую
E114: Якісна успішність по групі | F114: =IFERROR(AVERAGE(F112:Y112),"Очікую") -> Очікую
E115: Кількість бюджетників | F115: =IF(COUNTIF(C10:C109,"=Б")=0,IF(COUNTIF(C10:C109,"=К")=0,"Очікую",0),COUNTIF(C10:C109,"=Б")) -> Очікую
E116: Кількість контрактників | F116: =IF(COUNTIF(C10:C109,"=К")=0,IF(COUNTIF(C10:C109,"=Б")=0,"Очікую",0),COUNTIF(C10:C109,"=К")) -> Очікую | H116: Класний керівник
E117: Кількість соціального контингенту
E118: Вийшли на стипендію | F118: =IF(F115="Очікую","Очікую",IF(F115-COUNTIF(Z10:Z109," - ")<ROUNDDOWN(F115*0.4,0),F115-COUNTIF(Z10:Z109," - "),ROUNDDOWN(F115*0.4,0))) -> Очікую | H118: Завідувач відділення ПЗСО

Sheet ЛЗ1
A1: S
C3: ВІДОКРЕМЛЕНИЙ СТРУКТУРНИЙ ПІДРОЗДІЛ «ФАХОВИЙ КОЛЕДЖ НАФТОГАЗОВИХ ТЕХНОЛОГІЙ, ІНЖЕНЕРІЇ ТА ІНФРАСТРУКТУРИ СЕРВІСУ ОДЕСЬКОГО НАЦІОНАЛЬНОГО ТЕХНОЛОГІЧНОГО УНІВЕРСИТЕТУ»
C4: ЗВЕДЕНА ВІДОМІСТЬ
C5: Успішності студентів спеціальності XXX «XXXXX»
C6: За X семестр XXXX-XXXX н.р.
C7: Група XXXX курс X
C8: Б/К | D8: № п/п | E8: Прізвище, ім’я, по батькові | F8: Підсумкові оцінки дисциплін | Z8: Середній бал
F9: 1 | G9: 2 | H9: 3 | I9: 4 | J9: 5 | K9: 6 | L9: 7 | M9: 8 | N9: 9 | O9: 10 | P9: 11 | Q9: 12 | R9: 13 | S9: 14 | T9: 15 | U9: 16 | V9: 17 | W9: 18 | X9: 19 | Y9: 20
D10: 1 | Z10: =IF(COUNTIF(F10:Y10,"=*")>0,IF($C10="К","-"," - "),IF(COUNTIF(F10:Y10,"<4")>0,IF(C10="К","-"," - "),(IFERROR(AVERAGE(F10:Y10),"Очікую")))) -> Очікую
D11: 2 | Z11: =IF(COUNTIF(F11:Y11,"=*")>0,IF($C11="К","-"," - "),IF(COUNTIF(F11:Y11,"<4")>0,IF(C11="К","-"," - "),(IFERROR(AVERAGE(F11:Y11),"Очікую")))) -> Очікую
D12: 3 | Z12: =IF(COUNTIF(F12:Y12,"=*")>0,IF($C12="К","-"," - "),IF(COUNTIF(F12:Y12,"<4")>0,IF(C12="К","-"," - "),(IFERROR(AVERAGE(F12:Y12),"Очікую")))) -> Очікую
D13: 4 | Z13: =IF(COUNTIF(F13:Y13,"=*")>0,IF($C13="К","-"," - "),IF(COUNTIF(F13:Y13,"<4")>0,IF(C13="К","-"," - "),(IFERROR(AVERAGE(F13:Y13),"Очікую")))) -> Очікую
D14: 5 | Z14: =IF(COUNTIF(F14:Y14,"=*")>0,IF($C14="К","-"," - "),IF(COUNTIF(F14:Y14,"<4")>0,IF(C14="К","-"," - "),(IFERROR(AVERAGE(F14:Y14),"Очікую")))) -> Очікую
D15: 6 | Z15: =IF(COUNTIF(F15:Y15,"=*")>0,IF($C15="К","-"," - "),IF(COUNTIF(F15:Y15,"<4")>0,IF(C15="К","-"," - "),(IFERROR(AVERAGE(F15:Y15),"Очікую")))) -> Очікую
D16: 7 | Z16: =IF(COUNTIF(F16:Y16,"=*")>0,IF($C16="К","-"," - "),IF(COUNTIF(F16:Y16,"<4")>0,IF(C16="К","-"," - "),(IFERROR(AVERAGE(F16:Y16),"Очікую")))) -> Очікую
D17: 8 | Z17: =IF(COUNTIF(F17:Y17,"=*")>0,IF($C17="К","-"," - "),IF(COUNTIF(F17:Y17,"<4")>0,IF(C17="К","-"," - "),(IFERROR(AVERAGE(F17:Y17),"Очікую")))) -> Очікую
D18: 9 | Z18: =IF(COUNTIF(F18:Y18,"=*")>0,IF($C18="К","-"," - "),IF(COUNTIF(F18:Y18,"<4")>0,IF(C18="К","-"," - "),(IFERROR(AVERAGE(F18:Y18),"Очікую")))) -> Очікую
D19: 10 | Z19: =IF(COUNTIF(F19:Y19,"=*")>0,IF($C19="К","-"," - "),IF(COUNTIF(F19:Y19,"<4")>0,IF(C19="К","-"," - "),(IFERROR(AVERAGE(F19:Y19),"Очікую")))) -> Очікую
D20: 11 | Z20: =IF(COUNTIF(F20:Y20,"=*")>0,IF($C20="К","-"," - "),IF(COUNTIF(F20:Y20,"<4")>0,IF(C20="К","-"," - "),(IFERROR(AVERAGE(F20:Y20),"Очікую")))) -> Очікую
D21: 12 | Z21: =IF(COUNTIF(F21:Y21,"=*")>0,IF($C21="К","-"," - "),IF(COUNTIF(F21:Y21,"<4")>0,IF(C21="К","-"," - "),(IFERROR(AVERAGE(F21:Y21),"Очікую")))) -> Очікую
... D109: 100 | Z109: =IF(COUNTIF(F109:Y109,"=*")>0,IF($C109="К","-"," - "),IF(COUNTIF(F109:Y109,"<4")>0,IF(C109="К","-"," - "),(IFERROR(AVERAGE(F109:Y109),"Очікую")))) -> Очікую
E110: Середній бал успішності з дисципліни | F110: =IF(SUM(F10:F109)=0,IF(COUNTA(F10:F109)=0,"Очікую",0),SUM(F10:F109)/$D109) -> Очікую | G110: =IF(SUM(G10:G109)=0,IF(COUNTA(G10:G109)=0,"Очікую",0),SUM(G10:G109)/$D109) -> Очікую | H110: =IF(SUM(H10:H109)=0,IF(COUNTA(H10:H109)=0,"Очікую",0),SUM(H10:H109)/$D109) -> Очікую | I110: =IF(SUM(I10:I109)=0,IF(COUNTA(I10:I109)=0,"Очікую",0),SUM(I10:I109)/$D109) -> Очікую | J110: =IF(SUM(J10:J109)=0,IF(COUNTA(J10:J109)=0,"Очікую",0),SUM(J10:J109)/$D109) -> Очікую | K110: =IF(SUM(K10:K109)=0,IF(COUNTA(K10:K109)=0,"Очікую",0),SUM(K10:K109)/$D109) -> Очікую | L110: =IF(SUM(L10:L109)=0,IF(COUNTA(L10:L109)=0,"Очікую",0),SUM(L10:L109)/$D109) -> Очікую | M110: =IF(SUM(M10:M109)=0,IF(COUNTA(M10:M109)=0,"Очікую",0),SUM(M10:M109)/$D109) -> Очікую | ... Y110: =IF(SUM(Y10:Y109)=0,IF(COUNTA(Y10:Y109)=0,"Очікую",0),SUM(Y10:Y109)/$D109) -> Очікую | Z110: =IFERROR(AVERAGE(F110:Y110),"Очікую") -> Очікую
E111: Абсолютна успішність | F111: =IF(SUM(F10:F109)=0,IF(COUNTA(F10:F109)=0,"Очікую",0),IF(COUNTIF(F10:F109,">=4")=0,0,COUNTIF(F10:F109,">=4")/$D109*100)) -> Очікую | G111: =IF(SUM(G10:G109)=0,IF(COUNTA(G10:G109)=0,"Очікую",0),IF(COUNTIF(G10:G109,">=4")=0,0,COUNTIF(G10:G109,">=4")/$D109*100)) -> Очікую | H111: =IF(SUM(H10:H109)=0,IF(COUNTA(H10:H109)=0,"Очікую",0),IF(COUNTIF(H10:H109,">=4")=0,0,COUNTIF(H10:H109,">=4")/$D109*100)) -> Очікую | I111: =IF(SUM(I10:I109)=0,IF(COUNTA(I10:I109)=0,"Очікую",0),IF(COUNTIF(I10:I109,">=4")=0,0,COUNTIF(I10:I109,">=4")/$D109*100)) -> Очікую | J111: =IF(SUM(J10:J109)=0,IF(COUNTA(J10:J109)=0,"Очікую",0),IF(COUNTIF(J10:J109,">=4")=0,0,COUNTIF(J10:J109,">=4")/$D109*100)) -> Очікую | K111: =IF(SUM(K10:K109)=0,IF(COUNTA(K10:K109)=0,"Очікую",0),IF(COUNTIF(K10:K109,">=4")=0,0,COUNTIF(K10:K109,">=4")/$D109*100)) -> Очікую | L111: =IF(SUM(L10:L109)=0,IF(COUNTA(L10:L109)=0,"Очікую",0),IF(COUNTIF(L10:L109,">=4")=0,0,COUNTIF(L10:L109,">=4")/$D109*100)) -> Очікую | M111: =IF(SUM(M10:M109)=0,IF(COUNTA(M10:M109)=0,"Очікую",0),IF(COUNTIF(M10:M109,">=4")=0,0,COUNTIF(M10:M109,">=4")/$D109*100)) -> Очікую | ... Y111: =IF(SUM(Y10:Y109)=0,IF(COUNTA(Y10:Y109)=0,"Очікую",0),IF(COUNTIF(Y10:Y109,">=4")=0,0,COUNTIF(Y10:Y109,">=4")/$D109*100)) -> Очікую
E112: Якісна успішність | F112: =IF(SUM(F10:F109)=0,IF(COUNTA(F10:F109)=0,"Очікую",0),IF(COUNTIF(F10:F109,">=7")=0,0,COUNTIF(F10:F109,">=7")/$D109*100)) -> Очікую | G112: =IF(SUM(G10:G109)=0,IF(COUNTA(G10:G109)=0,"Очікую",0),IF(COUNTIF(G10:G109,">=7")=0,0,COUNTIF(G10:G109,">=7")/$D109*100)) -> Очікую | H112: =IF(SUM(H10:H109)=0,IF(COUNTA(H10:H109)=0,"Очікую",0),IF(COUNTIF(H10:H109,">=7")=0,0,COUNTIF(H10:H109,">=7")/$D109*100)) -> Очікую | I112: =IF(SUM(I10:I109)=0,IF(COUNTA(I10:I109)=0,"Очікую",0),IF(COUNTIF(I10:I109,">=7")=0,0,COUNTIF(I10:I109,">=7")/$D109*100)) -> Очікую | J112: =IF(SUM(J10:J109)=0,IF(COUNTA(J10:J109)=0,"Очікую",0),IF(COUNTIF(J10:J109,">=7")=0,0,COUNTIF(J10:J109,">=7")/$D109*100)) -> Очікую | K112: =IF(SUM(K10:K109)=0,IF(COUNTA(K10:K109)=0,"Очікую",0),IF(COUNTIF(K10:K109,">=7")=0,0,COUNTIF(K10:K109,">=7")/$D109*100)) -> Очікую | L112: =IF(SUM(L10:L109)=0,IF(COUNTA(L10:L109)=0,"Очікую",0),IF(COUNTIF(L10:L109,">=7")=0,0,COUNTIF(L10:L109,">=7")/$D109*100)) -> Очікую | M112: =IF(SUM(M10:M109)=0,IF(COUNTA(M10:M109)=0,"Очікую",0),IF(COUNTIF(M10:M109,">=7")=0,0,COUNTIF(M10:M109,">=7")/$D109*100)) -> Очікую | ... Y112: =IF(SUM(Y10:Y109)=0,IF(COUNTA(Y10:Y109)=0,"Очікую",0),IF(COUNTIF(Y10:Y109,">=7")=0,0,COUNTIF(Y10:Y109,">=7")/$D109*100)) -> Очікую
E113: Абсолютна успішність по групі | F113: =IFERROR(AVERAGE(F111:Y111),"Очікую") -> Очікую
E114: Якісна успішність по групі | F114: =IFERROR(AVERAGE(F112:Y112),"Очікую") -> Очікую
E115: Кількість бюджетників | F115: =IF(COUNTIF(C10:C109,"=Б")=0,IF(COUNTIF(C10:C109,"=К")=0,"Очікую",0),COUNTIF(C10:C109,"=Б")) -> Очікую
E116: Кількість контрактників | F116: =IF(COUNTIF(C10:C109,"=К")=0,IF(COUNTIF(C10:C109,"=Б")=0,"Очікую",0),COUNTIF(C10:C109,"=К")) -> Очікую | H116: Класний керівник
E117: Кількість соціального контингенту
E118: Вийшли на стипендію | F118: =IF(F115="Очікую","Очікую",IF(F115-COUNTIF(Z10:Z109," - ")<ROUNDDOWN(F115*0.4,0),F115-COUNTIF(Z10:Z109," - "),ROUNDDOWN(F115*0.4,0))) -> Очікую | H118: Завідувач відділення ПЗСО

Sheet ЛЗ2
A1: S
C3: ВІДОКРЕМЛЕНИЙ СТРУКТУРНИЙ ПІДРОЗДІЛ «ФАХОВИЙ КОЛЕДЖ НАФТОГАЗОВИХ ТЕХНОЛОГІЙ, ІНЖЕНЕРІЇ ТА ІНФРАСТРУКТУРИ СЕРВІСУ ОДЕСЬКОГО НАЦІОНАЛЬНОГО ТЕХНОЛОГІЧНОГО УНІВЕРСИТЕТУ»
C4: ЗВЕДЕНА ВІДОМІСТЬ
C5: Успішності студентів спеціальності XXX «XXXXX»
C6: За X семестр XXXX-XXXX н.р.
C7: Група XXXX курс X
C8: Б/К | D8: № п/п | E8: Прізвище, ім’я, по батькові | F8: Підсумкові оцінки дисциплін | Z8: Середній бал
F9: 1 | G9: 2 | H9: 3 | I9: 4 | J9: 5 | K9: 6 | L9: 7 | M9: 8 | N9: 9 | O9: 10 | P9: 11 | Q9: 12 | R9: 13 | S9: 14 | T9: 15 | U9: 16 | V9: 17 | W9: 18 | X9: 19 | Y9: 20
D10: 1 | Z10: =IF(COUNTIF(F10:Y10,"=*")>0,IF($C10="К","-"," - "),IF(COUNTIF(F10:Y10,"<4")>0,IF(C10="К","-"," - "),(IFERROR(AVERAGE(F10:Y10),"Очікую")))) -> Очікую
D11: 2 | Z11: =IF(COUNTIF(F11:Y11,"=*")>0,IF($C11="К","-"," - "),IF(COUNTIF(F11:Y11,"<4")>0,IF(C11="К","-"," - "),(IFERROR(AVERAGE(F11:Y11),"Очікую")))) -> Очікую
D12: 3 | Z12: =IF(COUNTIF(F12:Y12,"=*")>0,IF($C12="К","-"," - "),IF(COUNTIF(F12:Y12,"<4")>0,IF(C12="К","-"," - "),(IFERROR(AVERAGE(F12:Y12),"Очікую")))) -> Очікую
D13: 4 | Z13: =IF(COUNTIF(F13:Y13,"=*")>0,IF($C13="К","-"," - "),IF(COUNTIF(F13:Y13,"<4")>0,IF(C13="К","-"," - "),(IFERROR(AVERAGE(F13:Y13),"Очікую")))) -> Очікую
D14: 5 | Z14: =IF(COUNTIF(F14:Y14,"=*")>0,IF($C14="К","-"," - "),IF(COUNTIF(F14:Y14,"<4")>0,IF(C14="К","-"," - "),(IFERROR(AVERAGE(F14:Y14),"Очікую")))) -> Очікую
D15: 6 | Z15: =IF(COUNTIF(F15:Y15,"=*")>0,IF($C15="К","-"," - "),IF(COUNTIF(F15:Y15,"<4")>0,IF(C15="К","-"," - "),(IFERROR(AVERAGE(F15:Y15),"Очікую")))) -> Очікую
D16: 7 | Z16: =IF(COUNTIF(F16:Y16,"=*")>0,IF($C16="К","-"," - "),IF(COUNTIF(F16:Y16,"<4")>0,IF(C16="К","-"," - "),(IFERROR(AVERAGE(F16:Y16),"Очікую")))) -> Очікую
D17: 8 | Z17: =IF(COUNTIF(F17:Y17,"=*")>0,IF($C17="К","-"," - "),IF(COUNTIF(F17:Y17,"<4")>0,IF(C17="К","-"," - "),(IFERROR(AVERAGE(F17:Y17),"Очікую")))) -> Очікую
D18: 9 | Z18: =IF(COUNTIF(F18:Y18,"=*")>0,IF($C18="К","-"," - "),IF(COUNTIF(F18:Y18,"<4")>0,IF(C18="К","-"," - "),(IFERROR(AVERAGE(F18:Y18),"Очікую")))) -> Очікую
D19: 10 | Z19: =IF(COUNTIF(F19:Y19,"=*")>0,IF($C19="К","-"," - "),IF(COUNTIF(F19:Y19,"<4")>0,IF(C19="К","-"," - "),(IFERROR(AVERAGE(F19:Y19),"Очікую")))) -> Очікую
D20: 11 | Z20: =IF(COUNTIF(F20:Y20,"=*")>0,IF($C20="К","-"," - "),IF(COUNTIF(F20:Y20,"<4")>0,IF(C20="К","-"," - "),(IFERROR(AVERAGE(F20:Y20),"Очікую")))) -> Очікую
D21: 12 | Z21: =IF(COUNTIF(F21:Y21,"=*")>0,IF($C21="К","-"," - "),IF(COUNTIF(F21:Y21,"<4")>0,IF(C21="К","-"," - "),(IFERROR(AVERAGE(F21:Y21),"Очікую")))) -> Очікую
... D109: 100 | Z109: =IF(COUNTIF(F109:Y109,"=*")>0,IF($C109="К","-"," - "),IF(COUNTIF(F109:Y109,"<4")>0,IF(C109="К","-"," - "),(IFERROR(AVERAGE(F109:Y109),"Очікую")))) -> Очікую
E110: Середній бал успішності з дисципліни | F110: =IF(SUM(F10:F109)=0,IF(COUNTA(F10:F109)=0,"Очікую",0),SUM(F10:F109)/$D109) -> Очікую | G110: =IF(SUM(G10:G109)=0,IF(COUNTA(G10:G109)=0,"Очікую",0),SUM(G10:G109)/$D109) -> Очікую | H110: =IF(SUM(H10:H109)=0,IF(COUNTA(H10:H109)=0,"Очікую",0),SUM(H10:H109)/$D109) -> Очікую | I110: =IF(SUM(I10:I109)=0,IF(COUNTA(I10:I109)=0,"Очікую",0),SUM(I10:I109)/$D109) -> Очікую | J110: =IF(SUM(J10:J109)=0,IF(COUNTA(J10:J109)=0,"Очікую",0),SUM(J10:J109)/$D109) -> Очікую | K110: =IF(SUM(K10:K109)=0,IF(COUNTA(K10:K109)=0,"Очікую",0),SUM(K10:K109)/$D109) -> Очікую | L110: =IF(SUM(L10:L109)=0,IF(COUNTA(L10:L109)=0,"Очікую",0),SUM(L10:L109)/$D109) -> Очікую | M110: =IF(SUM(M10:M109)=0,IF(COUNTA(M10:M109)=0,"Очікую",0),SUM(M10:M109)/$D109) -> Очікую | ... Y110: =IF(SUM(Y10:Y109)=0,IF(COUNTA(Y10:Y109)=0,"Очікую",0),SUM(Y10:Y109)/$D109) -> Очікую | Z110: =IFERROR(AVERAGE(F110:Y110),"Очікую") -> Очікую
E111: Абсолютна успішність | F111: =IF(SUM(F10:F109)=0,IF(COUNTA(F10:F109)=0,"Очікую",0),IF(COUNTIF(F10:F109,">=4")=0,0,COUNTIF(F10:F109,">=4")/$D109*100)) -> Очікую | G111: =IF(SUM(G10:G109)=0,IF(COUNTA(G10:G109)=0,"Очікую",0),IF(COUNTIF(G10:G109,">=4")=0,0,COUNTIF(G10:G109,">=4")/$D109*100)) -> Очікую | H111: =IF(SUM(H10:H109)=0,IF(COUNTA(H10:H109)=0,"Очікую",0),IF(COUNTIF(H10:H109,">=4")=0,0,COUNTIF(H10:H109,">=4")/$D109*100)) -> Очікую | I111: =IF(SUM(I10:I109)=0,IF(COUNTA(I10:I109)=0,"Очікую",0),IF(COUNTIF(I10:I109,">=4")=0,0,COUNTIF(I10:I109,">=4")/$D109*100)) -> Очікую | J111: =IF(SUM(J10:J109)=0,IF(COUNTA(J10:J109)=0,"Очікую",0),IF(COUNTIF(J10:J109,">=4")=0,0,COUNTIF(J10:J109,">=4")/$D109*100)) -> Очікую | K111: =IF(SUM(K10:K109)=0,IF(COUNTA(K10:K109)=0,"Очікую",0),IF(COUNTIF(K10:K109,">=4")=0,0,COUNTIF(K10:K109,">=4")/$D109*100)) -> Очікую | L111: =IF(SUM(L10:L109)=0,IF(COUNTA(L10:L109)=0,"Очікую",0),IF(COUNTIF(L10:L109,">=4")=0,0,COUNTIF(L10:L109,">=4")/$D109*100)) -> Очікую | M111: =IF(SUM(M10:M109)=0,IF(COUNTA(M10:M109)=0,"Очікую",0),IF(COUNTIF(M10:M109,">=4")=0,0,COUNTIF(M10:M109,">=4")/$D109*100)) -> Очікую | ... Y111: =IF(SUM(Y10:Y109)=0,IF(COUNTA(Y10:Y109)=0,"Очікую",0),IF(COUNTIF(Y10:Y109,">=4")=0,0,COUNTIF(Y10:Y109,">=4")/$D109*100)) -> Очікую
E112: Якісна успішність | F112: =IF(SUM(F10:F109)=0,IF(COUNTA(F10:F109)=0,"Очікую",0),IF(COUNTIF(F10:F109,">=7")=0,0,COUNTIF(F10:F109,">=7")/$D109*100)) -> Очікую | G112: =IF(SUM(G10:G109)=0,IF(COUNTA(G10:G109)=0,"Очікую",0),IF(COUNTIF(G10:G109,">=7")=0,0,COUNTIF(G10:G109,">=7")/$D109*100)) -> Очікую | H112: =IF(SUM(H10:H109)=0,IF(COUNTA(H10:H109)=0,"Очікую",0),IF(COUNTIF(H10:H109,">=7")=0,0,COUNTIF(H10:H109,">=7")/$D109*100)) -> Очікую | I112: =IF(SUM(I10:I109)=0,IF(COUNTA(I10:I109)=0,"Очікую",0),IF(COUNTIF(I10:I109,">=7")=0,0,COUNTIF(I10:I109,">=7")/$D109*100)) -> Очікую | J112: =IF(SUM(J10:J109)=0,IF(COUNTA(J10:J109)=0,"Очікую",0),IF(COUNTIF(J10:J109,">=7")=0,0,COUNTIF(J10:J109,">=7")/$D109*100)) -> Очікую | K112: =IF(SUM(K10:K109)=0,IF(COUNTA(K10:K109)=0,"Очікую",0),IF(COUNTIF(K10:K109,">=7")=0,0,COUNTIF(K10:K109,">=7")/$D109*100)) -> Очікую | L112: =IF(SUM(L10:L109)=0,IF(COUNTA(L10:L109)=0,"Очікую",0),IF(COUNTIF(L10:L109,">=7")=0,0,COUNTIF(L10:L109,">=7")/$D109*100)) -> Очікую | M112: =IF(SUM(M10:M109)=0,IF(COUNTA(M10:M109)=0,"Очікую",0),IF(COUNTIF(M10:M109,">=7")=0,0,COUNTIF(M10:M109,">=7")/$D109*100)) -> Очікую | ... Y112: =IF(SUM(Y10:Y109)=0,IF(COUNTA(Y10:Y109)=0,"Очікую",0),IF(COUNTIF(Y10:Y109,">=7")=0,0,COUNTIF(Y10:Y109,">=7")/$D109*100)) -> Очікую
E113: Абсолютна успішність по групі | F113: =IFERROR(AVERAGE(F111:Y111),"Очікую") -> Очікую
E114: Якісна успішність по групі | F114: =IFERROR(AVERAGE(F112:Y112),"Очікую") -> Очікую
E115: Кількість бюджетників | F115: =IF(COUNTIF(C10:C109,"=Б")=0,IF(COUNTIF(C10:C109,"=К")=0,"Очікую",0),COUNTIF(C10:C109,"=Б")) -> Очікую
E116: Кількість контрактників | F116: =IF(COUNTIF(C10:C109,"=К")=0,IF(COUNTIF(C10:C109,"=Б")=0,"Очікую",0),COUNTIF(C10:C109,"=К")) -> Очікую | H116: Класний керівник
E117: Кількість соціального контингенту
E118: Вийшли на стипендію | F118: =IF(F115="Очікую","Очікую",IF(F115-COUNTIF(Z10:Z109," - ")<ROUNDDOWN(F115*0.4,0),F115-COUNTIF(Z10:Z109," - "),ROUNDDOWN(F115*0.4,0))) -> Очікую | H118: Завідувач відділення ПЗСО

Sheet ЛЗ3
A1: S
C3: ВІДОКРЕМЛЕНИЙ СТРУКТУРНИЙ ПІДРОЗДІЛ «ФАХОВИЙ КОЛЕДЖ НАФТОГАЗОВИХ ТЕХНОЛОГІЙ, ІНЖЕНЕРІЇ ТА ІНФРАСТРУКТУРИ СЕРВІСУ ОДЕСЬКОГО НАЦІОНАЛЬНОГО ТЕХНОЛОГІЧНОГО УНІВЕРСИТЕТУ»
C4: ЗВЕДЕНА ВІДОМІСТЬ
C5: Успішності студентів спеціальності XXX «XXXXX»
C6: За X семестр XXXX-XXXX н.р.
C7: Група XXXX курс X
C8: Б/К | D8: № п/п | E8: Прізвище, ім’я, по батькові | F8: Підсумкові оцінки дисциплін | Z8: Середній бал
F9: 1 | G9: 2 | H9: 3 | I9: 4 | J9: 5 | K9: 6 | L9: 7 | M9: 8 | N9: 9 | O9: 10 | P9: 11 | Q9: 12 | R9: 13 | S9: 14 | T9: 15 | U9: 16 | V9: 17 | W9: 18 | X9: 19 | Y9: 20
D10: 1 | Z10: =IF(COUNTIF(F10:Y10,"=*")>0,IF($C10="К","-"," - "),IF(COUNTIF(F10:Y10,"<4")>0,IF(C10="К","-"," - "),(IFERROR(AVERAGE(F10:Y10),"Очікую")))) -> Очікую
D11: 2 | Z11: =IF(COUNTIF(F11:Y11,"=*")>0,IF($C11="К","-"," - "),IF(COUNTIF(F11:Y11,"<4")>0,IF(C11="К","-"," - "),(IFERROR(AVERAGE(F11:Y11),"Очікую")))) -> Очікую
D12: 3 | Z12: =IF(COUNTIF(F12:Y12,"=*")>0,IF($C12="К","-"," - "),IF(COUNTIF(F12:Y12,"<4")>0,IF(C12="К","-"," - "),(IFERROR(AVERAGE(F12:Y12),"Очікую")))) -> Очікую
D13: 4 | Z13: =IF(COUNTIF(F13:Y13,"=*")>0,IF($C13="К","-"," - "),IF(COUNTIF(F13:Y13,"<4")>0,IF(C13="К","-"," - "),(IFERROR(AVERAGE(F13:Y13),"Очікую")))) -> Очікую
D14: 5 | Z14: =IF(COUNTIF(F14:Y14,"=*")>0,IF($C14="К","-"," - "),IF(COUNTIF(F14:Y14,"<4")>0,IF(C14="К","-"," - "),(IFERROR(AVERAGE(F14:Y14),"Очікую")))) -> Очікую
D15: 6 | Z15: =IF(COUNTIF(F15:Y15,"=*")>0,IF($C15="К","-"," - "),IF(COUNTIF(F15:Y15,"<4")>0,IF(C15="К","-"," - "),(IFERROR(AVERAGE(F15:Y15),"Очікую")))) -> Очікую
D16: 7 | Z16: =IF(COUNTIF(F16:Y16,"=*")>0,IF($C16="К","-"," - "),IF(COUNTIF(F16:Y16,"<4")>0,IF(C16="К","-"," - "),(IFERROR(AVERAGE(F16:Y16),"Очікую")))) -> Очікую
D17: 8 | Z17: =IF(COUNTIF(F17:Y17,"=*")>0,IF($C17="К","-"," - "),IF(COUNTIF(F17:Y17,"<4")>0,IF(C17="К","-"," - "),(IFERROR(AVERAGE(F17:Y17),"Очікую")))) -> Очікую
D18: 9 | Z18: =IF(COUNTIF(F18:Y18,"=*")>0,IF($C18="К","-"," - "),IF(COUNTIF(F18:Y18,"<4")>0,IF(C18="К","-"," - "),(IFERROR(AVERAGE(F18:Y18),"Очікую")))) -> Очікую
D19: 10 | Z19: =IF(COUNTIF(F19:Y19,"=*")>0,IF($C19="К","-"," - "),IF(COUNTIF(F19:Y19,"<4")>0,IF(C19="К","-"," - "),(IFERROR(AVERAGE(F19:Y19),"Очікую")))) -> Очікую
D20: 11 | Z20: =IF(COUNTIF(F20:Y20,"=*")>0,IF($C20="К","-"," - "),IF(COUNTIF(F20:Y20,"<4")>0,IF(C20="К","-"," - "),(IFERROR(AVERAGE(F20:Y20),"Очікую")))) -> Очікую
D21: 12 | Z21: =IF(COUNTIF(F21:Y21,"=*")>0,IF($C21="К","-"," - "),IF(COUNTIF(F21:Y21,"<4")>0,IF(C21="К","-"," - "),(IFERROR(AVERAGE(F21:Y21),"Очікую")))) -> Очікую
... D109: 100 | Z109: =IF(COUNTIF(F109:Y109,"=*")>0,IF($C109="К","-"," - "),IF(COUNTIF(F109:Y109,"<4")>0,IF(C109="К","-"," - "),(IFERROR(AVERAGE(F109:Y109),"Очікую")))) -> Очікую
E110: Середній бал успішності з дисципліни | F110: =IF(SUM(F10:F109)=0,IF(COUNTA(F10:F109)=0,"Очікую",0),SUM(F10:F109)/$D109) -> Очікую | G110: =IF(SUM(G10:G109)=0,IF(COUNTA(G10:G109)=0,"Очікую",0),SUM(G10:G109)/$D109) -> Очікую | H110: =IF(SUM(H10:H109)=0,IF(COUNTA(H10:H109)=0,"Очікую",0),SUM(H10:H109)/$D109) -> Очікую | I110: =IF(SUM(I10:I109)=0,IF(COUNTA(I10:I109)=0,"Очікую",0),SUM(I10:I109)/$D109) -> Очікую | J110: =IF(SUM(J10:J109)=0,IF(COUNTA(J10:J109)=0,"Очікую",0),SUM(J10:J109)/$D109) -> Очікую | K110: =IF(SUM(K10:K109)=0,IF(COUNTA(K10:K109)=0,"Очікую",0),SUM(K10:K109)/$D109) -> Очікую | L110: =IF(SUM(L10:L109)=0,IF(COUNTA(L10:L109)=0,"Очікую",0),SUM(L10:L109)/$D109) -> Очікую | M110: =IF(SUM(M10:M109)=0,IF(COUNTA(M10:M109)=0,"Очікую",0),SUM(M10:M109)/$D109) -> Очікую | ... Y110: =IF(SUM(Y10:Y109)=0,IF(COUNTA(Y10:Y109)=0,"Очікую",0),SUM(Y10:Y109)/$D109) -> Очікую | Z110: =IFERROR(AVERAGE(F110:Y110),"Очікую") -> Очікую
E111: Абсолютна успішність | F111: =IF(SUM(F10:F109)=0,IF(COUNTA(F10:F109)=0,"Очікую",0),IF(COUNTIF(F10:F109,">=4")=0,0,COUNTIF(F10:F109,">=4")/$D109*100)) -> Очікую | G111: =IF(SUM(G10:G109)=0,IF(COUNTA(G10:G109)=0,"Очікую",0),IF(COUNTIF(G10:G109,">=4")=0,0,COUNTIF(G10:G109,">=4")/$D109*100)) -> Очікую | H111: =IF(SUM(H10:H109)=0,IF(COUNTA(H10:H109)=0,"Очікую",0),IF(COUNTIF(H10:H109,">=4")=0,0,COUNTIF(H10:H109,">=4")/$D109*100)) -> Очікую | I111: =IF(SUM(I10:I109)=0,IF(COUNTA(I10:I109)=0,"Очікую",0),IF(COUNTIF(I10:I109,">=4")=0,0,COUNTIF(I10:I109,">=4")/$D109*100)) -> Очікую | J111: =IF(SUM(J10:J109)=0,IF(COUNTA(J10:J109)=0,"Очікую",0),IF(COUNTIF(J10:J109,">=4")=0,0,COUNTIF(J10:J109,">=4")/$D109*100)) -> Очікую | K111: =IF(SUM(K10:K109)=0,IF(COUNTA(K10:K109)=0,"Очікую",0),IF(COUNTIF(K10:K109,">=4")=0,0,COUNTIF(K10:K109,">=4")/$D109*100)) -> Очікую | L111: =IF(SUM(L10:L109)=0,IF(COUNTA(L10:L109)=0,"Очікую",0),IF(COUNTIF(L10:L109,">=4")=0,0,COUNTIF(L10:L109,">=4")/$D109*100)) -> Очікую | M111: =IF(SUM(M10:M109)=0,IF(COUNTA(M10:M109)=0,"Очікую",0),IF(COUNTIF(M10:M109,">=4")=0,0,COUNTIF(M10:M109,">=4")/$D109*100)) -> Очікую | ... Y111: =IF(SUM(Y10:Y109)=0,IF(COUNTA(Y10:Y109)=0,"Очікую",0),IF(COUNTIF(Y10:Y109,">=4")=0,0,COUNTIF(Y10:Y109,">=4")/$D109*100)) -> Очікую
E112: Якісна успішність | F112: =IF(SUM(F10:F109)=0,IF(COUNTA(F10:F109)=0,"Очікую",0),IF(COUNTIF(F10:F109,">=7")=0,0,COUNTIF(F10:F109,">=7")/$D109*100)) -> Очікую | G112: =IF(SUM(G10:G109)=0,IF(COUNTA(G10:G109)=0,"Очікую",0),IF(COUNTIF(G10:G109,">=7")=0,0,COUNTIF(G10:G109,">=7")/$D109*100)) -> Очікую | H112: =IF(SUM(H10:H109)=0,IF(COUNTA(H10:H109)=0,"Очікую",0),IF(COUNTIF(H10:H109,">=7")=0,0,COUNTIF(H10:H109,">=7")/$D109*100)) -> Очікую | I112: =IF(SUM(I10:I109)=0,IF(COUNTA(I10:I109)=0,"Очікую",0),IF(COUNTIF(I10:I109,">=7")=0,0,COUNTIF(I10:I109,">=7")/$D109*100)) -> Очікую | J112: =IF(SUM(J10:J109)=0,IF(COUNTA(J10:J109)=0,"Очікую",0),IF(COUNTIF(J10:J109,">=7")=0,0,COUNTIF(J10:J109,">=7")/$D109*100)) -> Очікую | K112: =IF(SUM(K10:K109)=0,IF(COUNTA(K10:K109)=0,"Очікую",0),IF(COUNTIF(K10:K109,">=7")=0,0,COUNTIF(K10:K109,">=7")/$D109*100)) -> Очікую | L112: =IF(SUM(L10:L109)=0,IF(COUNTA(L10:L109)=0,"Очікую",0),IF(COUNTIF(L10:L109,">=7")=0,0,COUNTIF(L10:L109,">=7")/$D109*100)) -> Очікую | M112: =IF(SUM(M10:M109)=0,IF(COUNTA(M10:M109)=0,"Очікую",0),IF(COUNTIF(M10:M109,">=7")=0,0,COUNTIF(M10:M109,">=7")/$D109*100)) -> Очікую | ... Y112: =IF(SUM(Y10:Y109)=0,IF(COUNTA(Y10:Y109)=0,"Очікую",0),IF(COUNTIF(Y10:Y109,">=7")=0,0,COUNTIF(Y10:Y109,">=7")/$D109*100)) -> Очікую
E113: Абсолютна успішність по групі | F113: =IFERROR(AVERAGE(F111:Y111),"Очікую") -> Очікую
E114: Якісна успішність по групі | F114: =IFERROR(AVERAGE(F112:Y112),"Очікую") -> Очікую
E115: Кількість бюджетників | F115: =IF(COUNTIF(C10:C109,"=Б")=0,IF(COUNTIF(C10:C109,"=К")=0,"Очікую",0),COUNTIF(C10:C109,"=Б")) -> Очікую
E116: Кількість контрактників | F116: =IF(COUNTIF(C10:C109,"=К")=0,IF(COUNTIF(C10:C109,"=Б")=0,"Очікую",0),COUNTIF(C10:C109,"=К")) -> Очікую | H116: Класний керівник
E117: Кількість соціального контингенту
E118: Вийшли на стипендію | F118: =IF(F115="Очікую","Очікую",IF(F115-COUNTIF(Z10:Z109," - ")<ROUNDDOWN(F115*0.4,0),F115-COUNTIF(Z10:Z109," - "),ROUNDDOWN(F115*0.4,0))) -> Очікую | H118: Завідувач відділення ПЗСО

Sheet ЛЗ4
A1: S
C3: ВІДОКРЕМЛЕНИЙ СТРУКТУРНИЙ ПІДРОЗДІЛ «ФАХОВИЙ КОЛЕДЖ НАФТОГАЗОВИХ ТЕХНОЛОГІЙ, ІНЖЕНЕРІЇ ТА ІНФРАСТРУКТУРИ СЕРВІСУ ОДЕСЬКОГО НАЦІОНАЛЬНОГО ТЕХНОЛОГІЧНОГО УНІВЕРСИТЕТУ»
C4: ЗВЕДЕНА ВІДОМІСТЬ
C5: Успішності студентів спеціальності XXX «XXXXX»
C6: За X семестр XXXX-XXXX н.р.
C7: Група XXXX курс X
C8: Б/К | D8: № п/п | E8: Прізвище, ім’я, по батькові | F8: Підсумкові оцінки дисциплін | Z8: Середній бал
F9: 1 | G9: 2 | H9: 3 | I9: 4 | J9: 5 | K9: 6 | L9: 7 | M9: 8 | N9: 9 | O9: 10 | P9: 11 | Q9: 12 | R9: 13 | S9: 14 | T9: 15 | U9: 16 | V9: 17 | W9: 18 | X9: 19 | Y9: 20
D10: 1 | Z10: =IF(COUNTIF(F10:Y10,"=*")>0,IF($C10="К","-"," - "),IF(COUNTIF(F10:Y10,"<4")>0,IF(C10="К","-"," - "),(IFERROR(AVERAGE(F10:Y10),"Очікую")))) -> Очікую
D11: 2 | Z11: =IF(COUNTIF(F11:Y11,"=*")>0,IF($C11="К","-"," - "),IF(COUNTIF(F11:Y11,"<4")>0,IF(C11="К","-"," - "),(IFERROR(AVERAGE(F11:Y11),"Очікую")))) -> Очікую
D12: 3 | Z12: =IF(COUNTIF(F12:Y12,"=*")>0,IF($C12="К","-"," - "),IF(COUNTIF(F12:Y12,"<4")>0,IF(C12="К","-"," - "),(IFERROR(AVERAGE(F12:Y12),"Очікую")))) -> Очікую
D13: 4 | Z13: =IF(COUNTIF(F13:Y13,"=*")>0,IF($C13="К","-"," - "),IF(COUNTIF(F13:Y13,"<4")>0,IF(C13="К","-"," - "),(IFERROR(AVERAGE(F13:Y13),"Очікую")))) -> Очікую
D14: 5 | Z14: =IF(COUNTIF(F14:Y14,"=*")>0,IF($C14="К","-"," - "),IF(COUNTIF(F14:Y14,"<4")>0,IF(C14="К","-"," - "),(IFERROR(AVERAGE(F14:Y14),"Очікую")))) -> Очікую
D15: 6 | Z15: =IF(COUNTIF(F15:Y15,"=*")>0,IF($C15="К","-"," - "),IF(COUNTIF(F15:Y15,"<4")>0,IF(C15="К","-"," - "),(IFERROR(AVERAGE(F15:Y15),"Очікую")))) -> Очікую
D16: 7 | Z16: =IF(COUNTIF(F16:Y16,"=*")>0,IF($C16="К","-"," - "),IF(COUNTIF(F16:Y16,"<4")>0,IF(C16="К","-"," - "),(IFERROR(AVERAGE(F16:Y16),"Очікую")))) -> Очікую
D17: 8 | Z17: =IF(COUNTIF(F17:Y17,"=*")>0,IF($C17="К","-"," - "),IF(COUNTIF(F17:Y17,"<4")>0,IF(C17="К","-"," - "),(IFERROR(AVERAGE(F17:Y17),"Очікую")))) -> Очікую
D18: 9 | Z18: =IF(COUNTIF(F18:Y18,"=*")>0,IF($C18="К","-"," - "),IF(COUNTIF(F18:Y18,"<4")>0,IF(C18="К","-"," - "),(IFERROR(AVERAGE(F18:Y18),"Очікую")))) -> Очікую
D19: 10 | Z19: =IF(COUNTIF(F19:Y19,"=*")>0,IF($C19="К","-"," - "),IF(COUNTIF(F19:Y19,"<4")>0,IF(C19="К","-"," - "),(IFERROR(AVERAGE(F19:Y19),"Очікую")))) -> Очікую
D20: 11 | Z20: =IF(COUNTIF(F20:Y20,"=*")>0,IF($C20="К","-"," - "),IF(COUNTIF(F20:Y20,"<4")>0,IF(C20="К","-"," - "),(IFERROR(AVERAGE(F20:Y20),"Очікую")))) -> Очікую
D21: 12 | Z21: =IF(COUNTIF(F21:Y21,"=*")>0,IF($C21="К","-"," - "),IF(COUNTIF(F21:Y21,"<4")>0,IF(C21="К","-"," - "),(IFERROR(AVERAGE(F21:Y21),"Очікую")))) -> Очікую
... D109: 100 | Z109: =IF(COUNTIF(F109:Y109,"=*")>0,IF($C109="К","-"," - "),IF(COUNTIF(F109:Y109,"<4")>0,IF(C109="К","-"," - "),(IFERROR(AVERAGE(F109:Y109),"Очікую")))) -> Очікую
E110: Середній бал успішності з дисципліни | F110: =IF(SUM(F10:F109)=0,IF(COUNTA(F10:F109)=0,"Очікую",0),SUM(F10:F109)/$D109) -> Очікую | G110: =IF(SUM(G10:G109)=0,IF(COUNTA(G10:G109)=0,"Очікую",0),SUM(G10:G109)/$D109) -> Очікую | H110: =IF(SUM(H10:H109)=0,IF(COUNTA(H10:H109)=0,"Очікую",0),SUM(H10:H109)/$D109) -> Очікую | I110: =IF(SUM(I10:I109)=0,IF(COUNTA(I10:I109)=0,"Очікую",0),SUM(I10:I109)/$D109) -> Очікую | J110: =IF(SUM(J10:J109)=0,IF(COUNTA(J10:J109)=0,"Очікую",0),SUM(J10:J109)/$D109) -> Очікую | K110: =IF(SUM(K10:K109)=0,IF(COUNTA(K10:K109)=0,"Очікую",0),SUM(K10:K109)/$D109) -> Очікую | L110: =IF(SUM(L10:L109)=0,IF(COUNTA(L10:L109)=0,"Очікую",0),SUM(L10:L109)/$D109) -> Очікую | M110: =IF(SUM(M10:M109)=0,IF(COUNTA(M10:M109)=0,"Очікую",0),SUM(M10:M109)/$D109) -> Очікую | ... Y110: =IF(SUM(Y10:Y109)=0,IF(COUNTA(Y10:Y109)=0,"Очікую",0),SUM(Y10:Y109)/$D109) -> Очікую | Z110: =IFERROR(AVERAGE(F110:Y110),"Очікую") -> Очікую
E111: Абсолютна успішність | F111: =IF(SUM(F10:F109)=0,IF(COUNTA(F10:F109)=0,"Очікую",0),IF(COUNTIF(F10:F109,">=4")=0,0,COUNTIF(F10:F109,">=4")/$D109*100)) -> Очікую | G111: =IF(SUM(G10:G109)=0,IF(COUNTA(G10:G109)=0,"Очікую",0),IF(COUNTIF(G10:G109,">=4")=0,0,COUNTIF(G10:G109,">=4")/$D109*100)) -> Очікую | H111: =IF(SUM(H10:H109)=0,IF(COUNTA(H10:H109)=0,"Очікую",0),IF(COUNTIF(H10:H109,">=4")=0,0,COUNTIF(H10:H109,">=4")/$D109*100)) -> Очікую | I111: =IF(SUM(I10:I109)=0,IF(COUNTA(I10:I109)=0,"Очікую",0),IF(COUNTIF(I10:I109,">=4")=0,0,COUNTIF(I10:I109,">=4")/$D109*100)) -> Очікую | J111: =IF(SUM(J10:J109)=0,IF(COUNTA(J10:J109)=0,"Очікую",0),IF(COUNTIF(J10:J109,">=4")=0,0,COUNTIF(J10:J109,">=4")/$D109*100)) -> Очікую | K111: =IF(SUM(K10:K109)=0,IF(COUNTA(K10:K109)=0,"Очікую",0),IF(COUNTIF(K10:K109,">=4")=0,0,COUNTIF(K10:K109,">=4")/$D109*100)) -> Очікую | L111: =IF(SUM(L10:L109)=0,IF(COUNTA(L10:L109)=0,"Очікую",0),IF(COUNTIF(L10:L109,">=4")=0,0,COUNTIF(L10:L109,">=4")/$D109*100)) -> Очікую | M111: =IF(SUM(M10:M109)=0,IF(COUNTA(M10:M109)=0,"Очікую",0),IF(COUNTIF(M10:M109,">=4")=0,0,COUNTIF(M10:M109,">=4")/$D109*100)) -> Очікую | ... Y111: =IF(SUM(Y10:Y109)=0,IF(COUNTA(Y10:Y109)=0,"Очікую",0),IF(COUNTIF(Y10:Y109,">=4")=0,0,COUNTIF(Y10:Y109,">=4")/$D109*100)) -> Очікую
E112: Якісна успішність | F112: =IF(SUM(F10:F109)=0,IF(COUNTA(F10:F109)=0,"Очікую",0),IF(COUNTIF(F10:F109,">=7")=0,0,COUNTIF(F10:F109,">=7")/$D109*100)) -> Очікую | G112: =IF(SUM(G10:G109)=0,IF(COUNTA(G10:G109)=0,"Очікую",0),IF(COUNTIF(G10:G109,">=7")=0,0,COUNTIF(G10:G109,">=7")/$D109*100)) -> Очікую | H112: =IF(SUM(H10:H109)=0,IF(COUNTA(H10:H109)=0,"Очікую",0),IF(COUNTIF(H10:H109,">=7")=0,0,COUNTIF(H10:H109,">=7")/$D109*100)) -> Очікую | I112: =IF(SUM(I10:I109)=0,IF(COUNTA(I10:I109)=0,"Очікую",0),IF(COUNTIF(I10:I109,">=7")=0,0,COUNTIF(I10:I109,">=7")/$D109*100)) -> Очікую | J112: =IF(SUM(J10:J109)=0,IF(COUNTA(J10:J109)=0,"Очікую",0),IF(COUNTIF(J10:J109,">=7")=0,0,COUNTIF(J10:J109,">=7")/$D109*100)) -> Очікую | K112: =IF(SUM(K10:K109)=0,IF(COUNTA(K10:K109)=0,"Очікую",0),IF(COUNTIF(K10:K109,">=7")=0,0,COUNTIF(K10:K109,">=7")/$D109*100)) -> Очікую | L112: =IF(SUM(L10:L109)=0,IF(COUNTA(L10:L109)=0,"Очікую",0),IF(COUNTIF(L10:L109,">=7")=0,0,COUNTIF(L10:L109,">=7")/$D109*100)) -> Очікую | M112: =IF(SUM(M10:M109)=0,IF(COUNTA(M10:M109)=0,"Очікую",0),IF(COUNTIF(M10:M109,">=7")=0,0,COUNTIF(M10:M109,">=7")/$D109*100)) -> Очікую | ... Y112: =IF(SUM(Y10:Y109)=0,IF(COUNTA(Y10:Y109)=0,"Очікую",0),IF(COUNTIF(Y10:Y109,">=7")=0,0,COUNTIF(Y10:Y109,">=7")/$D109*100)) -> Очікую
E113: Абсолютна успішність по групі | F113: =IFERROR(AVERAGE(F111:Y111),"Очікую") -> Очікую
E114: Якісна успішність по групі | F114: =IFERROR(AVERAGE(F112:Y112),"Очікую") -> Очікую
E115: Кількість бюджетників | F115: =IF(COUNTIF(C10:C109,"=Б")=0,IF(COUNTIF(C10:C109,"=К")=0,"Очікую",0),COUNTIF(C10:C109,"=Б")) -> Очікую
E116: Кількість контрактників | F116: =IF(COUNTIF(C10:C109,"=К")=0,IF(COUNTIF(C10:C109,"=Б")=0,"Очікую",0),COUNTIF(C10:C109,"=К")) -> Очікую | H116: Класний керівник
E117: Кількість соціального контингенту
E118: Вийшли на стипендію | F118: =IF(F115="Очікую","Очікую",IF(F115-COUNTIF(Z10:Z109," - ")<ROUNDDOWN(F115*0.4,0),F115-COUNTIF(Z10:Z109," - "),ROUNDDOWN(F115*0.4,0))) -> Очікую | H118: Завідувач відділення ПЗСО

Sheet ЛЗ5
A1: S
C3: ВІДОКРЕМЛЕНИЙ СТРУКТУРНИЙ ПІДРОЗДІЛ «ФАХОВИЙ КОЛЕДЖ НАФТОГАЗОВИХ ТЕХНОЛОГІЙ, ІНЖЕНЕРІЇ ТА ІНФРАСТРУКТУРИ СЕРВІСУ ОДЕСЬКОГО НАЦІОНАЛЬНОГО ТЕХНОЛОГІЧНОГО УНІВЕРСИТЕТУ»
C4: ЗВЕДЕНА ВІДОМІСТЬ
C5: Успішності студентів спеціальності XXX «XXXXX»
C6: За X семестр XXXX-XXXX н.р.
C7: Група XXXX курс X
C8: Б/К | D8: № п/п | E8: Прізвище, ім’я, по батькові | F8: Підсумкові оцінки дисциплін | Z8: Середній бал
F9: 1 | G9: 2 | H9: 3 | I9: 4 | J9: 5 | K9: 6 | L9: 7 | M9: 8 | N9: 9 | O9: 10 | P9: 11 | Q9: 12 | R9: 13 | S9: 14 | T9: 15 | U9: 16 | V9: 17 | W9: 18 | X9: 19 | Y9: 20
D10: 1 | Z10: =IF(COUNTIF(F10:Y10,"=*")>0,IF($C10="К","-"," - "),IF(COUNTIF(F10:Y10,"<4")>0,IF(C10="К","-"," - "),(IFERROR(AVERAGE(F10:Y10),"Очікую")))) -> Очікую
D11: 2 | Z11: =IF(COUNTIF(F11:Y11,"=*")>0,IF($C11="К","-"," - "),IF(COUNTIF(F11:Y11,"<4")>0,IF(C11="К","-"," - "),(IFERROR(AVERAGE(F11:Y11),"Очікую")))) -> Очікую
D12: 3 | Z12: =IF(COUNTIF(F12:Y12,"=*")>0,IF($C12="К","-"," - "),IF(COUNTIF(F12:Y12,"<4")>0,IF(C12="К","-"," - "),(IFERROR(AVERAGE(F12:Y12),"Очікую")))) -> Очікую
D13: 4 | Z13: =IF(COUNTIF(F13:Y13,"=*")>0,IF($C13="К","-"," - "),IF(COUNTIF(F13:Y13,"<4")>0,IF(C13="К","-"," - "),(IFERROR(AVERAGE(F13:Y13),"Очікую")))) -> Очікую
D14: 5 | Z14: =IF(COUNTIF(F14:Y14,"=*")>0,IF($C14="К","-"," - "),IF(COUNTIF(F14:Y14,"<4")>0,IF(C14="К","-"," - "),(IFERROR(AVERAGE(F14:Y14),"Очікую")))) -> Очікую
D15: 6 | Z15: =IF(COUNTIF(F15:Y15,"=*")>0,IF($C15="К","-"," - "),IF(COUNTIF(F15:Y15,"<4")>0,IF(C15="К","-"," - "),(IFERROR(AVERAGE(F15:Y15),"Очікую")))) -> Очікую
D16: 7 | Z16: =IF(COUNTIF(F16:Y16,"=*")>0,IF($C16="К","-"," - "),IF(COUNTIF(F16:Y16,"<4")>0,IF(C16="К","-"," - "),(IFERROR(AVERAGE(F16:Y16),"Очікую")))) -> Очікую
D17: 8 | Z17: =IF(COUNTIF(F17:Y17,"=*")>0,IF($C17="К","-"," - "),IF(COUNTIF(F17:Y17,"<4")>0,IF(C17="К","-"," - "),(IFERROR(AVERAGE(F17:Y17),"Очікую")))) -> Очікую
D18: 9 | Z18: =IF(COUNTIF(F18:Y18,"=*")>0,IF($C18="К","-"," - "),IF(COUNTIF(F18:Y18,"<4")>0,IF(C18="К","-"," - "),(IFERROR(AVERAGE(F18:Y18),"Очікую")))) -> Очікую
D19: 10 | Z19: =IF(COUNTIF(F19:Y19,"=*")>0,IF($C19="К","-"," - "),IF(COUNTIF(F19:Y19,"<4")>0,IF(C19="К","-"," - "),(IFERROR(AVERAGE(F19:Y19),"Очікую")))) -> Очікую
D20: 11 | Z20: =IF(COUNTIF(F20:Y20,"=*")>0,IF($C20="К","-"," - "),IF(COUNTIF(F20:Y20,"<4")>0,IF(C20="К","-"," - "),(IFERROR(AVERAGE(F20:Y20),"Очікую")))) -> Очікую
D21: 12 | Z21: =IF(COUNTIF(F21:Y21,"=*")>0,IF($C21="К","-"," - "),IF(COUNTIF(F21:Y21,"<4")>0,IF(C21="К","-"," - "),(IFERROR(AVERAGE(F21:Y21),"Очікую")))) -> Очікую
... D109: 100 | Z109: =IF(COUNTIF(F109:Y109,"=*")>0,IF($C109="К","-"," - "),IF(COUNTIF(F109:Y109,"<4")>0,IF(C109="К","-"," - "),(IFERROR(AVERAGE(F109:Y109),"Очікую")))) -> Очікую
E110: Середній бал успішності з дисципліни | F110: =IF(SUM(F10:F109)=0,IF(COUNTA(F10:F109)=0,"Очікую",0),SUM(F10:F109)/$D109) -> Очікую | G110: =IF(SUM(G10:G109)=0,IF(COUNTA(G10:G109)=0,"Очікую",0),SUM(G10:G109)/$D109) -> Очікую | H110: =IF(SUM(H10:H109)=0,IF(COUNTA(H10:H109)=0,"Очікую",0),SUM(H10:H109)/$D109) -> Очікую | I110: =IF(SUM(I10:I109)=0,IF(COUNTA(I10:I109)=0,"Очікую",0),SUM(I10:I109)/$D109) -> Очікую | J110: =IF(SUM(J10:J109)=0,IF(COUNTA(J10:J109)=0,"Очікую",0),SUM(J10:J109)/$D109) -> Очікую | K110: =IF(SUM(K10:K109)=0,IF(COUNTA(K10:K109)=0,"Очікую",0),SUM(K10:K109)/$D109) -> Очікую | L110: =IF(SUM(L10:L109)=0,IF(COUNTA(L10:L109)=0,"Очікую",0),SUM(L10:L109)/$D109) -> Очікую | M110: =IF(SUM(M10:M109)=0,IF(COUNTA(M10:M109)=0,"Очікую",0),SUM(M10:M109)/$D109) -> Очікую | ... Y110: =IF(SUM(Y10:Y109)=0,IF(COUNTA(Y10:Y109)=0,"Очікую",0),SUM(Y10:Y109)/$D109) -> Очікую | Z110: =IFERROR(AVERAGE(F110:Y110),"Очікую") -> Очікую
E111: Абсолютна успішність | F111: =IF(SUM(F10:F109)=0,IF(COUNTA(F10:F109)=0,"Очікую",0),IF(COUNTIF(F10:F109,">=4")=0,0,COUNTIF(F10:F109,">=4")/$D109*100)) -> Очікую | G111: =IF(SUM(G10:G109)=0,IF(COUNTA(G10:G109)=0,"Очікую",0),IF(COUNTIF(G10:G109,">=4")=0,0,COUNTIF(G10:G109,">=4")/$D109*100)) -> Очікую | H111: =IF(SUM(H10:H109)=0,IF(COUNTA(H10:H109)=0,"Очікую",0),IF(COUNTIF(H10:H109,">=4")=0,0,COUNTIF(H10:H109,">=4")/$D109*100)) -> Очікую | I111: =IF(SUM(I10:I109)=0,IF(COUNTA(I10:I109)=0,"Очікую",0),IF(COUNTIF(I10:I109,">=4")=0,0,COUNTIF(I10:I109,">=4")/$D109*100)) -> Очікую | J111: =IF(SUM(J10:J109)=0,IF(COUNTA(J10:J109)=0,"Очікую",0),IF(COUNTIF(J10:J109,">=4")=0,0,COUNTIF(J10:J109,">=4")/$D109*100)) -> Очікую | K111: =IF(SUM(K10:K109)=0,IF(COUNTA(K10:K109)=0,"Очікую",0),IF(COUNTIF(K10:K109,">=4")=0,0,COUNTIF(K10:K109,">=4")/$D109*100)) -> Очікую | L111: =IF(SUM(L10:L109)=0,IF(COUNTA(L10:L109)=0,"Очікую",0),IF(COUNTIF(L10:L109,">=4")=0,0,COUNTIF(L10:L109,">=4")/$D109*100)) -> Очікую | M111: =IF(SUM(M10:M109)=0,IF(COUNTA(M10:M109)=0,"Очікую",0),IF(COUNTIF(M10:M109,">=4")=0,0,COUNTIF(M10:M109,">=4")/$D109*100)) -> Очікую | ... Y111: =IF(SUM(Y10:Y109)=0,IF(COUNTA(Y10:Y109)=0,"Очікую",0),IF(COUNTIF(Y10:Y109,">=4")=0,0,COUNTIF(Y10:Y109,">=4")/$D109*100)) -> Очікую
E112: Якісна успішність | F112: =IF(SUM(F10:F109)=0,IF(COUNTA(F10:F109)=0,"Очікую",0),IF(COUNTIF(F10:F109,">=7")=0,0,COUNTIF(F10:F109,">=7")/$D109*100)) -> Очікую | G112: =IF(SUM(G10:G109)=0,IF(COUNTA(G10:G109)=0,"Очікую",0),IF(COUNTIF(G10:G109,">=7")=0,0,COUNTIF(G10:G109,">=7")/$D109*100)) -> Очікую | H112: =IF(SUM(H10:H109)=0,IF(COUNTA(H10:H109)=0,"Очікую",0),IF(COUNTIF(H10:H109,">=7")=0,0,COUNTIF(H10:H109,">=7")/$D109*100)) -> Очікую | I112: =IF(SUM(I10:I109)=0,IF(COUNTA(I10:I109)=0,"Очікую",0),IF(COUNTIF(I10:I109,">=7")=0,0,COUNTIF(I10:I109,">=7")/$D109*100)) -> Очікую | J112: =IF(SUM(J10:J109)=0,IF(COUNTA(J10:J109)=0,"Очікую",0),IF(COUNTIF(J10:J109,">=7")=0,0,COUNTIF(J10:J109,">=7")/$D109*100)) -> Очікую | K112: =IF(SUM(K10:K109)=0,IF(COUNTA(K10:K109)=0,"Очікую",0),IF(COUNTIF(K10:K109,">=7")=0,0,COUNTIF(K10:K109,">=7")/$D109*100)) -> Очікую | L112: =IF(SUM(L10:L109)=0,IF(COUNTA(L10:L109)=0,"Очікую",0),IF(COUNTIF(L10:L109,">=7")=0,0,COUNTIF(L10:L109,">=7")/$D109*100)) -> Очікую | M112: =IF(SUM(M10:M109)=0,IF(COUNTA(M10:M109)=0,"Очікую",0),IF(COUNTIF(M10:M109,">=7")=0,0,COUNTIF(M10:M109,">=7")/$D109*100)) -> Очікую | ... Y112: =IF(SUM(Y10:Y109)=0,IF(COUNTA(Y10:Y109)=0,"Очікую",0),IF(COUNTIF(Y10:Y109,">=7")=0,0,COUNTIF(Y10:Y109,">=7")/$D109*100)) -> Очікую
E113: Абсолютна успішність по групі | F113: =IFERROR(AVERAGE(F111:Y111),"Очікую") -> Очікую
E114: Якісна успішність по групі | F114: =IFERROR(AVERAGE(F112:Y112),"Очікую") -> Очікую
E115: Кількість бюджетників | F115: =IF(COUNTIF(C10:C109,"=Б")=0,IF(COUNTIF(C10:C109,"=К")=0,"Очікую",0),COUNTIF(C10:C109,"=Б")) -> Очікую
E116: Кількість контрактників | F116: =IF(COUNTIF(C10:C109,"=К")=0,IF(COUNTIF(C10:C109,"=Б")=0,"Очікую",0),COUNTIF(C10:C109,"=К")) -> Очікую | H116: Класний керівник
E117: Кількість соціального контингенту
E118: Вийшли на стипендію | F118: =IF(F115="Очікую","Очікую",IF(F115-COUNTIF(Z10:Z109," - ")<ROUNDDOWN(F115*0.4,0),F115-COUNTIF(Z10:Z109," - "),ROUNDDOWN(F115*0.4,0))) -> Очікую | H118: Завідувач відділення ПЗСО

Sheet ЛЗ6
A1: S
C3: ВІДОКРЕМЛЕНИЙ СТРУКТУРНИЙ ПІДРОЗДІЛ «ФАХОВИЙ КОЛЕДЖ НАФТОГАЗОВИХ ТЕХНОЛОГІЙ, ІНЖЕНЕРІЇ ТА ІНФРАСТРУКТУРИ СЕРВІСУ ОДЕСЬКОГО НАЦІОНАЛЬНОГО ТЕХНОЛОГІЧНОГО УНІВЕРСИТЕТУ»
C4: ЗВЕДЕНА ВІДОМІСТЬ
C5: Успішності студентів спеціальності XXX «XXXXX»
C6: За X семестр XXXX-XXXX н.р.
C7: Група XXXX курс X
C8: Б/К | D8: № п/п | E8: Прізвище, ім’я, по батькові | F8: Підсумкові оцінки дисциплін | Z8: Середній бал
F9: 1 | G9: 2 | H9: 3 | I9: 4 | J9: 5 | K9: 6 | L9: 7 | M9: 8 | N9: 9 | O9: 10 | P9: 11 | Q9: 12 | R9: 13 | S9: 14 | T9: 15 | U9: 16 | V9: 17 | W9: 18 | X9: 19 | Y9: 20
D10: 1 | Z10: =IF(COUNTIF(F10:Y10,"=*")>0,IF($C10="К","-"," - "),IF(COUNTIF(F10:Y10,"<4")>0,IF(C10="К","-"," - "),(IFERROR(AVERAGE(F10:Y10),"Очікую")))) -> Очікую
D11: 2 | Z11: =IF(COUNTIF(F11:Y11,"=*")>0,IF($C11="К","-"," - "),IF(COUNTIF(F11:Y11,"<4")>0,IF(C11="К","-"," - "),(IFERROR(AVERAGE(F11:Y11),"Очікую")))) -> Очікую
D12: 3 | Z12: =IF(COUNTIF(F12:Y12,"=*")>0,IF($C12="К","-"," - "),IF(COUNTIF(F12:Y12,"<4")>0,IF(C12="К","-"," - "),(IFERROR(AVERAGE(F12:Y12),"Очікую")))) -> Очікую
D13: 4 | Z13: =IF(COUNTIF(F13:Y13,"=*")>0,IF($C13="К","-"," - "),IF(COUNTIF(F13:Y13,"<4")>0,IF(C13="К","-"," - "),(IFERROR(AVERAGE(F13:Y13),"Очікую")))) -> Очікую
D14: 5 | Z14: =IF(COUNTIF(F14:Y14,"=*")>0,IF($C14="К","-"," - "),IF(COUNTIF(F14:Y14,"<4")>0,IF(C14="К","-"," - "),(IFERROR(AVERAGE(F14:Y14),"Очікую")))) -> Очікую
D15: 6 | Z15: =IF(COUNTIF(F15:Y15,"=*")>0,IF($C15="К","-"," - "),IF(COUNTIF(F15:Y15,"<4")>0,IF(C15="К","-"," - "),(IFERROR(AVERAGE(F15:Y15),"Очікую")))) -> Очікую
D16: 7 | Z16: =IF(COUNTIF(F16:Y16,"=*")>0,IF($C16="К","-"," - "),IF(COUNTIF(F16:Y16,"<4")>0,IF(C16="К","-"," - "),(IFERROR(AVERAGE(F16:Y16),"Очікую")))) -> Очікую
D17: 8 | Z17: =IF(COUNTIF(F17:Y17,"=*")>0,IF($C17="К","-"," - "),IF(COUNTIF(F17:Y17,"<4")>0,IF(C17="К","-"," - "),(IFERROR(AVERAGE(F17:Y17),"Очікую")))) -> Очікую
D18: 9 | Z18: =IF(COUNTIF(F18:Y18,"=*")>0,IF($C18="К","-"," - "),IF(COUNTIF(F18:Y18,"<4")>0,IF(C18="К","-"," - "),(IFERROR(AVERAGE(F18:Y18),"Очікую")))) -> Очікую
D19: 10 | Z19: =IF(COUNTIF(F19:Y19,"=*")>0,IF($C19="К","-"," - "),IF(COUNTIF(F19:Y19,"<4")>0,IF(C19="К","-"," - "),(IFERROR(AVERAGE(F19:Y19),"Очікую")))) -> Очікую
D20: 11 | Z20: =IF(COUNTIF(F20:Y20,"=*")>0,IF($C20="К","-"," - "),IF(COUNTIF(F20:Y20,"<4")>0,IF(C20="К","-"," - "),(IFERROR(AVERAGE(F20:Y20),"Очікую")))) -> Очікую
D21: 12 | Z21: =IF(COUNTIF(F21:Y21,"=*")>0,IF($C21="К","-"," - "),IF(COUNTIF(F21:Y21,"<4")>0,IF(C21="К","-"," - "),(IFERROR(AVERAGE(F21:Y21),"Очікую")))) -> Очікую
... D109: 100 | Z109: =IF(COUNTIF(F109:Y109,"=*")>0,IF($C109="К","-"," - "),IF(COUNTIF(F109:Y109,"<4")>0,IF(C109="К","-"," - "),(IFERROR(AVERAGE(F109:Y109),"Очікую")))) -> Очікую
E110: Середній бал успішності з дисципліни | F110: =IF(SUM(F10:F109)=0,IF(COUNTA(F10:F109)=0,"Очікую",0),SUM(F10:F109)/$D109) -> Очікую | G110: =IF(SUM(G10:G109)=0,IF(COUNTA(G10:G109)=0,"Очікую",0),SUM(G10:G109)/$D109) -> Очікую | H110: =IF(SUM(H10:H109)=0,IF(COUNTA(H10:H109)=0,"Очікую",0),SUM(H10:H109)/$D109) -> Очікую | I110: =IF(SUM(I10:I109)=0,IF(COUNTA(I10:I109)=0,"Очікую",0),SUM(I10:I109)/$D109) -> Очікую | J110: =IF(SUM(J10:J109)=0,IF(COUNTA(J10:J109)=0,"Очікую",0),SUM(J10:J109)/$D109) -> Очікую | K110: =IF(SUM(K10:K109)=0,IF(COUNTA(K10:K109)=0,"Очікую",0),SUM(K10:K109)/$D109) -> Очікую | L110: =IF(SUM(L10:L109)=0,IF(COUNTA(L10:L109)=0,"Очікую",0),SUM(L10:L109)/$D109) -> Очікую | M110: =IF(SUM(M10:M109)=0,IF(COUNTA(M10:M109)=0,"Очікую",0),SUM(M10:M109)/$D109) -> Очікую | ... Y110: =IF(SUM(Y10:Y109)=0,IF(COUNTA(Y10:Y109)=0,"Очікую",0),SUM(Y10:Y109)/$D109) -> Очікую | Z110: =IFERROR(AVERAGE(F110:Y110),"Очікую") -> Очікую
E111: Абсолютна успішність | F111: =IF(SUM(F10:F109)=0,IF(COUNTA(F10:F109)=0,"Очікую",0),IF(COUNTIF(F10:F109,">=4")=0,0,COUNTIF(F10:F109,">=4")/$D109*100)) -> Очікую | G111: =IF(SUM(G10:G109)=0,IF(COUNTA(G10:G109)=0,"Очікую",0),IF(COUNTIF(G10:G109,">=4")=0,0,COUNTIF(G10:G109,">=4")/$D109*100)) -> Очікую | H111: =IF(SUM(H10:H109)=0,IF(COUNTA(H10:H109)=0,"Очікую",0),IF(COUNTIF(H10:H109,">=4")=0,0,COUNTIF(H10:H109,">=4")/$D109*100)) -> Очікую | I111: =IF(SUM(I10:I109)=0,IF(COUNTA(I10:I109)=0,"Очікую",0),IF(COUNTIF(I10:I109,">=4")=0,0,COUNTIF(I10:I109,">=4")/$D109*100)) -> Очікую | J111: =IF(SUM(J10:J109)=0,IF(COUNTA(J10:J109)=0,"Очікую",0),IF(COUNTIF(J10:J109,">=4")=0,0,COUNTIF(J10:J109,">=4")/$D109*100)) -> Очікую | K111: =IF(SUM(K10:K109)=0,IF(COUNTA(K10:K109)=0,"Очікую",0),IF(COUNTIF(K10:K109,">=4")=0,0,COUNTIF(K10:K109,">=4")/$D109*100)) -> Очікую | L111: =IF(SUM(L10:L109)=0,IF(COUNTA(L10:L109)=0,"Очікую",0),IF(COUNTIF(L10:L109,">=4")=0,0,COUNTIF(L10:L109,">=4")/$D109*100)) -> Очікую | M111: =IF(SUM(M10:M109)=0,IF(COUNTA(M10:M109)=0,"Очікую",0),IF(COUNTIF(M10:M109,">=4")=0,0,COUNTIF(M10:M109,">=4")/$D109*100)) -> Очікую | ... Y111: =IF(SUM(Y10:Y109)=0,IF(COUNTA(Y10:Y109)=0,"Очікую",0),IF(COUNTIF(Y10:Y109,">=4")=0,0,COUNTIF(Y10:Y109,">=4")/$D109*100)) -> Очікую
E112: Якісна успішність | F112: =IF(SUM(F10:F109)=0,IF(COUNTA(F10:F109)=0,"Очікую",0),IF(COUNTIF(F10:F109,">=7")=0,0,COUNTIF(F10:F109,">=7")/$D109*100)) -> Очікую | G112: =IF(SUM(G10:G109)=0,IF(COUNTA(G10:G109)=0,"Очікую",0),IF(COUNTIF(G10:G109,">=7")=0,0,COUNTIF(G10:G109,">=7")/$D109*100)) -> Очікую | H112: =IF(SUM(H10:H109)=0,IF(COUNTA(H10:H109)=0,"Очікую",0),IF(COUNTIF(H10:H109,">=7")=0,0,COUNTIF(H10:H109,">=7")/$D109*100)) -> Очікую | I112: =IF(SUM(I10:I109)=0,IF(COUNTA(I10:I109)=0,"Очікую",0),IF(COUNTIF(I10:I109,">=7")=0,0,COUNTIF(I10:I109,">=7")/$D109*100)) -> Очікую | J112: =IF(SUM(J10:J109)=0,IF(COUNTA(J10:J109)=0,"Очікую",0),IF(COUNTIF(J10:J109,">=7")=0,0,COUNTIF(J10:J109,">=7")/$D109*100)) -> Очікую | K112: =IF(SUM(K10:K109)=0,IF(COUNTA(K10:K109)=0,"Очікую",0),IF(COUNTIF(K10:K109,">=7")=0,0,COUNTIF(K10:K109,">=7")/$D109*100)) -> Очікую | L112: =IF(SUM(L10:L109)=0,IF(COUNTA(L10:L109)=0,"Очікую",0),IF(COUNTIF(L10:L109,">=7")=0,0,COUNTIF(L10:L109,">=7")/$D109*100)) -> Очікую | M112: =IF(SUM(M10:M109)=0,IF(COUNTA(M10:M109)=0,"Очікую",0),IF(COUNTIF(M10:M109,">=7")=0,0,COUNTIF(M10:M109,">=7")/$D109*100)) -> Очікую | ... Y112: =IF(SUM(Y10:Y109)=0,IF(COUNTA(Y10:Y109)=0,"Очікую",0),IF(COUNTIF(Y10:Y109,">=7")=0,0,COUNTIF(Y10:Y109,">=7")/$D109*100)) -> Очікую
E113: Абсолютна успішність по групі | F113: =IFERROR(AVERAGE(F111:Y111),"Очікую") -> Очікую
E114: Якісна успішність по групі | F114: =IFERROR(AVERAGE(F112:Y112),"Очікую") -> Очікую
E115: Кількість бюджетників | F115: =IF(COUNTIF(C10:C109,"=Б")=0,IF(COUNTIF(C10:C109,"=К")=0,"Очікую",0),COUNTIF(C10:C109,"=Б")) -> Очікую
E116: Кількість контрактників | F116: =IF(COUNTIF(C10:C109,"=К")=0,IF(COUNTIF(C10:C109,"=Б")=0,"Очікую",0),COUNTIF(C10:C109,"=К")) -> Очікую | H116: Класний керівник
E117: Кількість соціального контингенту
E118: Вийшли на стипендію | F118: =IF(F115="Очікую","Очікую",IF(F115-COUNTIF(Z10:Z109," - ")<ROUNDDOWN(F115*0.4,0),F115-COUNTIF(Z10:Z109," - "),ROUNDDOWN(F115*0.4,0))) -> Очікую | H118: Завідувач відділення ПЗСО

Sheet ЛЗ7
A1: S
C3: ВІДОКРЕМЛЕНИЙ СТРУКТУРНИЙ ПІДРОЗДІЛ «ФАХОВИЙ КОЛЕДЖ НАФТОГАЗОВИХ ТЕХНОЛОГІЙ, ІНЖЕНЕРІЇ ТА ІНФРАСТРУКТУРИ СЕРВІСУ ОДЕСЬКОГО НАЦІОНАЛЬНОГО ТЕХНОЛОГІЧНОГО УНІВЕРСИТЕТУ»
C4: ЗВЕДЕНА ВІДОМІСТЬ
C5: Успішності студентів спеціальності XXX «XXXXX»
C6: За X семестр XXXX-XXXX н.р.
C7: Група XXXX курс X
C8: Б/К | D8: № п/п | E8: Прізвище, ім’я, по батькові | F8: Підсумкові оцінки дисциплін | Z8: Середній бал
F9: 1 | G9: 2 | H9: 3 | I9: 4 | J9: 5 | K9: 6 | L9: 7 | M9: 8 | N9: 9 | O9: 10 | P9: 11 | Q9: 12 | R9: 13 | S9: 14 | T9: 15 | U9: 16 | V9: 17 | W9: 18 | X9: 19 | Y9: 20
D10: 1 | Z10: =IF(COUNTIF(F10:Y10,"=*")>0,IF($C10="К","-"," - "),IF(COUNTIF(F10:Y10,"<4")>0,IF(C10="К","-"," - "),(IFERROR(AVERAGE(F10:Y10),"Очікую")))) -> Очікую
D11: 2 | Z11: =IF(COUNTIF(F11:Y11,"=*")>0,IF($C11="К","-"," - "),IF(COUNTIF(F11:Y11,"<4")>0,IF(C11="К","-"," - "),(IFERROR(AVERAGE(F11:Y11),"Очікую")))) -> Очікую
D12: 3 | Z12: =IF(COUNTIF(F12:Y12,"=*")>0,IF($C12="К","-"," - "),IF(COUNTIF(F12:Y12,"<4")>0,IF(C12="К","-"," - "),(IFERROR(AVERAGE(F12:Y12),"Очікую")))) -> Очікую
D13: 4 | Z13: =IF(COUNTIF(F13:Y13,"=*")>0,IF($C13="К","-"," - "),IF(COUNTIF(F13:Y13,"<4")>0,IF(C13="К","-"," - "),(IFERROR(AVERAGE(F13:Y13),"Очікую")))) -> Очікую
D14: 5 | Z14: =IF(COUNTIF(F14:Y14,"=*")>0,IF($C14="К","-"," - "),IF(COUNTIF(F14:Y14,"<4")>0,IF(C14="К","-"," - "),(IFERROR(AVERAGE(F14:Y14),"Очікую")))) -> Очікую
D15: 6 | Z15: =IF(COUNTIF(F15:Y15,"=*")>0,IF($C15="К","-"," - "),IF(COUNTIF(F15:Y15,"<4")>0,IF(C15="К","-"," - "),(IFERROR(AVERAGE(F15:Y15),"Очікую")))) -> Очікую
D16: 7 | Z16: =IF(COUNTIF(F16:Y16,"=*")>0,IF($C16="К","-"," - "),IF(COUNTIF(F16:Y16,"<4")>0,IF(C16="К","-"," - "),(IFERROR(AVERAGE(F16:Y16),"Очікую")))) -> Очікую
D17: 8 | Z17: =IF(COUNTIF(F17:Y17,"=*")>0,IF($C17="К","-"," - "),IF(COUNTIF(F17:Y17,"<4")>0,IF(C17="К","-"," - "),(IFERROR(AVERAGE(F17:Y17),"Очікую")))) -> Очікую
D18: 9 | Z18: =IF(COUNTIF(F18:Y18,"=*")>0,IF($C18="К","-"," - "),IF(COUNTIF(F18:Y18,"<4")>0,IF(C18="К","-"," - "),(IFERROR(AVERAGE(F18:Y18),"Очікую")))) -> Очікую
D19: 10 | Z19: =IF(COUNTIF(F19:Y19,"=*")>0,IF($C19="К","-"," - "),IF(COUNTIF(F19:Y19,"<4")>0,IF(C19="К","-"," - "),(IFERROR(AVERAGE(F19:Y19),"Очікую")))) -> Очікую
D20: 11 | Z20: =IF(COUNTIF(F20:Y20,"=*")>0,IF($C20="К","-"," - "),IF(COUNTIF(F20:Y20,"<4")>0,IF(C20="К","-"," - "),(IFERROR(AVERAGE(F20:Y20),"Очікую")))) -> Очікую
D21: 12 | Z21: =IF(COUNTIF(F21:Y21,"=*")>0,IF($C21="К","-"," - "),IF(COUNTIF(F21:Y21,"<4")>0,IF(C21="К","-"," - "),(IFERROR(AVERAGE(F21:Y21),"Очікую")))) -> Очікую
... D109: 100 | Z109: =IF(COUNTIF(F109:Y109,"=*")>0,IF($C109="К","-"," - "),IF(COUNTIF(F109:Y109,"<4")>0,IF(C109="К","-"," - "),(IFERROR(AVERAGE(F109:Y109),"Очікую")))) -> Очікую
E110: Середній бал успішності з дисципліни | F110: =IF(SUM(F10:F109)=0,IF(COUNTA(F10:F109)=0,"Очікую",0),SUM(F10:F109)/$D109) -> Очікую | G110: =IF(SUM(G10:G109)=0,IF(COUNTA(G10:G109)=0,"Очікую",0),SUM(G10:G109)/$D109) -> Очікую | H110: =IF(SUM(H10:H109)=0,IF(COUNTA(H10:H109)=0,"Очікую",0),SUM(H10:H109)/$D109) -> Очікую | I110: =IF(SUM(I10:I109)=0,IF(COUNTA(I10:I109)=0,"Очікую",0),SUM(I10:I109)/$D109) -> Очікую | J110: =IF(SUM(J10:J109)=0,IF(COUNTA(J10:J109)=0,"Очікую",0),SUM(J10:J109)/$D109) -> Очікую | K110: =IF(SUM(K10:K109)=0,IF(COUNTA(K10:K109)=0,"Очікую",0),SUM(K10:K109)/$D109) -> Очікую | L110: =IF(SUM(L10:L109)=0,IF(COUNTA(L10:L109)=0,"Очікую",0),SUM(L10:L109)/$D109) -> Очікую | M110: =IF(SUM(M10:M109)=0,IF(COUNTA(M10:M109)=0,"Очікую",0),SUM(M10:M109)/$D109) -> Очікую | ... Y110: =IF(SUM(Y10:Y109)=0,IF(COUNTA(Y10:Y109)=0,"Очікую",0),SUM(Y10:Y109)/$D109) -> Очікую | Z110: =IFERROR(AVERAGE(F110:Y110),"Очікую") -> Очікую
E111: Абсолютна успішність | F111: =IF(SUM(F10:F109)=0,IF(COUNTA(F10:F109)=0,"Очікую",0),IF(COUNTIF(F10:F109,">=4")=0,0,COUNTIF(F10:F109,">=4")/$D109*100)) -> Очікую | G111: =IF(SUM(G10:G109)=0,IF(COUNTA(G10:G109)=0,"Очікую",0),IF(COUNTIF(G10:G109,">=4")=0,0,COUNTIF(G10:G109,">=4")/$D109*100)) -> Очікую | H111: =IF(SUM(H10:H109)=0,IF(COUNTA(H10:H109)=0,"Очікую",0),IF(COUNTIF(H10:H109,">=4")=0,0,COUNTIF(H10:H109,">=4")/$D109*100)) -> Очікую | I111: =IF(SUM(I10:I109)=0,IF(COUNTA(I10:I109)=0,"Очікую",0),IF(COUNTIF(I10:I109,">=4")=0,0,COUNTIF(I10:I109,">=4")/$D109*100)) -> Очікую | J111: =IF(SUM(J10:J109)=0,IF(COUNTA(J10:J109)=0,"Очікую",0),IF(COUNTIF(J10:J109,">=4")=0,0,COUNTIF(J10:J109,">=4")/$D109*100)) -> Очікую | K111: =IF(SUM(K10:K109)=0,IF(COUNTA(K10:K109)=0,"Очікую",0),IF(COUNTIF(K10:K109,">=4")=0,0,COUNTIF(K10:K109,">=4")/$D109*100)) -> Очікую | L111: =IF(SUM(L10:L109)=0,IF(COUNTA(L10:L109)=0,"Очікую",0),IF(COUNTIF(L10:L109,">=4")=0,0,COUNTIF(L10:L109,">=4")/$D109*100)) -> Очікую | M111: =IF(SUM(M10:M109)=0,IF(COUNTA(M10:M109)=0,"Очікую",0),IF(COUNTIF(M10:M109,">=4")=0,0,COUNTIF(M10:M109,">=4")/$D109*100)) -> Очікую | ... Y111: =IF(SUM(Y10:Y109)=0,IF(COUNTA(Y10:Y109)=0,"Очікую",0),IF(COUNTIF(Y10:Y109,">=4")=0,0,COUNTIF(Y10:Y109,">=4")/$D109*100)) -> Очікую
E112: Якісна успішність | F112: =IF(SUM(F10:F109)=0,IF(COUNTA(F10:F109)=0,"Очікую",0),IF(COUNTIF(F10:F109,">=7")=0,0,COUNTIF(F10:F109,">=7")/$D109*100)) -> Очікую | G112: =IF(SUM(G10:G109)=0,IF(COUNTA(G10:G109)=0,"Очікую",0),IF(COUNTIF(G10:G109,">=7")=0,0,COUNTIF(G10:G109,">=7")/$D109*100)) -> Очікую | H112: =IF(SUM(H10:H109)=0,IF(COUNTA(H10:H109)=0,"Очікую",0),IF(COUNTIF(H10:H109,">=7")=0,0,COUNTIF(H10:H109,">=7")/$D109*100)) -> Очікую | I112: =IF(SUM(I10:I109)=0,IF(COUNTA(I10:I109)=0,"Очікую",0),IF(COUNTIF(I10:I109,">=7")=0,0,COUNTIF(I10:I109,">=7")/$D109*100)) -> Очікую | J112: =IF(SUM(J10:J109)=0,IF(COUNTA(J10:J109)=0,"Очікую",0),IF(COUNTIF(J10:J109,">=7")=0,0,COUNTIF(J10:J109,">=7")/$D109*100)) -> Очікую | K112: =IF(SUM(K10:K109)=0,IF(COUNTA(K10:K109)=0,"Очікую",0),IF(COUNTIF(K10:K109,">=7")=0,0,COUNTIF(K10:K109,">=7")/$D109*100)) -> Очікую | L112: =IF(SUM(L10:L109)=0,IF(COUNTA(L10:L109)=0,"Очікую",0),IF(COUNTIF(L10:L109,">=7")=0,0,COUNTIF(L10:L109,">=7")/$D109*100)) -> Очікую | M112: =IF(SUM(M10:M109)=0,IF(COUNTA(M10:M109)=0,"Очікую",0),IF(COUNTIF(M10:M109,">=7")=0,0,COUNTIF(M10:M109,">=7")/$D109*100)) -> Очікую | ... Y112: =IF(SUM(Y10:Y109)=0,IF(COUNTA(Y10:Y109)=0,"Очікую",0),IF(COUNTIF(Y10:Y109,">=7")=0,0,COUNTIF(Y10:Y109,">=7")/$D109*100)) -> Очікую
E113: Абсолютна успішність по групі | F113: =IFERROR(AVERAGE(F111:Y111),"Очікую") -> Очікую
E114: Якісна успішність по групі | F114: =IFERROR(AVERAGE(F112:Y112),"Очікую") -> Очікую
E115: Кількість бюджетників | F115: =IF(COUNTIF(C10:C109,"=Б")=0,IF(COUNTIF(C10:C109,"=К")=0,"Очікую",0),COUNTIF(C10:C109,"=Б")) -> Очікую
E116: Кількість контрактників | F116: =IF(COUNTIF(C10:C109,"=К")=0,IF(COUNTIF(C10:C109,"=Б")=0,"Очікую",0),COUNTIF(C10:C109,"=К")) -> Очікую | H116: Класний керівник
E117: Кількість соціального контингенту
E118: Вийшли на стипендію | F118: =IF(F115="Очікую","Очікую",IF(F115-COUNTIF(Z10:Z109," - ")<ROUNDDOWN(F115*0.4,0),F115-COUNTIF(Z10:Z109," - "),ROUNDDOWN(F115*0.4,0))) -> Очікую | H118: Завідувач відділення ПЗСО

Sheet ЛЗ8
A1: S
C3: ВІДОКРЕМЛЕНИЙ СТРУКТУРНИЙ ПІДРОЗДІЛ «ФАХОВИЙ КОЛЕДЖ НАФТОГАЗОВИХ ТЕХНОЛОГІЙ, ІНЖЕНЕРІЇ ТА ІНФРАСТРУКТУРИ СЕРВІСУ ОДЕСЬКОГО НАЦІОНАЛЬНОГО ТЕХНОЛОГІЧНОГО УНІВЕРСИТЕТУ»
C4: ЗВЕДЕНА ВІДОМІСТЬ
C5: Успішності студентів спеціальності XXX «XXXXX»
C6: За X семестр XXXX-XXXX н.р.
C7: Група XXXX курс X
C8: Б/К | D8: № п/п | E8: Прізвище, ім’я, по батькові | F8: Підсумкові оцінки дисциплін | Z8: Середній бал
F9: 1 | G9: 2 | H9: 3 | I9: 4 | J9: 5 | K9: 6 | L9: 7 | M9: 8 | N9: 9 | O9: 10 | P9: 11 | Q9: 12 | R9: 13 | S9: 14 | T9: 15 | U9: 16 | V9: 17 | W9: 18 | X9: 19 | Y9: 20
D10: 1 | Z10: =IF(COUNTIF(F10:Y10,"=*")>0,IF($C10="К","-"," - "),IF(COUNTIF(F10:Y10,"<4")>0,IF(C10="К","-"," - "),(IFERROR(AVERAGE(F10:Y10),"Очікую")))) -> Очікую
D11: 2 | Z11: =IF(COUNTIF(F11:Y11,"=*")>0,IF($C11="К","-"," - "),IF(COUNTIF(F11:Y11,"<4")>0,IF(C11="К","-"," - "),(IFERROR(AVERAGE(F11:Y11),"Очікую")))) -> Очікую
D12: 3 | Z12: =IF(COUNTIF(F12:Y12,"=*")>0,IF($C12="К","-"," - "),IF(COUNTIF(F12:Y12,"<4")>0,IF(C12="К","-"," - "),(IFERROR(AVERAGE(F12:Y12),"Очікую")))) -> Очікую
D13: 4 | Z13: =IF(COUNTIF(F13:Y13,"=*")>0,IF($C13="К","-"," - "),IF(COUNTIF(F13:Y13,"<4")>0,IF(C13="К","-"," - "),(IFERROR(AVERAGE(F13:Y13),"Очікую")))) -> Очікую
D14: 5 | Z14: =IF(COUNTIF(F14:Y14,"=*")>0,IF($C14="К","-"," - "),IF(COUNTIF(F14:Y14,"<4")>0,IF(C14="К","-"," - "),(IFERROR(AVERAGE(F14:Y14),"Очікую")))) -> Очікую
D15: 6 | Z15: =IF(COUNTIF(F15:Y15,"=*")>0,IF($C15="К","-"," - "),IF(COUNTIF(F15:Y15,"<4")>0,IF(C15="К","-"," - "),(IFERROR(AVERAGE(F15:Y15),"Очікую")))) -> Очікую
D16: 7 | Z16: =IF(COUNTIF(F16:Y16,"=*")>0,IF($C16="К","-"," - "),IF(COUNTIF(F16:Y16,"<4")>0,IF(C16="К","-"," - "),(IFERROR(AVERAGE(F16:Y16),"Очікую")))) -> Очікую
D17: 8 | Z17: =IF(COUNTIF(F17:Y17,"=*")>0,IF($C17="К","-"," - "),IF(COUNTIF(F17:Y17,"<4")>0,IF(C17="К","-"," - "),(IFERROR(AVERAGE(F17:Y17),"Очікую")))) -> Очікую
D18: 9 | Z18: =IF(COUNTIF(F18:Y18,"=*")>0,IF($C18="К","-"," - "),IF(COUNTIF(F18:Y18,"<4")>0,IF(C18="К","-"," - "),(IFERROR(AVERAGE(F18:Y18),"Очікую")))) -> Очікую
D19: 10 | Z19: =IF(COUNTIF(F19:Y19,"=*")>0,IF($C19="К","-"," - "),IF(COUNTIF(F19:Y19,"<4")>0,IF(C19="К","-"," - "),(IFERROR(AVERAGE(F19:Y19),"Очікую")))) -> Очікую
D20: 11 | Z20: =IF(COUNTIF(F20:Y20,"=*")>0,IF($C20="К","-"," - "),IF(COUNTIF(F20:Y20,"<4")>0,IF(C20="К","-"," - "),(IFERROR(AVERAGE(F20:Y20),"Очікую")))) -> Очікую
D21: 12 | Z21: =IF(COUNTIF(F21:Y21,"=*")>0,IF($C21="К","-"," - "),IF(COUNTIF(F21:Y21,"<4")>0,IF(C21="К","-"," - "),(IFERROR(AVERAGE(F21:Y21),"Очікую")))) -> Очікую
... D109: 100 | Z109: =IF(COUNTIF(F109:Y109,"=*")>0,IF($C109="К","-"," - "),IF(COUNTIF(F109:Y109,"<4")>0,IF(C109="К","-"," - "),(IFERROR(AVERAGE(F109:Y109),"Очікую")))) -> Очікую
