Workbook
Name A1048577: #REF!
Name A1048577: #REF!
Name A1048577: #REF!
Name A1048577: #REF!
Name A1048577: #REF!
Name A1048577: #REF!
Name Ф80: #REF!
Name Ф80: #REF!
Name Ф80: #REF!
Name Ф80: #REF!
Name Ф80: #REF!
Name Ф80: #REF!

Sheet Зведена відомість 075
A1: ВСП «ФАХОВИЙ КОЛЕДЖ НАФТОГАЗОВИХ ТЕХНОЛОГІЙ, ІНЖЕНЕРІЇ ТА ІНФРАСТРУКТУРИ СЕРВІСУ
A2: ОДЕСЬКОГО НАЦІОНАЛЬНОГО ТЕХНОЛОГІЧНОГО УНІВЕРСИТЕТУ»
A3: ЗВЕДЕНА ВІДОМІСТЬ
A4: Успішності студентів спеціальності 075 «Маркетинг»
A5: За I семестр 2022-2023 н.р.
A6: Група 22-1 курс І
A7: Б/К | B7: № п/п | C7: Прізвище, ім’я, по батькові | D7: Підсумкові оцінки дисциплін
D8: Біологія Богданенко О.В. | E8: Всесвітня історія Мельничук С.А. | F8: Географія Наговська Т.С. | G8: Зарубіжна література Пруднікова Я.П. | H8: ЗУ Стельмах Н.Ю. | I8: Іноземна мова Кучер О.П. | J8: Інформатика Вівдіч М.І. | K8: Історія України Левчук Т.Г. | L8: Математика Ромчук В.В. | M8: Українська література Нестеренко А.О. | N8: Українська мова Нестеренко А.О. | O8: Фізика Калюта Н.М. | P8: Фізична культура Кулатов В.М. | Q8: Хімія Леонова Д.І. | R8: Середній бал
A9: К | B9: 1 | C9: Бушовецька Дарія Віталіївна | D9: 7 | E9: 10 | F9: 9 | G9: 10 | H9: 9 | I9: 8 | J9: 10 | K9: 8 | L9: 10 | M9: 10 | N9: 6 | O9: 7 | P9: 7 | Q9: 5 | R9: =IF(COUNTIF(D9:Q9,"=*")>0,"-",(IFERROR(AVERAGE(D9:Q9),""))) -> 8.2857143
A10: Б | B10: 2 | C10: Горошинська Анна Олегівна | D10: 7 | E10: 10 | F10: 10 | G10: 8 | H10: 9 | I10: 8 | J10: 10 | K10: 8 | L10: 8 | M10: 8 | N10: 8 | O10: 9 | P10: 7 | Q10: 7 | R10: =IF(COUNTIF(D10:Q10,"=*")>0,"-",(IFERROR(AVERAGE(D10:Q10),""))) -> 8.3571429
A11: Б | B11: 3 | C11: Гуменюк Аміна Міххтіївна | D11: 7 | E11: 9 | F11: 7 | G11: 4 | H11: 7 | I11: 6 | J11: 5 | K11: 8 | L11: 6 | M11: 7 | N11: 10 | O11: 6 | P11: 10 | Q11: 6 | R11: =IF(COUNTIF(D11:Q11,"=*")>0,"-",(IFERROR(AVERAGE(D11:Q11),""))) -> 7
A12: Б | B12: 4 | C12: Гуркіна Анна Ігорівна | D12: 10 | E12: 10 | F12: 10 | G12: 9 | H12: 10 | I12: 10 | J12: 10 | K12: 9 | L12: 10 | M12: 10 | N12: 10 | O12: 10 | P12: 10 | Q12: 10 | R12: =IF(COUNTIF(D12:Q12,"=*")>0,"-",(IFERROR(AVERAGE(D12:Q12),""))) -> 9.8571429
A13: Б | B13: 5 | C13: Діденко Софья Андріївна | D13: 9 | E13: 9 | F13: 10 | G13: 10 | H13: 10 | I13: 10 | J13: 8 | K13: 9 | L13: 9 | M13: 10 | N13: 9 | O13: 6 | P13: 10 | Q13: 8 | R13: =IF(COUNTIF(D13:Q13,"=*")>0,"-",(IFERROR(AVERAGE(D13:Q13),""))) -> 9.0714286
A14: Б | B14: 6 | C14: Дмуховська Аліса Андріївна | D14: 9 | E14: 10 | F14: 10 | G14: 9 | H14: 10 | I14: 10 | J14: 10 | K14: 9 | L14: 8 | M14: 10 | N14: 10 | O14: 8 | P14: 10 | Q14: 7 | R14: =IF(COUNTIF(D14:Q14,"=*")>0,"-",(IFERROR(AVERAGE(D14:Q14),""))) -> 9.2857143
A15: Б | B15: 7 | C15: Дурбалов Андрій Геннадійович | D15: 10 | E15: 10 | F15: 10 | G15: 10 | H15: 10 | I15: 11 | J15: 11 | K15: 10 | L15: 10 | M15: 10 | N15: 10 | O15: 10 | P15: 10 | Q15: 10 | R15: =IF(COUNTIF(D15:Q15,"=*")>0,"-",(IFERROR(AVERAGE(D15:Q15),""))) -> 10.142857
A16: Б | B16: 8 | C16: Єремеєва Дар’я Сергіївна | D16: 10 | E16: 10 | F16: 10 | G16: 10 | H16: 9 | I16: 11 | J16: 10 | K16: 9 | L16: 10 | M16: 10 | N16: 10 | O16: 10 | P16: 10 | Q16: 10 | R16: =IF(COUNTIF(D16:Q16,"=*")>0,"-",(IFERROR(AVERAGE(D16:Q16),""))) -> 9.9285714
A17: Б | B17: 9 | C17: Калугіна Анастасія Дмитрівна | D17: 9 | E17: 10 | F17: 10 | G17: 10 | H17: 10 | I17: 10 | J17: 10 | K17: 9 | L17: 10 | M17: 10 | N17: 9 | O17: 10 | P17: 10 | Q17: 8 | R17: =IF(COUNTIF(D17:Q17,"=*")>0,"-",(IFERROR(AVERAGE(D17:Q17),""))) -> 9.6428571
A18: К | B18: 10 | C18: Карпенко Уляна Вікторівна | D18: 10 | E18: 10 | F18: 10 | G18: 9 | H18: 9 | I18: 8 | J18: 9 | K18: 8 | L18: 9 | M18: 10 | N18: 10 | O18: 9 | P18: 10 | Q18: 8 | R18: =IF(COUNTIF(D18:Q18,"=*")>0,"-",(IFERROR(AVERAGE(D18:Q18),""))) -> 9.2142857
A19: К | B19: 11 | C19: Кононенко Анастасія Ігорівна | D19: 9 | E19: 9 | F19: 9 | G19: 9 | H19: 9 | I19: 7 | J19: 6 | K19: 6 | L19: 5 | M19: 10 | N19: 7 | O19: 6 | P19: 8 | Q19: 9 | R19: =IF(COUNTIF(D19:Q19,"=*")>0,"-",(IFERROR(AVERAGE(D19:Q19),""))) -> 7.7857143
A20: К | B20: 12 | C20: Лещенко Марія Григорівна | D20: 9 | E20: 8 | F20: 8 | G20: 4 | H20: 6 | I20: 6 | J20: 4 | K20: 7 | L20: 4 | M20: 7 | N20: 6 | O20: н/а | P20: 4 | Q20: 5 | R20: =IF(COUNTIF(D20:Q20,"=*")>0,"-",(IFERROR(AVERAGE(D20:Q20),""))) -> -
A21: К | B21: 13 | C21: Лукашевич Вікторія Леонідівна | D21: 8 | E21: 8 | F21: 8 | G21: 9 | H21: 9 | I21: 8 | J21: 10 | K21: 8 | L21: 8 | M21: 9 | N21: 9 | O21: 9 | P21: 8 | Q21: 5 | R21: =IF(COUNTIF(D21:Q21,"=*")>0,"-",(IFERROR(AVERAGE(D21:Q21),""))) -> 8.2857143
A22: Б | B22: 14 | C22: Марківська Людмила Олександрівна | D22: 10 | E22: 9 | F22: 10 | G22: 10 | H22: 10 | I22: 11 | J22: 10 | K22: 8 | L22: 10 | M22: 10 | N22: 11 | O22: 10 | P22: 10 | Q22: 10 | R22: =IF(COUNTIF(D22:Q22,"=*")>0,"-",(IFERROR(AVERAGE(D22:Q22),""))) -> 9.9285714
A23: Б | B23: 15 | C23: Огородник Поліна Олегівна | D23: 8 | E23: 10 | F23: 10 | G23: 8 | H23: 10 | I23: 10 | J23: 8 | K23: 8 | L23: 8 | M23: 9 | N23: 9 | O23: 9 | P23: 10 | Q23: 7 | R23: =IF(COUNTIF(D23:Q23,"=*")>0,"-",(IFERROR(AVERAGE(D23:Q23),""))) -> 8.8571429
A24: К | B24: 16 | C24: Олівська Ірина Володимирівна | D24: 7 | E24: 8 | F24: 7 | G24: 6 | H24: 8 | I24: 8 | J24: 8 | K24: 8 | L24: 7 | M24: 8 | N24: 10 | O24: 7 | P24: 8 | Q24: 6 | R24: =IF(COUNTIF(D24:Q24,"=*")>0,"-",(IFERROR(AVERAGE(D24:Q24),""))) -> 7.5714286
A25: Б | B25: 17 | C25: Пулєва Таїсія Михайлівна | D25: 5 | E25: 8 | F25: 9 | G25: 6 | H25: 9 | I25: 6 | J25: 7 | K25: 8 | L25: 6 | M25: 9 | N25: 9 | O25: 6 | P25: 6 | Q25: 6 | R25: =IF(COUNTIF(D25:Q25,"=*")>0,"-",(IFERROR(AVERAGE(D25:Q25),""))) -> 7.1428571
A26: К | B26: 18 | C26: Семкова Олеся Олександрівна | D26: 8 | E26: 9 | F26: 10 | G26: 9 | H26: 10 | I26: 10 | J26: 10 | K26: 8 | L26: 7 | M26: 10 | N26: 10 | O26: 9 | P26: 6 | Q26: 8 | R26: =IF(COUNTIF(D26:Q26,"=*")>0,"-",(IFERROR(AVERAGE(D26:Q26),""))) -> 8.8571429
A27: Б | B27: 19 | C27: Тимусяк Юлія Ігорівна | D27: 8 | E27: 10 | F27: 10 | G27: 9 | H27: 9 | I27: 11 | J27: 8 | K27: 7 | L27: 8 | M27: 9 | N27: 10 | O27: 9 | P27: 8 | Q27: 8 | R27: =IF(COUNTIF(D27:Q27,"=*")>0,"-",(IFERROR(AVERAGE(D27:Q27),""))) -> 8.8571429
A28: К | B28: 20 | C28: Тищенко Дар'я Олександрівна | D28: 8 | E28: 10 | F28: 8 | G28: 10 | H28: 10 | I28: 8 | J28: 9 | K28: 8 | L28: 8 | M28: 8 | N28: 10 | O28: 8 | P28: 8 | Q28: 9 | R28: =IF(COUNTIF(D28:Q28,"=*")>0,"-",(IFERROR(AVERAGE(D28:Q28),""))) -> 8.7142857
A29: Б | B29: 21 | C29: Фурсова Тетяна Валеріївна | D29: 9 | E29: 10 | F29: 10 | G29: 10 | H29: 8 | I29: 10 | J29: 10 | K29: 8 | L29: 10 | M29: 10 | N29: 10 | O29: 10 | P29: 9 | Q29: 9 | R29: =IF(COUNTIF(D29:Q29,"=*")>0,"-",(IFERROR(AVERAGE(D29:Q29),""))) -> 9.5
A30: К | B30: 22 | C30: Холодняк Софія Романівна | D30: 7 | E30: 7 | F30: 5 | G30: н/а | H30: 6 | I30: 6 | J30: 4 | K30: 6 | L30: 6 | M30: 4 | N30: 6 | O30: н/а | P30: 6 | Q30: 7 | R30: =IF(COUNTIF(D30:Q30,"=*")>0,"-",(IFERROR(AVERAGE(D30:Q30),""))) -> -
A31: К | B31: 23 | C31: Царан Максим Андрійович | D31: 4 | E31: 6 | F31: 7 | G31: 4 | H31: 4 | I31: 6 | J31: 6 | K31: 6 | L31: 6 | M31: 4 | N31: 4 | O31: н/а | P31: 10 | Q31: 7 | R31: =IF(COUNTIF(D31:Q31,"=*")>0,"-",(IFERROR(AVERAGE(D31:Q31),""))) -> -
A32: Б | B32: 24 | C32: Цибульська Ольга Євгенівна | D32: 9 | E32: 9 | F32: 9 | G32: 8 | H32: 10 | I32: 7 | J32: 8 | K32: 9 | L32: 8 | M32: 9 | N32: 10 | O32: 8 | P32: 8 | Q32: 7 | R32: =IF(COUNTIF(D32:Q32,"=*")>0,"-",(IFERROR(AVERAGE(D32:Q32),""))) -> 8.5
A33: Б | B33: 25 | C33: Цибульська Поліна Ігорівна | D33: 8 | E33: 9 | F33: 9 | G33: 9 | H33: 9 | I33: 7 | J33: 7 | K33: 7 | L33: 5 | M33: 9 | N33: 10 | O33: 7 | P33: 9 | Q33: 6 | R33: =IF(COUNTIF(D33:Q33,"=*")>0,"-",(IFERROR(AVERAGE(D33:Q33),""))) -> 7.9285714
A34: Б | B34: 26 | C34: Чабан Каріна Ігорівна | D34: 9 | E34: 10 | F34: 10 | G34: 10 | H34: 10 | I34: 9 | J34: 10 | K34: 9 | L34: 8 | M34: 10 | N34: 9 | O34: 10 | P34: 10 | Q34: 7 | R34: =IF(COUNTIF(D34:Q34,"=*")>0,"-",(IFERROR(AVERAGE(D34:Q34),""))) -> 9.3571429
C35: Середній бал успішності з дисципліни | D35: =IF(SUM(D9:D34)/B34=0,"",SUM(D9:D34)/B34) -> 8.2307692 | E35: =IF(SUM(E9:E34)/B34=0,"",SUM(E9:E34)/B34) -> 9.1538462 | F35: =IF(SUM(F9:F34)/B34=0,"",SUM(F9:F34)/B34) -> 9.0384615 | G35: =IF(SUM(G9:G34)/B34=0,"",SUM(G9:G34)/B34) -> 8.0769231 | H35: =IF(SUM(H9:H34)/B34=0,"",SUM(H9:H34)/B34) -> 8.8461538 | I35: =IF(SUM(I9:I34)/B34=0,"",SUM(I9:I34)/B34) -> 8.5384615 | J35: =IF(SUM(J9:J34)/B34=0,"",SUM(J9:J34)/B34) -> 8.3846154 | K35: =IF(SUM(K9:K34)/B34=0,"",SUM(K9:K34)/B34) -> 8 | L35: =IF(SUM(L9:L34)/B34=0,"",SUM(L9:L34)/B34) -> 7.8461538 | M35: =IF(SUM(M9:M34)/B34=0,"",SUM(M9:M34)/B34) -> 8.8461538 | N35: =IF(SUM(N9:N34)/B34=0,"",SUM(N9:N34)/B34) -> 8.9230769 | O35: =IF(SUM(O9:O34)/B34=0,"",SUM(O9:O34)/B34) -> 7.4230769 | P35: =IF(SUM(P9:P34)/B34=0,"",SUM(P9:P34)/B34) -> 8.5384615 | Q35: =IF(SUM(Q9:Q34)/B34=0,"",SUM(Q9:Q34)/B34) -> 7.5 | R35: =IFERROR(AVERAGE(D35:Q35),"") -> 8.3818681
C36: Абсолютна успішність | D36: =IF(COUNTIF(D9:D34,">=4")/B34*100=0,"",COUNTIF(D9:D34,">=4")/B34*100) -> 100 | E36: =IF(COUNTIF(E9:E34,">=4")/B34*100=0,"",COUNTIF(E9:E34,">=4")/B34*100) -> 100 | F36: =IF(COUNTIF(F9:F34,">=4")/B34*100=0,"",COUNTIF(F9:F34,">=4")/B34*100) -> 100 | G36: =IF(COUNTIF(G9:G34,">=4")/B34*100=0,"",COUNTIF(G9:G34,">=4")/B34*100) -> 96.153846 | H36: =IF(COUNTIF(H9:H34,">=4")/B34*100=0,"",COUNTIF(H9:H34,">=4")/B34*100) -> 100 | I36: =IF(COUNTIF(I9:I34,">=4")/B34*100=0,"",COUNTIF(I9:I34,">=4")/B34*100) -> 100 | J36: =IF(COUNTIF(J9:J34,">=4")/B34*100=0,"",COUNTIF(J9:J34,">=4")/B34*100) -> 100 | K36: =IF(COUNTIF(K9:K34,">=4")/B34*100=0,"",COUNTIF(K9:K34,">=4")/B34*100) -> 100 | L36: =IF(COUNTIF(L9:L34,">=4")/B34*100=0,"",COUNTIF(L9:L34,">=4")/B34*100) -> 100 | M36: =IF(COUNTIF(M9:M34,">=4")/B34*100=0,"",COUNTIF(M9:M34,">=4")/B34*100) -> 100 | N36: =IF(COUNTIF(N9:N34,">=4")/B34*100=0,"",COUNTIF(N9:N34,">=4")/B34*100) -> 100 | O36: =IF(COUNTIF(O9:O34,">=4")/B34*100=0,"",COUNTIF(O9:O34,">=4")/B34*100) -> 88.461538 | P36: =IF(COUNTIF(P9:P34,">=4")/B34*100=0,"",COUNTIF(P9:P34,">=4")/B34*100) -> 100 | Q36: =IF(COUNTIF(Q9:Q34,">=4")/B34*100=0,"",COUNTIF(Q9:Q34,">=4")/B34*100) -> 100
C37: Якісна успішність | D37: =IF(COUNTIF(D9:D34,">=7")/B34*100=0,"",COUNTIF(D9:D34,">=7")/B34*100) -> 92.307692 | E37: =IF(COUNTIF(E9:E34,">=7")/B34*100=0,"",COUNTIF(E9:E34,">=7")/B34*100) -> 96.153846 | F37: =IF(COUNTIF(F9:F34,">=7")/B34*100=0,"",COUNTIF(F9:F34,">=7")/B34*100) -> 96.153846 | G37: =IF(COUNTIF(G9:G34,">=7")/B34*100=0,"",COUNTIF(G9:G34,">=7")/B34*100) -> 76.923077 | H37: =IF(COUNTIF(H9:H34,">=7")/B34*100=0,"",COUNTIF(H9:H34,">=7")/B34*100) -> 88.461538 | I37: =IF(COUNTIF(I9:I34,">=7")/B34*100=0,"",COUNTIF(I9:I34,">=7")/B34*100) -> 80.769231 | J37: =IF(COUNTIF(J9:J34,">=7")/B34*100=0,"",COUNTIF(J9:J34,">=7")/B34*100) -> 80.769231 | K37: =IF(COUNTIF(K9:K34,">=7")/B34*100=0,"",COUNTIF(K9:K34,">=7")/B34*100) -> 88.461538 | L37: =IF(COUNTIF(L9:L34,">=7")/B34*100=0,"",COUNTIF(L9:L34,">=7")/B34*100) -> 73.076923 | M37: =IF(COUNTIF(M9:M34,">=7")/B34*100=0,"",COUNTIF(M9:M34,">=7")/B34*100) -> 92.307692 | N37: =IF(COUNTIF(N9:N34,">=7")/B34*100=0,"",COUNTIF(N9:N34,">=7")/B34*100) -> 84.615385 | O37: =IF(COUNTIF(O9:O34,">=7")/B34*100=0,"",COUNTIF(O9:O34,">=7")/B34*100) -> 73.076923 | P37: =IF(COUNTIF(P9:P34,">=7")/B34*100=0,"",COUNTIF(P9:P34,">=7")/B34*100) -> 84.615385 | Q37: =IF(COUNTIF(Q9:Q34,">=7")/B34*100=0,"",COUNTIF(Q9:Q34,">=7")/B34*100) -> 73.076923
C38: Абсолютна успішність по групі | D38: =IFERROR(AVERAGE(D36:Q36),"") -> 98.901099
C39: Якісна успішність по групі | D39: =IFERROR(AVERAGE(D37:Q37),"") -> 84.340659
C40: Кількість бюджетників | D40: =IF(COUNTIF(A9:A34,"=Б")=0,"",COUNTIF(A9:A34,"=Б")) -> 16
...

Sheet Зведена відомість 161
A1: ВСП «ФАХОВИЙ КОЛЕДЖ НАФТОГАЗОВИХ ТЕХНОЛОГІЙ, ІНЖЕНЕРІЇ ТА ІНФРАСТРУКТУРИ СЕРВІСУ
A2: ОДЕСЬКОГО НАЦІОНАЛЬНОГО ТЕХНОЛОГІЧНОГО УНІВЕРСИТЕТУ»
A3: ЗВЕДЕНА ВІДОМІСТЬ
A4: Успішності студентів спеціальності 161 «Хімічні технології»
A5: За I семестр 2022-2023 н.р.
A6: Група 22-1 курс І
A7: Б/К | B7: № п/п | C7: Прізвище, ім’я, по батькові | D7: Підсумкові оцінки дисциплін
D8: Біологія Богданенко О.В. | E8: Всесвітня історія Мельничук С.А. | F8: Географія Наговська Т.С. | G8: Зарубіжна література Пруднікова Я.П. | H8: ЗУ Стельмах Н.Ю. | I8: Іноземна мова Кучер О.П. | J8: Інформатика Вівдіч М.І. | K8: Історія України Левчук Т.Г. | L8: Математика Ромчук В.В. | M8: Українська література Нестеренко А.О. | N8: Українська мова Нестеренко А.О. | O8: Фізика Калюта Н.М. | P8: Фізична культура Кулатов В.М. | Q8: Хімія Леонова Д.І. | R8: Середній бал
A9: Б | B9: 1 | C9: Автушко Гліб Валерійович | D9: 4 | E9: 4 | F9: 5 | G9: 4 | H9: 4 | I9: 4 | J9: 5 | K9: 4 | L9: 4 | M9: 4 | N9: 4 | O9: 4 | P9: 4 | Q9: 5 | R9: =IF(COUNTIF(D9:Q9,"=*")>0,"-",(IFERROR(AVERAGE(D9:Q9),""))) -> 4.2142857
A10: Б | B10: 2 | C10: Добровольский Олександр Олександрович | D10: 8 | E10: 10 | F10: 10 | G10: 8 | H10: 9 | I10: 9 | J10: 10 | K10: 8 | L10: 7 | M10: 10 | N10: 10 | O10: 8 | P10: 10 | Q10: 10 | R10: =IF(COUNTIF(D10:Q10,"=*")>0,"-",(IFERROR(AVERAGE(D10:Q10),""))) -> 9.0714286
A11: Б | B11: 3 | C11: Сухом’ясов Олексій Валерійович | D11: 6 | E11: 6 | F11: 6 | G11: 5 | H11: 9 | I11: 6 | J11: 7 | K11: 7 | L11: 6 | M11: 8 | N11: 7 | O11: 5 | P11: 10 | Q11: 7 | R11: =IF(COUNTIF(D11:Q11,"=*")>0,"-",(IFERROR(AVERAGE(D11:Q11),""))) -> 6.7857143
C12: Середній бал успішності з дисципліни | D12: =IF(SUM(D9:D11)/B11=0,"",SUM(D9:D11)/B11) -> 6 | E12: =IF(SUM(E9:E11)/B11=0,"",SUM(E9:E11)/B11) -> 6.6666667 | F12: =IF(SUM(F9:F11)/B11=0,"",SUM(F9:F11)/B11) -> 7 | G12: =IF(SUM(G9:G11)/B11=0,"",SUM(G9:G11)/B11) -> 5.6666667 | H12: =IF(SUM(H9:H11)/B11=0,"",SUM(H9:H11)/B11) -> 7.3333333 | I12: =IF(SUM(I9:I11)/B11=0,"",SUM(I9:I11)/B11) -> 6.3333333 | J12: =IF(SUM(J9:J11)/B11=0,"",SUM(J9:J11)/B11) -> 7.3333333 | K12: =IF(SUM(K9:K11)/B11=0,"",SUM(K9:K11)/B11) -> 6.3333333 | L12: =IF(SUM(L9:L11)/B11=0,"",SUM(L9:L11)/B11) -> 5.6666667 | M12: =IF(SUM(M9:M11)/B11=0,"",SUM(M9:M11)/B11) -> 7.3333333 | N12: =IF(SUM(N9:N11)/B11=0,"",SUM(N9:N11)/B11) -> 7 | O12: =IF(SUM(O9:O11)/B11=0,"",SUM(O9:O11)/B11) -> 5.6666667 | P12: =IF(SUM(P9:P11)/B11=0,"",SUM(P9:P11)/B11) -> 8 | Q12: =IF(SUM(Q9:Q11)/B11=0,"",SUM(Q9:Q11)/B11) -> 7.3333333 | R12: =IFERROR(AVERAGE(D12:Q12),"") -> 6.6904762
C13: Абсолютна успішність | D13: =IF(COUNTIF(D9:D11,">=4")/B11*100=0,"",COUNTIF(D9:D11,">=4")/B11*100) -> 100 | E13: =IF(COUNTIF(E9:E11,">=4")/B11*100=0,"",COUNTIF(E9:E11,">=4")/B11*100) -> 100 | F13: =IF(COUNTIF(F9:F11,">=4")/B11*100=0,"",COUNTIF(F9:F11,">=4")/B11*100) -> 100 | G13: =IF(COUNTIF(G9:G11,">=4")/B11*100=0,"",COUNTIF(G9:G11,">=4")/B11*100) -> 100 | H13: =IF(COUNTIF(H9:H11,">=4")/B11*100=0,"",COUNTIF(H9:H11,">=4")/B11*100) -> 100 | I13: =IF(COUNTIF(I9:I11,">=4")/B11*100=0,"",COUNTIF(I9:I11,">=4")/B11*100) -> 100 | J13: =IF(COUNTIF(J9:J11,">=4")/B11*100=0,"",COUNTIF(J9:J11,">=4")/B11*100) -> 100 | K13: =IF(COUNTIF(K9:K11,">=4")/B11*100=0,"",COUNTIF(K9:K11,">=4")/B11*100) -> 100 | L13: =IF(COUNTIF(L9:L11,">=4")/B11*100=0,"",COUNTIF(L9:L11,">=4")/B11*100) -> 100 | M13: =IF(COUNTIF(M9:M11,">=4")/B11*100=0,"",COUNTIF(M9:M11,">=4")/B11*100) -> 100 | N13: =IF(COUNTIF(N9:N11,">=4")/B11*100=0,"",COUNTIF(N9:N11,">=4")/B11*100) -> 100 | O13: =IF(COUNTIF(O9:O11,">=4")/B11*100=0,"",COUNTIF(O9:O11,">=4")/B11*100) -> 100 | P13: =IF(COUNTIF(P9:P11,">=4")/B11*100=0,"",COUNTIF(P9:P11,">=4")/B11*100) -> 100 | Q13: =IF(COUNTIF(Q9:Q11,">=4")/B11*100=0,"",COUNTIF(Q9:Q11,">=4")/B11*100) -> 100
C14: Якісна успішність | D14: =IF(COUNTIF(D9:D11,">=7")/B11*100=0,"",COUNTIF(D9:D11,">=7")/B11*100) -> 33.333333 | E14: =IF(COUNTIF(E9:E11,">=7")/B11*100=0,"",COUNTIF(E9:E11,">=7")/B11*100) -> 33.333333 | F14: =IF(COUNTIF(F9:F11,">=7")/B11*100=0,"",COUNTIF(F9:F11,">=7")/B11*100) -> 33.333333 | G14: =IF(COUNTIF(G9:G11,">=7")/B11*100=0,"",COUNTIF(G9:G11,">=7")/B11*100) -> 33.333333 | H14: =IF(COUNTIF(H9:H11,">=7")/B11*100=0,"",COUNTIF(H9:H11,">=7")/B11*100) -> 66.666667 | I14: =IF(COUNTIF(I9:I11,">=7")/B11*100=0,"",COUNTIF(I9:I11,">=7")/B11*100) -> 33.333333 | J14: =IF(COUNTIF(J9:J11,">=7")/B11*100=0,"",COUNTIF(J9:J11,">=7")/B11*100) -> 66.666667 | K14: =IF(COUNTIF(K9:K11,">=7")/B11*100=0,"",COUNTIF(K9:K11,">=7")/B11*100) -> 66.666667 | L14: =IF(COUNTIF(L9:L11,">=7")/B11*100=0,"",COUNTIF(L9:L11,">=7")/B11*100) -> 33.333333 | M14: =IF(COUNTIF(M9:M11,">=7")/B11*100=0,"",COUNTIF(M9:M11,">=7")/B11*100) -> 66.666667 | N14: =IF(COUNTIF(N9:N11,">=7")/B11*100=0,"",COUNTIF(N9:N11,">=7")/B11*100) -> 66.666667 | O14: =IF(COUNTIF(O9:O11,">=7")/B11*100=0,"",COUNTIF(O9:O11,">=7")/B11*100) -> 33.333333 | P14: =IF(COUNTIF(P9:P11,">=7")/B11*100=0,"",COUNTIF(P9:P11,">=7")/B11*100) -> 66.666667 | Q14: =IF(COUNTIF(Q9:Q11,">=7")/B11*100=0,"",COUNTIF(Q9:Q11,">=7")/B11*100) -> 66.666667
C15: Абсолютна успішність по групі | D15: =IFERROR(AVERAGE(D13:Q13),"") -> 100
C16: Якісна успішність по групі | D16: =IFERROR(AVERAGE(D14:Q14),"") -> 50
C17: Кількість бюджетників | D17: =IF(COUNTIF(A9:A11,"=Б")=0,"",COUNTIF(A9:A11,"=Б")) -> 3
C18: Кількість контрактників | D18: 0 | F18: Класний керівник | M18: Віра МЄШКОВА
C19: Кількість соціального контингенту | D19: 1
C20: Вийшли на стипендію | D20: ='Рейтингова відомість 161'!D15 -> 1 | F20: Завідувач відділення ПЗСО | M20: Маргарита БРІТІКОВА

Sheet Зведена відомість 241
A1: ВСП «ФАХОВИЙ КОЛЕДЖ НАФТОГАЗОВИХ ТЕХНОЛОГІЙ, ІНЖЕНЕРІЇ ТА ІНФРАСТРУКТУРИ СЕРВІСУ
A2: ОДЕСЬКОГО НАЦІОНАЛЬНОГО ТЕХНОЛОГІЧНОГО УНІВЕРСИТЕТУ»
A3: ЗВЕДЕНА ВІДОМІСТЬ
A4: Успішності студентів спеціальності 241 «Готельно-ресторанна справа»
A5: За I семестр 2022-2023 н.р.
A6: Група 22-1 курс І
A7: Б/К | B7: № п/п | C7: Прізвище, ім’я, по батькові | D7: Підсумкові оцінки дисциплін
D8: Біологія Богданенко О.В. | E8: Всесвітня історія Мельничук С.А. | F8: Географія Наговська Т.С. | G8: Зарубіжна література Пруднікова Я.П. | H8: ЗУ Стельмах Н.Ю. | I8: Іноземна мова Кучер О.П. | J8: Інформатика Вівдіч М.І. | K8: Історія України Левчук Т.Г. | L8: Математика Ромчук В.В. | M8: Українська література Нестеренко А.О. | N8: Українська мова Нестеренко А.О. | O8: Фізика Калюта Н.М. | P8: Фізична культура Кулатов В.М. | Q8: Хімія Леонова Д.І. | R8: Середній бал
A9: К | B9: 1 | C9: Андрєєва Анна Сергіївна | D9: 4 | E9: 6 | F9: 7 | G9: 4 | H9: 7 | I9: 6 | J9: 5 | K9: 6 | L9: 4 | M9: 5 | N9: 4 | O9: 4 | P9: 4 | Q9: 5 | R9: =IF(COUNTIF(D9:Q9,"=*")>0,"-",(IFERROR(AVERAGE(D9:Q9),""))) -> 5.0714286
A10: К | B10: 2 | C10: Журавльова Дар’я Олександрівна | D10: 7 | E10: 6 | F10: 6 | G10: 4 | H10: 5 | I10: 4 | J10: 6 | K10: 7 | L10: 4 | M10: 9 | N10: 9 | O10: н/а | P10: 6 | Q10: 5 | R10: =IF(COUNTIF(D10:Q10,"=*")>0,"-",(IFERROR(AVERAGE(D10:Q10),""))) -> -
C11: Середній бал успішності з дисципліни | D11: =IF(SUM(D9:D10)/B10=0,"",SUM(D9:D10)/B10) -> 5.5 | E11: =IF(SUM(E9:E10)/B10=0,"",SUM(E9:E10)/B10) -> 6 | F11: =IF(SUM(F9:F10)/B10=0,"",SUM(F9:F10)/B10) -> 6.5 | G11: =IF(SUM(G9:G10)/B10=0,"",SUM(G9:G10)/B10) -> 4 | H11: =IF(SUM(H9:H10)/B10=0,"",SUM(H9:H10)/B10) -> 6 | I11: =IF(SUM(I9:I10)/B10=0,"",SUM(I9:I10)/B10) -> 5 | J11: =IF(SUM(J9:J10)/B10=0,"",SUM(J9:J10)/B10) -> 5.5 | K11: =IF(SUM(K9:K10)/B10=0,"",SUM(K9:K10)/B10) -> 6.5 | L11: =IF(SUM(L9:L10)/B10=0,"",SUM(L9:L10)/B10) -> 4 | M11: =IF(SUM(M9:M10)/B10=0,"",SUM(M9:M10)/B10) -> 7 | N11: =IF(SUM(N9:N10)/B10=0,"",SUM(N9:N10)/B10) -> 6.5 | O11: =IF(SUM(O9:O10)/B10=0,"",SUM(O9:O10)/B10) -> 2 | P11: =IF(SUM(P9:P10)/B10=0,"",SUM(P9:P10)/B10) -> 5 | Q11: =IF(SUM(Q9:Q10)/B10=0,"",SUM(Q9:Q10)/B10) -> 5 | R11: =IFERROR(AVERAGE(D11:Q11),"") -> 5.3214286
C12: Абсолютна успішність | D12: =IF(COUNTIF(D9:D10,">=4")/B10*100=0,"",COUNTIF(D9:D10,">=4")/B10*100) -> 100 | E12: =IF(COUNTIF(E9:E10,">=4")/B10*100=0,"",COUNTIF(E9:E10,">=4")/B10*100) -> 100 | F12: =IF(COUNTIF(F9:F10,">=4")/B10*100=0,"",COUNTIF(F9:F10,">=4")/B10*100) -> 100 | G12: =IF(COUNTIF(G9:G10,">=4")/B10*100=0,"",COUNTIF(G9:G10,">=4")/B10*100) -> 100 | H12: =IF(COUNTIF(H9:H10,">=4")/B10*100=0,"",COUNTIF(H9:H10,">=4")/B10*100) -> 100 | I12: =IF(COUNTIF(I9:I10,">=4")/B10*100=0,"",COUNTIF(I9:I10,">=4")/B10*100) -> 100 | J12: =IF(COUNTIF(J9:J10,">=4")/B10*100=0,"",COUNTIF(J9:J10,">=4")/B10*100) -> 100 | K12: =IF(COUNTIF(K9:K10,">=4")/B10*100=0,"",COUNTIF(K9:K10,">=4")/B10*100) -> 100 | L12: =IF(COUNTIF(L9:L10,">=4")/B10*100=0,"",COUNTIF(L9:L10,">=4")/B10*100) -> 100 | M12: =IF(COUNTIF(M9:M10,">=4")/B10*100=0,"",COUNTIF(M9:M10,">=4")/B10*100) -> 100 | N12: =IF(COUNTIF(N9:N10,">=4")/B10*100=0,"",COUNTIF(N9:N10,">=4")/B10*100) -> 100 | O12: =IF(COUNTIF(O9:O10,">=4")/B10*100=0,"",COUNTIF(O9:O10,">=4")/B10*100) -> 50 | P12: =IF(COUNTIF(P9:P10,">=4")/B10*100=0,"",COUNTIF(P9:P10,">=4")/B10*100) -> 100 | Q12: =IF(COUNTIF(Q9:Q10,">=4")/B10*100=0,"",COUNTIF(Q9:Q10,">=4")/B10*100) -> 100
C13: Якісна успішність | D13: =IF(COUNTIF(D9:D10,">=7")/B10*100=0,"",COUNTIF(D9:D10,">=7")/B10*100) -> 50 | E13: 0 | F13: =IF(COUNTIF(F9:F10,">=7")/B10*100=0,"",COUNTIF(F9:F10,">=7")/B10*100) -> 50 | G13: 0 | H13: =IF(COUNTIF(H9:H10,">=7")/B10*100=0,"",COUNTIF(H9:H10,">=7")/B10*100) -> 50 | I13: 0 | J13: 0 | K13: =IF(COUNTIF(K9:K10,">=7")/B10*100=0,"",COUNTIF(K9:K10,">=7")/B10*100) -> 50 | L13: 0 | M13: =IF(COUNTIF(M9:M10,">=7")/B10*100=0,"",COUNTIF(M9:M10,">=7")/B10*100) -> 50 | N13: =IF(COUNTIF(N9:N10,">=7")/B10*100=0,"",COUNTIF(N9:N10,">=7")/B10*100) -> 50 | O13: 0 | P13: 0 | Q13: 0
C14: Абсолютна успішність по групі | D14: =IFERROR(AVERAGE(D12:Q12),"") -> 96.428571
C15: Якісна успішність по групі | D15: =IFERROR(AVERAGE(D13:Q13),"") -> 21.428571
C16: Кількість бюджетників | D16: 0 | F16: Класний керівник | M16: Віра МЄШКОВА
C17: Кількість контрактників | D17: 2
C18: Кількість соціального контингенту | D18: 0 | F18: Завідувач відділення ПЗСО | M18: Маргарита БРІТІКОВА

Sheet Рейтингова відомість 075
A1: ВСП «ФАХОВИЙ КОЛЕДЖ НАФТОГАЗОВИХ ТЕХНОЛОГІЙ, ІНЖЕНЕРІЇ ТА ІНФРАСТРУКТУРИ СЕРВІСУ
A2: ОДЕСЬКОГО НАЦІОНАЛЬНОГО ТЕХНОЛОГІЧНОГО УНІВЕРСИТЕТУ»
A3: РЕЙТИНГОВА ВІДОМІСТЬ
A4: Успішності студентів спеціальності 075 «Маркетинг»
A5: За I семестр 2022-2023 н.р.
A6: Група 22-1 курс І
A7: Б/К | B7: № п/п | C7: Прізвище, ім’я, по батькові | D7: Підсумкові оцінки дисциплін
D8: Біологія Богданенко О.В. | E8: Всесвітня історія Мельничук С.А. | F8: Географія Наговська Т.С. | G8: Зарубіжна література Пруднікова Я.П. | H8: ЗУ Стельмах Н.Ю. | I8: Іноземна мова Кучер О.П. | J8: Інформатика Вівдіч М.І. | K8: Історія України Левчук Т.Г. | L8: Математика Ромчук В.В. | M8: Українська література Нестеренко А.О. | N8: Українська мова Нестеренко А.О. | O8: Фізика Калюта Н.М. | P8: Фізична культура Кулатов В.М. | Q8: Хімія Леонова Д.І. | R8: Середній бал | S8: Рейтинговий бал
A9: Б | B9: 1 | C9: Дурбалов Андрій Геннадійович | D9: 10 | E9: 10 | F9: 10 | G9: 10 | H9: 10 | I9: 11 | J9: 11 | K9: 10 | L9: 10 | M9: 10 | N9: 10 | O9: 10 | P9: 10 | Q9: 10 | R9: =IF(COUNTIF(D9:Q9,"=*")>0,"-",(IFERROR(AVERAGE(D9:Q9),""))) -> 10.142857 | S9: =R9*90/12 -> 76.071429
A10: Б | B10: 2 | C10: Єремеєва Дар’я Сергіївна | D10: 10 | E10: 10 | F10: 10 | G10: 10 | H10: 9 | I10: 11 | J10: 10 | K10: 9 | L10: 10 | M10: 10 | N10: 10 | O10: 10 | P10: 10 | Q10: 10 | R10: =IF(COUNTIF(D10:Q10,"=*")>0,"-",(IFERROR(AVERAGE(D10:Q10),""))) -> 9.9285714 | S10: =R10*90/12 -> 74.464286
A11: Б | B11: 3 | C11: Марківська Людмила Олександрівна | D11: 10 | E11: 9 | F11: 10 | G11: 10 | H11: 10 | I11: 11 | J11: 10 | K11: 8 | L11: 10 | M11: 10 | N11: 11 | O11: 10 | P11: 10 | Q11: 10 | R11: =IF(COUNTIF(D11:Q11,"=*")>0,"-",(IFERROR(AVERAGE(D11:Q11),""))) -> 9.9285714 | S11: =R11*90/12 -> 74.464286
A12: Б | B12: 4 | C12: Гуркіна Анна Ігорівна | D12: 10 | E12: 10 | F12: 10 | G12: 9 | H12: 10 | I12: 10 | J12: 10 | K12: 9 | L12: 10 | M12: 10 | N12: 10 | O12: 10 | P12: 10 | Q12: 10 | R12: =IF(COUNTIF(D12:Q12,"=*")>0,"-",(IFERROR(AVERAGE(D12:Q12),""))) -> 9.8571429 | S12: =R12*90/12 -> 73.928571
A13: Б | B13: 5 | C13: Калугіна Анастасія Дмитрівна | D13: 9 | E13: 10 | F13: 10 | G13: 10 | H13: 10 | I13: 10 | J13: 10 | K13: 9 | L13: 10 | M13: 10 | N13: 9 | O13: 10 | P13: 10 | Q13: 8 | R13: =IF(COUNTIF(D13:Q13,"=*")>0,"-",(IFERROR(AVERAGE(D13:Q13),""))) -> 9.6428571 | S13: =R13*90/12 -> 72.321429
A14: Б | B14: 6 | C14: Фурсова Тетяна Валеріївна | D14: 9 | E14: 10 | F14: 10 | G14: 10 | H14: 8 | I14: 10 | J14: 10 | K14: 8 | L14: 10 | M14: 10 | N14: 10 | O14: 10 | P14: 9 | Q14: 9 | R14: =IF(COUNTIF(D14:Q14,"=*")>0,"-",(IFERROR(AVERAGE(D14:Q14),""))) -> 9.5 | S14: =R14*90/12 -> 71.25
A15: Б | B15: 7 | C15: Чабан Каріна Ігорівна | D15: 9 | E15: 10 | F15: 10 | G15: 10 | H15: 10 | I15: 9 | J15: 10 | K15: 9 | L15: 8 | M15: 10 | N15: 9 | O15: 10 | P15: 10 | Q15: 7 | R15: =IF(COUNTIF(D15:Q15,"=*")>0,"-",(IFERROR(AVERAGE(D15:Q15),""))) -> 9.3571429 | S15: =R15*90/12 -> 70.178571
A16: Б | B16: 8 | C16: Дмуховська Аліса Андріївна | D16: 9 | E16: 10 | F16: 10 | G16: 9 | H16: 10 | I16: 10 | J16: 10 | K16: 9 | L16: 8 | M16: 10 | N16: 10 | O16: 8 | P16: 10 | Q16: 7 | R16: =IF(COUNTIF(D16:Q16,"=*")>0,"-",(IFERROR(AVERAGE(D16:Q16),""))) -> 9.2857143 | S16: =R16*90/12 -> 69.642857
A17: Б | B17: 9 | C17: Діденко Софья Андріївна | D17: 9 | E17: 9 | F17: 10 | G17: 10 | H17: 10 | I17: 10 | J17: 8 | K17: 9 | L17: 9 | M17: 10 | N17: 9 | O17: 6 | P17: 10 | Q17: 8 | R17: =IF(COUNTIF(D17:Q17,"=*")>0,"-",(IFERROR(AVERAGE(D17:Q17),""))) -> 9.0714286 | S17: =R17*90/12 -> 68.035714
A18: Б | B18: 10 | C18: Огородник Поліна Олегівна | D18: 8 | E18: 10 | F18: 10 | G18: 8 | H18: 10 | I18: 10 | J18: 8 | K18: 8 | L18: 8 | M18: 9 | N18: 9 | O18: 9 | P18: 10 | Q18: 7 | R18: =IF(COUNTIF(D18:Q18,"=*")>0,"-",(IFERROR(AVERAGE(D18:Q18),""))) -> 8.8571429 | S18: =R18*90/12 -> 66.428571
A19: Б | B19: 11 | C19: Тимусяк Юлія Ігорівна | D19: 8 | E19: 10 | F19: 10 | G19: 9 | H19: 9 | I19: 11 | J19: 8 | K19: 7 | L19: 8 | M19: 9 | N19: 10 | O19: 9 | P19: 8 | Q19: 8 | R19: =IF(COUNTIF(D19:Q19,"=*")>0,"-",(IFERROR(AVERAGE(D19:Q19),""))) -> 8.8571429 | S19: =R19*90/12 -> 66.428571
A20: Б | B20: 12 | C20: Цибульська Ольга Євгенівна | D20: 9 | E20: 9 | F20: 9 | G20: 8 | H20: 10 | I20: 7 | J20: 8 | K20: 9 | L20: 8 | M20: 9 | N20: 10 | O20: 8 | P20: 8 | Q20: 7 | R20: =IF(COUNTIF(D20:Q20,"=*")>0,"-",(IFERROR(AVERAGE(D20:Q20),""))) -> 8.5 | S20: =R20*90/12 -> 63.75
... A24: Б | B24: 16 | C24: Гуменюк Аміна Міххтіївна | D24: 7 | E24: 9 | F24: 7 | G24: 4 | H24: 7 | I24: 6 | J24: 5 | K24: 8 | L24: 6 | M24: 7 | N24: 10 | O24: 6 | P24: 10 | Q24: 6 | R24: =IF(COUNTIF(D24:Q24,"=*")>0,"-",(IFERROR(AVERAGE(D24:Q24),""))) -> 7 | S24: =R24*90/12 -> 52.5
C25: Кількість бюджетників | D25: ='Зведена відомість 075'!D40 -> 16
C26: Кількість контрактників | D26: ='Зведена відомість 075'!D41 -> 10 | F26: Класний керівник | M26: Віра МЄШКОВА
C27: Кількість соціального контингенту | D27: ='Зведена відомість 075'!D42 -> 2
C28: Вийшли на стипендію | D28: 6 | F28: Завідувач відділення ПЗСО | M28: Маргарита БРІТІКОВА

Sheet Рейтингова відомість 161
A1: ВСП «ФАХОВИЙ КОЛЕДЖ НАФТОГАЗОВИХ ТЕХНОЛОГІЙ, ІНЖЕНЕРІЇ ТА ІНФРАСТРУКТУРИ СЕРВІСУ
A2: ОДЕСЬКОГО НАЦІОНАЛЬНОГО ТЕХНОЛОГІЧНОГО УНІВЕРСИТЕТУ»
A3: РЕЙТИНГОВА ВІДОМІСТЬ
A4: Успішності студентів спеціальності 161 «Хімічні технології»
A5: За I семестр 2022-2023 н.р.
A6: Група 22-1 курс І
A7: Б/К | B7: № п/п | C7: Прізвище, ім’я, по батькові | D7: Підсумкові оцінки дисциплін
D8: Біологія Богданенко О.В. | E8: Всесвітня історія Мельничук С.А. | F8: Географія Наговська Т.С. | G8: Зарубіжна література Пруднікова Я.П. | H8: ЗУ Стельмах Н.Ю. | I8: Іноземна мова Кучер О.П. | J8: Інформатика Вівдіч М.І. | K8: Історія України Левчук Т.Г. | L8: Математика Ромчук В.В. | M8: Українська література Нестеренко А.О. | N8: Українська мова Нестеренко А.О. | O8: Фізика Калюта Н.М. | P8: Фізична культура Кулатов В.М. | Q8: Хімія Леонова Д.І. | R8: Середній бал | S8: Рейтинговий бал
A9: Б | B9: 1 | C9: Добровольский Олександр Олександрович | D9: 8 | E9: 10 | F9: 10 | G9: 8 | H9: 9 | I9: 9 | J9: 10 | K9: 8 | L9: 7 | M9: 10 | N9: 10 | O9: 8 | P9: 10 | Q9: 10 | R9: =IF(COUNTIF(D9:Q9,"=*")>0,"-",(IFERROR(AVERAGE(D9:Q9),""))) -> 9.0714286 | S9: =R9*90/12 -> 68.035714
A10: Б | B10: 2 | C10: Сухом’ясов Олексій Валерійович | D10: 6 | E10: 6 | F10: 6 | G10: 5 | H10: 9 | I10: 6 | J10: 7 | K10: 7 | L10: 6 | M10: 8 | N10: 7 | O10: 5 | P10: 10 | Q10: 7 | R10: =IF(COUNTIF(D10:Q10,"=*")>0,"-",(IFERROR(AVERAGE(D10:Q10),""))) -> 6.7857143 | S10: =R10*90/12 -> 50.892857
A11: Б | B11: 3 | C11: Автушко Гліб Валерійович | D11: 4 | E11: 4 | F11: 5 | G11: 4 | H11: 4 | I11: 4 | J11: 5 | K11: 4 | L11: 4 | M11: 4 | N11: 4 | O11: 4 | P11: 4 | Q11: 5 | R11: =IF(COUNTIF(D11:Q11,"=*")>0,"-",(IFERROR(AVERAGE(D11:Q11),""))) -> 4.2142857 | S11: =R11*90/12 -> 31.607143
C12: Кількість бюджетників | D12: ='Зведена відомість 161'!D17 -> 3
C13: Кількість контрактників | D13: ='Зведена відомість 161'!D18 -> 0 | F13: Класний керівник | M13: Віра МЄШКОВА
C14: Кількість соціального контингенту | D14: ='Зведена відомість 161'!D19 -> 1
C15: Вийшли на стипендію | D15: 1 | F15: Завідувач відділення ПЗСО | M15: Маргарита БРІТІКОВА
