Workbook
Name Ф80: #REF!
Name Ф80: #REF!
Name Ф80: #REF!

Sheet Зведена 101
C3: ВІДОКРЕМЛЕНИЙ СТРУКТУРНИЙ ПІДРОЗДІЛ «ФАХОВИЙ КОЛЕДЖ НАФТОГАЗОВИХ ТЕХНОЛОГІЙ, ІНЖЕНЕРІЇ ТА ІНФРАСТРУКТУРИ СЕРВІСУ
C4: ОДЕСЬКОГО НАЦІОНАЛЬНОГО ТЕХНОЛОГІЧНОГО УНІВЕРСИТЕТУ»
C5: ЗВЕДЕНА ВІДОМІСТЬ
C6: Успішності студентів спеціальності 241 «Готельно-ресторанна справа»
C7: За рік 2023-2024 н.р.
C8: Група 23-6 курс І
C9: Б/К | D9: № п/п | E9: Прізвище, ім’я, по батькові | F9: Підсумкові оцінки дисциплін
F10: Астрономія Наговська Т.С. | G10: Біологія Богданенко О.В. | H10: Всесвітня історія Мельничук С.А. | I10: Географія Наговська Т.С. | J10: Зарубіжна література Сербулова Ю.А. | K10: Захист України Лазар В.І. | L10: Іноземна мова Сербулова Ю.А. | M10: Інформатика Вівдіч М.І. | N10: Історія України Левчук Т.Г. | O10: Математика Нужна Н.В. | P10: Українська література Антропова Л.І. | Q10: Українська мова Антропова Л.І. | R10: Фізика Калюта Н.М. | S10: Фізична культура Галеніна І.С. | T10: Хімія Леонова Д.І. | U10: Середній бал
C11: К | D11: 1 | E11: Бакрив Олександра Сергіївна | F11: ='Лист1'!C3 -> 9 | G11: ='Лист1'!D3 -> 8 | H11: ='Лист1'!E3 -> 8 | I11: ='Лист1'!F3 -> 10 | J11: ='Лист1'!G3 -> 10 | K11: ='Лист1'!H3 -> 8 | L11: ='Лист1'!I3 -> 7 | M11: ='Лист1'!J3 -> 9 | ... T11: ='Лист1'!Q3 -> 7 | U11: =IF(COUNTIF(F11:T11,"=*")>0,"-",IF(COUNTIF(F11:T11,"<4")>0,"-",(IFERROR(AVERAGE(F11:T11),"")))) -> 8
C12: К | D12: 2 | E12: Башли Владлена Анатоліївна | F12: ='Лист1'!C4 -> 10 | G12: ='Лист1'!D4 -> 8 | H12: ='Лист1'!E4 -> 10 | I12: ='Лист1'!F4 -> 10 | J12: ='Лист1'!G4 -> 10 | K12: ='Лист1'!H4 -> 9 | L12: ='Лист1'!I4 -> 10 | M12: ='Лист1'!J4 -> 7 | ... T12: ='Лист1'!Q4 -> 7 | U12: =IF(COUNTIF(F12:T12,"=*")>0,"-",IF(COUNTIF(F12:T12,"<4")>0,"-",(IFERROR(AVERAGE(F12:T12),"")))) -> 8.8666667
C13: К | D13: 3 | E13: Бубнова Ірина Олегівна | F13: ='Лист1'!C6 -> 7 | G13: ='Лист1'!D6 -> 6 | H13: ='Лист1'!E6 -> 9 | I13: ='Лист1'!F6 -> 8 | J13: ='Лист1'!G6 -> 11 | K13: ='Лист1'!H6 -> н/а | L13: ='Лист1'!I6 -> 10 | M13: ='Лист1'!J6 -> 6 | ... S13: ='Лист1'!P6 -> 4 | T13: ='Лист1'!Q5 -> 9 | U13: =IF(COUNTIF(F13:T13,"=*")>0,"-",IF(COUNTIF(F13:T13,"<4")>0,"-",(IFERROR(AVERAGE(F13:T13),"")))) -> -
C14: К | D14: 4 | E14: Вдов Евеліна Віталіївна | F14: ='Лист1'!C7 -> 8 | G14: ='Лист1'!D7 -> 5 | H14: ='Лист1'!E7 -> 9 | I14: ='Лист1'!F7 -> 9 | J14: ='Лист1'!G7 -> 9 | K14: ='Лист1'!H7 -> н/а | L14: ='Лист1'!I7 -> 7 | M14: ='Лист1'!J7 -> 4 | ... S14: ='Лист1'!P7 -> 4 | T14: ='Лист1'!Q6 -> 6 | U14: =IF(COUNTIF(F14:T14,"=*")>0,"-",IF(COUNTIF(F14:T14,"<4")>0,"-",(IFERROR(AVERAGE(F14:T14),"")))) -> -
C15: К | D15: 5 | E15: Войт Кіра Максимівна | F15: ='Лист1'!C9 -> 10 | G15: ='Лист1'!D9 -> 10 | H15: ='Лист1'!E9 -> 10 | I15: ='Лист1'!F9 -> 10 | J15: ='Лист1'!G9 -> 10 | K15: ='Лист1'!H9 -> 11 | L15: ='Лист1'!I9 -> 11 | M15: ='Лист1'!J9 -> 10 | ... S15: ='Лист1'!P9 -> 11 | T15: ='Лист1'!Q7 -> 6 | U15: =IF(COUNTIF(F15:T15,"=*")>0,"-",IF(COUNTIF(F15:T15,"<4")>0,"-",(IFERROR(AVERAGE(F15:T15),"")))) -> 9.8666667
C16: К | D16: 6 | E16: Іванова Анастасія Анатоліївна | F16: ='Лист1'!C12 -> 9 | G16: ='Лист1'!D12 -> 9 | H16: ='Лист1'!E12 -> 10 | I16: ='Лист1'!F12 -> 9 | J16: ='Лист1'!G12 -> 11 | K16: ='Лист1'!H12 -> н/а | L16: ='Лист1'!I12 -> 10 | M16: ='Лист1'!J12 -> 7 | ... S16: ='Лист1'!P12 -> 4 | T16: ='Лист1'!Q8 -> 5 | U16: =IF(COUNTIF(F16:T16,"=*")>0,"-",IF(COUNTIF(F16:T16,"<4")>0,"-",(IFERROR(AVERAGE(F16:T16),"")))) -> -
C17: К | D17: 7 | E17: Івненко Аліна Володимирівна | F17: ='Лист1'!C13 -> 7 | G17: ='Лист1'!D13 -> 5 | H17: ='Лист1'!E13 -> 6 | I17: ='Лист1'!F13 -> 6 | J17: ='Лист1'!G13 -> 5 | K17: ='Лист1'!H13 -> 4 | L17: ='Лист1'!I13 -> 5 | M17: ='Лист1'!J13 -> н/а | ... S17: ='Лист1'!P13 -> 4 | T17: ='Лист1'!Q9 -> 9 | U17: =IF(COUNTIF(F17:T17,"=*")>0,"-",IF(COUNTIF(F17:T17,"<4")>0,"-",(IFERROR(AVERAGE(F17:T17),"")))) -> -
C18: К | D18: 8 | E18: Карнаушенко Софія Романівна | F18: ='Лист1'!C14 -> 9 | G18: ='Лист1'!D14 -> 7 | H18: ='Лист1'!E14 -> 8 | I18: ='Лист1'!F14 -> 10 | J18: ='Лист1'!G14 -> 10 | K18: ='Лист1'!H14 -> 8 | L18: ='Лист1'!I14 -> 10 | M18: ='Лист1'!J14 -> 5 | ... S18: ='Лист1'!P14 -> 10 | T18: ='Лист1'!Q10 -> 5 | U18: =IF(COUNTIF(F18:T18,"=*")>0,"-",IF(COUNTIF(F18:T18,"<4")>0,"-",(IFERROR(AVERAGE(F18:T18),"")))) -> 7.2
C19: К | D19: 9 | E19: Коновальчук Назар Сергійович | F19: ='Лист1'!C15 -> 7 | G19: ='Лист1'!D15 -> 7 | H19: ='Лист1'!E15 -> 8 | I19: ='Лист1'!F15 -> 8 | J19: ='Лист1'!G15 -> 7 | K19: ='Лист1'!H15 -> н/а | L19: ='Лист1'!I15 -> 7 | M19: ='Лист1'!J15 -> 7 | ... S19: ='Лист1'!P15 -> 5 | T19: ='Лист1'!Q11 -> 8 | U19: =IF(COUNTIF(F19:T19,"=*")>0,"-",IF(COUNTIF(F19:T19,"<4")>0,"-",(IFERROR(AVERAGE(F19:T19),"")))) -> -
C20: К | D20: 10 | E20: Костюченко Вікторія Костянтинівна | F20: ='Лист1'!C16 -> 8 | G20: ='Лист1'!D16 -> 8 | H20: ='Лист1'!E16 -> 8 | I20: ='Лист1'!F16 -> 6 | J20: ='Лист1'!G16 -> 9 | K20: ='Лист1'!H16 -> н/а | L20: ='Лист1'!I16 -> 7 | M20: ='Лист1'!J16 -> 7 | ... S20: ='Лист1'!P16 -> 4 | T20: ='Лист1'!Q12 -> 6 | U20: =IF(COUNTIF(F20:T20,"=*")>0,"-",IF(COUNTIF(F20:T20,"<4")>0,"-",(IFERROR(AVERAGE(F20:T20),"")))) -> -
C21: К | D21: 11 | E21: Крешун Ірина Сергіївна | F21: ='Лист1'!C17 -> 10 | G21: ='Лист1'!D17 -> 10 | H21: ='Лист1'!E17 -> 10 | I21: ='Лист1'!F17 -> 10 | J21: ='Лист1'!G17 -> 11 | K21: ='Лист1'!H17 -> 10 | L21: ='Лист1'!I17 -> 11 | M21: ='Лист1'!J17 -> 7 | ... S21: ='Лист1'!P17 -> 10 | T21: ='Лист1'!Q13 -> 5 | U21: =IF(COUNTIF(F21:T21,"=*")>0,"-",IF(COUNTIF(F21:T21,"<4")>0,"-",(IFERROR(AVERAGE(F21:T21),"")))) -> 9.0666667
C22: К | D22: 12 | E22: Майорова Анна Романівна | F22: ='Лист1'!C18 -> 10 | G22: ='Лист1'!D18 -> 8 | H22: ='Лист1'!E18 -> 9 | I22: ='Лист1'!F18 -> 9 | J22: ='Лист1'!G18 -> 10 | K22: ='Лист1'!H18 -> 8 | L22: ='Лист1'!I18 -> 6 | M22: ='Лист1'!J18 -> 6 | ... S22: ='Лист1'!P18 -> 8 | T22: ='Лист1'!Q14 -> 5 | U22: =IF(COUNTIF(F22:T22,"=*")>0,"-",IF(COUNTIF(F22:T22,"<4")>0,"-",(IFERROR(AVERAGE(F22:T22),"")))) -> 7.4666667
C23: К | D23: 13 | E23: Мартишев Давид Денисович | F23: ='Лист1'!C19 -> 9 | G23: ='Лист1'!D19 -> 9 | H23: ='Лист1'!E19 -> 8 | I23: ='Лист1'!F19 -> 9 | J23: ='Лист1'!G19 -> 9 | K23: ='Лист1'!H19 -> 8 | L23: ='Лист1'!I19 -> 9 | M23: ='Лист1'!J19 -> 7 | ... S23: ='Лист1'!P19 -> 9 | T23: ='Лист1'!Q15 -> 6 | U23: =IF(COUNTIF(F23:T23,"=*")>0,"-",IF(COUNTIF(F23:T23,"<4")>0,"-",(IFERROR(AVERAGE(F23:T23),"")))) -> 8.0666667
C24: К | D24: 14 | E24: Мирненко Анна Олександрівна | F24: ='Лист1'!C20 -> 9 | G24: ='Лист1'!D20 -> 7 | H24: ='Лист1'!E20 -> 8 | I24: ='Лист1'!F20 -> 9 | J24: ='Лист1'!G20 -> 10 | K24: ='Лист1'!H20 -> 6 | L24: ='Лист1'!I20 -> 9 | M24: ='Лист1'!J20 -> 9 | ... S24: ='Лист1'!P20 -> 7 | T24: ='Лист1'!Q16 -> 5 | U24: =IF(COUNTIF(F24:T24,"=*")>0,"-",IF(COUNTIF(F24:T24,"<4")>0,"-",(IFERROR(AVERAGE(F24:T24),"")))) -> 7.7333333
C25: К | D25: 15 | E25: Мозгова Тетяна Віталіївна | F25: ='Лист1'!C21 -> 7 | G25: ='Лист1'!D21 -> 7 | H25: ='Лист1'!E21 -> 6 | I25: ='Лист1'!F21 -> 8 | J25: ='Лист1'!G21 -> 9 | K25: ='Лист1'!H21 -> н/а | L25: ='Лист1'!I21 -> 5 | M25: ='Лист1'!J21 -> н/а | ... S25: ='Лист1'!P21 -> 5 | T25: ='Лист1'!Q17 -> 9 | U25: =IF(COUNTIF(F25:T25,"=*")>0,"-",IF(COUNTIF(F25:T25,"<4")>0,"-",(IFERROR(AVERAGE(F25:T25),"")))) -> -
C26: К | D26: 16 | E26: Моісеєнко Анатолій Вікторович | F26: ='Лист1'!C22 -> 9 | G26: ='Лист1'!D22 -> 8 | H26: ='Лист1'!E22 -> 10 | I26: ='Лист1'!F22 -> 9 | J26: ='Лист1'!G22 -> 9 | K26: ='Лист1'!H22 -> 11 | L26: ='Лист1'!I22 -> 8 | M26: ='Лист1'!J22 -> 6 | ... S26: ='Лист1'!P22 -> 10 | T26: ='Лист1'!Q18 -> 7 | U26: =IF(COUNTIF(F26:T26,"=*")>0,"-",IF(COUNTIF(F26:T26,"<4")>0,"-",(IFERROR(AVERAGE(F26:T26),"")))) -> 8
C27: К | D27: 17 | E27: Молдованенко Ангеліна Олександрівна | F27: ='Лист1'!C23 -> 10 | G27: ='Лист1'!D23 -> 9 | H27: ='Лист1'!E23 -> 9 | I27: ='Лист1'!F23 -> 10 | J27: ='Лист1'!G23 -> 10 | K27: ='Лист1'!H23 -> 9 | L27: ='Лист1'!I23 -> 10 | M27: ='Лист1'!J23 -> 10 | ... S27: ='Лист1'!P23 -> 9 | T27: ='Лист1'!Q19 -> 7 | U27: =IF(COUNTIF(F27:T27,"=*")>0,"-",IF(COUNTIF(F27:T27,"<4")>0,"-",(IFERROR(AVERAGE(F27:T27),"")))) -> 9.2666667
C28: К | D28: 18 | E28: Нальотова Олександра Миколаївна | F28: ='Лист1'!C25 -> 9 | G28: ='Лист1'!D25 -> 8 | H28: ='Лист1'!E25 -> 8 | I28: ='Лист1'!F25 -> 9 | J28: ='Лист1'!G25 -> 10 | K28: ='Лист1'!H25 -> 6 | L28: ='Лист1'!I25 -> 9 | M28: ='Лист1'!J25 -> 7 | ... S28: ='Лист1'!P25 -> 8 | T28: ='Лист1'!Q20 -> 6 | U28: =IF(COUNTIF(F28:T28,"=*")>0,"-",IF(COUNTIF(F28:T28,"<4")>0,"-",(IFERROR(AVERAGE(F28:T28),"")))) -> 8.0666667
C29: К | D29: 19 | E29: Непом`яща Єлизавета Олександрівна | F29: ='Лист1'!C26 -> 9 | G29: ='Лист1'!D26 -> 6 | H29: ='Лист1'!E26 -> 9 | I29: ='Лист1'!F26 -> 9 | J29: ='Лист1'!G26 -> 9 | K29: ='Лист1'!H26 -> 8 | L29: ='Лист1'!I26 -> 7 | M29: ='Лист1'!J26 -> н/а | ... S29: ='Лист1'!P26 -> 9 | T29: ='Лист1'!Q21 -> 5 | U29: =IF(COUNTIF(F29:T29,"=*")>0,"-",IF(COUNTIF(F29:T29,"<4")>0,"-",(IFERROR(AVERAGE(F29:T29),"")))) -> -
C30: К | D30: 20 | E30: Олійник Олександра Сергіївна | F30: ='Лист1'!C27 -> 8 | G30: ='Лист1'!D27 -> 6 | H30: ='Лист1'!E27 -> 9 | I30: ='Лист1'!F27 -> 8 | J30: ='Лист1'!G27 -> 7 | K30: ='Лист1'!H27 -> н/а | L30: ='Лист1'!I27 -> 6 | M30: ='Лист1'!J27 -> 7 | ... S30: ='Лист1'!P27 -> 4 | T30: ='Лист1'!Q22 -> 6 | U30: =IF(COUNTIF(F30:T30,"=*")>0,"-",IF(COUNTIF(F30:T30,"<4")>0,"-",(IFERROR(AVERAGE(F30:T30),"")))) -> -
C31: К | D31: 21 | E31: Павлов Юрій Сергійович | F31: ='Лист1'!C28 -> 8 | G31: ='Лист1'!D28 -> 6 | H31: ='Лист1'!E28 -> 6 | I31: ='Лист1'!F28 -> 8 | J31: ='Лист1'!G28 -> 5 | K31: ='Лист1'!H28 -> н/а | L31: ='Лист1'!I28 -> 5 | M31: ='Лист1'!J28 -> 5 | ... S31: ='Лист1'!P28 -> 9 | T31: ='Лист1'!Q23 -> 7 | U31: =IF(COUNTIF(F31:T31,"=*")>0,"-",IF(COUNTIF(F31:T31,"<4")>0,"-",(IFERROR(AVERAGE(F31:T31),"")))) -> -
C32: К | D32: 22 | E32: Пащенко Ілля Володимирович | F32: ='Лист1'!C29 -> 6 | G32: ='Лист1'!D29 -> 6 | H32: ='Лист1'!E29 -> 6 | I32: ='Лист1'!F29 -> 5 | J32: ='Лист1'!G29 -> 5 | K32: ='Лист1'!H29 -> 4 | L32: ='Лист1'!I29 -> 5 | M32: ='Лист1'!J29 -> н/а | ... S32: ='Лист1'!P29 -> 5 | T32: ='Лист1'!Q24 -> 8 | U32: =IF(COUNTIF(F32:T32,"=*")>0,"-",IF(COUNTIF(F32:T32,"<4")>0,"-",(IFERROR(AVERAGE(F32:T32),"")))) -> -
C33: К | D33: 23 | E33: Підмогильна Валерія Вадимівна | F33: ='Лист1'!C30 -> 10 | G33: ='Лист1'!D30 -> 8 | H33: ='Лист1'!E30 -> 9 | I33: ='Лист1'!F30 -> 10 | J33: ='Лист1'!G30 -> 8 | K33: ='Лист1'!H30 -> 7 | L33: ='Лист1'!I30 -> 9 | M33: ='Лист1'!J30 -> 7 | ... S33: ='Лист1'!P30 -> 9 | T33: ='Лист1'!Q25 -> 6 | U33: =IF(COUNTIF(F33:T33,"=*")>0,"-",IF(COUNTIF(F33:T33,"<4")>0,"-",(IFERROR(AVERAGE(F33:T33),"")))) -> 7.9333333
C34: К | D34: 24 | E34: Ракітіна Маргарита Романівна | F34: ='Лист1'!C31 -> 10 | G34: ='Лист1'!D31 -> 8 | H34: ='Лист1'!E31 -> 10 | I34: ='Лист1'!F31 -> 10 | J34: ='Лист1'!G31 -> 10 | K34: ='Лист1'!H31 -> 7 | L34: ='Лист1'!I31 -> 7 | M34: ='Лист1'!J31 -> 7 | ... S34: ='Лист1'!P31 -> 7 | T34: ='Лист1'!Q26 -> 6 | U34: =IF(COUNTIF(F34:T34,"=*")>0,"-",IF(COUNTIF(F34:T34,"<4")>0,"-",(IFERROR(AVERAGE(F34:T34),"")))) -> 8.1333333
C35: К | D35: 25 | E35: Рибальченко Софія Олександрівна | F35: ='Лист1'!C32 -> 9 | G35: ='Лист1'!D32 -> 7 | H35: ='Лист1'!E32 -> 9 | I35: ='Лист1'!F32 -> 10 | J35: ='Лист1'!G32 -> 8 | K35: ='Лист1'!H32 -> 8 | L35: ='Лист1'!I32 -> 9 | M35: ='Лист1'!J32 -> 6 | ... S35: ='Лист1'!P32 -> 7 | T35: ='Лист1'!Q27 -> 5 | U35: =IF(COUNTIF(F35:T35,"=*")>0,"-",IF(COUNTIF(F35:T35,"<4")>0,"-",(IFERROR(AVERAGE(F35:T35),"")))) -> 7.1333333
C36: К | D36: 26 | E36: Сінькова Владлена Олександрівна | F36: ='Лист1'!C35 -> 10 | G36: ='Лист1'!D35 -> 10 | H36: ='Лист1'!E35 -> 10 | I36: ='Лист1'!F35 -> 10 | J36: ='Лист1'!G35 -> 10 | K36: ='Лист1'!H35 -> 8 | L36: ='Лист1'!I35 -> 9 | M36: ='Лист1'!J35 -> 10 | ... S36: ='Лист1'!P35 -> 8 | T36: ='Лист1'!Q28 -> 6 | U36: =IF(COUNTIF(F36:T36,"=*")>0,"-",IF(COUNTIF(F36:T36,"<4")>0,"-",(IFERROR(AVERAGE(F36:T36),"")))) -> 8.9333333
C37: К | D37: 27 | E37: Шестопалова Олександра Віталіївна | F37: ='Лист1'!C37 -> 10 | G37: ='Лист1'!D37 -> 10 | H37: ='Лист1'!E37 -> 9 | I37: ='Лист1'!F37 -> 9 | J37: ='Лист1'!G37 -> 11 | K37: ='Лист1'!H37 -> 9 | L37: ='Лист1'!I37 -> 11 | M37: ='Лист1'!J37 -> 10 | ... S37: ='Лист1'!P37 -> 9 | T37: ='Лист1'!Q29 -> 5 | U37: =IF(COUNTIF(F37:T37,"=*")>0,"-",IF(COUNTIF(F37:T37,"<4")>0,"-",(IFERROR(AVERAGE(F37:T37),"")))) -> 9.3333333
E38: Середній бал успішності з дисципліни | F38: =IF(SUM(F11:F37)=0,"",SUM(F11:F37)/$D37) -> 8.7777778 | G38: =IF(SUM(G11:G37)=0,"",SUM(G11:G37)/$D37) -> 7.6296296 | H38: =IF(SUM(H11:H37)=0,"",SUM(H11:H37)/$D37) -> 8.5555556 | I38: =IF(SUM(I11:I37)=0,"",SUM(I11:I37)/$D37) -> 8.8148148 | J38: =IF(SUM(J11:J37)=0,"",SUM(J11:J37)/$D37) -> 9 | K38: =IF(SUM(K11:K37)=0,"",SUM(K11:K37)/$D37) -> 5.5185185 | L38: =IF(SUM(L11:L37)=0,"",SUM(L11:L37)/$D37) -> 8.1111111 | M38: =IF(SUM(M11:M37)=0,"",SUM(M11:M37)/$D37) -> 6.1481481 | ... T38: =IF(SUM(T11:T37)=0,"",SUM(T11:T37)/$D37) -> 6.3703704 | U38: =IFERROR(AVERAGE(F38:T38),"") -> 7.3185185
E39: Абсолютна успішність | F39: =IF(SUM(F11:F37)=0,"",IF(COUNTIF(F11:F37,">=4")=0,0,COUNTIF(F11:F37,">=4")/$D37*100)) -> 100 | G39: =IF(SUM(G11:G37)=0,"",IF(COUNTIF(G11:G37,">=4")=0,0,COUNTIF(G11:G37,">=4")/$D37*100)) -> 100 | H39: =IF(SUM(H11:H37)=0,"",IF(COUNTIF(H11:H37,">=4")=0,0,COUNTIF(H11:H37,">=4")/$D37*100)) -> 100 | I39: =IF(SUM(I11:I37)=0,"",IF(COUNTIF(I11:I37,">=4")=0,0,COUNTIF(I11:I37,">=4")/$D37*100)) -> 100 | J39: =IF(SUM(J11:J37)=0,"",IF(COUNTIF(J11:J37,">=4")=0,0,COUNTIF(J11:J37,">=4")/$D37*100)) -> 100 | K39: =IF(SUM(K11:K37)=0,"",IF(COUNTIF(K11:K37,">=4")=0,0,COUNTIF(K11:K37,">=4")/$D37*100)) -> 70.37037 | L39: =IF(SUM(L11:L37)=0,"",IF(COUNTIF(L11:L37,">=4")=0,0,COUNTIF(L11:L37,">=4")/$D37*100)) -> 100 | M39: =IF(SUM(M11:M37)=0,"",IF(COUNTIF(M11:M37,">=4")=0,0,COUNTIF(M11:M37,">=4")/$D37*100)) -> 85.185185 | ... T39: =IF(SUM(T11:T37)=0,"",IF(COUNTIF(T11:T37,">=4")=0,0,COUNTIF(T11:T37,">=4")/$D37*100)) -> 100
E40: Якісна успішність | F40: =IF(SUM(F11:F37)=0,"",IF(COUNTIF(F11:F37,">=7")=0,0,COUNTIF(F11:F37,">=7")/$D37*100)) -> 96.296296 | G40: =IF(SUM(G11:G37)=0,"",IF(COUNTIF(G11:G37,">=7")=0,0,COUNTIF(G11:G37,">=7")/$D37*100)) -> 74.074074 | H40: =IF(SUM(H11:H37)=0,"",IF(COUNTIF(H11:H37,">=7")=0,0,COUNTIF(H11:H37,">=7")/$D37*100)) -> 85.185185 | I40: =IF(SUM(I11:I37)=0,"",IF(COUNTIF(I11:I37,">=7")=0,0,COUNTIF(I11:I37,">=7")/$D37*100)) -> 88.888889 | J40: =IF(SUM(J11:J37)=0,"",IF(COUNTIF(J11:J37,">=7")=0,0,COUNTIF(J11:J37,">=7")/$D37*100)) -> 88.888889 | K40: =IF(SUM(K11:K37)=0,"",IF(COUNTIF(K11:K37,">=7")=0,0,COUNTIF(K11:K37,">=7")/$D37*100)) -> 55.555556 | L40: =IF(SUM(L11:L37)=0,"",IF(COUNTIF(L11:L37,">=7")=0,0,COUNTIF(L11:L37,">=7")/$D37*100)) -> 77.777778 | M40: =IF(SUM(M11:M37)=0,"",IF(COUNTIF(M11:M37,">=7")=0,0,COUNTIF(M11:M37,">=7")/$D37*100)) -> 59.259259 | ... T40: =IF(SUM(T11:T37)=0,"",IF(COUNTIF(T11:T37,">=7")=0,0,COUNTIF(T11:T37,">=7")/$D37*100)) -> 37.037037
E41: Абсолютна успішність по групі | F41: =IFERROR(AVERAGE(F39:T39),"") -> 95.308642
E42: Якісна успішність по групі | F42: =IFERROR(AVERAGE(F40:T40),"") -> 67.901235
...

Sheet Зведена 161
C3: ВІДОКРЕМЛЕНИЙ СТРУКТУРНИЙ ПІДРОЗДІЛ «ФАХОВИЙ КОЛЕДЖ НАФТОГАЗОВИХ ТЕХНОЛОГІЙ, ІНЖЕНЕРІЇ ТА ІНФРАСТРУКТУРИ СЕРВІСУ
C4: ОДЕСЬКОГО НАЦІОНАЛЬНОГО ТЕХНОЛОГІЧНОГО УНІВЕРСИТЕТУ»
C5: ЗВЕДЕНА ВІДОМІСТЬ
C6: Успішності студентів спеціальності 242 «Туризм»
C7: За рік 2023-2024 н.р.
C8: Група 23-6 курс І
C9: Б/К | D9: № п/п | E9: Прізвище, ім’я, по батькові | F9: Підсумкові оцінки дисциплін
F10: Астрономія Наговська Т.С. | G10: Біологія Богданенко О.В. | H10: Всесвітня історія Мельничук С.А. | I10: Географія Наговська Т.С. | J10: Зарубіжна література Сербулова Ю.А. | K10: Захист України Лазар В.І. | L10: Іноземна мова Сербулова Ю.А. | M10: Інформатика Вівдіч М.І. | N10: Історія України Левчук Т.Г. | O10: Математика Нужна Н.В. | P10: Українська література Антропова Л.І. | Q10: Українська мова Антропова Л.І. | R10: Фізика Калюта Н.М. | S10: Фізична культура Галеніна І.С. | T10: Хімія Леонова Д.І. | U10: Середній бал
C11: К | D11: 1 | E11: Бочкур Олександра Василівна | F11: ='Лист1'!C5 -> 10 | G11: ='Лист1'!D5 -> 9 | H11: ='Лист1'!E5 -> 10 | I11: ='Лист1'!F5 -> 10 | J11: ='Лист1'!G5 -> 11 | K11: ='Лист1'!H5 -> 8 | L11: ='Лист1'!I5 -> 10 | M11: ='Лист1'!J5 -> 10 | ... S11: ='Лист1'!P5 -> 7 | T11: ='Лист1'!Q32 -> 6 | U11: =IF(COUNTIF(F11:T11,"=*")>0,"-",IF(COUNTIF(F11:T11,"<4")>0,"-",(IFERROR(AVERAGE(F11:T11),"")))) -> 9
C12: К | D12: 2 | E12: Віннічук Анастасія Миколаївна | F12: ='Лист1'!C8 -> 7 | G12: ='Лист1'!D8 -> 7 | H12: ='Лист1'!E8 -> 9 | I12: ='Лист1'!F8 -> 8 | J12: ='Лист1'!G8 -> 8 | K12: ='Лист1'!H8 -> н/а | L12: ='Лист1'!I8 -> 8 | M12: ='Лист1'!J8 -> 6 | ... S12: ='Лист1'!P8 -> 4 | T12: ='Лист1'!Q33 -> 5 | U12: =IF(COUNTIF(F12:T12,"=*")>0,"-",IF(COUNTIF(F12:T12,"<4")>0,"-",(IFERROR(AVERAGE(F12:T12),"")))) -> -
C13: К | D13: 3 | E13: Грабчак Катерина Сергіївна | F13: ='Лист1'!C10 -> 7 | G13: ='Лист1'!D10 -> 7 | H13: ='Лист1'!E10 -> 6 | I13: ='Лист1'!F10 -> 8 | J13: ='Лист1'!G10 -> 7 | K13: ='Лист1'!H10 -> н/а | L13: ='Лист1'!I10 -> 7 | M13: ='Лист1'!J10 -> н/а | ... S13: ='Лист1'!P10 -> 4 | T13: ='Лист1'!Q34 -> 6 | U13: =IF(COUNTIF(F13:T13,"=*")>0,"-",IF(COUNTIF(F13:T13,"<4")>0,"-",(IFERROR(AVERAGE(F13:T13),"")))) -> -
C14: К | D14: 4 | E14: Гусак Дар`я Вячеславівна | F14: ='Лист1'!C11 -> 9 | G14: ='Лист1'!D11 -> 10 | H14: ='Лист1'!E11 -> 10 | I14: ='Лист1'!F11 -> 10 | J14: ='Лист1'!G11 -> 11 | K14: ='Лист1'!H11 -> 11 | L14: ='Лист1'!I11 -> 11 | M14: ='Лист1'!J11 -> 9 | ... S14: ='Лист1'!P11 -> 10 | T14: ='Лист1'!Q35 -> 6 | U14: =IF(COUNTIF(F14:T14,"=*")>0,"-",IF(COUNTIF(F14:T14,"<4")>0,"-",(IFERROR(AVERAGE(F14:T14),"")))) -> 9.6
C15: К | D15: 5 | E15: Найден Марина Юріївна | F15: ='Лист1'!C24 -> 9 | G15: ='Лист1'!D24 -> 9 | H15: ='Лист1'!E24 -> 9 | I15: ='Лист1'!F24 -> 10 | J15: ='Лист1'!G24 -> 11 | K15: ='Лист1'!H24 -> 8 | L15: ='Лист1'!I24 -> 11 | M15: ='Лист1'!J24 -> 10 | ... S15: ='Лист1'!P24 -> 9 | T15: ='Лист1'!Q36 -> 7 | U15: =IF(COUNTIF(F15:T15,"=*")>0,"-",IF(COUNTIF(F15:T15,"<4")>0,"-",(IFERROR(AVERAGE(F15:T15),"")))) -> 9.3333333
C16: К | D16: 6 | E16: Рувінська Олександра Ігорівна | F16: ='Лист1'!C33 -> 7 | G16: ='Лист1'!D33 -> 7 | H16: ='Лист1'!E33 -> 6 | I16: ='Лист1'!F33 -> 6 | J16: ='Лист1'!G33 -> 9 | K16: ='Лист1'!H33 -> 5 | L16: ='Лист1'!I33 -> 6 | M16: ='Лист1'!J33 -> н/а | ... S16: ='Лист1'!P33 -> 4 | T16: ='Лист1'!Q37 -> 7 | U16: =IF(COUNTIF(F16:T16,"=*")>0,"-",IF(COUNTIF(F16:T16,"<4")>0,"-",(IFERROR(AVERAGE(F16:T16),"")))) -> -
C17: К | D17: 7 | E17: Синчук Владислава Олександрівна | F17: ='Лист1'!C34 -> 10 | G17: ='Лист1'!D34 -> 9 | H17: ='Лист1'!E34 -> 8 | I17: ='Лист1'!F34 -> 9 | J17: ='Лист1'!G34 -> 11 | K17: ='Лист1'!H34 -> 7 | L17: ='Лист1'!I34 -> 9 | M17: ='Лист1'!J34 -> 10 | ... S17: ='Лист1'!P34 -> 4 | T17: ='Лист1'!Q38 -> 7 | U17: =IF(COUNTIF(F17:T17,"=*")>0,"-",IF(COUNTIF(F17:T17,"<4")>0,"-",(IFERROR(AVERAGE(F17:T17),"")))) -> 8.1333333
C18: К | D18: 8 | E18: Шаульська Каріна Сергіївна | F18: ='Лист1'!C36 -> 10 | G18: ='Лист1'!D36 -> 10 | H18: ='Лист1'!E36 -> 9 | I18: ='Лист1'!F36 -> 10 | J18: ='Лист1'!G36 -> 11 | K18: ='Лист1'!H36 -> 10 | L18: ='Лист1'!I36 -> 11 | M18: ='Лист1'!J36 -> 9 | ... S18: ='Лист1'!P36 -> 11 | T18: =Лист1!#REF! -> #ERROR! | U18: =IF(COUNTIF(F18:T18,"=*")>0,"-",IF(COUNTIF(F18:T18,"<4")>0,"-",(IFERROR(AVERAGE(F18:T18),""))))
C19: К | D19: 9 | E19: Ябурова Аделіна Олексіївна | F19: ='Лист1'!C38 -> 10 | G19: ='Лист1'!D38 -> 10 | H19: ='Лист1'!E38 -> 10 | I19: ='Лист1'!F38 -> 9 | J19: ='Лист1'!G38 -> 10 | K19: ='Лист1'!H38 -> 10 | L19: ='Лист1'!I38 -> 10 | M19: ='Лист1'!J38 -> 10 | ... S19: ='Лист1'!P38 -> 10 | T19: ='Лист1'!Q39 -> 4.5833333 | U19: =IF(COUNTIF(F19:T19,"=*")>0,"-",IF(COUNTIF(F19:T19,"<4")>0,"-",(IFERROR(AVERAGE(F19:T19),"")))) -> 9.1055556
E20: Середній бал успішності з дисципліни | F20: =IF(SUM(F11:F19)=0,"",SUM(F11:F19)/$D19) -> 8.7777778 | G20: =IF(SUM(G11:G19)=0,"",SUM(G11:G19)/$D19) -> 8.6666667 | H20: =IF(SUM(H11:H19)=0,"",SUM(H11:H19)/$D19) -> 8.5555556 | I20: =IF(SUM(I11:I19)=0,"",SUM(I11:I19)/$D19) -> 8.8888889 | J20: =IF(SUM(J11:J19)=0,"",SUM(J11:J19)/$D19) -> 9.8888889 | K20: =IF(SUM(K11:K19)=0,"",SUM(K11:K19)/$D19) -> 6.5555556 | L20: =IF(SUM(L11:L19)=0,"",SUM(L11:L19)/$D19) -> 9.2222222 | M20: =IF(SUM(M11:M19)=0,"",SUM(M11:M19)/$D19) -> 7.1111111 | ... T20: =IF(SUM(T11:T19)=0,"",SUM(T11:T19)/$D19) -> #ERROR! | U20: =IFERROR(AVERAGE(F20:T20),"")
E21: Абсолютна успішність | F21: =IF(SUM(F11:F19)=0,"",IF(COUNTIF(F11:F19,">=4")=0,0,COUNTIF(F11:F19,">=4")/$D19*100)) -> 100 | G21: =IF(SUM(G11:G19)=0,"",IF(COUNTIF(G11:G19,">=4")=0,0,COUNTIF(G11:G19,">=4")/$D19*100)) -> 100 | H21: =IF(SUM(H11:H19)=0,"",IF(COUNTIF(H11:H19,">=4")=0,0,COUNTIF(H11:H19,">=4")/$D19*100)) -> 100 | I21: =IF(SUM(I11:I19)=0,"",IF(COUNTIF(I11:I19,">=4")=0,0,COUNTIF(I11:I19,">=4")/$D19*100)) -> 100 | J21: =IF(SUM(J11:J19)=0,"",IF(COUNTIF(J11:J19,">=4")=0,0,COUNTIF(J11:J19,">=4")/$D19*100)) -> 100 | K21: =IF(SUM(K11:K19)=0,"",IF(COUNTIF(K11:K19,">=4")=0,0,COUNTIF(K11:K19,">=4")/$D19*100)) -> 77.777778 | L21: =IF(SUM(L11:L19)=0,"",IF(COUNTIF(L11:L19,">=4")=0,0,COUNTIF(L11:L19,">=4")/$D19*100)) -> 100 | M21: =IF(SUM(M11:M19)=0,"",IF(COUNTIF(M11:M19,">=4")=0,0,COUNTIF(M11:M19,">=4")/$D19*100)) -> 77.777778 | ... T21: =IF(SUM(T11:T19)=0,"",IF(COUNTIF(T11:T19,">=4")=0,0,COUNTIF(T11:T19,">=4")/$D19*100)) -> #ERROR!
E22: Якісна успішність | F22: =IF(SUM(F11:F19)=0,"",IF(COUNTIF(F11:F19,">=7")=0,0,COUNTIF(F11:F19,">=7")/$D19*100)) -> 100 | G22: =IF(SUM(G11:G19)=0,"",IF(COUNTIF(G11:G19,">=7")=0,0,COUNTIF(G11:G19,">=7")/$D19*100)) -> 100 | H22: =IF(SUM(H11:H19)=0,"",IF(COUNTIF(H11:H19,">=7")=0,0,COUNTIF(H11:H19,">=7")/$D19*100)) -> 77.777778 | I22: =IF(SUM(I11:I19)=0,"",IF(COUNTIF(I11:I19,">=7")=0,0,COUNTIF(I11:I19,">=7")/$D19*100)) -> 88.888889 | J22: =IF(SUM(J11:J19)=0,"",IF(COUNTIF(J11:J19,">=7")=0,0,COUNTIF(J11:J19,">=7")/$D19*100)) -> 100 | K22: =IF(SUM(K11:K19)=0,"",IF(COUNTIF(K11:K19,">=7")=0,0,COUNTIF(K11:K19,">=7")/$D19*100)) -> 66.666667 | L22: =IF(SUM(L11:L19)=0,"",IF(COUNTIF(L11:L19,">=7")=0,0,COUNTIF(L11:L19,">=7")/$D19*100)) -> 88.888889 | M22: =IF(SUM(M11:M19)=0,"",IF(COUNTIF(M11:M19,">=7")=0,0,COUNTIF(M11:M19,">=7")/$D19*100)) -> 66.666667 | ... T22: =IF(SUM(T11:T19)=0,"",IF(COUNTIF(T11:T19,">=7")=0,0,COUNTIF(T11:T19,">=7")/$D19*100)) -> #ERROR!
E23: Абсолютна успішність по групі | F23: =IFERROR(AVERAGE(F21:T21),"")
E24: Якісна успішність по групі | F24: =IFERROR(AVERAGE(F22:T22),"")
E25: Кількість бюджетників | F25: =IF(COUNTIF(C11:C19,"=Б")=0,IF(COUNTIF(C11:C19,"=К")=0,"",0),COUNTIF(C11:C19,"=Б")) -> 0
E26: Кількість контрактників | F26: =IF(COUNTIF(C11:C19,"=К")=0,IF(COUNTIF(C11:C19,"=Б")=0,"",0),COUNTIF(C11:C19,"=К")) -> 9 | I26: Класний керівник | P26: Юлія СЕРБУЛОВА
E27: Кількість соціального контингенту | F27: 0
E28: Вийшли на стипендію | F28: 0 | I28: Завідувач відділення ПЗСО | P28: Маргарита БРІТІКОВА

Sheet Лист1
C2: Астрономія Наговська Т.С. | D2: Біологія Богданенко О.В. | E2: Всесвітня історія Мельничук С.А. | F2: Географія Наговська Т.С. | G2: Зарубіжна література Сербулова Ю.А. | H2: Захист України Лазар В.І. | I2: Іноземна мова Сербулова Ю.А. | J2: Інформатика Вівдіч М.І. | K2: Історія України Левчук Т.Г. | L2: Математика Земляна Т.М. | M2: Українська література Антропова Л.І. | N2: Українська мова Антропова Л.І. | O2: Фізика Калюта Н.М. | P2: Фізична культура Галеніна І.С. | Q2: Хімія Леонова Д.І.
A3: 1 | B3: Бакрив Олександра Сергіївна | C3: 9 | D3: 8 | E3: 8 | F3: 10 | G3: 10 | H3: 8 | I3: 7 | J3: 9 | K3: 8 | L3: 7 | M3: 7 | N3: 7 | O3: 7 | P3: 8 | Q3: 7
A4: 2 | B4: Башли Владлена Анатоліївна | C4: 10 | D4: 8 | E4: 10 | F4: 10 | G4: 10 | H4: 9 | I4: 10 | J4: 7 | K4: 8 | L4: 9 | M4: 9 | N4: 9 | O4: 7 | P4: 10 | Q4: 7
A5: 3 | B5: Бочкур Олександра Василівна | C5: 10 | D5: 9 | E5: 10 | F5: 10 | G5: 11 | H5: 8 | I5: 10 | J5: 10 | K5: 9 | L5: 9 | M5: 9 | N5: 10 | O5: 7 | P5: 7 | Q5: 9
A6: 4 | B6: Бубнова Ірина Олегівна | C6: 7 | D6: 6 | E6: 9 | F6: 8 | G6: 11 | H6: н/а | I6: 10 | J6: 6 | K6: 8 | L6: 5 | M6: 8 | N6: 9 | O6: 4 | P6: 4 | Q6: 6
A7: 5 | B7: Вдов Евеліна Віталіївна | C7: 8 | D7: 5 | E7: 9 | F7: 9 | G7: 9 | H7: н/а | I7: 7 | J7: 4 | K7: 5 | L7: 4 | M7: 6 | N7: 5 | O7: н/а | P7: 4 | Q7: 6
A8: 6 | B8: Віннічук Анастасія Миколаївна | C8: 7 | D8: 7 | E8: 9 | F8: 8 | G8: 8 | H8: н/а | I8: 8 | J8: 6 | K8: 7 | L8: 4 | M8: 6 | N8: 5 | O8: 4 | P8: 4 | Q8: 5
A9: 7 | B9: Войт Кіра Максимівна | C9: 10 | D9: 10 | E9: 10 | F9: 10 | G9: 10 | H9: 11 | I9: 11 | J9: 10 | K9: 9 | L9: 10 | M9: 10 | N9: 10 | O9: 10 | P9: 11 | Q9: 9
A10: 8 | B10: Грабчак Катерина Сергіївна | C10: 7 | D10: 7 | E10: 6 | F10: 8 | G10: 7 | H10: н/а | I10: 7 | J10: н/а | K10: н/а | L10: н/а | M10: 7 | N10: 5 | O10: н/а | P10: 4 | Q10: 5
A11: 9 | B11: Гусак Дар`я Вячеславівна | C11: 9 | D11: 10 | E11: 10 | F11: 10 | G11: 11 | H11: 11 | I11: 11 | J11: 9 | K11: 9 | L11: 10 | M11: 10 | N11: 9 | O11: 9 | P11: 10 | Q11: 8
A12: 10 | B12: Іванова Анастасія Анатоліївна | C12: 9 | D12: 9 | E12: 10 | F12: 9 | G12: 11 | H12: н/а | I12: 10 | J12: 7 | K12: 8 | L12: 6 | M12: 8 | N12: 7 | O12: 6 | P12: 4 | Q12: 6
A13: 11 | B13: Івненко Аліна Володимирівна | C13: 7 | D13: 5 | E13: 6 | F13: 6 | G13: 5 | H13: 4 | I13: 5 | J13: н/а | K13: 5 | L13: н/а | M13: 6 | N13: 6 | O13: 4 | P13: 4 | Q13: 5
A14: 12 | B14: Карнаушенко Софія Романівна | C14: 9 | D14: 7 | E14: 8 | F14: 10 | G14: 10 | H14: 8 | I14: 10 | J14: 5 | K14: 6 | L14: 4 | M14: 6 | N14: 6 | O14: 4 | P14: 10 | Q14: 5
A15: 13 | B15: Коновальчук Назар Сергійович | C15: 7 | D15: 7 | E15: 8 | F15: 8 | G15: 7 | H15: н/а | I15: 7 | J15: 7 | K15: 8 | L15: 5 | M15: 8 | N15: 8 | O15: 4 | P15: 5 | Q15: 6
A16: 14 | B16: Костюченко Вікторія Костянтинівна | C16: 8 | D16: 8 | E16: 8 | F16: 6 | G16: 9 | H16: н/а | I16: 7 | J16: 7 | K16: 5 | L16: 5 | M16: 7 | N16: 6 | O16: 5 | P16: 4 | Q16: 5
A17: 15 | B17: Крешун Ірина Сергіївна | C17: 10 | D17: 10 | E17: 10 | F17: 10 | G17: 11 | H17: 10 | I17: 11 | J17: 7 | K17: 6 | L17: 9 | M17: 9 | N17: 9 | O17: 9 | P17: 10 | Q17: 9
A18: 16 | B18: Майорова Анна Романівна | C18: 10 | D18: 8 | E18: 9 | F18: 9 | G18: 10 | H18: 8 | I18: 6 | J18: 6 | K18: 8 | L18: 5 | M18: 6 | N18: 8 | O18: 6 | P18: 8 | Q18: 7
A19: 17 | B19: Мартишев Давид Денисович | C19: 9 | D19: 9 | E19: 8 | F19: 9 | G19: 9 | H19: 8 | I19: 9 | J19: 7 | K19: 8 | L19: 7 | M19: 9 | N19: 8 | O19: 6 | P19: 9 | Q19: 7
A20: 18 | B20: Мирненко Анна Олександрівна | C20: 9 | D20: 7 | E20: 8 | F20: 9 | G20: 10 | H20: 6 | I20: 9 | J20: 9 | K20: 7 | L20: 7 | M20: 8 | N20: 9 | O20: 6 | P20: 7 | Q20: 6
A21: 19 | B21: Мозгова Тетяна Віталіївна | C21: 7 | D21: 7 | E21: 6 | F21: 8 | G21: 9 | H21: н/а | I21: 5 | J21: н/а | K21: н/а | L21: 4 | M21: 5 | N21: 7 | O21: н/а | P21: 5 | Q21: 5
A22: 20 | B22: Моісеєнко Анатолій Вікторович | C22: 9 | D22: 8 | E22: 10 | F22: 9 | G22: 9 | H22: 11 | I22: 8 | J22: 6 | K22: 8 | L22: 4 | M22: 8 | N22: 8 | O22: 5 | P22: 10 | Q22: 6
A23: 21 | B23: Молдованенко Ангеліна Олександрівна | C23: 10 | D23: 9 | E23: 9 | F23: 10 | G23: 10 | H23: 9 | I23: 10 | J23: 10 | K23: 10 | L23: 7 | M23: 10 | N23: 10 | O23: 9 | P23: 9 | Q23: 7
A24: 22 | B24: Найден Марина Юріївна | C24: 9 | D24: 9 | E24: 9 | F24: 10 | G24: 11 | H24: 8 | I24: 11 | J24: 10 | K24: 9 | L24: 10 | M24: 10 | N24: 10 | O24: 8 | P24: 9 | Q24: 8
A25: 23 | B25: Нальотова Олександра Миколаївна | C25: 9 | D25: 8 | E25: 8 | F25: 9 | G25: 10 | H25: 6 | I25: 9 | J25: 7 | K25: 8 | L25: 7 | M25: 9 | N25: 9 | O25: 8 | P25: 8 | Q25: 6
A26: 24 | B26: Непом`яща Єлизавета Олександрівна | C26: 9 | D26: 6 | E26: 9 | F26: 9 | G26: 9 | H26: 8 | I26: 7 | J26: н/а | K26: 8 | L26: 6 | M26: 7 | N26: 8 | O26: 6 | P26: 9 | Q26: 6
A27: 25 | B27: Олійник Олександра Сергіївна | C27: 8 | D27: 6 | E27: 9 | F27: 8 | G27: 7 | H27: н/а | I27: 6 | J27: 7 | K27: 5 | L27: 5 | M27: 7 | N27: 6 | O27: 5 | P27: 4 | Q27: 5
A28: 26 | B28: Павлов Юрій Сергійович | C28: 8 | D28: 6 | E28: 6 | F28: 8 | G28: 5 | H28: н/а | I28: 5 | J28: 5 | K28: н/а | L28: 4 | M28: 5 | N28: 6 | O28: н/а | P28: 9 | Q28: 6
A29: 27 | B29: Пащенко Ілля Володимирович | C29: 6 | D29: 6 | E29: 6 | F29: 5 | G29: 5 | H29: 4 | I29: 5 | J29: н/а | K29: 6 | L29: н/а | M29: 6 | N29: 7 | O29: 4 | P29: 5 | Q29: 5
A30: 28 | B30: Підмогильна Валерія Вадимівна | C30: 10 | D30: 8 | E30: 9 | F30: 10 | G30: 8 | H30: 7 | I30: 9 | J30: 7 | K30: 8 | L30: 8 | M30: 7 | N30: 7 | O30: 6 | P30: 9 | Q30: 5
A31: 29 | B31: Ракітіна Маргарита Романівна | C31: 10 | D31: 8 | E31: 10 | F31: 10 | G31: 10 | H31: 7 | I31: 7 | J31: 7 | K31: 9 | L31: 7 | M31: 9 | N31: 9 | O31: 6 | P31: 7 | Q31: 6
A32: 30 | B32: Рибальченко Софія Олександрівна | C32: 9 | D32: 7 | E32: 9 | F32: 10 | G32: 8 | H32: 8 | I32: 9 | J32: 6 | K32: 6 | L32: 5 | M32: 7 | N32: 7 | O32: 4 | P32: 7 | Q32: 6
A33: 31 | B33: Рувінська Олександра Ігорівна | C33: 7 | D33: 7 | E33: 6 | F33: 6 | G33: 9 | H33: 5 | I33: 6 | J33: н/а | K33: 4 | L33: н/а | M33: 6 | N33: 6 | O33: 4 | P33: 4 | Q33: 5
A34: 32 | B34: Синчук Владислава Олександрівна | C34: 10 | D34: 9 | E34: 8 | F34: 9 | G34: 11 | H34: 7 | I34: 9 | J34: 10 | K34: 7 | L34: 7 | M34: 9 | N34: 9 | O34: 6 | P34: 4 | Q34: 6
A35: 33 | B35: Сінькова Владлена Олександрівна | C35: 10 | D35: 10 | E35: 10 | F35: 10 | G35: 10 | H35: 8 | I35: 9 | J35: 10 | K35: 8 | L35: 7 | M35: 9 | N35: 10 | O35: 9 | P35: 8 | Q35: 6
A36: 34 | B36: Шаульська Каріна Сергіївна | C36: 10 | D36: 10 | E36: 9 | F36: 10 | G36: 11 | H36: 10 | I36: 11 | J36: 9 | K36: 10 | L36: 10 | M36: 9 | N36: 10 | O36: 9 | P36: 11 | Q36: 7
A37: 35 | B37: Шестопалова Олександра Віталіївна | C37: 10 | D37: 10 | E37: 9 | F37: 9 | G37: 11 | H37: 9 | I37: 11 | J37: 10 | K37: 9 | L37: 10 | M37: 10 | N37: 10 | O37: 8 | P37: 9 | Q37: 7
A38: 36 | B38: Ябурова Аделіна Олексіївна | C38: 10 | D38: 10 | E38: 10 | F38: 9 | G38: 10 | H38: 10 | I38: 10 | J38: 10 | K38: 7 | L38: 9 | M38: 9 | N38: 9 | O38: 9 | P38: 10 | Q38: 7
B39: Середній бал успішності з дисципліни | C39: =IF(SUM(C3:C38)=0,"",SUM(C12:C38)/$A38) -> 6.6388889 | D39: =IF(SUM(D3:D38)=0,"",SUM(D12:D38)/$A38) -> 5.9444444 | E39: =IF(SUM(E3:E38)=0,"",SUM(E12:E38)/$A38) -> 6.3055556 | F39: =IF(SUM(F3:F38)=0,"",SUM(F12:F38)/$A38) -> 6.5277778 | G39: =IF(SUM(G3:G38)=0,"",SUM(G12:G38)/$A38) -> 6.8055556 | H39: =IF(SUM(H3:H38)=0,"",SUM(H12:H38)/$A38) -> 4.4722222 | I39: =IF(SUM(I3:I38)=0,"",SUM(I12:I38)/$A38) -> 6.1388889 | J39: =IF(SUM(J3:J38)=0,"",SUM(J12:J38)/$A38) -> 4.6944444 | ... Q39: =IF(SUM(Q3:Q38)=0,"",SUM(Q12:Q38)/$A38) -> 4.5833333
B40: Абсолютна успішність | C40: =IF(SUM(C3:C38)=0,"",IF(COUNTIF(C12:C38,">=4")=0,0,COUNTIF(C12:C38,">=4")/$A38*100)) -> 75 | D40: =IF(SUM(D3:D38)=0,"",IF(COUNTIF(D12:D38,">=4")=0,0,COUNTIF(D12:D38,">=4")/$A38*100)) -> 75 | E40: =IF(SUM(E3:E38)=0,"",IF(COUNTIF(E12:E38,">=4")=0,0,COUNTIF(E12:E38,">=4")/$A38*100)) -> 75 | F40: =IF(SUM(F3:F38)=0,"",IF(COUNTIF(F12:F38,">=4")=0,0,COUNTIF(F12:F38,">=4")/$A38*100)) -> 75 | G40: =IF(SUM(G3:G38)=0,"",IF(COUNTIF(G12:G38,">=4")=0,0,COUNTIF(G12:G38,">=4")/$A38*100)) -> 75 | H40: =IF(SUM(H3:H38)=0,"",IF(COUNTIF(H12:H38,">=4")=0,0,COUNTIF(H12:H38,">=4")/$A38*100)) -> 58.333333 | I40: =IF(SUM(I3:I38)=0,"",IF(COUNTIF(I12:I38,">=4")=0,0,COUNTIF(I12:I38,">=4")/$A38*100)) -> 75 | J40: =IF(SUM(J3:J38)=0,"",IF(COUNTIF(J12:J38,">=4")=0,0,COUNTIF(J12:J38,">=4")/$A38*100)) -> 61.111111 | ... Q40: =IF(SUM(Q3:Q38)=0,"",IF(COUNTIF(Q12:Q38,">=4")=0,0,COUNTIF(Q12:Q38,">=4")/$A38*100)) -> 75
B41: Якісна успішність | C41: =IF(SUM(C3:C38)=0,"",IF(COUNTIF(C12:C38,">=7")=0,0,COUNTIF(C12:C38,">=7")/$A38*100)) -> 72.222222 | D41: =IF(SUM(D3:D38)=0,"",IF(COUNTIF(D12:D38,">=7")=0,0,COUNTIF(D12:D38,">=7")/$A38*100)) -> 61.111111 | E41: =IF(SUM(E3:E38)=0,"",IF(COUNTIF(E12:E38,">=7")=0,0,COUNTIF(E12:E38,">=7")/$A38*100)) -> 61.111111 | F41: =IF(SUM(F3:F38)=0,"",IF(COUNTIF(F12:F38,">=7")=0,0,COUNTIF(F12:F38,">=7")/$A38*100)) -> 63.888889 | G41: =IF(SUM(G3:G38)=0,"",IF(COUNTIF(G12:G38,">=7")=0,0,COUNTIF(G12:G38,">=7")/$A38*100)) -> 66.666667 | H41: =IF(SUM(H3:H38)=0,"",IF(COUNTIF(H12:H38,">=7")=0,0,COUNTIF(H12:H38,">=7")/$A38*100)) -> 44.444444 | I41: =IF(SUM(I3:I38)=0,"",IF(COUNTIF(I12:I38,">=7")=0,0,COUNTIF(I12:I38,">=7")/$A38*100)) -> 55.555556 | J41: =IF(SUM(J3:J38)=0,"",IF(COUNTIF(J12:J38,">=7")=0,0,COUNTIF(J12:J38,">=7")/$A38*100)) -> 47.222222 | ... Q41: =IF(SUM(Q3:Q38)=0,"",IF(COUNTIF(Q12:Q38,">=7")=0,0,COUNTIF(Q12:Q38,">=7")/$A38*100)) -> 22.222222
