Workbook

Sheet Зведена відомість 161
A1: ВСП "ФАХОВИЙ КОЛЕДЖ НАФТОГАЗОВИХ ТЕХНОЛОГІЙ, ІНЖЕНЕРІЇ ТА ІНФРАСТРУКТУРИ СЕРВІСУ
A2: ОДЕСЬКОЇ НАЦІОНАЛЬНОЇ АКАДЕМІЇ ХАРЧОВИХ ТЕХНОЛОГІЙ"
A3: ЗВЕДЕНА ВІДОМІСТЬ
A4: Успішності студентів спеціальності 161 «Хімічні технології та інженерія»
A5: За І семестр 2021-2022 н.р.
A6: Група 21-4 курс І
A7: Б/К | B7: № п/п | C7: Прізвище, ім’я по батькові | D7: Підсумкові оцінки дисциплін
D8: Українська література Грубіна О.П. | E8: Всесвітня історія Мельничук С.А. | F8: Математика Земляна Т.М. | G8: Фізика Калюта Н.М. | H8: Хімія Сахно Н.О. | I8: Інформатика Охримчук В.С. | J8: Українська мова Грубіна О.П. | K8: Зарубіжна література Пруднікова Я.П. | L8: Біологія Богданенко О.В. | M8: Фізичне виховання Галеніна І.С. | N8: Іноземна мова Кубова Т.М. | O8: ЗУ Лазар В.І. Стельмах Н.Ю. Черкашин А.Д. | P8: Історія України Левчук Т.Г. | Q8: Географія Наговська Т.С. | R8: Середній бал
A11: К | B11: 1 | C11: Беспалько В’ячеслав Геннадійович | D11: 4 | E11: 5 | F11: 4 | G11: 4 | H11: 4 | I11: 5 | J11: 4 | K11: 8 | L11: 6 | M11: 6 | N11: 4 | O11: 4 | P11: 5 | Q11: 5 | R11: =AVERAGE(D11:Q11) -> 4.8571429
A12: Б | B12: 2 | C12: Білий Ніл Олександрович | D12: 6 | E12: 9 | F12: 4 | G12: 6 | H12: 6 | I12: 8 | J12: 6 | K12: 9 | L12: 6 | M12: 10 | N12: 6 | O12: 8 | P12: 6 | Q12: 9 | R12: =AVERAGE(D12:Q12) -> 7.0714286
A13: Б | B13: 3 | C13: Будко Володимир Володимирович | D13: 5 | E13: 9 | F13: 4 | G13: 4 | H13: 7 | I13: 7 | J13: 5 | K13: 8 | L13: 5 | M13: 8 | N13: 4 | O13: 6 | P13: н/а | Q13: 7 | R13: =AVERAGE(D13:Q13) -> 6.0769231
A14: Б | B14: 4 | C14: Гайдаржи Олександр Микол. | D14: н/а | E14: 4 | F14: н/а | G14: н/а | H14: н/а | I14: 4 | J14: н/а | K14: 4 | L14: н/а | M14: н/а | N14: н/а | O14: н/а | P14: н/а | Q14: н/а | R14: =AVERAGE(D14:Q14) -> 4
A15: Б | B15: 5 | C15: Дімітрова Василіка Віталіївна | D15: 11 | E15: 10 | F15: 8 | G15: 10 | H15: 10 | I15: 10 | J15: 10 | K15: 10 | L15: 10 | M15: 10 | N15: 10 | O15: 9 | P15: 9 | Q15: 10 | R15: =AVERAGE(D15:Q15) -> 9.7857143
A16: Б | B16: 6 | C16: Казанджій Богдан Миколайович | D16: 4 | E16: 5 | F16: 4 | G16: 2 | H16: 4 | I16: 5 | J16: 4 | K16: 5 | L16: 4 | M16: 5 | N16: 4 | O16: 5 | P16: 6 | Q16: н/а | R16: =AVERAGE(D16:Q16) -> 4.3846154
A17: Б | B17: 7 | C17: Калінку Дарія Андріївна | D17: н/а | E17: н/а | F17: н/а | G17: н/а | H17: н/а | I17: н/а | J17: н/а | K17: н/а | L17: н/а | M17: н/а | N17: н/а | O17: н/а | P17: н/а | Q17: н/а | R17: 0
A18: Б | B18: 8 | C18: Мешкова Вікторія Ігорівна | D18: 4 | E18: 5 | F18: 4 | G18: 5 | H18: 6 | I18: 4 | J18: 4 | K18: 5 | L18: 4 | M18: н/а | N18: 4 | O18: 5 | P18: 6 | Q18: 7 | R18: =AVERAGE(D18:Q18) -> 4.8461538
A19: Б | B19: 9 | C19: Пасічник Артем Сергійович | D19: 5 | E19: 8 | F19: 4 | G19: 7 | H19: 7 | I19: 5 | J19: 5 | K19: 7 | L19: 6 | M19: 5 | N19: 5 | O19: 7 | P19: 6 | Q19: 8 | R19: =AVERAGE(D19:Q19) -> 6.0714286
A20: Б | B20: 10 | C20: Салтанова Катерина Ігорівна | D20: 7 | E20: 8 | F20: 4 | G20: 5 | H20: 7 | I20: 8 | J20: 6 | K20: 6 | L20: 5 | M20: 6 | N20: 4 | O20: 7 | P20: 5 | Q20: 8 | R20: =AVERAGE(D20:Q20) -> 6.1428571
A21: Б | B21: 11 | C21: Цуканов Іван Павлович | D21: 8 | E21: 9 | F21: 5 | G21: 6 | H21: 6 | I21: 8 | J21: 7 | K21: 9 | L21: 8 | M21: 10 | N21: 7 | O21: 7 | P21: 8 | Q21: 8 | R21: =AVERAGE(D21:Q21) -> 7.5714286
C22: Середній бал успішності з дисципліни | D22: =AVERAGE(D11:D21) -> 6 | E22: =AVERAGE(E11:E21) -> 7.2 | F22: =AVERAGE(F11:F21) -> 4.5555556 | G22: =AVERAGE(G11:G21) -> 5.4444444 | H22: =AVERAGE(H11:H21) -> 6.3333333 | I22: =AVERAGE(I11:I21) -> 6.4 | J22: =AVERAGE(J11:J21) -> 5.6666667 | K22: =AVERAGE(K11:K21) -> 7.1 | ... Q22: =AVERAGE(Q11:Q21) -> 7.75 | R22: =AVERAGE(D22:Q22) -> 6.2930556
C23: Абсолютна успішність | D23: =(COUNT(D11:D21))/(COUNT(R11:R21))*100 -> 81.818182 | E23: =(COUNT(E11:E21))/(COUNT(R11:R21))*100 -> 90.909091 | F23: =(COUNT(F11:F21))/(COUNT(R11:R21))*100 -> 81.818182 | G23: =(COUNT(G11:G21))/(COUNT(R11:R21))*100 -> 81.818182 | H23: =(COUNT(H11:H21))/(COUNT(R11:R21))*100 -> 81.818182 | I23: =(COUNT(I11:I21))/(COUNT(R11:R21))*100 -> 90.909091 | J23: =(COUNT(J11:J21))/(COUNT(R11:R21))*100 -> 81.818182 | K23: =(COUNT(K11:K21))/(COUNT(R11:R21))*100 -> 90.909091 | L23: =(COUNT(L11:L21))/(COUNT(R11:R21))*100 -> 81.818182 | M23: =(COUNT(M11:M21))/(COUNT(R11:R21))*100 -> 72.727273 | N23: =(COUNT(N11:N21))/(COUNT(R11:R21))*100 -> 81.818182 | O23: =(COUNT(O11:O21))/(COUNT(R11:R21))*100 -> 81.818182 | P23: =(COUNT(P11:P21))/(COUNT(R11:R21))*100 -> 72.727273 | Q23: =(COUNT(Q11:Q21))/(COUNT(R11:R21))*100 -> 72.727273
C24: Якісна успішність | D24: =(COUNTIF(D11:D21,">6"))/(COUNT(R11:R21))*100 -> 27.272727 | E24: =(COUNTIF(E11:E21,">6"))/(COUNT(R11:R21))*100 -> 54.545455 | F24: =(COUNTIF(F11:F21,">6"))/(COUNT(R11:R21))*100 -> 9.0909091 | G24: =(COUNTIF(G11:G21,">6"))/(COUNT(R11:R21))*100 -> 18.181818 | H24: =(COUNTIF(H11:H21,">6"))/(COUNT(R11:R21))*100 -> 36.363636 | I24: =(COUNTIF(I11:I21,">6"))/(COUNT(R11:R21))*100 -> 45.454545 | J24: =(COUNTIF(J11:J21,">6"))/(COUNT(R11:R21))*100 -> 18.181818 | K24: =(COUNTIF(K11:K21,">6"))/(COUNT(R11:R21))*100 -> 54.545455 | L24: =(COUNTIF(L11:L21,">6"))/(COUNT(R11:R21))*100 -> 18.181818 | M24: =(COUNTIF(M11:M21,">6"))/(COUNT(R11:R21))*100 -> 36.363636 | N24: =(COUNTIF(N11:N21,">6"))/(COUNT(R11:R21))*100 -> 18.181818 | O24: =(COUNTIF(O11:O21,">6"))/(COUNT(R11:R21))*100 -> 45.454545 | P24: =(COUNTIF(P11:P21,">6"))/(COUNT(R11:R21))*100 -> 18.181818 | Q24: =(COUNTIF(Q11:Q21,">6"))/(COUNT(R11:R21))*100 -> 63.636364
C25: Абсолютна успішність по групі | D25: =AVERAGE(D23:Q23) -> 81.818182
C26: Якісна успішність по групі | D26: =AVERAGE(D24:Q24) -> 33.116883
C27: Кількість бюджетників | D27: =COUNTIF(A11:A21,"=Б") -> 10
C28: Кількість контрактників | D28: =COUNTIF(A11:A21,"=К") -> 1 | H28: Класний керівник | O28: Ярослава ПРУДНІКОВА
C29: Кількість соціального контингенту | D29: 0
C30: Вийшли на стипендію | D30: =INT(D27/100*40) -> 4 | H30: Завідувач відділення ПЗСО | O30: Маргарита БРІТІКОВА
A60: =D27 -> 10 | B60: =D28 -> 1 | C60: =D29 -> 0 | D60: =D30 -> 4
A61: =D27 -> 10 | B61: =D28 -> 1 | C61: =D29 -> 0 | D61: =D30 -> 4
A62: =D27 -> 10 | B62: =D28 -> 1 | C62: =D29 -> 0 | D62: =D30 -> 4
A63: =D27 -> 10 | B63: =D28 -> 1 | C63: =D29 -> 0 | D63: =D30 -> 4
A64: =D27 -> 10 | B64: =D28 -> 1 | C64: =D29 -> 0 | D64: =D30 -> 4
A65: =D27 -> 10 | B65: =D28 -> 1 | C65: =D29 -> 0 | D65: =D30 -> 4
A66: =D27 -> 10 | B66: =D28 -> 1 | C66: =D29 -> 0 | D66: =D30 -> 4
A67: =D27 -> 10 | B67: =D28 -> 1 | C67: =D29 -> 0 | D67: =D30 -> 4
A68: =D27 -> 10 | B68: =D28 -> 1 | C68: =D29 -> 0 | D68: =D30 -> 4
A69: =D27 -> 10 | B69: =D28 -> 1 | C69: =D29 -> 0 | D69: =D30 -> 4
A70: =D27 -> 10 | B70: =D28 -> 1 | C70: =D29 -> 0 | D70: =D30 -> 4
A71: =D27 -> 10 | B71: =D28 -> 1 | C71: =D29 -> 0 | D71: =D30 -> 4
...

Sheet Рейтингова відомість 161
A1: ВСП "ФАХОВИЙ КОЛЕДЖ НАФТОГАЗОВИХ ТЕХНОЛОГІЙ, ІНЖЕНЕРІЇ ТА ІНФРАСТРУКТУРИ СЕРВІСУ
A2: ОДЕСЬКОЇ НАЦІОНАЛЬНОЇ АКАДЕМІЇ ХАРЧОВИХ ТЕХНОЛОГІЙ"
A3: РЕЙТИНГОВА ВІДОМІСТЬ
A4: Успішності студентів спеціальності 161 «Хімічні технології та інженерія»
A5: За І семестр 2021-2022 н.р.
A6: Група 21-4 курс І
A7: Б/К | B7: № п/п | C7: Прізвище, ім’я по батькові | D7: Підсумкові оцінки дисциплін
D8: Українська література Грубіна О.П. | E8: Всесвітня історія Мельничук С.А. | F8: Математика Земляна Т.М. | G8: Фізика Калюта Н.М. | H8: Хімія Сахно Н.О. | I8: Інформатика Охримчук В.С. | J8: Українська мова Грубіна О.П. | K8: Зарубіжна література Пруднікова Я.П. | L8: Біологія Богданенко О.В. | M8: Фізичне виховання Галеніна І.С. | N8: Іноземна мова Кубова Т.М. | O8: ЗУ Лазар В.І. Стельмах Н.Ю. Черкашин А.Д. | P8: Історія України Левчук Т.Г. | Q8: Географія Наговська Т.С. | R8: Середній бал | S8: Рейтинг
A11: Б | B11: 1 | C11: Дімітрова Василіка Віталіївна | D11: 11 | E11: 10 | F11: 8 | G11: 10 | H11: 10 | I11: 10 | J11: 10 | K11: 10 | L11: 10 | M11: 10 | N11: 10 | O11: 9 | P11: 9 | Q11: 10 | R11: =AVERAGE(D11:Q11) -> 9.7857143 | S11: =R11*90/12 -> 73.392857
A12: Б | B12: 2 | C12: Цуканов Іван Павлович | D12: 8 | E12: 9 | F12: 5 | G12: 6 | H12: 6 | I12: 8 | J12: 7 | K12: 9 | L12: 8 | M12: 10 | N12: 7 | O12: 7 | P12: 8 | Q12: 8 | R12: =AVERAGE(D12:Q12) -> 7.5714286 | S12: =R12*90/12 -> 56.785714
A13: Б | B13: 3 | C13: Білий Ніл Олександрович | D13: 6 | E13: 9 | F13: 4 | G13: 6 | H13: 6 | I13: 8 | J13: 6 | K13: 9 | L13: 6 | M13: 10 | N13: 6 | O13: 8 | P13: 6 | Q13: 9 | R13: =AVERAGE(D13:Q13) -> 7.0714286 | S13: =R13*90/12 -> 53.035714
A14: Б | B14: 4 | C14: Салтанова Катерина Ігорівна | D14: 7 | E14: 8 | F14: 4 | G14: 5 | H14: 7 | I14: 8 | J14: 6 | K14: 6 | L14: 5 | M14: 6 | N14: 4 | O14: 7 | P14: 5 | Q14: 8 | R14: =AVERAGE(D14:Q14) -> 6.1428571 | S14: =R14*90/12 -> 46.071429
A15: Б | B15: 5 | C15: Пасічник Артем Сергійович | D15: 5 | E15: 8 | F15: 4 | G15: 7 | H15: 7 | I15: 5 | J15: 5 | K15: 7 | L15: 6 | M15: 5 | N15: 5 | O15: 7 | P15: 6 | Q15: 8 | R15: =AVERAGE(D15:Q15) -> 6.0714286 | S15: =R15*90/12 -> 45.535714
C16: Кількість бюджетників | D16: ='Зведена відомість 161'!A95 -> 10
C17: Кількість контрактників | D17: ='Зведена відомість 161'!B95 -> 1
C18: Кількість соціального контингенту | D18: ='Зведена відомість 161'!C95 -> 0 | G18: Класний керівник | N18: Ярослава ПРУДНІКОВА
C19: Вийшли на стипендію | D19: ='Зведена відомість 161'!D95 -> 4
G20: Завідувач відділення ПЗСО | N20: Маргарита БРІТІКОВА
A80: =COUNTIF(A11:A40,"=Б") -> 5
A81: =COUNTIF(A11:A40,"=Б") -> 5
A82: =COUNTIF(A11:A40,"=Б") -> 5
A83: =COUNTIF(A11:A40,"=Б") -> 5
A84: =COUNTIF(A11:A40,"=Б") -> 5
A85: =COUNTIF(A11:A40,"=Б") -> 5
A86: =COUNTIF(A11:A40,"=Б") -> 5
A87: =COUNTIF(A11:A40,"=Б") -> 5
A88: =COUNTIF(A11:A40,"=Б") -> 5
A89: =COUNTIF(A11:A40,"=Б") -> 5
A90: =COUNTIF(A11:A40,"=Б") -> 5
A91: =COUNTIF(A11:A40,"=Б") -> 5
A92: =COUNTIF(A11:A40,"=Б") -> 5
A93: =COUNTIF(A11:A40,"=Б") -> 5
A94: =COUNTIF(A11:A40,"=Б") -> 5
A95: =COUNTIF(A11:A40,"=Б") -> 5
A96: =COUNTIF(A11:A40,"=Б") -> 5
A97: =COUNTIF(A11:A40,"=Б") -> 5
A98: =COUNTIF(A11:A40,"=Б") -> 5
A99: =COUNTIF(A11:A40,"=Б") -> 5
A100: =COUNTIF(A11:A40,"=Б") -> 5
A101: =COUNTIF(A11:A40,"=Б") -> 5
...

Sheet Зведена відомість 101
A1: ВСП "ФАХОВИЙ КОЛЕДЖ НАФТОГАЗОВИХ ТЕХНОЛОГІЙ, ІНЖЕНЕРІЇ ТА ІНФРАСТРУКТУРИ СЕРВІСУ
A2: ОДЕСЬКОЇ НАЦІОНАЛЬНОЇ АКАДЕМІЇ ХАРЧОВИХ ТЕХНОЛОГІЙ"
A3: ЗВЕДЕНА ВІДОМІСТЬ
A4: Успішності студентів спеціальності 101 «Екологія»
A5: За І семестр 2021-2022 н.р.
A6: Група 21-4 курс І
A7: Б/К | B7: № п/п | C7: Прізвище, ім’я по батькові | D7: Підсумкові оцінки дисциплін
D8: Українська література Грубіна О.П. | E8: Всесвітня історія Мельничук С.А. | F8: Математика Земляна Т.М. | G8: Фізика Калюта Н.М. | H8: Хімія Сахно Н.О. | I8: Інформатика Охримчук В.С. | J8: Українська мова Грубіна О.П. | K8: Зарубіжна література Пруднікова Я.П. | L8: Біологія Богданенко О.В. | M8: Фізичне виховання Галеніна І.С. | N8: Іноземна мова Кубова Т.М. | O8: ЗУ Лазар В.І. Стельмах Н.Ю. Черкашин А.Д. | P8: Історія України Левчук Т.Г. | Q8: Географія Наговська Т.С. | R8: Середній бал
A11: К | B11: 1 | C11: Абабіна Ірина Олександрівна | D11: 6 | E11: 9 | F11: 4 | G11: 5 | H11: 6 | I11: 9 | J11: 7 | K11: 8 | L11: 7 | M11: 10 | N11: 6 | O11: 7 | P11: 6 | Q11: 8 | R11: =AVERAGE(D11:Q11) -> 7
A12: Б | B12: 2 | C12: Варьоха Вероніка Андріївна | D12: 9 | E12: 8 | F12: 8 | G12: 9 | H12: 9 | I12: 9 | J12: 8 | K12: 10 | L12: 9 | M12: 6 | N12: 10 | O12: 9 | P12: 8 | Q12: 9 | R12: =AVERAGE(D12:Q12) -> 8.6428571
A13: Б | B13: 3 | C13: Дорошук Олена Володимирівна | D13: 9 | E13: 10 | F13: 8 | G13: 8 | H13: 8 | I13: 10 | J13: 7 | K13: 10 | L13: 8 | M13: 10 | N13: 10 | O13: 9 | P13: 8 | Q13: 9 | R13: =AVERAGE(D13:Q13) -> 8.8571429
A14: К | B14: 4 | C14: Жуковська Олександра Олександрівна | D14: 6 | E14: 6 | F14: 4 | G14: 5 | H14: 6 | I14: 8 | J14: 6 | K14: 7 | L14: 6 | M14: н/а | N14: 6 | O14: 6 | P14: 5 | Q14: 8 | R14: =AVERAGE(D14:Q14) -> 6.0769231
A15: Б | B15: 5 | C15: Карпенко Анна Сергіївна | D15: 8 | E15: 9 | F15: 7 | G15: 7 | H15: 8 | I15: 10 | J15: 8 | K15: 10 | L15: 8 | M15: 10 | N15: 9 | O15: 8 | P15: 7 | Q15: 9 | R15: =AVERAGE(D15:Q15) -> 8.4285714
A16: К | B16: 6 | C16: Катуніна Валерія Євгенівна | D16: 9 | E16: 10 | F16: 5 | G16: 7 | H16: 7 | I16: 9 | J16: 9 | K16: 10 | L16: 8 | M16: 10 | N16: 9 | O16: 8 | P16: 7 | Q16: 9 | R16: =AVERAGE(D16:Q16) -> 8.3571429
A17: К | B17: 7 | C17: Ковальов Максим Олегович | D17: 4 | E17: 7 | F17: 4 | G17: 5 | H17: 4 | I17: 4 | J17: 4 | K17: 5 | L17: 4 | M17: 7 | N17: 4 | O17: 4 | P17: 6 | Q17: 4 | R17: =AVERAGE(D17:Q17) -> 4.7142857
A18: К | B18: 8 | C18: Козуб Станіслав Валентинович | D18: 4 | E18: 7 | F18: 4 | G18: 4 | H18: 6 | I18: 6 | J18: 4 | K18: 7 | L18: 7 | M18: 10 | N18: 7 | O18: 5 | P18: 5 | Q18: 5 | R18: =AVERAGE(D18:Q18) -> 5.7857143
A19: Б | B19: 9 | C19: Максимова Віолетта Олександрівна | D19: 8 | E19: 9 | F19: 6 | G19: 7 | H19: 9 | I19: 10 | J19: 8 | K19: 10 | L19: 9 | M19: 10 | N19: 9 | O19: 8 | P19: 7 | Q19: 10 | R19: =AVERAGE(D19:Q19) -> 8.5714286
A20: Б | B20: 10 | C20: Михайленко Марія Вячесавівн | D20: 7 | E20: 9 | F20: 4 | G20: 5 | H20: 7 | I20: 9 | J20: 7 | K20: 8 | L20: 9 | M20: 7 | N20: 7 | O20: 9 | P20: 7 | Q20: 9 | R20: =AVERAGE(D20:Q20) -> 7.4285714
A21: Б | B21: 11 | C21: Нєдов Ярослав Васильович | D21: 9 | E21: 10 | F21: 7 | G21: 9 | H21: 9 | I21: 10 | J21: 8 | K21: 10 | L21: 9 | M21: 8 | N21: 9 | O21: 9 | P21: 8 | Q21: 10 | R21: =AVERAGE(D21:Q21) -> 8.9285714
A22: Б | B22: 12 | C22: Петренко Софія Сергіївна | D22: 10 | E22: 10 | F22: 9 | G22: 10 | H22: 9 | I22: 10 | J22: 10 | K22: 10 | L22: 10 | M22: 10 | N22: 9 | O22: 9 | P22: 8 | Q22: 10 | R22: =AVERAGE(D22:Q22) -> 9.5714286
A23: Б | B23: 13 | C23: Ротар Софія Василівна | D23: 7 | E23: 10 | F23: 4 | G23: 6 | H23: 6 | I23: 10 | J23: 8 | K23: 10 | L23: 10 | M23: 10 | N23: 5 | O23: 10 | P23: 7 | Q23: 10 | R23: =AVERAGE(D23:Q23) -> 8.0714286
A24: Б | B24: 14 | C24: Хемій Мирослава Василівна | D24: 8 | E24: 9 | F24: 7 | G24: 8 | H24: 9 | I24: 10 | J24: 7 | K24: 10 | L24: 8 | M24: 10 | N24: 9 | O24: 8 | P24: 8 | Q24: 9 | R24: =AVERAGE(D24:Q24) -> 8.5714286
A25: Б | B25: 15 | C25: Храмченкова Єва Сергіївна | D25: 7 | E25: 9 | F25: 4 | G25: 7 | H25: 7 | I25: 8 | J25: 6 | K25: 10 | L25: 6 | M25: 10 | N25: 7 | O25: 7 | P25: 6 | Q25: 9 | R25: =AVERAGE(D25:Q25) -> 7.3571429
C26: Середній бал успішності з дисципліни | D26: =AVERAGE(D11:D25) -> 7.4 | E26: =AVERAGE(E11:E25) -> 8.8 | F26: =AVERAGE(F11:F25) -> 5.6666667 | G26: =AVERAGE(G11:G25) -> 6.8 | H26: =AVERAGE(H11:H25) -> 7.3333333 | I26: =AVERAGE(I11:I25) -> 8.8 | J26: =AVERAGE(J11:J25) -> 7.1333333 | K26: =AVERAGE(K11:K25) -> 9 | ... Q26: =AVERAGE(Q11:Q25) -> 8.5333333 | R26: =AVERAGE(D26:Q26) -> 7.7721088
C27: Абсолютна успішність | D27: =(COUNT(D11:D25))/(COUNT(R11:R25))*100 -> 100 | E27: =(COUNT(E11:E25))/(COUNT(R11:R25))*100 -> 100 | F27: =(COUNT(F11:F25))/(COUNT(R11:R25))*100 -> 100 | G27: =(COUNT(G11:G25))/(COUNT(R11:R25))*100 -> 100 | H27: =(COUNT(H11:H25))/(COUNT(R11:R25))*100 -> 100 | I27: =(COUNT(I11:I25))/(COUNT(R11:R25))*100 -> 100 | J27: =(COUNT(J11:J25))/(COUNT(R11:R25))*100 -> 100 | K27: =(COUNT(K11:K25))/(COUNT(R11:R25))*100 -> 100 | L27: =(COUNT(L11:L25))/(COUNT(R11:R25))*100 -> 100 | M27: =(COUNT(M11:M25))/(COUNT(R11:R25))*100 -> 93.333333 | N27: =(COUNT(N11:N25))/(COUNT(R11:R25))*100 -> 100 | O27: =(COUNT(O11:O25))/(COUNT(R11:R25))*100 -> 100 | P27: =(COUNT(P11:P25))/(COUNT(R11:R25))*100 -> 100 | Q27: =(COUNT(Q11:Q25))/(COUNT(R11:R25))*100 -> 100
C28: Якісна успішність | D28: =(COUNTIF(D11:D25,">6"))/(COUNT(R11:R25))*100 -> 73.333333 | E28: =(COUNTIF(E11:E25,">6"))/(COUNT(R11:R25))*100 -> 93.333333 | F28: =(COUNTIF(F11:F25,">6"))/(COUNT(R11:R25))*100 -> 40 | G28: =(COUNTIF(G11:G25,">6"))/(COUNT(R11:R25))*100 -> 60 | H28: =(COUNTIF(H11:H25,">6"))/(COUNT(R11:R25))*100 -> 66.666667 | I28: =(COUNTIF(I11:I25,">6"))/(COUNT(R11:R25))*100 -> 86.666667 | J28: =(COUNTIF(J11:J25,">6"))/(COUNT(R11:R25))*100 -> 73.333333 | K28: =(COUNTIF(K11:K25,">6"))/(COUNT(R11:R25))*100 -> 93.333333 | L28: =(COUNTIF(L11:L25,">6"))/(COUNT(R11:R25))*100 -> 80 | M28: =(COUNTIF(M11:M25,">6"))/(COUNT(R11:R25))*100 -> 86.666667 | N28: =(COUNTIF(N11:N25,">6"))/(COUNT(R11:R25))*100 -> 73.333333 | O28: =(COUNTIF(O11:O25,">6"))/(COUNT(R11:R25))*100 -> 80 | P28: =(COUNTIF(P11:P25,">6"))/(COUNT(R11:R25))*100 -> 66.666667 | Q28: =(COUNTIF(Q11:Q25,">6"))/(COUNT(R11:R25))*100 -> 86.666667
C29: Абсолютна успішність по групі | D29: =AVERAGE(D27:Q27) -> 99.52381
C30: Якісна успішність по групі | D30: =AVERAGE(D28:Q28) -> 75.714286
C31: Кількість бюджетників | D31: =COUNTIF(A11:A25,"=Б") -> 10
C32: Кількість контрактників | D32: =COUNTIF(A11:A25,"=К") -> 5 | H32: Класний керівник | O32: Ярослава ПРУДНІКОВА
C33: Кількість соціального контингенту | D33: 1
C34: Вийшли на стипендію | D34: =INT(D31/100*40) -> 4 | H34: Завідувач відділення ПЗСО | O34: Маргарита БРІТІКОВА
A64: =D31 -> 10 | B64: =D32 -> 5 | C64: =D33 -> 1 | D64: =D34 -> 4
A65: =D31 -> 10 | B65: =D32 -> 5 | C65: =D33 -> 1 | D65: =D34 -> 4
A66: =D31 -> 10 | B66: =D32 -> 5 | C66: =D33 -> 1 | D66: =D34 -> 4
A67: =D31 -> 10 | B67: =D32 -> 5 | C67: =D33 -> 1 | D67: =D34 -> 4
A68: =D31 -> 10 | B68: =D32 -> 5 | C68: =D33 -> 1 | D68: =D34 -> 4
A69: =D31 -> 10 | B69: =D32 -> 5 | C69: =D33 -> 1 | D69: =D34 -> 4
A70: =D31 -> 10 | B70: =D32 -> 5 | C70: =D33 -> 1 | D70: =D34 -> 4
A71: =D31 -> 10 | B71: =D32 -> 5 | C71: =D33 -> 1 | D71: =D34 -> 4
...

Sheet Рейтингова відомість 101
A1: ВСП "ФАХОВИЙ КОЛЕДЖ НАФТОГАЗОВИХ ТЕХНОЛОГІЙ, ІНЖЕНЕРІЇ ТА ІНФРАСТРУКТУРИ СЕРВІСУ
A2: ОДЕСЬКОЇ НАЦІОНАЛЬНОЇ АКАДЕМІЇ ХАРЧОВИХ ТЕХНОЛОГІЙ"
A3: РЕЙТИНГОВА ВІДОМІСТЬ
A4: Успішності студентів спеціальності 101 «Екологія»
A5: За І семестр 2021-2022 н.р.
A6: Група 21-4 курс І
A7: Б/К | B7: № п/п | C7: Прізвище, ім’я по батькові | D7: Підсумкові оцінки дисциплін
D8: Українська література Грубіна О.П. | E8: Всесвітня історія Мельничук С.А. | F8: Математика Земляна Т.М. | G8: Фізика Калюта Н.М. | H8: Хімія Сахно Н.О. | I8: Інформатика Охримчук В.С. | J8: Українська мова Грубіна О.П. | K8: Зарубіжна література Пруднікова Я.П. | L8: Біологія Богданенко О.В. | M8: Фізичне виховання Галеніна І.С. | N8: Іноземна мова Кубова Т.М. | O8: ЗУ Лазар В.І. Стельмах Н.Ю. Черкашин А.Д. | P8: Історія України Левчук Т.Г. | Q8: Географія Наговська Т.С. | R8: Середній бал | S8: Рейтинг
A11: Б | B11: 1 | C11: Петренко Софія Сергіївна | D11: 10 | E11: 10 | F11: 9 | G11: 10 | H11: 9 | I11: 10 | J11: 10 | K11: 10 | L11: 10 | M11: 10 | N11: 9 | O11: 9 | P11: 8 | Q11: 10 | R11: =AVERAGE(D11:Q11) -> 9.5714286 | S11: =R11*90/12 -> 71.785714
A12: Б | B12: 2 | C12: Нєдов Ярослав Васильович | D12: 9 | E12: 10 | F12: 7 | G12: 9 | H12: 9 | I12: 10 | J12: 8 | K12: 10 | L12: 9 | M12: 8 | N12: 9 | O12: 9 | P12: 8 | Q12: 10 | R12: =AVERAGE(D12:Q12) -> 8.9285714 | S12: =R12*90/12 -> 66.964286
A13: Б | B13: 3 | C13: Дорошук Олена Володимирівна | D13: 9 | E13: 10 | F13: 8 | G13: 8 | H13: 8 | I13: 10 | J13: 7 | K13: 10 | L13: 8 | M13: 10 | N13: 10 | O13: 9 | P13: 8 | Q13: 9 | R13: =AVERAGE(D13:Q13) -> 8.8571429 | S13: =R13*90/12 -> 66.428571
A14: Б | B14: 4 | C14: Варьоха Вероніка Андріївна | D14: 9 | E14: 8 | F14: 8 | G14: 9 | H14: 9 | I14: 9 | J14: 8 | K14: 10 | L14: 9 | M14: 6 | N14: 10 | O14: 9 | P14: 8 | Q14: 9 | R14: =AVERAGE(D14:Q14) -> 8.6428571 | S14: =R14*90/12 -> 64.821429
A15: Б | B15: 5 | C15: Максимова Віолетта Олександрівна | D15: 8 | E15: 9 | F15: 6 | G15: 7 | H15: 9 | I15: 10 | J15: 8 | K15: 10 | L15: 9 | M15: 10 | N15: 9 | O15: 8 | P15: 7 | Q15: 10 | R15: =AVERAGE(D15:Q15) -> 8.5714286 | S15: =R15*90/12 -> 64.285714
A16: Б | B16: 6 | C16: Хемій Мирослава Василівна | D16: 8 | E16: 9 | F16: 7 | G16: 8 | H16: 9 | I16: 10 | J16: 7 | K16: 10 | L16: 8 | M16: 10 | N16: 9 | O16: 8 | P16: 8 | Q16: 9 | R16: =AVERAGE(D16:Q16) -> 8.5714286 | S16: =R16*90/12 -> 64.285714
A17: Б | B17: 7 | C17: Карпенко Анна Сергіївна | D17: 8 | E17: 9 | F17: 7 | G17: 7 | H17: 8 | I17: 10 | J17: 8 | K17: 10 | L17: 8 | M17: 10 | N17: 9 | O17: 8 | P17: 7 | Q17: 9 | R17: =AVERAGE(D17:Q17) -> 8.4285714 | S17: =R17*90/12 -> 63.214286
A18: Б | B18: 8 | C18: Ротар Софія Василівна | D18: 7 | E18: 10 | F18: 4 | G18: 6 | H18: 6 | I18: 10 | J18: 8 | K18: 10 | L18: 10 | M18: 10 | N18: 5 | O18: 10 | P18: 7 | Q18: 10 | R18: =AVERAGE(D18:Q18) -> 8.0714286 | S18: =R18*90/12 -> 60.535714
A19: Б | B19: 9 | C19: Михайленко Марія Вячесавівн | D19: 7 | E19: 9 | F19: 4 | G19: 5 | H19: 7 | I19: 9 | J19: 7 | K19: 8 | L19: 9 | M19: 7 | N19: 7 | O19: 9 | P19: 7 | Q19: 9 | R19: =AVERAGE(D19:Q19) -> 7.4285714 | S19: =R19*90/12 -> 55.714286
A20: Б | B20: 10 | C20: Храмченкова Єва Сергіївна | D20: 7 | E20: 9 | F20: 4 | G20: 7 | H20: 7 | I20: 8 | J20: 6 | K20: 10 | L20: 6 | M20: 10 | N20: 7 | O20: 7 | P20: 6 | Q20: 9 | R20: =AVERAGE(D20:Q20) -> 7.3571429 | S20: =R20*90/12 -> 55.178571
C21: Кількість бюджетників | D21: ='Зведена відомість 101'!D31 -> 10
C22: Кількість контрактників | D22: ='Зведена відомість 101'!D32 -> 5
C23: Кількість соціального контингенту | D23: ='Зведена відомість 101'!D33 -> 1 | G23: Класний керівник | N23: Ярослава ПРУДНІКОВА
C24: Вийшли на стипендію | D24: ='Зведена відомість 101'!D34 -> 4
G25: Завідувач відділення ПЗСО | N25: Маргарита БРІТІКОВА
A80: =COUNTIF(A11:A40,"=Б") -> 10
A81: =COUNTIF(A11:A40,"=Б") -> 10
A82: =COUNTIF(A11:A40,"=Б") -> 10
A83: =COUNTIF(A11:A40,"=Б") -> 10
A84: =COUNTIF(A11:A40,"=Б") -> 10
A85: =COUNTIF(A11:A40,"=Б") -> 10
A86: =COUNTIF(A11:A40,"=Б") -> 10
A87: =COUNTIF(A11:A40,"=Б") -> 10
A88: =COUNTIF(A11:A40,"=Б") -> 10
A89: =COUNTIF(A11:A40,"=Б") -> 10
A90: =COUNTIF(A11:A40,"=Б") -> 10
A91: =COUNTIF(A11:A40,"=Б") -> 10
A92: =COUNTIF(A11:A40,"=Б") -> 10
A93: =COUNTIF(A11:A40,"=Б") -> 10
A94: =COUNTIF(A11:A40,"=Б") -> 10
A95: =COUNTIF(A11:A40,"=Б") -> 10
A96: =COUNTIF(A11:A40,"=Б") -> 10
...
