Workbook
Name A1048577: #REF!
Name Ф80: #REF!

Sheet Зведена відомість 172
A1: ВСП «ФАХОВИЙ КОЛЕДЖ НАФТОГАЗОВИХ ТЕХНОЛОГІЙ, ІНЖЕНЕРІЇ ТА ІНФРАСТРУКТУРИ СЕРВІСУ
A2: ОДЕСЬКОГО НАЦІОНАЛЬНОГО ТЕХНОЛОГІЧНОГО УНІВЕРСИТЕТУ»
A3: ЗВЕДЕНА ВІДОМІСТЬ
A4: Успішності студентів спеціальності 172 «Телекомунікації та радіотехніка»
A5: За IІ семестр 2021-2022 н.р.
A6: Група 21-7 курс І
A7: Б/К | B7: № п/п | C7: Прізвище, ім’я по батькові | D7: Підсумкові оцінки дисциплін
D8: Астрономія Калюта Н.М. | E8: Біологія Леонова Д.І. | F8: Всесвітня історія Мельничук С.А. | G8: Географія Наговська Т.С. | H8: Зарубіжна література Пруднікова Я.П. | I8: ЗВ Черкашин А.Д. | J8: Іноземна мова Нічик Н.О. | K8: Інформатика Охримчук В.С. | L8: Історія України Левчук Т.Г. | M8: Математика Земляна Т.М. | N8: Українська література Нестеренко А.О. | O8: Українська мова Нестеренко А.О. | P8: Фізика Швець М.В. | Q8: Фізична культура Акрабова О.Г. | R8: Хімія Леонова Д.І. | S8: Середній бал
A11: Б | B11: 1 | C11: Бальжик Даніель Сергійович | D11: 8 | E11: 8 | F11: 7 | G11: 8 | H11: 5 | I11: 7 | J11: 10 | K11: 9 | L11: 8 | M11: 4 | N11: 9 | O11: 8 | P11: 5 | Q11: 10 | R11: 8 | S11: =IF(COUNTIF(D11:R11,"=*")>0,"-",(AVERAGE(D11:R11))) -> 7.6
A12: Б | B12: 2 | C12: Бурлака Михайло Аркадійович | D12: 6 | E12: 7 | F12: 10 | G12: 8 | H12: 4 | I12: 9 | J12: 7 | K12: 9 | L12: 7 | M12: 5 | N12: 5 | O12: 6 | P12: 6 | Q12: 10 | R12: 8 | S12: =IF(COUNTIF(D12:R12,"=*")>0,"-",(AVERAGE(D12:R12))) -> 7.1333333
A13: Б | B13: 3 | C13: Єнчев Денис Сергійович | D13: 8 | E13: 10 | F13: 10 | G13: 9 | H13: 7 | I13: 8 | J13: 11 | K13: 8 | L13: 8 | M13: 7 | N13: 8 | O13: 6 | P13: 7 | Q13: 8 | R13: 8 | S13: =IF(COUNTIF(D13:R13,"=*")>0,"-",(AVERAGE(D13:R13))) -> 8.2
A14: Б | B14: 4 | C14: Любченко Ірина Володимирів. | D14: 4 | E14: 6 | F14: 7 | G14: 8 | H14: 4 | I14: 5 | J14: 4 | K14: 6 | L14: 6 | M14: н/а | N14: 8 | O14: 9 | P14: 7 | Q14: 9 | R14: 7 | S14: =IF(COUNTIF(D14:R14,"=*")>0,"-",(AVERAGE(D14:R14))) -> -
A15: К | B15: 5 | C15: Нікольська Діана Геннадіївна | D15: 4 | E15: 7 | F15: 10 | G15: 4 | H15: 4 | I15: 6 | J15: 4 | K15: 4 | L15: 7 | M15: 4 | N15: 7 | O15: 8 | P15: 5 | Q15: 10 | R15: 6 | S15: =IF(COUNTIF(D15:R15,"=*")>0,"-",(AVERAGE(D15:R15))) -> 6
A16: К | B16: 6 | C16: Післарь Валерія Віталіївна | D16: 4 | E16: 6 | F16: 10 | G16: 4 | H16: 5 | I16: 6 | J16: 4 | K16: 6 | L16: 7 | M16: 4 | N16: 5 | O16: 7 | P16: 6 | Q16: 6 | R16: 7 | S16: =IF(COUNTIF(D16:R16,"=*")>0,"-",(AVERAGE(D16:R16))) -> 5.8
A17: Б | B17: 7 | C17: Трушковська Анастасія Юріїв. | D17: 4 | E17: 5 | F17: 10 | G17: 8 | H17: 4 | I17: н/а | J17: 4 | K17: 8 | L17: 6 | M17: 4 | N17: 5 | O17: 7 | P17: 6 | Q17: 6 | R17: 6 | S17: =IF(COUNTIF(D17:R17,"=*")>0,"-",(AVERAGE(D17:R17))) -> -
A18: Б | B18: 8 | C18: Туриця Дарія Олексіївна | D18: 11 | E18: 11 | F18: 10 | G18: 10 | H18: 10 | I18: 9 | J18: 8 | K18: 8 | L18: 8 | M18: 7 | N18: 10 | O18: 9 | P18: 10 | Q18: 10 | R18: 10 | S18: =IF(COUNTIF(D18:R18,"=*")>0,"-",(AVERAGE(D18:R18))) -> 9.4
A19: Б | B19: 9 | C19: Фенько Михайло Олександров. | D19: н/а | E19: 4 | F19: 9 | G19: 5 | H19: 4 | I19: н/а | J19: 4 | K19: 4 | L19: н/а | M19: н/а | N19: 8 | O19: 4 | P19: 5 | Q19: 5 | R19: 4 | S19: =IF(COUNTIF(D19:R19,"=*")>0,"-",(AVERAGE(D19:R19))) -> -
A20: Б | B20: 10 | C20: Фурик Дарія Василівна | D20: 7 | E20: 6 | F20: 10 | G20: 9 | H20: 5 | I20: 7 | J20: 7 | K20: 5 | L20: 7 | M20: н/а | N20: 7 | O20: 7 | P20: 6 | Q20: 6 | R20: 6 | S20: =IF(COUNTIF(D20:R20,"=*")>0,"-",(AVERAGE(D20:R20))) -> -
A21: Б | B21: 11 | C21: Чернов Владислав Олексійович | D21: 5 | E21: 5 | F21: 10 | G21: 8 | H21: 5 | I21: 8 | J21: 4 | K21: 4 | L21: 4 | M21: н/а | N21: 7 | O21: 7 | P21: 5 | Q21: 6 | R21: 6 | S21: =IF(COUNTIF(D21:R21,"=*")>0,"-",(AVERAGE(D21:R21))) -> -
C22: Середній бал успішності з дисципліни | D22: =AVERAGE(D11:D21) -> 6.1 | E22: =AVERAGE(E11:E21) -> 6.8181818 | F22: =AVERAGE(F11:F21) -> 9.3636364 | G22: =AVERAGE(G11:G21) -> 7.3636364 | H22: =AVERAGE(H11:H21) -> 5.1818182 | I22: =AVERAGE(I11:I21) -> 7.2222222 | J22: =AVERAGE(J11:J21) -> 6.0909091 | K22: =AVERAGE(K11:K21) -> 6.4545455 | ... R22: =AVERAGE(R11:R21) -> 6.9090909 | S22: =IF(COUNTIF(D22:R22,"=*")>0,"-",(AVERAGE(D22:R22))) -> 6.7717845
C23: Абсолютна успішність | D23: =(COUNT(D11:D21))/(COUNT(B11:B21))*100 -> 90.909091 | E23: =(COUNT(E11:E21))/(COUNT(B11:B21))*100 -> 100 | F23: =(COUNT(F11:F21))/(COUNT(B11:B21))*100 -> 100 | G23: =(COUNT(G11:G21))/(COUNT(B11:B21))*100 -> 100 | H23: =(COUNT(H11:H21))/(COUNT(B11:B21))*100 -> 100 | I23: =(COUNT(I11:I21))/(COUNT(B11:B21))*100 -> 81.818182 | J23: =(COUNT(J11:J21))/(COUNT(B11:B21))*100 -> 100 | K23: =(COUNT(K11:K21))/(COUNT(B11:B21))*100 -> 100 | L23: =(COUNT(L11:L21))/(COUNT(B11:B21))*100 -> 90.909091 | M23: =(COUNT(M11:M21))/(COUNT(B11:B21))*100 -> 63.636364 | N23: =(COUNT(N11:N21))/(COUNT(B11:B21))*100 -> 100 | O23: =(COUNT(O11:O21))/(COUNT(B11:B21))*100 -> 100 | P23: =(COUNT(P11:P21))/(COUNT(B11:B21))*100 -> 100 | Q23: =(COUNT(Q11:Q21))/(COUNT(B11:B21))*100 -> 100 | R23: =(COUNT(R11:R21))/(COUNT(B11:B21))*100 -> 100
C24: Якісна успішність | D24: =(COUNTIF(D11:D21,">=7"))/(COUNT(B11:B21))*100 -> 36.363636 | E24: =(COUNTIF(E11:E21,">=7"))/(COUNT(B11:B21))*100 -> 45.454545 | F24: =(COUNTIF(F11:F21,">=7"))/(COUNT(B11:B21))*100 -> 100 | G24: =(COUNTIF(G11:G21,">=7"))/(COUNT(B11:B21))*100 -> 72.727273 | H24: =(COUNTIF(H11:H21,">=7"))/(COUNT(B11:B21))*100 -> 18.181818 | I24: =(COUNTIF(I11:I21,">=7"))/(COUNT(B11:B21))*100 -> 54.545455 | J24: =(COUNTIF(J11:J21,">=7"))/(COUNT(B11:B21))*100 -> 45.454545 | K24: =(COUNTIF(K11:K21,">=7"))/(COUNT(B11:B21))*100 -> 45.454545 | L24: =(COUNTIF(L11:L21,">=7"))/(COUNT(B11:B21))*100 -> 63.636364 | M24: =(COUNTIF(M11:M21,">=7"))/(COUNT(B11:B21))*100 -> 18.181818 | N24: =(COUNTIF(N11:N21,">=7"))/(COUNT(B11:B21))*100 -> 72.727273 | O24: =(COUNTIF(O11:O21,">=7"))/(COUNT(B11:B21))*100 -> 72.727273 | P24: =(COUNTIF(P11:P21,">=7"))/(COUNT(B11:B21))*100 -> 27.272727 | Q24: =(COUNTIF(Q11:Q21,">=7"))/(COUNT(B11:B21))*100 -> 54.545455 | R24: =(COUNTIF(R11:R21,">=7"))/(COUNT(B11:B21))*100 -> 54.545455
C25: Абсолютна успішність по групі | D25: =AVERAGE(D23:R23) -> 95.151515
C26: Якісна успішність по групі | D26: =AVERAGE(D24:R24) -> 52.121212
C27: Кількість бюджетників | D27: =COUNTIF(A11:A21,"=Б") -> 9
C28: Кількість контрактників | D28: =COUNTIF(A11:A21,"=К") -> 2 | G28: Класний керівник | N28: Марія ЖУРАВЛЬОВА
C29: Кількість соціального контингенту | D29: 1
C30: Вийшли на стипендію | D30: =INT(D27/100*40) -> 3 | G30: Завідувач відділення ПЗСО | N30: Маргарита БРІТІКОВА

Sheet Зведена відомість 185
A1: ВСП «ФАХОВИЙ КОЛЕДЖ НАФТОГАЗОВИХ ТЕХНОЛОГІЙ, ІНЖЕНЕРІЇ ТА ІНФРАСТРУКТУРИ СЕРВІСУ
A2: ОДЕСЬКОГО НАЦІОНАЛЬНОГО ТЕХНОЛОГІЧНОГО УНІВЕРСИТЕТУ»
A3: ЗВЕДЕНА ВІДОМІСТЬ
A4: Успішності студентів спеціальності 185 «Нафтогазова інженерія та технології»
A5: За IІ семестр 2021-2022 н.р.
A6: Група 21-7 курс І
A7: Б/К | B7: № п/п | C7: Прізвище, ім’я по батькові | D7: Підсумкові оцінки дисциплін
D8: Астрономія Калюта Н.М. | E8: Біологія Леонова Д.І. | F8: Всесвітня історія Мельничук С.А. | G8: Географія Наговська Т.С. | H8: Зарубіжна література Пруднікова Я.П. | I8: ЗВ Черкашин А.Д. | J8: Іноземна мова Нічик Н.О. | K8: Інформатика Охримчук В.С. | L8: Історія України Левчук Т.Г. | M8: Математика Земляна Т.М. | N8: Українська література Нестеренко А.О. | O8: Українська мова Нестеренко А.О. | P8: Фізика Швець М.В. | Q8: Фізична культура Акрабова О.Г. | R8: Хімія Леонова Д.І. | S8: Середній бал
A11: Б | B11: 1 | C11: Аль-Фарра Давід Баширович | D11: 4 | E11: 4 | F11: 4 | G11: 4 | H11: 4 | I11: н/а | J11: 4 | K11: 5 | L11: 4 | M11: 4 | N11: 4 | O11: 5 | P11: 4 | Q11: н/а | R11: 4 | S11: =IF(COUNTIF(D11:R11,"=*")>0,"-",(AVERAGE(D11:R11))) -> -
A12: Б | B12: 2 | C12: Бакланов Михайло Віталійович | D12: н/а | E12: 4 | F12: 5 | G12: 4 | H12: 4 | I12: н/а | J12: 4 | K12: 4 | L12: н/а | M12: н/а | N12: 4 | O12: 5 | P12: 5 | Q12: 4 | R12: 5 | S12: =IF(COUNTIF(D12:R12,"=*")>0,"-",(AVERAGE(D12:R12))) -> -
A13: Б | B13: 3 | C13: Волошина Віолета Миколаївна | D13: 5 | E13: 5 | F13: 9 | G13: 7 | H13: 4 | I13: 9 | J13: 4 | K13: 6 | L13: н/а | M13: 4 | N13: 5 | O13: 5 | P13: 5 | Q13: 6 | R13: 5 | S13: =IF(COUNTIF(D13:R13,"=*")>0,"-",(AVERAGE(D13:R13))) -> -
A14: Б | B14: 4 | C14: Джасімов Масуд Оскарович | D14: 4 | E14: 4 | F14: 4 | G14: 7 | H14: 4 | I14: 9 | J14: 4 | K14: 5 | L14: н/а | M14: 4 | N14: 4 | O14: 4 | P14: 5 | Q14: 6 | R14: 4 | S14: =IF(COUNTIF(D14:R14,"=*")>0,"-",(AVERAGE(D14:R14))) -> -
A15: К | B15: 5 | C15: Ільясов Ільяс Азерович | D15: н/а | E15: 4 | F15: 4 | G15: 4 | H15: 4 | I15: н/а | J15: 4 | K15: н/а | L15: н/а | M15: н/а | N15: 4 | O15: 4 | P15: 4 | Q15: н/а | R15: 4 | S15: =IF(COUNTIF(D15:R15,"=*")>0,"-",(AVERAGE(D15:R15))) -> -
A16: К | B16: 6 | C16: Колосов Ілля Олександрович | D16: 9 | E16: 10 | F16: 10 | G16: 9 | H16: 5 | I16: 7 | J16: 9 | K16: 6 | L16: 8 | M16: 8 | N16: 7 | O16: 7 | P16: 10 | Q16: 9 | R16: 10 | S16: =IF(COUNTIF(D16:R16,"=*")>0,"-",(AVERAGE(D16:R16))) -> 8.2666667
A17: Б | B17: 7 | C17: Лисейко Іван Богданович | D17: 10 | E17: 9 | F17: 10 | G17: 10 | H17: 10 | I17: 9 | J17: 9 | K17: 10 | L17: 8 | M17: 7 | N17: 9 | O17: 9 | P17: 10 | Q17: 9 | R17: 9 | S17: =IF(COUNTIF(D17:R17,"=*")>0,"-",(AVERAGE(D17:R17))) -> 9.2
A18: Б | B18: 8 | C18: Новік Олексій Олексійович | D18: 9 | E18: 10 | F18: 10 | G18: 9 | H18: 9 | I18: 9 | J18: 9 | K18: 7 | L18: 8 | M18: 6 | N18: 8 | O18: 9 | P18: 9 | Q18: 10 | R18: 8 | S18: =IF(COUNTIF(D18:R18,"=*")>0,"-",(AVERAGE(D18:R18))) -> 8.6666667
A19: Б | B19: 9 | C19: Паскалов Микола Миколайов. | D19: 4 | E19: 5 | F19: 7 | G19: 8 | H19: 4 | I19: 4 | J19: 4 | K19: н/а | L19: н/а | M19: 4 | N19: 4 | O19: 5 | P19: 5 | Q19: 4 | R19: 5 | S19: =IF(COUNTIF(D19:R19,"=*")>0,"-",(AVERAGE(D19:R19))) -> -
A20: К | B20: 10 | C20: Попов Максим Данилович | D20: 5 | E20: 7 | F20: 9 | G20: 6 | H20: 4 | I20: 4 | J20: 4 | K20: 4 | L20: 4 | M20: 4 | N20: 8 | O20: 9 | P20: 7 | Q20: 6 | R20: 6 | S20: =IF(COUNTIF(D20:R20,"=*")>0,"-",(AVERAGE(D20:R20))) -> 5.8
A21: Б | B21: 11 | C21: Чебан Максим Павлович | D21: 4 | E21: 5 | F21: 9 | G21: 7 | H21: 4 | I21: н/а | J21: 4 | K21: 4 | L21: 5 | M21: 4 | N21: 6 | O21: 6 | P21: 4 | Q21: 7 | R21: 4 | S21: =IF(COUNTIF(D21:R21,"=*")>0,"-",(AVERAGE(D21:R21))) -> -
A22: Б | B22: 12 | C22: Чумак Мар’я Владиславівна | D22: н/а | E22: 6 | F22: 9 | G22: 4 | H22: 4 | I22: н/а | J22: 4 | K22: 4 | L22: н/а | M22: н/а | N22: 5 | O22: 6 | P22: 4 | Q22: н/а | R22: 5 | S22: =IF(COUNTIF(D22:R22,"=*")>0,"-",(AVERAGE(D22:R22))) -> -
A23: Б | B23: 13 | C23: Шевченко Олександр Володим. | D23: н/а | E23: н/а | F23: 4 | G23: 4 | H23: 4 | I23: н/а | J23: 4 | K23: н/а | L23: н/а | M23: н/а | N23: н/а | O23: н/а | P23: 4 | Q23: н/а | R23: н/а | S23: =IF(COUNTIF(D23:R23,"=*")>0,"-",(AVERAGE(D23:R23))) -> -
A24: Б | B24: 14 | C24: Ярмолович Данило Олегович | D24: 4 | E24: 8 | F24: 10 | G24: 7 | H24: 4 | I24: 6 | J24: 4 | K24: 4 | L24: 6 | M24: 4 | N24: 8 | O24: 7 | P24: 7 | Q24: 6 | R24: 5 | S24: =IF(COUNTIF(D24:R24,"=*")>0,"-",(AVERAGE(D24:R24))) -> 6
C25: Середній бал успішності з дисципліни | D25: =AVERAGE(D11:D24) -> 5.8 | E25: =AVERAGE(E11:E24) -> 6.2307692 | F25: =AVERAGE(F11:F24) -> 7.4285714 | G25: =AVERAGE(G11:G24) -> 6.4285714 | H25: =AVERAGE(H11:H24) -> 4.8571429 | I25: =AVERAGE(I11:I24) -> 7.125 | J25: =AVERAGE(J11:J24) -> 5.0714286 | K25: =AVERAGE(K11:K24) -> 5.3636364 | ... R25: =AVERAGE(R11:R24) -> 5.6923077 | S25: =IF(COUNTIF(D25:R25,"=*")>0,"-",(AVERAGE(D25:R25))) -> 5.9830519
C26: Абсолютна успішність | D26: =(COUNT(D11:D24))/(COUNT(B11:B24))*100 -> 71.428571 | E26: =(COUNT(E11:E24))/(COUNT(B11:B24))*100 -> 92.857143 | F26: =(COUNT(F11:F24))/(COUNT(B11:B24))*100 -> 100 | G26: =(COUNT(G11:G24))/(COUNT(B11:B24))*100 -> 100 | H26: =(COUNT(H11:H24))/(COUNT(B11:B24))*100 -> 100 | I26: =(COUNT(I11:I24))/(COUNT(B11:B24))*100 -> 57.142857 | J26: =(COUNT(J11:J24))/(COUNT(B11:B24))*100 -> 100 | K26: =(COUNT(K11:K24))/(COUNT(B11:B24))*100 -> 78.571429 | L26: =(COUNT(L11:L24))/(COUNT(B11:B24))*100 -> 50 | M26: =(COUNT(M11:M24))/(COUNT(B11:B24))*100 -> 71.428571 | N26: =(COUNT(N11:N24))/(COUNT(B11:B24))*100 -> 92.857143 | O26: =(COUNT(O11:O24))/(COUNT(B11:B24))*100 -> 92.857143 | P26: =(COUNT(P11:P24))/(COUNT(B11:B24))*100 -> 100 | Q26: =(COUNT(Q11:Q24))/(COUNT(B11:B24))*100 -> 71.428571 | R26: =(COUNT(R11:R24))/(COUNT(B11:B24))*100 -> 92.857143
C27: Якісна успішність | D27: =(COUNTIF(D11:D24,">=7"))/(COUNT(B11:B24))*100 -> 21.428571 | E27: =(COUNTIF(E11:E24,">=7"))/(COUNT(B11:B24))*100 -> 35.714286 | F27: =(COUNTIF(F11:F24,">=7"))/(COUNT(B11:B24))*100 -> 64.285714 | G27: =(COUNTIF(G11:G24,">=7"))/(COUNT(B11:B24))*100 -> 57.142857 | H27: =(COUNTIF(H11:H24,">=7"))/(COUNT(B11:B24))*100 -> 14.285714 | I27: =(COUNTIF(I11:I24,">=7"))/(COUNT(B11:B24))*100 -> 35.714286 | J27: =(COUNTIF(J11:J24,">=7"))/(COUNT(B11:B24))*100 -> 21.428571 | K27: =(COUNTIF(K11:K24,">=7"))/(COUNT(B11:B24))*100 -> 14.285714 | L27: =(COUNTIF(L11:L24,">=7"))/(COUNT(B11:B24))*100 -> 21.428571 | M27: =(COUNTIF(M11:M24,">=7"))/(COUNT(B11:B24))*100 -> 14.285714 | N27: =(COUNTIF(N11:N24,">=7"))/(COUNT(B11:B24))*100 -> 35.714286 | O27: =(COUNTIF(O11:O24,">=7"))/(COUNT(B11:B24))*100 -> 35.714286 | P27: =(COUNTIF(P11:P24,">=7"))/(COUNT(B11:B24))*100 -> 35.714286 | Q27: =(COUNTIF(Q11:Q24,">=7"))/(COUNT(B11:B24))*100 -> 28.571429 | R27: =(COUNTIF(R11:R24,">=7"))/(COUNT(B11:B24))*100 -> 21.428571
C28: Абсолютна успішність по групі | D28: =AVERAGE(D26:R26) -> 84.761905
C29: Якісна успішність по групі | D29: =AVERAGE(D27:R27) -> 30.47619
C30: Кількість бюджетників | D30: =COUNTIF(A11:A24,"=Б") -> 11
C31: Кількість контрактників | D31: =COUNTIF(A11:A24,"=К") -> 3 | G31: Класний керівник | N31: Марія ЖУРАВЛЬОВА
C32: Кількість соціального контингенту | D32: 1
C33: Вийшли на стипендію | D33: =INT(D30/100*40) -> 4 | G33: Завідувач відділення ПЗСО | N33: Маргарита БРІТІКОВА

Sheet Рейтингова відомість 172
A1: ВСП «ФАХОВИЙ КОЛЕДЖ НАФТОГАЗОВИХ ТЕХНОЛОГІЙ, ІНЖЕНЕРІЇ ТА ІНФРАСТРУКТУРИ СЕРВІСУ
A2: ОДЕСЬКОГО НАЦІОНАЛЬНОГО ТЕХНОЛОГІЧНОГО УНІВЕРСИТЕТУ»
A3: РЕЙТИНГОВА ВІДОМІСТЬ
A4: Успішності студентів спеціальності 172 «Телекомунікації та радіотехніка»
A5: За IІ семестр 2021-2022 н.р.
A6: Група 21-7 курс І
A7: Б/К | B7: № п/п | C7: Прізвище, ім’я по батькові | D7: Підсумкові оцінки дисциплін
D8: Астрономія Калюта Н.М. | E8: Біологія Леонова Д.І. | F8: Всесвітня історія Мельничук С.А. | G8: Географія Наговська Т.С. | H8: Зарубіжна література Пруднікова Я.П. | I8: ЗВ Черкашин А.Д. | J8: Іноземна мова Нічик Н.О. | K8: Інформатика Охримчук В.С. | L8: Історія України Левчук Т.Г. | M8: Математика Земляна Т.М. | N8: Українська література Нестеренко А.О. | O8: Українська мова Нестеренко А.О. | P8: Фізика Швець М.В. | Q8: Фізична культура Акрабова О.Г. | R8: Хімія Леонова Д.І. | S8: Середній бал | T8: Рейтинг
A11: Б | B11: 1 | C11: Туриця Дарія Олексіївна | D11: 11 | E11: 11 | F11: 10 | G11: 10 | H11: 10 | I11: 9 | J11: 8 | K11: 8 | L11: 8 | M11: 7 | N11: 10 | O11: 9 | P11: 10 | Q11: 10 | R11: 10 | S11: =AVERAGE(D11:R11) -> 9.4 | T11: =S11*90/12 -> 70.5
A12: Б | B12: 2 | C12: Єнчев Денис Сергійович | D12: 8 | E12: 10 | F12: 10 | G12: 9 | H12: 7 | I12: 8 | J12: 11 | K12: 8 | L12: 8 | M12: 7 | N12: 8 | O12: 6 | P12: 7 | Q12: 8 | R12: 8 | S12: =AVERAGE(D12:R12) -> 8.2 | T12: =S12*90/12 -> 61.5
A13: Б | B13: 3 | C13: Бальжик Даніель Сергійович | D13: 8 | E13: 8 | F13: 7 | G13: 8 | H13: 5 | I13: 7 | J13: 10 | K13: 9 | L13: 8 | M13: 4 | N13: 9 | O13: 8 | P13: 5 | Q13: 10 | R13: 8 | S13: =AVERAGE(D13:R13) -> 7.6 | T13: =S13*90/12 -> 57
A14: Б | B14: 4 | C14: Бурлака Михайло Аркадійович | D14: 6 | E14: 7 | F14: 10 | G14: 8 | H14: 4 | I14: 9 | J14: 7 | K14: 9 | L14: 7 | M14: 5 | N14: 5 | O14: 6 | P14: 6 | Q14: 10 | R14: 8 | S14: =AVERAGE(D14:R14) -> 7.1333333 | T14: =S14*90/12 -> 53.5
C15: Кількість бюджетників | D15: ='Зведена відомість 172'!D27 -> 9
C16: Кількість контрактників | D16: ='Зведена відомість 172'!D28 -> 2
C17: Кількість соціального контингенту | D17: ='Зведена відомість 172'!D29 -> 1
C18: Вийшли на стипендію | D18: ='Зведена відомість 172'!D30 -> 3 | G18: Класний керівник | N18: Марія ЖУРАВЛЬОВА
G20: Завідувач відділення ПЗСО | N20: Маргарита БРІТІКОВА
A69: =COUNTIF(A15:A29,"=Б") -> 0
A70: =COUNTIF(A15:A29,"=Б") -> 0
A71: =COUNTIF(A15:A29,"=Б") -> 0
A72: =COUNTIF(A15:A29,"=Б") -> 0
A73: =COUNTIF(A15:A29,"=Б") -> 0
A74: =COUNTIF(A15:A29,"=Б") -> 0
A75: =COUNTIF(A15:A29,"=Б") -> 0
A76: =COUNTIF(A15:A29,"=Б") -> 0
A77: =COUNTIF(A15:A29,"=Б") -> 0
A78: =COUNTIF(A15:A29,"=Б") -> 0
A79: =COUNTIF(A15:A29,"=Б") -> 0
A80: =COUNTIF(A15:A29,"=Б") -> 0
A81: =COUNTIF(A15:A29,"=Б") -> 0
A82: =COUNTIF(A15:A29,"=Б") -> 0
A83: =COUNTIF(A15:A29,"=Б") -> 0
A84: =COUNTIF(A15:A29,"=Б") -> 0
A85: =COUNTIF(A15:A29,"=Б") -> 0
A86: =COUNTIF(A15:A29,"=Б") -> 0
A87: =COUNTIF(A15:A29,"=Б") -> 0
A88: =COUNTIF(A15:A29,"=Б") -> 0
A89: =COUNTIF(A15:A29,"=Б") -> 0
A90: =COUNTIF(A15:A29,"=Б") -> 0
A91: =COUNTIF(A15:A29,"=Б") -> 0
...

Sheet Рейтингова відомість 185
A1: ВСП «ФАХОВИЙ КОЛЕДЖ НАФТОГАЗОВИХ ТЕХНОЛОГІЙ, ІНЖЕНЕРІЇ ТА ІНФРАСТРУКТУРИ СЕРВІСУ
A2: ОДЕСЬКОГО НАЦІОНАЛЬНОГО ТЕХНОЛОГІЧНОГО УНІВЕРСИТЕТУ»
A3: РЕЙТИНГОВА ВІДОМІСТЬ
A4: Успішності студентів спеціальності 185 «Нафтогазова інженерія та технологі»
A5: За IІ семестр 2021-2022 н.р.
A6: Група 21-7 курс І
A7: Б/К | B7: № п/п | C7: Прізвище, ім’я по батькові | D7: Підсумкові оцінки дисциплін
D8: Астрономія Калюта Н.М. | E8: Біологія Леонова Д.І. | F8: Всесвітня історія Мельничук С.А. | G8: Географія Наговська Т.С. | H8: Зарубіжна література Пруднікова Я.П. | I8: ЗВ Черкашин А.Д. | J8: Іноземна мова Нічик Н.О. | K8: Інформатика Охримчук В.С. | L8: Історія України Левчук Т.Г. | M8: Математика Земляна Т.М. | N8: Українська література Нестеренко А.О. | O8: Українська мова Нестеренко А.О. | P8: Фізика Швець М.В. | Q8: Фізична культура Акрабова О.Г. | R8: Хімія Леонова Д.І. | S8: Середній бал | T8: Рейтинг
A11: Б | B11: 1 | C11: Лисейко Іван Богданович | D11: 10 | E11: 9 | F11: 10 | G11: 10 | H11: 10 | I11: 9 | J11: 9 | K11: 10 | L11: 8 | M11: 7 | N11: 9 | O11: 9 | P11: 10 | Q11: 9 | R11: 9 | S11: =AVERAGE(D11:R11) -> 9.2 | T11: =S11*90/12 -> 69
A12: Б | B12: 2 | C12: Новік Олексій Олексійович | D12: 9 | E12: 10 | F12: 10 | G12: 9 | H12: 9 | I12: 9 | J12: 9 | K12: 7 | L12: 8 | M12: 6 | N12: 8 | O12: 9 | P12: 9 | Q12: 10 | R12: 8 | S12: =AVERAGE(D12:R12) -> 8.6666667 | T12: =S12*90/12 -> 65
A13: Б | B13: 3 | C13: Ярмолович Данило Олегович | D13: 4 | E13: 8 | F13: 10 | G13: 7 | H13: 4 | I13: 6 | J13: 4 | K13: 4 | L13: 6 | M13: 4 | N13: 8 | O13: 7 | P13: 7 | Q13: 6 | R13: 5 | S13: =AVERAGE(D13:R13) -> 6 | T13: =S13*90/12 -> 45
C14: Кількість бюджетників | D14: ='Зведена відомість 185'!D30 -> 11
C15: Кількість контрактників | D15: ='Зведена відомість 185'!D31 -> 3
C16: Кількість соціального контингенту | D16: ='Зведена відомість 185'!D32 -> 1
C17: Вийшли на стипендію | D17: ='Зведена відомість 185'!D33 -> 4 | G17: Класний керівник | N17: Марія ЖУРАВЛЬОВА
G19: Завідувач відділення ПЗСО | N19: Маргарита БРІТІКОВА
A68: =COUNTIF(A14:A28,"=Б") -> 0
A69: =COUNTIF(A14:A28,"=Б") -> 0
A70: =COUNTIF(A14:A28,"=Б") -> 0
A71: =COUNTIF(A14:A28,"=Б") -> 0
A72: =COUNTIF(A14:A28,"=Б") -> 0
A73: =COUNTIF(A14:A28,"=Б") -> 0
A74: =COUNTIF(A14:A28,"=Б") -> 0
A75: =COUNTIF(A14:A28,"=Б") -> 0
A76: =COUNTIF(A14:A28,"=Б") -> 0
A77: =COUNTIF(A14:A28,"=Б") -> 0
A78: =COUNTIF(A14:A28,"=Б") -> 0
A79: =COUNTIF(A14:A28,"=Б") -> 0
A80: =COUNTIF(A14:A28,"=Б") -> 0
A81: =COUNTIF(A14:A28,"=Б") -> 0
A82: =COUNTIF(A14:A28,"=Б") -> 0
A83: =COUNTIF(A14:A28,"=Б") -> 0
A84: =COUNTIF(A14:A28,"=Б") -> 0
A85: =COUNTIF(A14:A28,"=Б") -> 0
A86: =COUNTIF(A14:A28,"=Б") -> 0
A87: =COUNTIF(A14:A28,"=Б") -> 0
A88: =COUNTIF(A14:A28,"=Б") -> 0
A89: =COUNTIF(A14:A28,"=Б") -> 0
A90: =COUNTIF(A14:A28,"=Б") -> 0
A91: =COUNTIF(A14:A28,"=Б") -> 0
...
