Workbook
Name A1048577: #REF!
Name Ф80: #REF!

Sheet Зведена відомість 101
A1: ВСП «ФАХОВИЙ КОЛЕДЖ НАФТОГАЗОВИХ ТЕХНОЛОГІЙ, ІНЖЕНЕРІЇ ТА ІНФРАСТРУКТУРИ СЕРВІСУ
A2: ОДЕСЬКОГО НАЦІОНАЛЬНОГО ТЕХНОЛОГІЧНОГО УНІВЕРСИТЕТУ»
A3: ЗВЕДЕНА ВІДОМІСТЬ
A4: Успішності студентів спеціальності 101 «Екологія»
A5: За IІ семестр 2021-2022 н.р.
A6: Група 21-4 курс І
A7: Б/К | B7: № п/п | C7: Прізвище, ім’я по батькові | D7: Підсумкові оцінки дисциплін
D8: Астрономія Калюта Н.М. | E8: Біологія Богданенко О.В. | F8: Всесвітня історія Мельничук С.А. | G8: Географія Наговська Т.С. | H8: Зарубіжна література Пруднікова Я.П. | I8: ЗВ Черкашин А.Д. | J8: Іноземна мова Кубова Т.М. | K8: Інформатика Охримчук В.С. | L8: Історія України Левчук Т.Г. | M8: Математика Земляна Т.М. | N8: Українська література Грубіна О.П. | O8: Українська мова Грубіна О.П. | P8: Фізика Калюта Н.М. | Q8: Фізична культура Галеніна І.С. | R8: Хімія Сахно Н.О. | S8: Середній бал
A11: К | B11: 1 | C11: Абабіна Ірина Олександрівна | D11: 4 | E11: 4 | F11: 10 | G11: 8 | H11: 5 | I11: н/а | J11: 5 | K11: 7 | L11: 5 | M11: 4 | N11: 4 | O11: 5 | P11: 4 | Q11: 6 | R11: 4 | S11: =IF(COUNTIF(D11:R11,"=*")>0,"-",(AVERAGE(D11:R11))) -> -
A12: Б | B12: 2 | C12: Варьоха Вероніка Андріївна | D12: 10 | E12: 10 | F12: 10 | G12: 9 | H12: 11 | I12: 10 | J12: 10 | K12: 9 | L12: 9 | M12: 7 | N12: 8 | O12: 8 | P12: 10 | Q12: 10 | R12: 8 | S12: =IF(COUNTIF(D12:R12,"=*")>0,"-",(AVERAGE(D12:R12))) -> 9.2666667
A13: Б | B13: 3 | C13: Дорошук Олена Володимирівна | D13: 9 | E13: 10 | F13: 10 | G13: 10 | H13: 8 | I13: 10 | J13: 11 | K13: 9 | L13: 9 | M13: 8 | N13: 9 | O13: 7 | P13: 9 | Q13: 8 | R13: 8 | S13: =IF(COUNTIF(D13:R13,"=*")>0,"-",(AVERAGE(D13:R13))) -> 9
A14: К | B14: 4 | C14: Жуковська Олександра Олександрівна | D14: 8 | E14: 8 | F14: 7 | G14: 8 | H14: 6 | I14: 8 | J14: 6 | K14: 7 | L14: 5 | M14: 5 | N14: 7 | O14: 6 | P14: 7 | Q14: 9 | R14: 7 | S14: =IF(COUNTIF(D14:R14,"=*")>0,"-",(AVERAGE(D14:R14))) -> 6.9333333
A15: Б | B15: 5 | C15: Карпенко Анна Сергіївна | D15: 10 | E15: 9 | F15: 10 | G15: 10 | H15: 11 | I15: 10 | J15: 8 | K15: 10 | L15: 9 | M15: 9 | N15: 8 | O15: 8 | P15: 10 | Q15: 11 | R15: 8 | S15: =IF(COUNTIF(D15:R15,"=*")>0,"-",(AVERAGE(D15:R15))) -> 9.4
A16: К | B16: 6 | C16: Катуніна Валерія Євгенівна | D16: 9 | E16: 10 | F16: 10 | G16: 10 | H16: 10 | I16: 9 | J16: 10 | K16: 7 | L16: 8 | M16: 6 | N16: 10 | O16: 9 | P16: 8 | Q16: 11 | R16: 8 | S16: =IF(COUNTIF(D16:R16,"=*")>0,"-",(AVERAGE(D16:R16))) -> 9
A17: К | B17: 7 | C17: Ковальов Максим Олегович | D17: н/а | E17: 4 | F17: 8 | G17: 6 | H17: 5 | I17: н/а | J17: 4 | K17: 4 | L17: 4 | M17: н/а | N17: 4 | O17: 4 | P17: н/а | Q17: 4 | R17: н/а | S17: =IF(COUNTIF(D17:R17,"=*")>0,"-",(AVERAGE(D17:R17))) -> -
A18: К | B18: 8 | C18: Козуб Станіслав Валентинович | D18: 4 | E18: 5 | F18: 8 | G18: 6 | H18: 7 | I18: 4 | J18: 6 | K18: 5 | L18: 5 | M18: 4 | N18: 4 | O18: 4 | P18: 4 | Q18: 7 | R18: 4 | S18: =IF(COUNTIF(D18:R18,"=*")>0,"-",(AVERAGE(D18:R18))) -> 5.1333333
A19: Б | B19: 9 | C19: Максимова Віолетта Олександрівна | D19: 8 | E19: 10 | F19: 10 | G19: 10 | H19: 10 | I19: 9 | J19: 10 | K19: 9 | L19: 8 | M19: 7 | N19: 9 | O19: 9 | P19: 9 | Q19: 11 | R19: 8 | S19: =IF(COUNTIF(D19:R19,"=*")>0,"-",(AVERAGE(D19:R19))) -> 9.1333333
A20: Б | B20: 10 | C20: Михайленко Марія Вячесавівн | D20: 5 | E20: 7 | F20: 10 | G20: 10 | H20: 9 | I20: н/а | J20: 7 | K20: 7 | L20: 6 | M20: н/а | N20: 7 | O20: 7 | P20: 4 | Q20: 5 | R20: 4 | S20: =IF(COUNTIF(D20:R20,"=*")>0,"-",(AVERAGE(D20:R20))) -> -
A21: Б | B21: 11 | C21: Нєдов Ярослав Васильович | D21: 10 | E21: 9 | F21: 10 | G21: 10 | H21: 8 | I21: 10 | J21: 8 | K21: 10 | L21: 7 | M21: 8 | N21: 8 | O21: 7 | P21: 10 | Q21: 7 | R21: 9 | S21: =IF(COUNTIF(D21:R21,"=*")>0,"-",(AVERAGE(D21:R21))) -> 8.7333333
A22: Б | B22: 12 | C22: Петренко Софія Сергіївна | D22: 11 | E22: 11 | F22: 10 | G22: 10 | H22: 11 | I22: 10 | J22: 10 | K22: 10 | L22: 10 | M22: 10 | N22: 10 | O22: 10 | P22: 10 | Q22: 11 | R22: 10 | S22: =IF(COUNTIF(D22:R22,"=*")>0,"-",(AVERAGE(D22:R22))) -> 10.266667
A23: Б | B23: 13 | C23: Ротар Софія Василівна | D23: 4 | E23: 9 | F23: 10 | G23: 8 | H23: 9 | I23: 6 | J23: 6 | K23: 7 | L23: 6 | M23: 4 | N23: 7 | O23: 7 | P23: 4 | Q23: 9 | R23: 4 | S23: =IF(COUNTIF(D23:R23,"=*")>0,"-",(AVERAGE(D23:R23))) -> 6.6666667
A24: Б | B24: 14 | C24: Хемій Мирослава Василівна | D24: 7 | E24: 8 | F24: 10 | G24: 10 | H24: 8 | I24: 9 | J24: 9 | K24: 8 | L24: 7 | M24: 5 | N24: 7 | O24: 7 | P24: 8 | Q24: 7 | R24: 8 | S24: =IF(COUNTIF(D24:R24,"=*")>0,"-",(AVERAGE(D24:R24))) -> 7.8666667
A25: Б | B25: 15 | C25: Храмченкова Єва Сергіївна | D25: 6 | E25: 6 | F25: 10 | G25: 8 | H25: 8 | I25: 7 | J25: 6 | K25: 8 | L25: 6 | M25: 4 | N25: 4 | O25: 4 | P25: 7 | Q25: 6 | R25: 7 | S25: =IF(COUNTIF(D25:R25,"=*")>0,"-",(AVERAGE(D25:R25))) -> 6.4666667
C26: Середній бал успішності з дисципліни | D26: =AVERAGE(D11:D25) -> 7.5 | E26: =AVERAGE(E11:E25) -> 8 | F26: =AVERAGE(F11:F25) -> 9.5333333 | G26: =AVERAGE(G11:G25) -> 8.8666667 | H26: =AVERAGE(H11:H25) -> 8.4 | I26: =AVERAGE(I11:I25) -> 8.5 | J26: =AVERAGE(J11:J25) -> 7.7333333 | K26: =AVERAGE(K11:K25) -> 7.8 | ... R26: =AVERAGE(R11:R25) -> 6.9285714 | S26: =IF(COUNTIF(D26:R26,"=*")>0,"-",(AVERAGE(D26:R26))) -> 7.7236386
C27: Абсолютна успішність | D27: =(COUNT(D11:D25))/(COUNT(B11:B25))*100 -> 93.333333 | E27: =(COUNT(E11:E25))/(COUNT(B11:B25))*100 -> 100 | F27: =(COUNT(F11:F25))/(COUNT(B11:B25))*100 -> 100 | G27: =(COUNT(G11:G25))/(COUNT(B11:B25))*100 -> 100 | H27: =(COUNT(H11:H25))/(COUNT(B11:B25))*100 -> 100 | I27: =(COUNT(I11:I25))/(COUNT(B11:B25))*100 -> 80 | J27: =(COUNT(J11:J25))/(COUNT(B11:B25))*100 -> 100 | K27: =(COUNT(K11:K25))/(COUNT(B11:B25))*100 -> 100 | L27: =(COUNT(L11:L25))/(COUNT(B11:B25))*100 -> 100 | M27: =(COUNT(M11:M25))/(COUNT(B11:B25))*100 -> 86.666667 | N27: =(COUNT(N11:N25))/(COUNT(B11:B25))*100 -> 100 | O27: =(COUNT(O11:O25))/(COUNT(B11:B25))*100 -> 100 | P27: =(COUNT(P11:P25))/(COUNT(B11:B25))*100 -> 93.333333 | Q27: =(COUNT(Q11:Q25))/(COUNT(B11:B25))*100 -> 100 | R27: =(COUNT(R11:R25))/(COUNT(B11:B25))*100 -> 93.333333
C28: Якісна успішність | D28: =(COUNTIF(D11:D25,">=7"))/(COUNT(B11:B25))*100 -> 60 | E28: =(COUNTIF(E11:E25,">=7"))/(COUNT(B11:B25))*100 -> 73.333333 | F28: =(COUNTIF(F11:F25,">=7"))/(COUNT(B11:B25))*100 -> 100 | G28: =(COUNTIF(G11:G25,">=7"))/(COUNT(B11:B25))*100 -> 86.666667 | H28: =(COUNTIF(H11:H25,">=7"))/(COUNT(B11:B25))*100 -> 80 | I28: =(COUNTIF(I11:I25,">=7"))/(COUNT(B11:B25))*100 -> 66.666667 | J28: =(COUNTIF(J11:J25,">=7"))/(COUNT(B11:B25))*100 -> 60 | K28: =(COUNTIF(K11:K25,">=7"))/(COUNT(B11:B25))*100 -> 86.666667 | L28: =(COUNTIF(L11:L25,">=7"))/(COUNT(B11:B25))*100 -> 53.333333 | M28: =(COUNTIF(M11:M25,">=7"))/(COUNT(B11:B25))*100 -> 40 | N28: =(COUNTIF(N11:N25,">=7"))/(COUNT(B11:B25))*100 -> 73.333333 | O28: =(COUNTIF(O11:O25,">=7"))/(COUNT(B11:B25))*100 -> 66.666667 | P28: =(COUNTIF(P11:P25,">=7"))/(COUNT(B11:B25))*100 -> 66.666667 | Q28: =(COUNTIF(Q11:Q25,">=7"))/(COUNT(B11:B25))*100 -> 73.333333 | R28: =(COUNTIF(R11:R25,">=7"))/(COUNT(B11:B25))*100 -> 66.666667
C29: Абсолютна успішність по групі | D29: =AVERAGE(D27:R27) -> 96.444444
C30: Якісна успішність по групі | D30: =AVERAGE(D28:R28) -> 70.222222
C31: Кількість бюджетників | D31: =COUNTIF(A11:A25,"=Б") -> 10
C32: Кількість контрактників | D32: =COUNTIF(A11:A25,"=К") -> 5 | G32: Класний керівник | N32: Ярослава ПРУДНІКОВА
C33: Кількість соціального контингенту | D33: 1
C34: Вийшли на стипендію | D34: =INT(D31/100*40) -> 4 | G34: Завідувач відділення ПЗСО | N34: Маргарита БРІТІКОВА

Sheet Зведена відомість 161
A1: ВСП «ФАХОВИЙ КОЛЕДЖ НАФТОГАЗОВИХ ТЕХНОЛОГІЙ, ІНЖЕНЕРІЇ ТА ІНФРАСТРУКТУРИ СЕРВІСУ
A2: ОДЕСЬКОГО НАЦІОНАЛЬНОГО ТЕХНОЛОГІЧНОГО УНІВЕРСИТЕТУ»
A3: ЗВЕДЕНА ВІДОМІСТЬ
A4: Успішності студентів спеціальності 161 «Хімічні технології та інженерія»
A5: За IІ семестр 2021-2022 н.р.
A6: Група 21-4 курс І
A7: Б/К | B7: № п/п | C7: Прізвище, ім’я по батькові | D7: Підсумкові оцінки дисциплін
D8: Астрономія Калюта Н.М. | E8: Біологія Богданенко О.В. | F8: Всесвітня історія Мельничук С.А. | G8: Географія Наговська Т.С. | H8: Зарубіжна література Пруднікова Я.П. | I8: ЗВ Черкашин А.Д. | J8: Іноземна мова Кубова Т.М. | K8: Інформатика Охримчук В.С. | L8: Історія України Левчук Т.Г. | M8: Математика Земляна Т.М. | N8: Українська література Грубіна О.П. | O8: Українська мова Грубіна О.П. | P8: Фізика Калюта Н.М. | Q8: Фізична культура Галеніна І.С. | R8: Хімія Сахно Н.О. | S8: Середній бал
A11: К | B11: 1 | C11: Беспалько В’ячеслав Геннадійович | D11: 4 | E11: 4 | F11: 6 | G11: 5 | H11: 5 | I11: н/а | J11: 4 | K11: 4 | L11: 5 | M11: н/а | N11: 4 | O11: 4 | P11: 2 | Q11: 5 | R11: 4 | S11: =IF(COUNTIF(D11:R11,"=*")>0,"-",(AVERAGE(D11:R11))) -> -
A12: Б | B12: 2 | C12: Білий Ніл Олександрович | D12: 3 | E12: 5 | F12: 10 | G12: 7 | H12: 6 | I12: н/а | J12: 7 | K12: 4 | L12: 5 | M12: н/а | N12: 5 | O12: 5 | P12: н/а | Q12: 5 | R12: 4 | S12: =IF(COUNTIF(D12:R12,"=*")>0,"-",(AVERAGE(D12:R12))) -> -
A13: Б | B13: 3 | C13: Будко Володимир Володимирович | D13: 2 | E13: 5 | F13: 10 | G13: 7 | H13: 5 | I13: 5 | J13: 4 | K13: 5 | L13: н/а | M13: 4 | N13: 4 | O13: 4 | P13: 2 | Q13: 5 | R13: 5 | S13: =IF(COUNTIF(D13:R13,"=*")>0,"-",(AVERAGE(D13:R13))) -> -
A14: Б | B14: 4 | C14: Гайдаржи Олександр Микол. | D14: н/а | E14: н/а | F14: 5 | G14: 4 | H14: 4 | I14: н/а | J14: н/а | K14: н/а | L14: н/а | M14: н/а | N14: н/а | O14: н/а | P14: н/а | Q14: 6 | R14: н/а | S14: =IF(COUNTIF(D14:R14,"=*")>0,"-",(AVERAGE(D14:R14))) -> -
A15: Б | B15: 5 | C15: Дімітрова Василіка Віталіївна | D15: 11 | E15: 11 | F15: 10 | G15: 11 | H15: 11 | I15: 10 | J15: 11 | K15: 10 | L15: 10 | M15: 10 | N15: 11 | O15: 10 | P15: 10 | Q15: 11 | R15: 10 | S15: =IF(COUNTIF(D15:R15,"=*")>0,"-",(AVERAGE(D15:R15))) -> 10.466667
A16: Б | B16: 6 | C16: Казанджій Богдан Миколайович | D16: н/а | E16: 4 | F16: 6 | G16: 4 | H16: 5 | I16: н/а | J16: 4 | K16: 4 | L16: н/а | M16: н/а | N16: 4 | O16: 4 | P16: н/а | Q16: 4 | R16: 4 | S16: =IF(COUNTIF(D16:R16,"=*")>0,"-",(AVERAGE(D16:R16))) -> -
A17: Б | B17: 7 | C17: Калінку Дарія Андріївна | D17: н/а | E17: н/а | F17: н/а | G17: 4 | H17: н/а | I17: н/а | J17: н/а | K17: н/а | L17: н/а | M17: н/а | N17: н/а | O17: н/а | P17: н/а | Q17: 5 | R17: н/а | S17: =IF(COUNTIF(D17:R17,"=*")>0,"-",(AVERAGE(D17:R17))) -> -
A18: Б | B18: 8 | C18: Мешкова Вікторія Ігорівна | D18: 3 | E18: 4 | F18: 6 | G18: 6 | H18: 5 | I18: н/а | J18: 4 | K18: 4 | L18: н/а | M18: 4 | N18: 4 | O18: 4 | P18: 4 | Q18: 5 | R18: н/а | S18: =IF(COUNTIF(D18:R18,"=*")>0,"-",(AVERAGE(D18:R18))) -> -
A19: Б | B19: 9 | C19: Пасічник Артем Сергійович | D19: 8 | E19: 6 | F19: 10 | G19: 8 | H19: 7 | I19: 6 | J19: 4 | K19: 5 | L19: 7 | M19: 4 | N19: 5 | O19: 4 | P19: 8 | Q19: 7 | R19: 7 | S19: =IF(COUNTIF(D19:R19,"=*")>0,"-",(AVERAGE(D19:R19))) -> 6.4
A20: Б | B20: 10 | C20: Салтанова Катерина Ігорівна | D20: н/а | E20: 6 | F20: 10 | G20: 6 | H20: 5 | I20: 6 | J20: 4 | K20: 9 | L20: 5 | M20: 4 | N20: 4 | O20: 4 | P20: 4 | Q20: 5 | R20: 6 | S20: =IF(COUNTIF(D20:R20,"=*")>0,"-",(AVERAGE(D20:R20))) -> -
A21: Б | B21: 11 | C21: Цуканов Іван Павлович | D21: 8 | E21: 9 | F21: 10 | G21: 9 | H21: 10 | I21: 7 | J21: 8 | K21: 6 | L21: 8 | M21: 7 | N21: 9 | O21: 7 | P21: 7 | Q21: 11 | R21: 7 | S21: =IF(COUNTIF(D21:R21,"=*")>0,"-",(AVERAGE(D21:R21))) -> 8.2
C22: Середній бал успішності з дисципліни | D22: =AVERAGE(D11:D21) -> 5.5714286 | E22: =AVERAGE(E11:E21) -> 6 | F22: =AVERAGE(F11:F21) -> 8.3 | G22: =AVERAGE(G11:G21) -> 6.4545455 | H22: =AVERAGE(H11:H21) -> 6.3 | I22: =AVERAGE(I11:I21) -> 6.8 | J22: =AVERAGE(J11:J21) -> 5.5555556 | K22: =AVERAGE(K11:K21) -> 5.6666667 | ... R22: =AVERAGE(R11:R21) -> 5.875 | S22: =IF(COUNTIF(D22:R22,"=*")>0,"-",(AVERAGE(D22:R22))) -> 6.0609981
C23: Абсолютна успішність | D23: =(COUNT(D11:D21))/(COUNT(B11:B21))*100 -> 63.636364 | E23: =(COUNT(E11:E21))/(COUNT(B11:B21))*100 -> 81.818182 | F23: =(COUNT(F11:F21))/(COUNT(B11:B21))*100 -> 90.909091 | G23: =(COUNT(G11:G21))/(COUNT(B11:B21))*100 -> 100 | H23: =(COUNT(H11:H21))/(COUNT(B11:B21))*100 -> 90.909091 | I23: =(COUNT(I11:I21))/(COUNT(B11:B21))*100 -> 45.454545 | J23: =(COUNT(J11:J21))/(COUNT(B11:B21))*100 -> 81.818182 | K23: =(COUNT(K11:K21))/(COUNT(B11:B21))*100 -> 81.818182 | L23: =(COUNT(L11:L21))/(COUNT(B11:B21))*100 -> 54.545455 | M23: =(COUNT(M11:M21))/(COUNT(B11:B21))*100 -> 54.545455 | N23: =(COUNT(N11:N21))/(COUNT(B11:B21))*100 -> 81.818182 | O23: =(COUNT(O11:O21))/(COUNT(B11:B21))*100 -> 81.818182 | P23: =(COUNT(P11:P21))/(COUNT(B11:B21))*100 -> 63.636364 | Q23: =(COUNT(Q11:Q21))/(COUNT(B11:B21))*100 -> 100 | R23: =(COUNT(R11:R21))/(COUNT(B11:B21))*100 -> 72.727273
C24: Якісна успішність | D24: =(COUNTIF(D11:D21,">=7"))/(COUNT(B11:B21))*100 -> 27.272727 | E24: =(COUNTIF(E11:E21,">=7"))/(COUNT(B11:B21))*100 -> 18.181818 | F24: =(COUNTIF(F11:F21,">=7"))/(COUNT(B11:B21))*100 -> 54.545455 | G24: =(COUNTIF(G11:G21,">=7"))/(COUNT(B11:B21))*100 -> 45.454545 | H24: =(COUNTIF(H11:H21,">=7"))/(COUNT(B11:B21))*100 -> 27.272727 | I24: =(COUNTIF(I11:I21,">=7"))/(COUNT(B11:B21))*100 -> 18.181818 | J24: =(COUNTIF(J11:J21,">=7"))/(COUNT(B11:B21))*100 -> 27.272727 | K24: =(COUNTIF(K11:K21,">=7"))/(COUNT(B11:B21))*100 -> 18.181818 | L24: =(COUNTIF(L11:L21,">=7"))/(COUNT(B11:B21))*100 -> 27.272727 | M24: =(COUNTIF(M11:M21,">=7"))/(COUNT(B11:B21))*100 -> 18.181818 | N24: =(COUNTIF(N11:N21,">=7"))/(COUNT(B11:B21))*100 -> 18.181818 | O24: =(COUNTIF(O11:O21,">=7"))/(COUNT(B11:B21))*100 -> 18.181818 | P24: =(COUNTIF(P11:P21,">=7"))/(COUNT(B11:B21))*100 -> 27.272727 | Q24: =(COUNTIF(Q11:Q21,">=7"))/(COUNT(B11:B21))*100 -> 27.272727 | R24: =(COUNTIF(R11:R21,">=7"))/(COUNT(B11:B21))*100 -> 27.272727
C25: Абсолютна успішність по групі | D25: =AVERAGE(D23:R23) -> 76.363636
C26: Якісна успішність по групі | D26: =AVERAGE(D24:R24) -> 26.666667
C27: Кількість бюджетників | D27: =COUNTIF(A11:A21,"=Б") -> 10
C28: Кількість контрактників | D28: =COUNTIF(A11:A21,"=К") -> 1 | G28: Класний керівник | N28: Ярослава ПРУДНІКОВА
C29: Кількість соціального контингенту | D29: 0
C30: Вийшли на стипендію | D30: =INT(D27/100*40) -> 4 | G30: Завідувач відділення ПЗСО | N30: Маргарита БРІТІКОВА

Sheet Рейтингова відомість 101
A1: ВСП «ФАХОВИЙ КОЛЕДЖ НАФТОГАЗОВИХ ТЕХНОЛОГІЙ, ІНЖЕНЕРІЇ ТА ІНФРАСТРУКТУРИ СЕРВІСУ
A2: ОДЕСЬКОГО НАЦІОНАЛЬНОГО ТЕХНОЛОГІЧНОГО УНІВЕРСИТЕТУ»
A3: РЕЙТИНГОВА ВІДОМІСТЬ
A4: Успішності студентів спеціальності 101 «Екологія»
A5: За IІ семестр 2021-2022 н.р.
A6: Група 21-4 курс І
A7: Б/К | B7: № п/п | C7: Прізвище, ім’я по батькові | D7: Підсумкові оцінки дисциплін
D8: Астрономія Калюта Н.М. | E8: Біологія Богданенко О.В. | F8: Всесвітня історія Мельничук С.А. | G8: Географія Наговська Т.С. | H8: Зарубіжна література Пруднікова Я.П. | I8: ЗВ Черкашин А.Д. | J8: Іноземна мова Кубова Т.М. | K8: Інформатика Охримчук В.С. | L8: Історія України Левчук Т.Г. | M8: Математика Земляна Т.М. | N8: Українська література Грубіна О.П. | O8: Українська мова Грубіна О.П. | P8: Фізика Калюта Н.М. | Q8: Фізична культура Галеніна І.С. | R8: Хімія Сахно Н.О. | S8: Середній бал | T8: Рейтинг
A11: Б | B11: 1 | C11: Петренко Софія Сергіївна | D11: 11 | E11: 11 | F11: 10 | G11: 10 | H11: 11 | I11: 10 | J11: 10 | K11: 10 | L11: 10 | M11: 10 | N11: 10 | O11: 10 | P11: 10 | Q11: 11 | R11: 10 | S11: =AVERAGE(D11:R11) -> 10.266667 | T11: =S11*90/12 -> 77
A12: Б | B12: 2 | C12: Карпенко Анна Сергіївна | D12: 10 | E12: 9 | F12: 10 | G12: 10 | H12: 11 | I12: 10 | J12: 8 | K12: 10 | L12: 9 | M12: 9 | N12: 8 | O12: 8 | P12: 10 | Q12: 11 | R12: 8 | S12: =AVERAGE(D12:R12) -> 9.4 | T12: =S12*90/12 -> 70.5
A13: Б | B13: 3 | C13: Варьоха Вероніка Андріївна | D13: 10 | E13: 10 | F13: 10 | G13: 9 | H13: 11 | I13: 10 | J13: 10 | K13: 9 | L13: 9 | M13: 7 | N13: 8 | O13: 8 | P13: 10 | Q13: 10 | R13: 8 | S13: =AVERAGE(D13:R13) -> 9.2666667 | T13: =S13*90/12 -> 69.5
A14: Б | B14: 4 | C14: Максимова Віолетта Олександрівна | D14: 8 | E14: 10 | F14: 10 | G14: 10 | H14: 10 | I14: 9 | J14: 10 | K14: 9 | L14: 8 | M14: 7 | N14: 9 | O14: 9 | P14: 9 | Q14: 11 | R14: 8 | S14: =AVERAGE(D14:R14) -> 9.1333333 | T14: =S14*90/12 -> 68.5
A15: Б | B15: 5 | C15: Дорошук Олена Володимирівна | D15: 9 | E15: 10 | F15: 10 | G15: 10 | H15: 8 | I15: 10 | J15: 11 | K15: 9 | L15: 9 | M15: 8 | N15: 9 | O15: 7 | P15: 9 | Q15: 8 | R15: 8 | S15: =AVERAGE(D15:R15) -> 9 | T15: =S15*90/12 -> 67.5
A16: Б | B16: 6 | C16: Нєдов Ярослав Васильович | D16: 10 | E16: 9 | F16: 10 | G16: 10 | H16: 8 | I16: 10 | J16: 8 | K16: 10 | L16: 7 | M16: 8 | N16: 8 | O16: 7 | P16: 10 | Q16: 7 | R16: 9 | S16: =AVERAGE(D16:R16) -> 8.7333333 | T16: =S16*90/12 -> 65.5
A17: Б | B17: 7 | C17: Хемій Мирослава Василівна | D17: 7 | E17: 8 | F17: 10 | G17: 10 | H17: 8 | I17: 9 | J17: 9 | K17: 8 | L17: 7 | M17: 5 | N17: 7 | O17: 7 | P17: 8 | Q17: 7 | R17: 8 | S17: =AVERAGE(D17:R17) -> 7.8666667 | T17: =S17*90/12 -> 59
A18: Б | B18: 8 | C18: Ротар Софія Василівна | D18: 4 | E18: 9 | F18: 10 | G18: 8 | H18: 9 | I18: 6 | J18: 6 | K18: 7 | L18: 6 | M18: 4 | N18: 7 | O18: 7 | P18: 4 | Q18: 9 | R18: 4 | S18: =AVERAGE(D18:R18) -> 6.6666667 | T18: =S18*90/12 -> 50
A19: Б | B19: 9 | C19: Храмченкова Єва Сергіївна | D19: 6 | E19: 6 | F19: 10 | G19: 8 | H19: 8 | I19: 7 | J19: 6 | K19: 8 | L19: 6 | M19: 4 | N19: 4 | O19: 4 | P19: 7 | Q19: 6 | R19: 7 | S19: =AVERAGE(D19:R19) -> 6.4666667 | T19: =S19*90/12 -> 48.5
C20: Кількість бюджетників | D20: ='Зведена відомість 101'!D31 -> 10
C21: Кількість контрактників | D21: ='Зведена відомість 101'!D32 -> 5 | G21: Класний керівник | N21: Ярослава ПРУДНІКОВА
C22: Кількість соціального контингенту | D22: ='Зведена відомість 101'!D33 -> 1
C23: Вийшли на стипендію | D23: ='Зведена відомість 101'!D34 -> 4 | G23: Завідувач відділення ПЗСО | N23: Маргарита БРІТІКОВА
A79: =COUNTIF(A20:A39,"=Б") -> 0
A80: =COUNTIF(A20:A39,"=Б") -> 0
A81: =COUNTIF(A20:A39,"=Б") -> 0
A82: =COUNTIF(A20:A39,"=Б") -> 0
A83: =COUNTIF(A20:A39,"=Б") -> 0
A84: =COUNTIF(A20:A39,"=Б") -> 0
A85: =COUNTIF(A20:A39,"=Б") -> 0
A86: =COUNTIF(A20:A39,"=Б") -> 0
A87: =COUNTIF(A20:A39,"=Б") -> 0
A88: =COUNTIF(A20:A39,"=Б") -> 0
A89: =COUNTIF(A20:A39,"=Б") -> 0
A90: =COUNTIF(A20:A39,"=Б") -> 0
A91: =COUNTIF(A20:A39,"=Б") -> 0
A92: =COUNTIF(A20:A39,"=Б") -> 0
A93: =COUNTIF(A20:A39,"=Б") -> 0
A94: =COUNTIF(A20:A39,"=Б") -> 0
A95: =COUNTIF(A20:A39,"=Б") -> 0
A96: =COUNTIF(A20:A39,"=Б") -> 0
A97: =COUNTIF(A20:A39,"=Б") -> 0
...

Sheet Рейтингова відомість 161
A1: ВСП «ФАХОВИЙ КОЛЕДЖ НАФТОГАЗОВИХ ТЕХНОЛОГІЙ, ІНЖЕНЕРІЇ ТА ІНФРАСТРУКТУРИ СЕРВІСУ
A2: ОДЕСЬКОГО НАЦІОНАЛЬНОГО ТЕХНОЛОГІЧНОГО УНІВЕРСИТЕТУ»
A3: РЕЙТИНГОВА ВІДОМІСТЬ
A4: Успішності студентів спеціальності 161 «Хімічні технології та інженерія»
A5: За IІ семестр 2021-2022 н.р.
A6: Група 21-4 курс І
A7: Б/К | B7: № п/п | C7: Прізвище, ім’я по батькові | D7: Підсумкові оцінки дисциплін
D8: Астрономія Калюта Н.М. | E8: Біологія Богданенко О.В. | F8: Всесвітня історія Мельничук С.А. | G8: Географія Наговська Т.С. | H8: Зарубіжна література Пруднікова Я.П. | I8: ЗВ Черкашин А.Д. | J8: Іноземна мова Кубова Т.М. | K8: Інформатика Охримчук В.С. | L8: Історія України Левчук Т.Г. | M8: Математика Земляна Т.М. | N8: Українська література Грубіна О.П. | O8: Українська мова Грубіна О.П. | P8: Фізика Калюта Н.М. | Q8: Фізична культура Галеніна І.С. | R8: Хімія Сахно Н.О. | S8: Середній бал | T8: Рейтинг
A11: Б | B11: 1 | C11: Дімітрова Василіка Віталіївна | D11: 11 | E11: 11 | F11: 10 | G11: 11 | H11: 11 | I11: 10 | J11: 11 | K11: 10 | L11: 10 | M11: 10 | N11: 11 | O11: 10 | P11: 10 | Q11: 11 | R11: 10 | S11: =AVERAGE(D11:R11) -> 10.466667 | T11: =S11*90/12 -> 78.5
A12: Б | B12: 2 | C12: Цуканов Іван Павлович | D12: 8 | E12: 9 | F12: 10 | G12: 9 | H12: 10 | I12: 7 | J12: 8 | K12: 6 | L12: 8 | M12: 7 | N12: 9 | O12: 7 | P12: 7 | Q12: 11 | R12: 7 | S12: =AVERAGE(D12:R12) -> 8.2 | T12: =S12*90/12 -> 61.5
A13: Б | B13: 3 | C13: Пасічник Артем Сергійович | D13: 8 | E13: 6 | F13: 10 | G13: 8 | H13: 7 | I13: 6 | J13: 4 | K13: 5 | L13: 7 | M13: 4 | N13: 5 | O13: 4 | P13: 8 | Q13: 7 | R13: 7 | S13: =AVERAGE(D13:R13) -> 6.4 | T13: =S13*90/12 -> 48
C14: Кількість бюджетників | D14: ='Зведена відомість 161'!D27 -> 10
C15: Кількість контрактників | D15: ='Зведена відомість 161'!D28 -> 1 | G15: Класний керівник | N15: Ярослава ПРУДНІКОВА
C16: Кількість соціального контингенту | D16: ='Зведена відомість 161'!D29 -> 0
C17: Вийшли на стипендію | D17: ='Зведена відомість 161'!D30 -> 4 | G17: Завідувач відділення ПЗСО | N17: Маргарита БРІТІКОВА
A78: =COUNTIF(A14:A38,"=Б") -> 0
A79: =COUNTIF(A14:A38,"=Б") -> 0
A80: =COUNTIF(A14:A38,"=Б") -> 0
A81: =COUNTIF(A14:A38,"=Б") -> 0
A82: =COUNTIF(A14:A38,"=Б") -> 0
A83: =COUNTIF(A14:A38,"=Б") -> 0
A84: =COUNTIF(A14:A38,"=Б") -> 0
A85: =COUNTIF(A14:A38,"=Б") -> 0
A86: =COUNTIF(A14:A38,"=Б") -> 0
A87: =COUNTIF(A14:A38,"=Б") -> 0
A88: =COUNTIF(A14:A38,"=Б") -> 0
A89: =COUNTIF(A14:A38,"=Б") -> 0
A90: =COUNTIF(A14:A38,"=Б") -> 0
A91: =COUNTIF(A14:A38,"=Б") -> 0
A92: =COUNTIF(A14:A38,"=Б") -> 0
A93: =COUNTIF(A14:A38,"=Б") -> 0
A94: =COUNTIF(A14:A38,"=Б") -> 0
A95: =COUNTIF(A14:A38,"=Б") -> 0
A96: =COUNTIF(A14:A38,"=Б") -> 0
A97: =COUNTIF(A14:A38,"=Б") -> 0
A98: =COUNTIF(A14:A38,"=Б") -> 0
A99: =COUNTIF(A14:A38,"=Б") -> 0
A100: =COUNTIF(A14:A38,"=Б") -> 0
A101: =COUNTIF(A14:A38,"=Б") -> 0
A102: =COUNTIF(A14:A38,"=Б") -> 0
...
